Workbook
Name \0: #REF!
Name \0: #REF!
Name \a: #N/A
Name \b: #N/A
Name \g: #N/A
Name \n: #N/A
Name ________kop2: #REF!
Name ________s2: #REF!
Name ________SKF1: #REF!
Name ________SKF2: #REF!
Name _______kop2: #REF!
Name _______s2: #REF!
Name _______SKF1: #REF!
Name _______SKF2: #REF!
Name ______kop2: #REF!
Name ______s2: #REF!
Name ______SKF1: #REF!
Name ______SKF2: #REF!
Name _____kop2: #REF!
Name _____s2: #REF!
Name _____SKF1: #REF!
Name _____SKF2: #REF!
Name ____kop2: #REF!
Name ____s2: #REF!
Name ____SKF1: #REF!
Name ____SKF2: #REF!
Name ___kop2: #REF!
Name ___s2: #REF!
Name ___SKF1: #REF!
Name ___SKF2: #REF!
Name __123Graph_AGAE_2: '[1]data-hujan'!$E$8:$AC$8
Name __123Graph_BGAE_2: '[1]data-hujan'!$E$14:$AC$14
Name __123Graph_CGAE_2: '[1]data-hujan'!$E$15:$AC$15
Name __123Graph_DGAE_2: '[1]data-hujan'!$E$16:$AC$16
Name __123Graph_EGAE_2: '[1]data-hujan'!$E$17:$AC$17
Name __123Graph_FGAE_2: '[1]data-hujan'!$E$18:$K$18
Name __123Graph_XGAE_2: '[1]data-hujan'!$E$3:$AC$3
Name __kop2: #REF!
Name __kop2: #REF!
Name __s2: #REF!
Name __s2: #REF!
Name __SKF1: #REF!
Name __SKF1: #REF!
Name __SKF2: #REF!
Name __SKF2: #REF!
Name _0: #REF!
Name _0: #REF!
Name _0_1: #REF!
Name _0_1_1: "$#REF!.$S$1"
Name _0_1_1_1: "$#REF!.$S$1"
Name _0_1_1_1_1: "$#REF!.$S$1"
Name _0_1_1_1_1_1: "$#REF!.$S$1"
Name _10_b_1: #REF!
Name _10_b_1: #REF!
Name _11_g_1: #REF!
Name _11_g_1: #REF!
Name _12_n_1: #REF!
Name _12_n_1: #REF!
Name _129_n_1: #REF!
Name _13_A_1: #REF!

Sheet COVER
C6: RENCANA KERJA PROYEK
C7: PENANAMAN PASTURA
C20: PT FASS FOREST DEVELOPMENT
C22: Tahun 2026 - 2028

Sheet Instalasi Air
A2: KEBUTUHAN INSTALASI PENGAIRAN BIBITAN 35 Hektar | H2: 35
A3: No | B3: Material | C3: Kebutuhan | D3: Satuan | E3: Harga | F3: Total | G3: Grand Total
A4: 1 | B4: Sumisansui | C4: 32 | D4: Roll | E4: 650000 | F4: =E4*C4 -> 20800000 | G4: =F4*$H$2 -> 728000000
A5: 2 | B5: Pipa 6" | C5: 1 | D5: Batang | E5: 690030 | F5: =E5*C5 -> 690030 | G5: =F5*$H$2 -> 24151050
A6: 2 | B6: Pipa 4" | C6: 25 | D6: Batang | E6: 332729 | F6: =E6*C6 -> 8318225 | G6: =F6*$H$2 -> 291137875
A7: 3 | B7: Pipa 2" | C7: 20 | D7: Batang | E7: 97614 | F7: =E7*C7 -> 1952280 | G7: =F7*$H$2 -> 68329800
A8: 4 | B8: Pipa 3/4 | C8: 1 | D8: Batang | E8: 31416 | F8: =E8*C8 -> 31416 | G8: =F8*$H$2 -> 1099560
A9: 5 | B9: Tee 4/2 | C9: 6 | D9: Pcs | E9: 95370 | F9: =E9*C9 -> 572220 | G9: =F9*$H$2 -> 20027700
A10: 6 | B10: Tee 2/2 | C10: 6 | D10: Pcs | E10: 17952 | F10: =E10*C10 -> 107712 | G10: =F10*$H$2 -> 3769920
A11: 7 | B11: Tee 2" ke 3/4 | C11: 32 | D11: Pcs | E11: 12342 | F11: =E11*C11 -> 394944 | G11: =F11*$H$2 -> 13823040
A12: 8 | B12: Gate valve/keran 2" | C12: 6 | D12: Pcs | E12: 1142196 | F12: =E12*C12 -> 6853176 | G12: =F12*$H$2 -> 239861160
A13: 9 | B13: Stopper pipa 2" | C13: 12 | D13: Pcs | E13: 40000 | F13: =E13*C13 -> 480000 | G13: =F13*$H$2 -> 16800000
A14: 10 | B14: Klem Stainless 3/4 | C14: 32 | D14: Pcs | E14: 1100 | F14: =E14*C14 -> 35200 | G14: =F14*$H$2 -> 1232000
A15: 11 | B15: Lem (400 ml) | C15: 1 | D15: PCs | E15: 30000 | F15: =E15*C15 -> 30000 | G15: =F15*$H$2 -> 1050000
A16: 12 | B16: Mesin Pompa Kecil | C16: 2 | D16: Unit | E16: 3000000 | G16: =E16*C16 -> 6000000
A17: 13 | B17: Pipa 6" | C17: =500/4 -> 125 | D17: Btg | E17: 690030 | G17: =E17*C17 -> 86253750
A18: 14 | B18: Selang Spiral 6" | C18: 10 | D18: Mtr | E18: 213180 | G18: =E18*C18 -> 2131800
B20: Grand Total | F20: =SUM(F4:F16) -> 40265203 | G20: =SUM(G4:G16) -> 1415282105
F21: per Ha | G21: =G20/H2 -> 40436632 | I21: =#REF! -> #REF! | J21: =G21/I21 -> #REF! | L21: =J21*1000 -> #REF!
F22: Sub total | I22: =1000/I21 -> #REF!
F23: HK
F24: GT | G24: =G23+G22 -> 0
F25: per Ha | G25: =G24/20 -> 0
F26: LC | G26: =6000000*20 -> 120000000
G27: =G26+G24 -> 120000000
G28: =G27/400000 -> 300
B31: Mesin Pompa Kecil | C31: 2 | D31: Unit | E31: 3000000 | G31: =E31*C31 -> 6000000
B32: Pipa 6" | C32: =500/4 -> 125 | D32: Btg | E32: 690030 | G32: =E32*C32 -> 86253750
B33: Selang Spiral 6" | C33: 10 | D33: Mtr | E33: 213180 | G33: =E33*C33 -> 2131800
F34: =G34/35 -> 2696730 | G34: =SUM(G31:G33) -> 94385550

Sheet RKP FFD
B1: RENCANA KERJA PROYEK ( RKP ) TANAM PASTURA
B2: PT FASS FOREST DEVELOPMENT
B3: KELOMPOK PASTURA | E3: Luas (Ha) | F3: Kg Produksi s.d 2028
D4: Indigofera | E4: ='SI TB LC Indigofera (FFD)'!E2 -> 27.8 | F4: ='SI TB LC Indigofera (FFD)'!AA2 -> 3058000 | G4: Kg
D5: Pakchong | E5: ='SI TB LC Pakchong (FFD)'!E2 -> 31.16 | F5: ='SI TB LC Pakchong (FFD)'!AA2 -> 38139840 | G5: Kg
B6: No. | C6: Uraian | D6: Rencana | F6: Unis Cost
D7: Volume | E7: Biaya
D8: ( Ha ) | E8: ( Rp ) | F8: Rp/Ha | G8: Rp/Kg
B9: 1 | C9: PEMBUKAAN LAHAN
C10: - Pembukaan Lahan Pastura Indigofera | D10: =$E$4 -> 27.8 | E10: ='SI TB LC Indigofera (FFD)'!Q34 -> 6.5474023e+08 | F10: =E10/D10 -> 23551807 | G10: =E10/$F$4 -> 214.10734
C11: - Pembukaan Lahan Pastura Pakchong | D11: =$E$5 -> 31.16 | E11: ='SI TB LC Pakchong (FFD)'!Q40 -> 4.7380506e+08 | F11: =E11/D11 -> 15205554 | G11: =E11/$F$5 -> 12.422838
B12: 2 | C12: PEMBUATAN SARANA PRASARANA
C13: - Sarana dan Prasarana Lahan Pastura Indigofera | D13: =$E$4 -> 27.8 | E13: ='SI TB LC Indigofera (FFD)'!Q114 -> 1.1312106e+08 | F13: =E13/D13 -> 4069103 | G13: =E13/$F$4 -> 36.991845
C14: - Sarana dan Prasarana Lahan Pastura Pakchong | D14: =$E$5 -> 31.16 | E14: ='SI TB LC Pakchong (FFD)'!Q120 -> 1.1447424e+08 | F14: =E14/D14 -> 3673756.2 | G14: =E14/$F$5 -> 3.0014348
B15: 3 | C15: TANAM DAN PEMELIHARAAN AWAL
C16: - Indigofera | D16: =$E$4 -> 27.8 | E16: ='SI TB LC Indigofera (FFD)'!Q207 -> 1.0499398e+09 | F16: =E16/D16 -> 37767620 | G16: =E16/$F$4 -> 343.342
C17: - Pakchong | D17: =$E$5 -> 31.16 | E17: ='SI TB LC Pakchong (FFD)'!Q202 -> 8.6067952e+08 | F17: =E17/D17 -> 27621294 | G17: =E17/$F$5 -> 22.566417
B18: 4 | C18: PANEN
C19: - Indigofera | D19: =$E$4 -> 27.8 | E19: ='SI TB LC Indigofera (FFD)'!Q213 -> 6.1980202e+08 | F19: =E19/D19 -> 22295037 | G19: =E19/$F$4 -> 202.68215
C20: - Pakchong | D20: =$E$5 -> 31.16 | E20: ='SI TB LC Pakchong (FFD)'!Q208 -> 3.8003028e+08 | F20: =E20/D20 -> 12196094 | G20: =E20/$F$5 -> 9.9641289
C21: Tatal Biaya Indigofera | D21: =D19 -> 27.8 | E21: =E19+E16+E13+E10 -> 2.4376032e+09 | F21: =E21/D21 -> 87683567 | G21: =E21/$F$4 -> 797.12333
C22: Total Biaya Pakchong | D22: =D20 -> 31.16 | E22: =E20+E17+E14+E11 -> 1.8289891e+09 | F22: =E22/D22 -> 58696698 | G22: =E22/$F$5 -> 47.954819
C23: Grand Total | E23: =E22+E21 -> 4.2665923e+09 | F23: =E23/(D21+D22) -> 72364183 | G23: =E23/(F4+F5) -> 103.56349
F25: Satui, 24 Agustus 2026
C26: Disetujui oleh, | D26: Diperiksa oleh, | F26: Dibuat oleh,
C30: ( Imam Satoto Yudiono ) | D30: ( Hairul Amri ) | F30: ( A r i f )
C31: Direktur Utama | D31: Direktur | F31: Pjs. GM Agronomi

Sheet Areal Stmt
B2: LUAS AREAL STATEMENT TANAM PASTURA
B3: No | C3: Blok | D3: Luas | E3: Lokasi | F3: Tahun | H3: Keterangan
F4: 2026 (ha) | G4: Luas Total
B5: I | C5: FFD
B6: 1 | C6: F29 | D6: 27.8 | E6: Ryn 2 | F6: =D6 -> 27.8 | G6: =SUM(F6:F6) -> 27.8
B7: 2 | C7: Kandang | D7: 14 | E7: Ryn 1 | F7: =D7 -> 14 | G7: =SUM(F7:F7) -> 14
B8: Sub Total | D8: =SUM(D6:D7) -> 41.8 | F8: =SUM(F6:F7) -> 41.8 | G8: =SUM(F8:F8) -> 41.8
B9: 3 | C9: H19 | D9: =(3.5*300)/10000 -> 0.105 | E9: Ryn 1 | F9: =D9 -> 0.105 | G9: =SUM(F9:F9) -> 0.105
B10: 4 | C10: H20 | D10: =(8*300)/10000 -> 0.24 | E10: Ryn 1 | F10: =D10 -> 0.24 | G10: =SUM(F10:F10) -> 0.24
B11: 5 | C11: H21 | D11: =(8.5*300)/10000 -> 0.255 | E11: Ryn 1 | F11: =D11 -> 0.255 | G11: =SUM(F11:F11) -> 0.255
B12: 6 | C12: H22 | D12: =(2.5*300)/10000 -> 0.075 | E12: Ryn 1 | F12: =D12 -> 0.075 | G12: =SUM(F12:F12) -> 0.075
B13: 7 | C13: H23 | D13: =(4*300)/10000 -> 0.12 | E13: Ryn 1 | F13: =D13 -> 0.12 | G13: =SUM(F13:F13) -> 0.12
B14: 8 | C14: H24 | D14: =(3*300)/10000 -> 0.09 | E14: Ryn 1 | F14: =D14 -> 0.09 | G14: =SUM(F14:F14) -> 0.09
B15: 9 | C15: H25 | D15: =(2*300)/10000 -> 0.06 | E15: Ryn 1 | F15: =D15 -> 0.06 | G15: =SUM(F15:F15) -> 0.06
B16: 10 | C16: H26 | D16: =(6*300)/10000 -> 0.18 | E16: Ryn 1 | F16: =D16 -> 0.18 | G16: =SUM(F16:F16) -> 0.18
B17: 11 | C17: H27 | D17: =(5*300)/10000 -> 0.15 | E17: Ryn 1 | F17: =D17 -> 0.15 | G17: =SUM(F17:F17) -> 0.15
B18: 12 | C18: H28 | D18: =(4*300)/10000 -> 0.12 | E18: Ryn 1 | F18: =D18 -> 0.12 | G18: =SUM(F18:F18) -> 0.12
B19: 13 | C19: H29A | D19: 6.5 | E19: Ryn 1 | F19: =D19 -> 6.5 | G19: =SUM(F19:F19) -> 6.5
B20: 14 | C20: H29B | D20: =(5.5*300)/10000 -> 0.165 | E20: Ryn 1 | F20: =D20 -> 0.165 | G20: =SUM(F20:F20) -> 0.165
B21: 15 | C21: JB14 | D21: 2.9 | E21: Ryn 1 | F21: =D21 -> 2.9 | G21: =SUM(F21:F21) -> 2.9
B22: 16 | C22: JB15 | D22: 1.2 | E22: Ryn 1 | F22: =D22 -> 1.2 | G22: =SUM(F22:F22) -> 1.2
B23: 17 | C23: JB25 | D23: 5 | E23: Ryn 1 | F23: =D23 -> 5 | G23: =SUM(F23:F23) -> 5
B24: Sub Total | D24: =SUM(D9:D23) -> 17.16 | F24: =SUM(F9:F23) -> 17.16 | G24: =SUM(F24:F24) -> 17.16
B25: Total | D25: =D8+D24 -> 58.96 | E25: =E8+E24 -> 0 | F25: =F8+F24 -> 58.96 | G25: =G8+G24 -> 58.96
B27: Rencana Tanam Pastura Areal Rumput Pakchong dan Indigofera
B28: No | C28: Blok | D28: Luas | E28: Lokasi | H28: Keterangan
G29: TOTAL
B31: I | C31: Luas Areal Indigofera
C32: FFD | D32: =SUM(D6:D6) -> 27.8 | F32: =SUM(F6:F6) -> 27.8 | G32: =SUM(F32:F32) -> 27.8
B33: Sub Total | D33: =SUM(D32:D32) -> 27.8 | F33: =SUM(F32:F32) -> 27.8 | G33: =SUM(F33:F33) -> 27.8
B34: II | C34: Luas Areal Pakchong
C35: FFD | D35: =SUM(D9:D23)+D7 -> 31.16 | F35: =SUM(F9:F23)+F7 -> 31.16 | G35: =SUM(F35:F35) -> 31.16
B36: Sub Total | D36: =SUM(D35:D35) -> 31.16 | F36: =SUM(F35:F35) -> 31.16 | G36: =SUM(F36:F36) -> 31.16

Sheet SCHEDULE-Indigofera
B2: RENCANA SCHEDULE PROJECT PASTURA KEBUN FFD INTI
C4: PT Fast Forest Development
C5: Departement | D5: : Agronomi
C6: Divisi | D6: : Replanting & Reklamasi
B7: RENCANA KEGIATAN TANAM PASTURA INDIGOFERA
B8: PT FFD
B9: No | C9: Kegiatan | E9: 2026 | J9: 2027 | W9: Keterangan
E10: Ags | F10: Sep | G10: Okt | H10: Nop | I10: Des | J10: Jan | K10: Feb | L10: Mar | M10: Apr | N10: Mei | O10: May | P10: Jun | Q10: Jul | R10: Aug | S10: Sep | T10: Oct | U10: Nov | V10: Dec
B11: 1 | C11: Dokumen Project | D11: Finalisasi RKP
B12: 2 | C12: Pembukaan Lahan | D12: Identifikasi Blok | W12: 1X Rotasi
D13: LC Manual dan Mekanis | W13: 1X Rotasi
D14: Pengolahan Tanah (Bajak) dan Pupuk Organik | W14: 1X Rotasi
D15: Penyemprotan Lalang Gulma & Pasar Rintis | W15: 1X Rotasi
B16: 3 | C16: Sarana & Prasarana | D16: Pembuatan Jalan Produksi
D17: Jembatan Gorong-Gorong | W17: 1X Rotasi
D18: Pembuatan Parit | W18: 1X Rotasi
B19: 4 | C19: Pembibitan Indigofera | D19: Pembuatan Bedengan | W19: 1X Rotasi
D20: Perakitan Instalasi Air | W20: 1X Rotasi
D21: Penanaman Benih Indigofera | W21: 1X Rotasi
D22: Pemeliharaan Weeding Atas | W22: 1X Rotasi
D23: Perakitan Instalasi Air
D24: Penyiraman Bibit | W24: 1X Rotasi
D25: Pemeliharaan Bibit | W25: 1X Rotasi
B26: 5 | C26: Tanam Indigofera | D26: Memancang | W26: 1X Rotasi
D27: Perbaikkan Struktur Tanah Titik Tanam (Aplikasi Jangkos) | W27: 1X Rotasi
D28: Penanaman Indigofera | W28: 1X Rotasi
B29: 6 | C29: Pemeliharaan Indigofera | D29: Perbaikkan Struktur Tanah Titik Tanam (Aplikasi Jangkos)
D30: Pemeliharaan Pokok (Konsolidasi Pokok) | W30: 3X Rotasi
D31: Sanitasi Lingkungan | W31: 1X Rotasi
D32: Pemupukan
B33: 7 | C33: Panen Indigofera | D33: Panen Perdana | W33: 1X Rotasi
D34: Panen Rutin Per 2 Bulan | W34: 6X pertahun

Sheet SCHEDULE-Pakchong
B2: RENCANA SCHEDULE PROJECT REKLAMASI KEBUN FFD INTI
C4: PT Fast Forest Development
C5: Departement | D5: : Agronomi
C6: Divisi | D6: : Replanting & Reklamasi
B7: RENCANA KEGIATAN TANAM PASTURA PAKCHONG
B8: PT FFD
B9: No | C9: Kegiatan | E9: 2026 | J9: 2027 | W9: Keterangan
E10: Ags | F10: Sep | G10: Okt | H10: Nop | I10: Des | J10: Jan | K10: Feb | L10: Mar | M10: Apr | N10: Mei | O10: May | P10: Jun | Q10: Jul | R10: Aug | S10: Sep | T10: Oct | U10: Nov | V10: Dec
B11: 1 | C11: Dokumen Project | D11: Finalisasi RKP
B12: 2 | C12: Pembukaan Lahan | D12: Identifikasi Blok | W12: 1X Rotasi
D13: LC Manual dan Mekanis | W13: 1X Rotasi
D14: Pengolahan Tanah (Bajak) dan Pupuk Organik | W14: 1X Rotasi
D15: Penyemprotan Lalang Gulma & Pasar Rintis | W15: 1X Rotasi
B16: 3 | C16: Sarana & Prasarana | D16: Pembuatan Jalan Produksi
D17: Jembatan Gorong-Gorong | W17: 1X Rotasi
D18: Pembuatan Parit | W18: 1X Rotasi
B19: 4 | C19: Pembibitan | D19: Penyiraman Bibit | W19: 1X Rotasi
B20: 5 | C20: Tanam Pakchong | D20: Memancang | W20: 1X Rotasi
D21: Perbaikkan Struktur Tanah Titik Tanam (Aplikasi Jangkos) | W21: 1X Rotasi
D22: Penanaman Pakchong | W22: 1X Rotasi
B23: 6 | C23: Pemeliharaan Pakchong | D23: Perbaikkan Struktur Tanah Titik Tanam (Aplikasi Jangkos)
D24: Pemeliharaan Pokok (Konsolidasi Pokok) | W24: 3X Rotasi
D25: Sanitasi Lingkungan | W25: 1X Rotasi
D26: Pemupukan
B27: 7 | C27: Panen Pakchong | D27: Panen Perdana | W27: 1X Rotasi
D28: Panen Rutin Per 1,5 Bulan | W28: 8X pertahun

Sheet SI TB LC Indigofera (FFD)
B1: RKP TANAM PASTURA (Indigofera)
D2: Luas: | E2: ='Areal Stmt'!G32 -> 27.8 | F2: Jumlah Populasi | G2: =E2*5000 -> 139000 | Q2: Hasil Panen | AA2: =11000*E2*AF11 -> 3058000 | AB2: Kg | AD2: Hasil Panen | AF2: Bulan | AG2: Tahun
B3: Pekerjaan | F3: Material | H3: Rotasi APD | J3: TB/LC | P3: 2026 s.d 2028 | R3: 2026 | T3: 2027 | V3: Rata-rata | X3: Keterangan | Y3: BIAYA/HA | Z3: Biaya/pkk | AA3: Rp/Ha | AB3: Persentase (%) | AD3: Tanam | AE3: 46266 | AG3: 2026
F4: Jenis | G4: Sat | J4: Sat | K4: Vol | M4: Norma | N4: Rotasi | O4: Jumlah Unit | P4: Rp Sat | Q4: Jumlah RP | R4: Rp Sat | S4: Jumlah RP | T4: Rp Sat | U4: Jumlah RP | V4: Rp Sat | W4: Jumlah RP | AD4: Panen | AE4: 1 | AF4: Mei | AG4: 2027
K5: % | L5: Luas/Mtr/Pkk/Unit | AE5: 2 | AF5: Juli | AG5: 20027
B6: PEMBUKAAN LAHAN | AE6: 3 | AF6: Sept | AG6: 20027
C7: IMAS,TUMBANG, PERUN | AE7: 4 | AF7: Nop | AG7: 20027
D8: Identifikasi Blok | F8: Upah PHL | G8: HK | J8: Ha | K8: 1 | L8: =E2 -> 27.8 | M8: 0.25 | N8: 1 | O8: =K8*L8*M8*N8 -> 6.95 | P8: =VLOOKUP($F8,'Master Harga'!$E$5:$L$348,6,FALSE) -> 151208.64 | Q8: =P8*$O8 -> 1050900 | R8: =VLOOKUP($F8,'Master Harga'!$E$5:$L$348,6,FALSE) -> 151208.64 | S8: =R8*$O8 -> 1050900 | T8: =VLOOKUP($F8,'Master Harga'!$E$5:$L$348,7,FALSE) -> 163305.33 | U8: =T8*$O8 -> 1134972.1 | V8: =W8/O8 -> 155240.87 | W8: =AVERAGEIF($P$4:$U$4,W$4,$P8:$U8) -> 1078924 | AA8: =Q8/$E$2 -> 37802.16 | AE8: 5 | AF8: 6 x | AG8: 2028
D9: Imas | E9: Hutan Primer | F9: Upah PHL | G9: HK | M9: 10 | N9: 1 | X9: Vol sesuai kondisi
E10: Hutan Sekunder | F10: Upah PHL | G10: HK | M10: 10 | N10: 1 | P10: 0
E11: Semak Belukar | F11: Upah PHL | G11: HK | J11: Ha | K11: 0.4 | L11: =L8 -> 27.8 | M11: 7 | N11: 1 | O11: =K11*L11*M11*N11 -> 77.84 | P11: =VLOOKUP($F11,'Master Harga'!$E$5:$L$348,6,FALSE) -> 151208.64 | Q11: =P11*$O11 -> 11770081 | R11: =VLOOKUP($F11,'Master Harga'!$E$5:$L$348,6,FALSE) -> 151208.64 | S11: =R11*$O11 -> 11770081 | T11: =VLOOKUP($F11,'Master Harga'!$E$5:$L$348,7,FALSE) -> 163305.33 | U11: =T11*$O11 -> 12711687 | V11: =W11/O11 -> 155240.87 | W11: =AVERAGEIF($P$4:$U$4,W$4,$P11:$U11) -> 12083949 | AA11: =Q11/$E$2 -> 423384.19 | AE11: Total | AF11: =((6*3)+4)-12 -> 10 | AG11: Kali Panen
D12: Perun Mekanis | E12: Hutan Primer | F12: Buldozer 1 | G12: HM | J12: Ha | K12: 0.888 | L12: =E2 -> 27.8 | M12: 8 | N12: 1 | O12: =K12*L12*M12*N12 -> 197.4912 | P12: =VLOOKUP($F12,'Master Harga'!$E$5:$L$348,6,FALSE) -> 1051433.7 | Q12: =O12*P12 -> 2.076489e+08 | AA12: =Q12/$E$2 -> 7469384.9
E13: Reklamasi | F13: Excavator 1 | G13: HM | J13: HM | K13: 0.6 | L13: =L8 -> 27.8 | M13: 8 | N13: 1 | O13: =K13*L13*M13*N13 -> 133.44 | P13: =VLOOKUP($F13,'Master Harga'!$E$5:$L$348,6,FALSE) -> 720338.07 | Q13: =O13*P13 -> 96121912 | AA13: =Q13/$E$2 -> 3457622.8
D14: Abu Jangkos 5 Ton/Ha | F14: Upah PHL | G14: HK | J14: Hk | K14: 1 | L14: =E2 -> 27.8 | M14: 10 | N14: 1 | O14: =K14*L14*M14*N14 -> 278 | P14: =VLOOKUP($F14,'Master Harga'!$E$5:$L$348,6,FALSE) -> 151208.64 | Q14: =P14*$O14 -> 42036002 | R14: =VLOOKUP($F14,'Master Harga'!$E$5:$L$348,6,FALSE) -> 151208.64 | S14: =R14*$O14 -> 42036002 | T14: =VLOOKUP($F14,'Master Harga'!$E$5:$L$348,7,FALSE) -> 163305.33 | U14: =T14*$O14 -> 45398882 | V14: =W14/O14 -> 155240.87 | W14: =AVERAGEIF($P$4:$U$4,W$4,$P14:$U14) -> 43156962 | X14: 5 Gram/Pkk | Z14: =W14 -> 43156962 | AA14: =Q14/$E$2 -> 1512086.4
F15: Angkutan Abu Boiler | G15: Ha | J15: Ton | K15: 1 | L15: =E2 -> 27.8 | M15: 5 | N15: 1 | O15: =K15*L15*M15*N15 -> 139 | P15: =VLOOKUP($F15,'Master Harga'!$E$5:$L$348,6,FALSE) -> 71700 | Q15: =P15*$O15 -> 9966300 | R15: =VLOOKUP($F15,'Master Harga'!$E$5:$L$348,6,FALSE) -> 71700 | S15: =R15*$O15 -> 9966300 | T15: =VLOOKUP($F15,'Master Harga'!$E$5:$L$348,7,FALSE) -> 81738 | U15: =T15*$O15 -> 11361582 | V15: =W15/O15 -> 75046 | W15: =AVERAGEIF($P$4:$U$4,W$4,$P15:$U15) -> 10431394 | X15: 5 Gram/Pkk | Z15: =W15 -> 10431394 | AA15: =Q15/$E$2 -> 358500
D16: Pengolahan Tanah I | F16: Farm Traktor 1 | G16: HM | J16: HM/Ha | K16: 1 | L16: =L13 -> 27.8 | M16: 3.5 | N16: 1 | O16: =K16*L16*M16*N16 -> 97.3 | P16: =VLOOKUP($F16,'Master Harga'!$E$5:$L$348,6,FALSE) -> 369600 | Q16: =O16*P16 -> 35962080 | AA16: =Q16/$E$2 -> 1293600
D17: Pupuk Kandang 5 Ton/Ha | F17: Upah PHL | G17: HK | J17: Hk | K17: 1 | L17: =E2 -> 27.8 | M17: 10 | N17: 1 | O17: =K17*L17*M17*N17 -> 278 | P17: =VLOOKUP($F17,'Master Harga'!$E$5:$L$348,6,FALSE) -> 151208.64 | Q17: =P17*$O17 -> 42036002 | R17: =VLOOKUP($F17,'Master Harga'!$E$5:$L$348,6,FALSE) -> 151208.64 | S17: =R17*$O17 -> 42036002 | T17: =VLOOKUP($F17,'Master Harga'!$E$5:$L$348,7,FALSE) -> 163305.33 | U17: =T17*$O17 -> 45398882 | V17: =W17/O17 -> 155240.87 | W17: =AVERAGEIF($P$4:$U$4,W$4,$P17:$U17) -> 43156962 | X17: 5 Gram/Pkk | Z17: =W17 -> 43156962 | AA17: =Q17/$E$2 -> 1512086.4
F18: Pupuk Kandang | G18: Ha | J18: Ton | K18: 1 | L18: =E2 -> 27.8 | M18: 5 | N18: 1 | O18: =K18*L18*M18*N18 -> 139 | P18: =VLOOKUP($F18,'Master Harga'!$E$5:$L$348,6,FALSE) -> 980000 | Q18: =P18*$O18 -> 1.3622e+08 | R18: =VLOOKUP($F18,'Master Harga'!$E$5:$L$348,6,FALSE) -> 980000 | S18: =R18*$O18 -> 1.3622e+08 | T18: =VLOOKUP($F18,'Master Harga'!$E$5:$L$348,7,FALSE) -> 1372000 | U18: =T18*$O18 -> 1.90708e+08 | V18: =W18/O18 -> 1110666.7 | W18: =AVERAGEIF($P$4:$U$4,W$4,$P18:$U18) -> 1.5438267e+08 | X18: 5 Gram/Pkk | Z18: =W18 -> 1.5438267e+08 | AA18: =Q18/$E$2 -> 4900000
D19: Pengolahan Tanah II | F19: Farm Traktor 1 | G19: HM | J19: HM/Ha | K19: 1 | L19: =L16 -> 27.8 | M19: 3.5 | N19: 1 | O19: =K19*L19*M19*N19 -> 97.3 | P19: =VLOOKUP($F19,'Master Harga'!$E$5:$L$348,6,FALSE) -> 369600 | Q19: =O19*P19 -> 35962080 | AA19: =Q19/$E$2 -> 1293600
D20: Pengolahan Tanah III | F20: Farm Traktor 1 | G20: HM | J20: HM/Ha | K20: 1 | L20: =L19 -> 27.8 | M20: 2.5 | N20: 1 | O20: =K20*L20*M20*N20 -> 69.5 | P20: =VLOOKUP($F20,'Master Harga'!$E$5:$L$348,6,FALSE) -> 369600 | Q20: =O20*P20 -> 25687200 | AA20: =Q20/$E$2 -> 924000
D21: Pemberantasan Lalang dan Gulma Lainnya | F21: Upah PHL | G21: HK | J21: Ha | K21: 1 | L21: =E2 -> 27.8 | M21: 1.5 | N21: 1 | O21: =K21*L21*M21*N21 -> 41.7 | P21: =VLOOKUP($F21,'Master Harga'!$E$5:$L$348,6,FALSE) -> 151208.64 | Q21: =P21*$O21 -> 6305400.3 | R21: =VLOOKUP($F21,'Master Harga'!$E$5:$L$348,6,FALSE) -> 151208.64 | S21: =R21*$O21 -> 6305400.3 | T21: =VLOOKUP($F21,'Master Harga'!$E$5:$L$348,7,FALSE) -> 163305.33 | U21: =T21*$O21 -> 6809832.3 | V21: =W21/O21 -> 155240.87 | W21: =AVERAGEIF($P$4:$U$4,W$4,$P21:$U21) -> 6473544.3 | AA21: =Q21/$E$2 -> 226812.96
F22: Sprayer (Inter) | G22: Buah | J22: Ha | K22: 1 | L22: =L21 -> 27.8 | M22: 0.031 | N22: 1 | O22: =K22*L22*M22*N22 -> 0.8618 | P22: =VLOOKUP($F22,'Master Harga'!$E$5:$L$348,6,FALSE) -> 1530444.7 | Q22: =P22*$O22 -> 1318937.3 | R22: =VLOOKUP($F22,'Master Harga'!$E$5:$L$348,6,FALSE) -> 1530444.7 | S22: =R22*$O22 -> 1318937.3 | T22: =VLOOKUP($F22,'Master Harga'!$E$5:$L$348,7,FALSE) -> 1714098.1 | U22: =T22*$O22 -> 1477209.7 | V22: =W22/O22 -> 1591662.5 | W22: =AVERAGEIF($P$4:$U$4,W$4,$P22:$U22) -> 1371694.8 | AA22: =Q22/$E$2 -> 47443.786
F23: Glyphosate | G23: Liter | J23: Ha | K23: 0.235 | L23: =L22 -> 27.8 | M23: 0.9 | N23: 1 | O23: =K23*L23*M23*N23 -> 5.8797 | P23: =VLOOKUP($F23,'Master Harga'!$E$5:$L$348,6,FALSE) -> 35343 | Q23: =P23*$O23 -> 207806.24 | AA23: =Q23/$E$2 -> 7475.0445
F24: Metil Metsulfuron | G24: Kg | J24: Ha | K24: 0.74 | L24: =L23 -> 27.8 | M24: 0.036 | N24: 1 | O24: =K24*L24*M24*N24 -> 0.740592 | P24: =VLOOKUP($F24,'Master Harga'!$E$5:$L$348,6,FALSE) -> 96390 | Q24: =P24*$O24 -> 71385.663 | R24: =VLOOKUP($F24,'Master Harga'!$E$5:$L$348,6,FALSE) -> 96390 | S24: =R24*$O24 -> 71385.663 | T24: =VLOOKUP($F24,'Master Harga'!$E$5:$L$348,7,FALSE) -> 109884.6 | U24: =T24*$O24 -> 81379.656 | V24: =W24/O24 -> 100888.2 | W24: =AVERAGEIF($P$4:$U$4,W$4,$P24:$U24) -> 74716.994 | AA24: =Q24/$E$2 -> 2567.8296
F25: Parakuat | G25: Liter | J25: Ha | K25: 0.5 | L25: =L24 -> 27.8 | M25: 0.9 | N25: 1 | O25: =K25*L25*M25*N25 -> 12.51 | P25: =VLOOKUP($F25,'Master Harga'!$E$5:$L$348,6,FALSE) -> 28381.5 | Q25: =P25*$O25 -> 355052.57 | R25: =VLOOKUP($F25,'Master Harga'!$E$5:$L$348,6,FALSE) -> 28381.5 | S25: =R25*$O25 -> 355052.57 | T25: =VLOOKUP($F25,'Master Harga'!$E$5:$L$348,7,FALSE) -> 32354.91 | U25: =T25*$O25 -> 404759.92 | V25: =W25/O25 -> 29705.97 | W25: =AVERAGEIF($P$4:$U$4,W$4,$P25:$U25) -> 371621.68 | AA25: =Q25/$E$2 -> 12771.675
F26: Perekat | G26: Liter | J26: Ha | K26: 0.74 | L26: =L25 -> 27.8 | M26: 0.27 | N26: 1 | O26: =K26*L26*M26*N26 -> 5.55444 | P26: =VLOOKUP($F26,'Master Harga'!$E$5:$L$348,6,FALSE) -> 44982 | Q26: =P26*$O26 -> 249849.82 | R26: =VLOOKUP($F26,'Master Harga'!$E$5:$L$348,6,FALSE) -> 44982 | S26: =R26*$O26 -> 249849.82 | T26: =VLOOKUP($F26,'Master Harga'!$E$5:$L$348,7,FALSE) -> 51279.48 | U26: =T26*$O26 -> 284828.79 | V26: =W26/O26 -> 47081.16 | W26: =AVERAGEIF($P$4:$U$4,W$4,$P26:$U26) -> 261509.48 | AA26: =Q26/$E$2 -> 8987.4036
F27: Premi Extra Fooding | G27: HK | J27: Ha | K27: 1 | L27: =L26 -> 27.8 | M27: =M21 -> 1.5 | N27: 1 | O27: =K27*L27*M27*N27 -> 41.7 | P27: =VLOOKUP($F27,'Master Harga'!$E$5:$L$348,6,FALSE) -> 3996 | Q27: =P27*$O27 -> 166633.2 | R27: =VLOOKUP($F27,'Master Harga'!$E$5:$L$348,6,FALSE) -> 3996 | S27: =R27*$O27 -> 166633.2 | T27: =VLOOKUP($F27,'Master Harga'!$E$5:$L$348,7,FALSE) -> 4315.68 | U27: =T27*$O27 -> 179963.86 | V27: =W27/O27 -> 4102.56 | W27: =AVERAGEIF($P$4:$U$4,W$4,$P27:$U27) -> 171076.75 | AA27: =Q27/$E$2 -> 5994
F28: Celemek | G28: Buah | H28: 4 | I28: X | J28: Ha | K28: 1 | L28: =L27 -> 27.8 | M28: =((M$21*N$21)/240*($H28/N28)) -> 0.025 | N28: 1 | O28: =K28*L28*M28*N28 -> 0.695 | P28: =VLOOKUP($F28,'Master Harga'!$E$5:$L$348,6,FALSE) -> 47980.8 | Q28: =P28*$O28 -> 33346.656 | R28: =VLOOKUP($F28,'Master Harga'!$E$5:$L$348,6,FALSE) -> 47980.8 | S28: =R28*$O28 -> 33346.656 | T28: =VLOOKUP($F28,'Master Harga'!$E$5:$L$348,7,FALSE) -> 53738.496 | U28: =T28*$O28 -> 37348.255 | V28: =W28/O28 -> 49900.032 | W28: =AVERAGEIF($P$4:$U$4,W$4,$P28:$U28) -> 34680.522 | AA28: =Q28/$E$2 -> 1199.52
F29: Masker Chemical | G29: Buah | H29: 12 | I29: X | J29: Ha | K29: 1 | L29: =L28 -> 27.8 | M29: =((M$21*N$21)/240*($H29/N29)) -> 0.075 | N29: 1 | O29: =K29*L29*M29*N29 -> 2.085 | P29: =VLOOKUP($F29,'Master Harga'!$E$5:$L$348,6,FALSE) -> 15680 | Q29: =P29*$O29 -> 32692.8 | R29: =VLOOKUP($F29,'Master Harga'!$E$5:$L$348,6,FALSE) -> 15680 | S29: =R29*$O29 -> 32692.8 | T29: =VLOOKUP($F29,'Master Harga'!$E$5:$L$348,7,FALSE) -> 17561.6 | U29: =T29*$O29 -> 36615.936 | V29: =W29/O29 -> 16307.2 | W29: =AVERAGEIF($P$4:$U$4,W$4,$P29:$U29) -> 34000.512 | AA29: =Q29/$E$2 -> 1176
F30: Kaca mata | G30: Buah | H30: 1 | I30: X | J30: Ha | K30: 1 | L30: =L29 -> 27.8 | M30: =((M$21*N$21)/240*($H30/N30)) -> 0.00625 | N30: 1 | O30: =K30*L30*M30*N30 -> 0.17375 | P30: =VLOOKUP($F30,'Master Harga'!$E$5:$L$348,6,FALSE) -> 41983.2 | Q30: =P30*$O30 -> 7294.581 | R30: =VLOOKUP($F30,'Master Harga'!$E$5:$L$348,6,FALSE) -> 41983.2 | S30: =R30*$O30 -> 7294.581 | T30: =VLOOKUP($F30,'Master Harga'!$E$5:$L$348,7,FALSE) -> 47021.184 | U30: =T30*$O30 -> 8169.9307 | V30: =W30/O30 -> 43662.528 | W30: =AVERAGEIF($P$4:$U$4,W$4,$P30:$U30) -> 7586.3642 | AA30: =Q30/$E$2 -> 262.395
F31: Sarung Tangan Karet | G31: Buah | H31: 2 | I31: X | J31: Ha | K31: 1 | L31: =L30 -> 27.8 | M31: =((M$21*N$21)/240*($H31/N31)) -> 0.0125 | N31: 1 | O31: =K31*L31*M31*N31 -> 0.3475 | P31: =VLOOKUP($F31,'Master Harga'!$E$5:$L$348,6,FALSE) -> 35985.6 | Q31: =P31*$O31 -> 12504.996 | R31: =VLOOKUP($F31,'Master Harga'!$E$5:$L$348,6,FALSE) -> 35985.6 | S31: =R31*$O31 -> 12504.996 | T31: =VLOOKUP($F31,'Master Harga'!$E$5:$L$348,7,FALSE) -> 40303.872 | U31: =T31*$O31 -> 14005.596 | V31: =W31/O31 -> 37425.024 | W31: =AVERAGEIF($P$4:$U$4,W$4,$P31:$U31) -> 13005.196 | AA31: =Q31/$E$2 -> 449.82
F32: Sepatu Boots | G32: Buah | H32: 1 | I32: X | J32: Ha | K32: 1 | L32: =L31 -> 27.8 | M32: =((M$21*N$21)/240*($H32/N32)) -> 0.00625 | N32: 1 | O32: =K32*L32*M32*N32 -> 0.17375 | P32: =VLOOKUP($F32,'Master Harga'!$E$5:$L$348,6,FALSE) -> 95961.6 | Q32: =P32*$O32 -> 16673.328 | R32: =VLOOKUP($F32,'Master Harga'!$E$5:$L$348,6,FALSE) -> 95961.6 | S32: =R32*$O32 -> 16673.328 | T32: =VLOOKUP($F32,'Master Harga'!$E$5:$L$348,7,FALSE) -> 107476.99 | U32: =T32*$O32 -> 18674.127 | V32: =W32/O32 -> 99800.064 | W32: =AVERAGEIF($P$4:$U$4,W$4,$P32:$U32) -> 17340.261 | AA32: =Q32/$E$2 -> 599.76
D33: Transportasi Air | F33: TUS 1 | G33: RIT | J33: Ha | K33: 1 | L33: =L32 -> 27.8 | M33: 0.27 | N33: 1 | O33: =K33*L33*M33*N33 -> 7.506 | P33: =200000 -> 200000 | Q33: =P33*$O33 -> 1501200 | R33: =VLOOKUP($F33,'Master Harga'!$E$5:$L$348,6,FALSE) -> 75235.44 | S33: =R33*$O33 -> 564717.21 | T33: =VLOOKUP($F33,'Master Harga'!$E$5:$L$348,7,FALSE) -> 85768.402 | U33: =T33*$O33 -> 643777.62 | V33: =W33/O33 -> 120334.61 | W33: =AVERAGEIF($P$4:$U$4,W$4,$P33:$U33) -> 903231.61 | AA33: =Q33/$E$2 -> 54000
D34: SUB JUMLAH IMAS TUMBANG PERUN | Q34: =SUM(Q8:Q33) -> 6.5474023e+08 | AA34: =Q34/$E$2 -> 23551807 | AB34: =Q34/$Q$214*100 -> 26.860001
B35: PEMBUATAN SARANA PRASARANA
C36: PEMBUATAN JALAN
D37: Pembuatan Jalan Produksi | F37: Upah PHL | G37: HK | J37: Ha | K37: 0.25 | L37: =E2 -> 27.8 | M37: 1 | N37: 1 | O37: =K37*L37*M37*N37 -> 6.95 | P37: =VLOOKUP($F37,'Master Harga'!$E$5:$L$348,6,FALSE) -> 151208.64 | Q37: =P37*$O37 -> 1050900 | R37: =VLOOKUP($F37,'Master Harga'!$E$5:$L$348,6,FALSE) -> 151208.64 | S37: =R37*$O37 -> 1050900 | T37: =VLOOKUP($F37,'Master Harga'!$E$5:$L$348,7,FALSE) -> 163305.33 | U37: =T37*$O37 -> 1134972.1 | V37: =W37/O37 -> 155240.87 | W37: =AVERAGEIF($P$4:$U$4,W$4,$P37:$U37) -> 1078924 | AA37: =Q37/$E$2 -> 37802.16
F38: Greader 1 | G38: HM | J38: HM | K38: 1 | L38: =E2*33.33 -> 926.574 | M38: 0.009 | N38: 1 | O38: =K38*L38*M38*N38 -> 8.339166 | P38: =VLOOKUP($F38,'Master Harga'!$E$5:$L$348,6,FALSE) -> 715047.83 | Q38: =P38*$O38 -> 5962902.5 | R38: =VLOOKUP($F38,'Master Harga'!$E$5:$L$348,6,FALSE) -> 715047.83 | S38: =R38*$O38 -> 5962902.5 | T38: =VLOOKUP($F38,'Master Harga'!$E$5:$L$348,7,FALSE) -> 751428.67 | U38: =T38*$O38 -> 6266288.4 | V38: =W38/O38 -> 727174.77 | W38: =AVERAGEIF($P$4:$U$4,W$4,$P38:$U38) -> 6064031.1 | AA38: =Q38/$E$2 -> 214492.9
D39: Pembuatan Jalan Produksi | F39: Upah PHL | G39: HK | J39: Ha | K39: 0.25 | L39: =E2 -> 27.8 | M39: 1 | N39: 1 | O39: =K39*L39*M39*N39 -> 6.95 | P39: =VLOOKUP($F39,'Master Harga'!$E$5:$L$348,6,FALSE) -> 151208.64 | Q39: =P39*$O39 -> 1050900 | R39: =VLOOKUP($F39,'Master Harga'!$E$5:$L$348,6,FALSE) -> 151208.64 | S39: =R39*$O39 -> 1050900 | T39: =VLOOKUP($F39,'Master Harga'!$E$5:$L$348,7,FALSE) -> 163305.33 | U39: =T39*$O39 -> 1134972.1 | V39: =W39/O39 -> 155240.87 | W39: =AVERAGEIF($P$4:$U$4,W$4,$P39:$U39) -> 1078924 | AA39: =Q39/$E$2 -> 37802.16
F40: Farm Traktor 1 | G40: HM | J40: HM | K40: 1 | L40: =E2 -> 27.8 | M40: 2 | N40: 1 | O40: =K40*L40*M40*N40 -> 55.6 | P40: =VLOOKUP($F40,'Master Harga'!$E$5:$L$348,6,FALSE) -> 369600 | Q40: =P40*$O40 -> 20549760 | R40: =VLOOKUP($F40,'Master Harga'!$E$5:$L$348,6,FALSE) -> 369600 | S40: =R40*$O40 -> 20549760 | T40: =VLOOKUP($F40,'Master Harga'!$E$5:$L$348,7,FALSE) -> 413952 | U40: =T40*$O40 -> 23015731 | V40: =W40/O40 -> 384384 | W40: =AVERAGEIF($P$4:$U$4,W$4,$P40:$U40) -> 21371750 | AA40: =Q40/$E$2 -> 739200
...

Sheet SI TB LC Pakchong (FFD)
B1: RKP TANAM PASTURA (Pakchong)
D2: Luas: | E2: ='Areal Stmt'!G35 -> 31.16 | F2: Jumlah Populasi | G2: =E2*5000 -> 155800 | Q2: Hasil Panen | AA2: =E2*72000*AF8 -> 38139840 | AB2: Kg | AD2: Hasil Panen | AF2: Bulan | AG2: Tahun
B3: Pekerjaan | F3: Material | H3: Rotasi APD | J3: TB/LC | P3: 2026 s.d 2028 | R3: 2026 | T3: 2027 | V3: Rata-rata | X3: Keterangan | Y3: BIAYA/HA | Z3: Biaya/pkk | AA3: Rp/Ha | AB3: Persentase (%) | AD3: Tanam | AE3: 46266 | AF3: Des | AG3: 2026
F4: Jenis | G4: Sat | J4: Sat | K4: Vol | M4: Norma | N4: Rotasi | O4: Jumlah Unit | P4: Rp Sat | Q4: Jumlah RP | R4: Rp Sat | S4: Jumlah RP | T4: Rp Sat | U4: Jumlah RP | V4: Rp Sat | W4: Jumlah RP | AD4: Panen | AE4: 1 | AF4: 8 x | AG4: 2027
K5: % | L5: Luas/Mtr/Pkk/Unit | AE5: 2 | AF5: 8 x | AG5: 2028
B6: PEMBUKAAN LAHAN
C7: IMAS,TUMBANG, PERUN
D8: Identifikasi Blok | F8: Upah PHL | G8: HK | J8: Ha | K8: 1 | L8: =E2 -> 31.16 | M8: 0.25 | N8: 1 | O8: =K8*L8*M8*N8 -> 7.79 | P8: =VLOOKUP($F8,'Master Harga'!$E$5:$L$348,6,FALSE) -> 151208.64 | Q8: =P8*$O8 -> 1177915.3 | R8: =VLOOKUP($F8,'Master Harga'!$E$5:$L$348,6,FALSE) -> 151208.64 | S8: =R8*$O8 -> 1177915.3 | T8: =VLOOKUP($F8,'Master Harga'!$E$5:$L$348,7,FALSE) -> 163305.33 | U8: =T8*$O8 -> 1272148.5 | V8: =W8/O8 -> 155240.87 | W8: =AVERAGEIF($P$4:$U$4,W$4,$P8:$U8) -> 1209326.4 | AA8: =Q8/$E$2 -> 37802.16 | AE8: Total | AF8: 17 | AG8: Kali Panen
D9: Imas | E9: Hutan Primer | F9: Upah PHL | G9: HK | M9: 10 | N9: 1 | X9: Vol sesuai kondisi
E10: Hutan Sekunder | F10: Upah PHL | G10: HK | M10: 10 | N10: 1 | P10: 0
E11: Semak Belukar | F11: Upah PHL | G11: HK | J11: Ha | K11: 0.4 | L11: =L8 -> 31.16 | M11: 10 | N11: 1 | O11: =K11*L11*M11*N11 -> 124.64 | P11: =VLOOKUP($F11,'Master Harga'!$E$5:$L$348,6,FALSE) -> 151208.64 | Q11: =P11*$O11 -> 18846645 | R11: =VLOOKUP($F11,'Master Harga'!$E$5:$L$348,6,FALSE) -> 151208.64 | S11: =R11*$O11 -> 18846645 | T11: =VLOOKUP($F11,'Master Harga'!$E$5:$L$348,7,FALSE) -> 163305.33 | U11: =T11*$O11 -> 20354376 | V11: =W11/O11 -> 155240.87 | W11: =AVERAGEIF($P$4:$U$4,W$4,$P11:$U11) -> 19349222 | AA11: =Q11/$E$2 -> 604834.56
D12: Perun Mekanis | E12: Hutan Primer | F12: Buldozer 1 | G12: HM | J12: Ha | K12: 0.08 | L12: =E2 -> 31.16 | M12: 18 | N12: 1 | O12: =K12*L12*M12*N12 -> 44.8704 | P12: =VLOOKUP($F12,'Master Harga'!$E$5:$L$348,6,FALSE) -> 1051433.7 | Q12: =P12*$O12 -> 47178250 | AA12: =Q12/$E$2 -> 1514064.5
E13: Reklamasi | F13: Excavator 1 | G13: HM | J13: HM | K13: 0.1 | L13: =L8 -> 31.16 | M13: 8 | N13: 1 | O13: =K13*L13*M13*N13 -> 24.928 | P13: =VLOOKUP($F13,'Master Harga'!$E$5:$L$348,6,FALSE) -> 720338.07 | Q13: =P13*$O13 -> 17956587 | AA13: =Q13/$E$2 -> 576270.46
D14: Abu Jangkos 5 Ton/Ha | F14: Upah PHL | G14: HK | J14: Hk | K14: 1 | L14: =E2 -> 31.16 | M14: 10 | N14: 1 | O14: =K14*L14*M14*N14 -> 311.6 | P14: =VLOOKUP($F14,'Master Harga'!$E$5:$L$348,6,FALSE) -> 151208.64 | Q14: =P14*$O14 -> 47116612 | R14: =VLOOKUP($F14,'Master Harga'!$E$5:$L$348,6,FALSE) -> 151208.64 | S14: =R14*$O14 -> 47116612 | T14: =VLOOKUP($F14,'Master Harga'!$E$5:$L$348,7,FALSE) -> 163305.33 | U14: =T14*$O14 -> 50885941 | V14: =W14/O14 -> 155240.87 | W14: =AVERAGEIF($P$4:$U$4,W$4,$P14:$U14) -> 48373055 | X14: 5 Gram/Pkk | Z14: =W14 -> 48373055 | AA14: =Q14/$E$2 -> 1512086.4
F15: Angkutan Abu Boiler | G15: Ha | J15: Ton | K15: 1 | L15: =E2 -> 31.16 | M15: 5 | N15: 1 | O15: =K15*L15*M15*N15 -> 155.8 | P15: =VLOOKUP($F15,'Master Harga'!$E$5:$L$348,6,FALSE) -> 71700 | Q15: =P15*$O15 -> 11170860 | R15: =VLOOKUP($F15,'Master Harga'!$E$5:$L$348,6,FALSE) -> 71700 | S15: =R15*$O15 -> 11170860 | T15: =VLOOKUP($F15,'Master Harga'!$E$5:$L$348,7,FALSE) -> 81738 | U15: =T15*$O15 -> 12734780 | V15: =W15/O15 -> 75046 | W15: =AVERAGEIF($P$4:$U$4,W$4,$P15:$U15) -> 11692167 | X15: 5 Gram/Pkk | Z15: =W15 -> 11692167 | AA15: =Q15/$E$2 -> 358500
D16: Pengolahan Tanah I | F16: Farm Traktor 1 | G16: HM | J16: HM/Ha | K16: 1 | L16: =L13 -> 31.16 | M16: 3.5 | N16: 1 | O16: =K16*L16*M16*N16 -> 109.06 | P16: =VLOOKUP($F16,'Master Harga'!$E$5:$L$348,6,FALSE) -> 369600 | Q16: =P16*$O16 -> 40308576 | AA16: =Q16/$E$2 -> 1293600
D17: Pupuk Kandang 5 Ton/Ha | F17: Upah PHL | G17: HK | J17: Hk | K17: 1 | L17: =E2 -> 31.16 | M17: 10 | N17: 1 | O17: =K17*L17*M17*N17 -> 311.6 | P17: =VLOOKUP($F17,'Master Harga'!$E$5:$L$348,6,FALSE) -> 151208.64 | Q17: =P17*$O17 -> 47116612 | R17: =VLOOKUP($F17,'Master Harga'!$E$5:$L$348,6,FALSE) -> 151208.64 | S17: =R17*$O17 -> 47116612 | T17: =VLOOKUP($F17,'Master Harga'!$E$5:$L$348,7,FALSE) -> 163305.33 | U17: =T17*$O17 -> 50885941 | V17: =W17/O17 -> 155240.87 | W17: =AVERAGEIF($P$4:$U$4,W$4,$P17:$U17) -> 48373055 | X17: 5 Gram/Pkk | Z17: =W17 -> 48373055 | AA17: =Q17/$E$2 -> 1512086.4
F18: Pupuk Kandang | G18: Ha | J18: Ton | K18: 1 | L18: =E2 -> 31.16 | M18: 5 | N18: 1 | O18: =K18*L18*M18*N18 -> 155.8 | P18: =VLOOKUP($F18,'Master Harga'!$E$5:$L$348,6,FALSE) -> 980000 | Q18: =P18*$O18 -> 1.52684e+08 | R18: =VLOOKUP($F18,'Master Harga'!$E$5:$L$348,6,FALSE) -> 980000 | S18: =R18*$O18 -> 1.52684e+08 | T18: =VLOOKUP($F18,'Master Harga'!$E$5:$L$348,7,FALSE) -> 1372000 | U18: =T18*$O18 -> 2.137576e+08 | V18: =W18/O18 -> 1110666.7 | W18: =AVERAGEIF($P$4:$U$4,W$4,$P18:$U18) -> 1.7304187e+08 | X18: 5 Gram/Pkk | Z18: =W18 -> 1.7304187e+08 | AA18: =Q18/$E$2 -> 4900000
D19: Pengolahan Tanah II | F19: Farm Traktor 1 | G19: HM | J19: HM/Ha | K19: 1 | L19: =L16 -> 31.16 | M19: 3.5 | N19: 1 | O19: =K19*L19*M19*N19 -> 109.06 | P19: =VLOOKUP($F19,'Master Harga'!$E$5:$L$348,6,FALSE) -> 369600 | Q19: =P19*$O19 -> 40308576 | AA19: =Q19/$E$2 -> 1293600
D20: Pengolahan Tanah III | F20: Farm Traktor 1 | G20: HM | J20: HM/Ha | K20: 1 | L20: =L19 -> 31.16 | M20: 2.5 | N20: 1 | O20: =K20*L20*M20*N20 -> 77.9 | P20: =VLOOKUP($F20,'Master Harga'!$E$5:$L$348,6,FALSE) -> 369600 | Q20: =P20*$O20 -> 28791840 | AA20: =Q20/$E$2 -> 924000
D21: Pembuatan Pagar | F21: Upah PHL | G21: HK | J21: Hk/Bbt | K21: 1 | L21: =L20 -> 31.16 | M21: 2 | N21: 1 | O21: =K21*L21*M21*N21 -> 62.32 | P21: =VLOOKUP($F21,'Master Harga'!$E$5:$L$348,6,FALSE) -> 151208.64 | Q21: =P21*$O21 -> 9423322.4 | AA21: =Q21/$E$2 -> 302417.28
F22: Plastik Hitam | G22: Mtr | J22: Mtr/Bbt | K22: 1 | L22: =L21 -> 31.16 | M22: 1.95 | N22: 1 | O22: =K22*L22*M22*N22 -> 60.762 | P22: =VLOOKUP($F22,'Master Harga'!$E$5:$L$348,6,FALSE) -> 3360 | Q22: =P22*$O22 -> 204160.32 | AA22: =Q22/$E$2 -> 6552
F23: Patok Kayu | G23: Btg | J23: Btg/Bbt | K23: 1 | L23: 0 | M23: 0.7506 | N23: 1 | O23: =K23*L23*M23*N23 -> 0 | P23: =VLOOKUP($F23,'Master Harga'!$E$5:$L$348,6,FALSE) -> 22400 | Q23: =P23*$O23 -> 0 | AA23: =Q23/$E$2 -> 0
F24: Kawat Duri | G24: Rol | J24: Mtr/Bbt | K24: 1 | L24: =L23 -> 0 | M24: 0.343 | N24: 1 | O24: =K24*L24*M24*N24 -> 0 | P24: =VLOOKUP($F24,'Master Harga'!$E$5:$L$348,6,FALSE) -> 178071.6 | Q24: =P24*$O24 -> 0 | AA24: =Q24/$E$2 -> 0
F25: Paku 1" | G25: Kg | J25: Kg/Bbt | K25: 1 | L25: =L24 -> 0 | M25: 0.15 | N25: 1 | O25: =K25*L25*M25*N25 -> 0 | P25: =VLOOKUP($F25,'Master Harga'!$E$5:$L$348,6,FALSE) -> 20263.32 | Q25: =P25*$O25 -> 0 | AA25: =Q25/$E$2 -> 0
F26: Paku 2.5" | G26: Kg | J26: Kg/Bbt | K26: 1 | L26: =L25 -> 0 | M26: 0.15 | N26: 1 | O26: =K26*L26*M26*N26 -> 0 | P26: =VLOOKUP($F26,'Master Harga'!$E$5:$L$348,6,FALSE) -> 18421.2 | Q26: =P26*$O26 -> 0 | AA26: =Q26/$E$2 -> 0
D27: Pemberantasan Lalang dan Gulma Lainnya | F27: Upah PHL | G27: HK | J27: Ha | K27: 1 | L27: =E2 -> 31.16 | M27: 1.5 | N27: 1 | O27: =K27*L27*M27*N27 -> 46.74 | P27: =VLOOKUP($F27,'Master Harga'!$E$5:$L$348,6,FALSE) -> 151208.64 | Q27: =P27*$O27 -> 7067491.8 | R27: =VLOOKUP($F27,'Master Harga'!$E$5:$L$348,6,FALSE) -> 151208.64 | S27: =R27*$O27 -> 7067491.8 | T27: =VLOOKUP($F27,'Master Harga'!$E$5:$L$348,7,FALSE) -> 163305.33 | U27: =T27*$O27 -> 7632891.2 | V27: =W27/O27 -> 155240.87 | W27: =AVERAGEIF($P$4:$U$4,W$4,$P27:$U27) -> 7255958.3 | AA27: =Q27/$E$2 -> 226812.96
F28: Sprayer (Inter) | G28: Buah | J28: Ha | K28: 1 | L28: =L27 -> 31.16 | M28: 0.031 | N28: 1 | O28: =K28*L28*M28*N28 -> 0.96596 | P28: =VLOOKUP($F28,'Master Harga'!$E$5:$L$348,6,FALSE) -> 1530444.7 | Q28: =P28*$O28 -> 1478348.4 | R28: =VLOOKUP($F28,'Master Harga'!$E$5:$L$348,6,FALSE) -> 1530444.7 | S28: =R28*$O28 -> 1478348.4 | T28: =VLOOKUP($F28,'Master Harga'!$E$5:$L$348,7,FALSE) -> 1714098.1 | U28: =T28*$O28 -> 1655750.2 | V28: =W28/O28 -> 1591662.5 | W28: =AVERAGEIF($P$4:$U$4,W$4,$P28:$U28) -> 1537482.3 | AA28: =Q28/$E$2 -> 47443.786
F29: Glyphosate | G29: Liter | J29: Ha | K29: 0.235 | L29: =L28 -> 31.16 | M29: 0.9 | N29: 1 | O29: =K29*L29*M29*N29 -> 6.59034 | P29: =VLOOKUP($F29,'Master Harga'!$E$5:$L$348,6,FALSE) -> 35343 | Q29: =P29*$O29 -> 232922.39 | AA29: =Q29/$E$2 -> 7475.0445
F30: Metil Metsulfuron | G30: Kg | J30: Ha | K30: 0.74 | L30: =L29 -> 31.16 | M30: 0.036 | N30: 1 | O30: =K30*L30*M30*N30 -> 0.8301024 | P30: =VLOOKUP($F30,'Master Harga'!$E$5:$L$348,6,FALSE) -> 96390 | Q30: =P30*$O30 -> 80013.57 | R30: =VLOOKUP($F30,'Master Harga'!$E$5:$L$348,6,FALSE) -> 96390 | S30: =R30*$O30 -> 80013.57 | T30: =VLOOKUP($F30,'Master Harga'!$E$5:$L$348,7,FALSE) -> 109884.6 | U30: =T30*$O30 -> 91215.47 | V30: =W30/O30 -> 100888.2 | W30: =AVERAGEIF($P$4:$U$4,W$4,$P30:$U30) -> 83747.537 | AA30: =Q30/$E$2 -> 2567.8296
F31: Parakuat | G31: Liter | J31: Ha | K31: 0.5 | L31: =L30 -> 31.16 | M31: 0.9 | N31: 1 | O31: =K31*L31*M31*N31 -> 14.022 | P31: =VLOOKUP($F31,'Master Harga'!$E$5:$L$348,6,FALSE) -> 28381.5 | Q31: =P31*$O31 -> 397965.39 | R31: =VLOOKUP($F31,'Master Harga'!$E$5:$L$348,6,FALSE) -> 28381.5 | S31: =R31*$O31 -> 397965.39 | T31: =VLOOKUP($F31,'Master Harga'!$E$5:$L$348,7,FALSE) -> 32354.91 | U31: =T31*$O31 -> 453680.55 | V31: =W31/O31 -> 29705.97 | W31: =AVERAGEIF($P$4:$U$4,W$4,$P31:$U31) -> 416537.11 | AA31: =Q31/$E$2 -> 12771.675
F32: Perekat | G32: Liter | J32: Ha | K32: 0.74 | L32: =L31 -> 31.16 | M32: 0.27 | N32: 1 | O32: =K32*L32*M32*N32 -> 6.225768 | P32: =VLOOKUP($F32,'Master Harga'!$E$5:$L$348,6,FALSE) -> 44982 | Q32: =P32*$O32 -> 280047.5 | R32: =VLOOKUP($F32,'Master Harga'!$E$5:$L$348,6,FALSE) -> 44982 | S32: =R32*$O32 -> 280047.5 | T32: =VLOOKUP($F32,'Master Harga'!$E$5:$L$348,7,FALSE) -> 51279.48 | U32: =T32*$O32 -> 319254.15 | V32: =W32/O32 -> 47081.16 | W32: =AVERAGEIF($P$4:$U$4,W$4,$P32:$U32) -> 293116.38 | AA32: =Q32/$E$2 -> 8987.4036
F33: Premi Extra Fooding | G33: HK | J33: Ha | K33: 1 | L33: =L32 -> 31.16 | M33: =M27 -> 1.5 | N33: 1 | O33: =K33*L33*M33*N33 -> 46.74 | P33: =VLOOKUP($F33,'Master Harga'!$E$5:$L$348,6,FALSE) -> 3996 | Q33: =P33*$O33 -> 186773.04 | R33: =VLOOKUP($F33,'Master Harga'!$E$5:$L$348,6,FALSE) -> 3996 | S33: =R33*$O33 -> 186773.04 | T33: =VLOOKUP($F33,'Master Harga'!$E$5:$L$348,7,FALSE) -> 4315.68 | U33: =T33*$O33 -> 201714.88 | V33: =W33/O33 -> 4102.56 | W33: =AVERAGEIF($P$4:$U$4,W$4,$P33:$U33) -> 191753.65 | AA33: =Q33/$E$2 -> 5994
F34: Celemek | G34: Buah | H34: 4 | I34: X | J34: Ha | K34: 1 | L34: =L33 -> 31.16 | M34: =((M$27*N$27)/240*($H34/N34)) -> 0.025 | N34: 1 | O34: =K34*L34*M34*N34 -> 0.779 | P34: =VLOOKUP($F34,'Master Harga'!$E$5:$L$348,6,FALSE) -> 47980.8 | Q34: =P34*$O34 -> 37377.043 | R34: =VLOOKUP($F34,'Master Harga'!$E$5:$L$348,6,FALSE) -> 47980.8 | S34: =R34*$O34 -> 37377.043 | T34: =VLOOKUP($F34,'Master Harga'!$E$5:$L$348,7,FALSE) -> 53738.496 | U34: =T34*$O34 -> 41862.288 | V34: =W34/O34 -> 49900.032 | W34: =AVERAGEIF($P$4:$U$4,W$4,$P34:$U34) -> 38872.125 | AA34: =Q34/$E$2 -> 1199.52
F35: Masker Chemical | G35: Buah | H35: 12 | I35: X | J35: Ha | K35: 1 | L35: =L34 -> 31.16 | M35: =((M$27*N$27)/240*($H35/N35)) -> 0.075 | N35: 1 | O35: =K35*L35*M35*N35 -> 2.337 | P35: =VLOOKUP($F35,'Master Harga'!$E$5:$L$348,6,FALSE) -> 15680 | Q35: =P35*$O35 -> 36644.16 | R35: =VLOOKUP($F35,'Master Harga'!$E$5:$L$348,6,FALSE) -> 15680 | S35: =R35*$O35 -> 36644.16 | T35: =VLOOKUP($F35,'Master Harga'!$E$5:$L$348,7,FALSE) -> 17561.6 | U35: =T35*$O35 -> 41041.459 | V35: =W35/O35 -> 16307.2 | W35: =AVERAGEIF($P$4:$U$4,W$4,$P35:$U35) -> 38109.926 | AA35: =Q35/$E$2 -> 1176
F36: Kaca mata | G36: Buah | H36: 1 | I36: X | J36: Ha | K36: 1 | L36: =L35 -> 31.16 | M36: =((M$27*N$27)/240*($H36/N36)) -> 0.00625 | N36: 1 | O36: =K36*L36*M36*N36 -> 0.19475 | P36: =VLOOKUP($F36,'Master Harga'!$E$5:$L$348,6,FALSE) -> 41983.2 | Q36: =P36*$O36 -> 8176.2282 | R36: =VLOOKUP($F36,'Master Harga'!$E$5:$L$348,6,FALSE) -> 41983.2 | S36: =R36*$O36 -> 8176.2282 | T36: =VLOOKUP($F36,'Master Harga'!$E$5:$L$348,7,FALSE) -> 47021.184 | U36: =T36*$O36 -> 9157.3756 | V36: =W36/O36 -> 43662.528 | W36: =AVERAGEIF($P$4:$U$4,W$4,$P36:$U36) -> 8503.2773 | AA36: =Q36/$E$2 -> 262.395
F37: Sarung Tangan Karet | G37: Buah | H37: 2 | I37: X | J37: Ha | K37: 1 | L37: =L36 -> 31.16 | M37: =((M$27*N$27)/240*($H37/N37)) -> 0.0125 | N37: 1 | O37: =K37*L37*M37*N37 -> 0.3895 | P37: =VLOOKUP($F37,'Master Harga'!$E$5:$L$348,6,FALSE) -> 35985.6 | Q37: =P37*$O37 -> 14016.391 | R37: =VLOOKUP($F37,'Master Harga'!$E$5:$L$348,6,FALSE) -> 35985.6 | S37: =R37*$O37 -> 14016.391 | T37: =VLOOKUP($F37,'Master Harga'!$E$5:$L$348,7,FALSE) -> 40303.872 | U37: =T37*$O37 -> 15698.358 | V37: =W37/O37 -> 37425.024 | W37: =AVERAGEIF($P$4:$U$4,W$4,$P37:$U37) -> 14577.047 | AA37: =Q37/$E$2 -> 449.82
F38: Sepatu Boots | G38: Buah | H38: 1 | I38: X | J38: Ha | K38: 1 | L38: =L37 -> 31.16 | M38: =((M$27*N$27)/240*($H38/N38)) -> 0.00625 | N38: 1 | O38: =K38*L38*M38*N38 -> 0.19475 | P38: =VLOOKUP($F38,'Master Harga'!$E$5:$L$348,6,FALSE) -> 95961.6 | Q38: =P38*$O38 -> 18688.522 | R38: =VLOOKUP($F38,'Master Harga'!$E$5:$L$348,6,FALSE) -> 95961.6 | S38: =R38*$O38 -> 18688.522 | T38: =VLOOKUP($F38,'Master Harga'!$E$5:$L$348,7,FALSE) -> 107476.99 | U38: =T38*$O38 -> 20931.144 | V38: =W38/O38 -> 99800.064 | W38: =AVERAGEIF($P$4:$U$4,W$4,$P38:$U38) -> 19436.062 | AA38: =Q38/$E$2 -> 599.76
E39: Transportasi Air | F39: TUS 1 | G39: RIT | J39: Ha | K39: 1 | L39: =L38 -> 31.16 | M39: 0.27 | N39: 1 | O39: =K39*L39*M39*N39 -> 8.4132 | P39: =200000 -> 200000 | Q39: =P39*$O39 -> 1682640 | R39: =VLOOKUP($F39,'Master Harga'!$E$5:$L$348,6,FALSE) -> 75235.44 | S39: =R39*$O39 -> 632970.8 | T39: =VLOOKUP($F39,'Master Harga'!$E$5:$L$348,7,FALSE) -> 85768.402 | U39: =T39*$O39 -> 721586.72 | V39: =W39/O39 -> 120334.61 | W39: =AVERAGEIF($P$4:$U$4,W$4,$P39:$U39) -> 1012399.2 | AA39: =Q39/$E$2 -> 54000
D40: SUB JUMLAH IMAS TUMBANG PERUN | Q40: =SUM(Q8:Q39) -> 4.7380506e+08 | AA40: =Q40/$E$2 -> 15205554 | AB40: =Q40/$Q$209*100 -> 25.905297
...

Sheet Kebutuhan TK FFD
B2: Project | D2: : Tanam Pastura
B3: Area | D3: : PT Fass Forest Development
B5: RENCANA KEBUTUHAN HK | O5: Indigofera | P5: Pakchong
B6: No | C6: Uraian | G6: Harga Sat (Rp) | H6: Estimasi Biaya (Rp) | I6: Pastura | K6: Rp/Ha | N6: Material | O6: =#REF! -> #REF! | P6: =#REF! -> #REF!
D7: Indigofera | E7: Pakchong | F7: Total | I7: Indigofera | J7: Pakchong | N7: HK | O7: =I9+I10+I11+I12 -> 1.2119753e+09 | P7: =J9+J10+J11+J12 -> 7.3964644e+08
D8: HK | E8: HK | I8: (Rp) | J8: (Rp) | N8: Alat Berat | O8: =#REF! -> #REF! | P8: =#REF! -> #REF!
B9: 1 | C9: Pembukaan Lahan | D9: ='SI TB LC Indigofera (FFD)'!O8+'SI TB LC Indigofera (FFD)'!O11+'SI TB LC Indigofera (FFD)'!O14+'SI TB LC Indigofera (FFD)'!O17+'SI TB LC Indigofera (FFD)'!O21 -> 682.49 | E9: ='SI TB LC Pakchong (FFD)'!O8+'SI TB LC Pakchong (FFD)'!O11+'SI TB LC Pakchong (FFD)'!O14+'SI TB LC Pakchong (FFD)'!O17+'SI TB LC Pakchong (FFD)'!O21+'SI TB LC Pakchong (FFD)'!O27 -> 864.69 | F9: =D9+E9 -> 1547.18 | G9: ='Master Harga'!$J$8 -> 151208.64 | H9: =G9*F9 -> 2.3394698e+08 | I9: =D9*G9 -> 1.0319838e+08 | J9: =G9*E9 -> 1.307486e+08 | K9: =H9/'Areal Stmt'!$G$25 -> 3967893.2 | N9: Lainnya | O9: =O10-(O6+O7+O8) -> #REF! | P9: =#REF!-(P6+P7+P8) -> #REF!
B10: 2 | C10: Pembuatan Sarana & Prasarana | D10: ='SI TB LC Indigofera (FFD)'!O37+'SI TB LC Indigofera (FFD)'!O39+'SI TB LC Indigofera (FFD)'!O64+'SI TB LC Indigofera (FFD)'!O69+'SI TB LC Indigofera (FFD)'!O71+'SI TB LC Indigofera (FFD)'!O73 -> 14.9 | E10: ='SI TB LC Pakchong (FFD)'!O43+'SI TB LC Pakchong (FFD)'!O45+'SI TB LC Pakchong (FFD)'!O70 -> 16.58 | F10: =D10+E10 -> 31.48 | G10: ='Master Harga'!$J$8 -> 151208.64 | H10: =G10*F10 -> 4760048 | I10: =D10*G10 -> 2253008.7 | J10: =G10*E10 -> 2507039.3 | K10: =H10/'Areal Stmt'!$G$25 -> 80733.514 | O10: =#REF! -> #REF! | P10: =#REF! -> #REF!
B11: 3 | C11: Tanam & Pemeliharaan Awal | D11: ='SI TB LC Indigofera (FFD)'!O119+'SI TB LC Indigofera (FFD)'!O121+'SI TB LC Indigofera (FFD)'!O128+'SI TB LC Indigofera (FFD)'!O130+'SI TB LC Indigofera (FFD)'!O131+'SI TB LC Indigofera (FFD)'!O132+'SI TB LC Indigofera (FFD)'!O134+'SI TB LC Indigofera (FFD)'!O158+'SI TB LC Indigofera (FFD)'!O160+'SI TB LC Indigofera (FFD)'!O161+'SI TB LC Indigofera (FFD)'!O164+'SI TB LC Indigofera (FFD)'!O185+'SI TB LC Indigofera (FFD)'!O187+'SI TB LC Indigofera (FFD)'!O191 -> 3981.862 | E11: ='SI TB LC Pakchong (FFD)'!O125+'SI TB LC Pakchong (FFD)'!O127+'SI TB LC Pakchong (FFD)'!O129+'SI TB LC Pakchong (FFD)'!O153+'SI TB LC Pakchong (FFD)'!O155+'SI TB LC Pakchong (FFD)'!O156+'SI TB LC Pakchong (FFD)'!O159+'SI TB LC Pakchong (FFD)'!O180+'SI TB LC Pakchong (FFD)'!O182+'SI TB LC Pakchong (FFD)'!O186 -> 2950.852 | F11: =D11+E11 -> 6932.714 | G11: ='Master Harga'!$J$8 -> 151208.64 | H11: =G11*F11 -> 1.0482862e+09 | I11: =D11*G11 -> 6.0209193e+08 | J11: =G11*E11 -> 4.4619432e+08 | K11: =H11/'Areal Stmt'!$G$25 -> 17779618
B12: 4 | C12: Panen | D12: ='SI TB LC Indigofera (FFD)'!O209 -> 3336 | E12: ='SI TB LC Pakchong (FFD)'!O204 -> 1059.44 | F12: =D12+E12 -> 4395.44 | G12: ='Master Harga'!$J$8 -> 151208.64 | H12: =G12*F12 -> 6.646285e+08 | I12: =D12*G12 -> 5.0443202e+08 | J12: =G12*E12 -> 1.6019648e+08 | K12: =H12/'Areal Stmt'!$G$25 -> 11272532
B13: 5 | C13: Angkutan, Borongan dan Lainnya | H13: =I13+J13 -> 6.6958377e+08 | I13: ='RKP FFD'!E21-('Kebutuhan TK FFD'!I9+'Kebutuhan TK FFD'!I10+'Kebutuhan TK FFD'!I11+'Kebutuhan TK FFD'!I12+'Kebutuhan Material FFD'!J40+'KeB.HM Alat Berat (FFD)'!K13) -> 4.4593481e+08 | J13: ='RKP FFD'!E22-('Kebutuhan TK FFD'!J9+'Kebutuhan TK FFD'!J10+'Kebutuhan TK FFD'!J11+'Kebutuhan TK FFD'!J12+'Kebutuhan Material FFD'!K40+'KeB.HM Alat Berat (FFD)'!L13) -> 2.2364896e+08 | K13: =H13/'Areal Stmt'!$G$25 -> 11356577
B14: Total | D14: =SUM(D9:D12) -> 8015.252 | E14: =SUM(E9:E12) -> 4891.562 | F14: =SUM(F9:F12) -> 12906.814 | H14: =SUM(H9:H13) -> 2.6212056e+09 | I14: =SUM(I9:I13) -> 1.6579102e+09 | J14: =SUM(J9:J13) -> 9.632954e+08 | K14: =H14/'Areal Stmt'!$G$25 -> 44457353

Sheet Kebutuhan Material FFD
B2: Project | D2: : | E2: Tanam Pastura
B3: Area | D3: : | E3: PT Fass Forest Development
B4: Luas (ha) | D4: : | E4: ='Areal Stmt'!G32+'Areal Stmt'!G35 -> 58.96 | F4: Ha
B5: RENCANA KEBUTUHAN MATERIAL
B6: No | C6: Uraian | D6: Sat | E6: Peruntukan | H6: Harga Sat (Rp) | I6: Estimasi Biaya (Rp) | J6: Pastura | L6: Rp/Ha
E7: Indigofera | F7: Pakchong | G7: Total | J7: Indigofera | K7: Pakchong
B8: 1 | C8: Benih / Bibit
C9: - Benih Indigofera | D9: Kg | E9: ='SI TB LC Indigofera (FFD)'!O120 -> 3.1784667 | G9: =SUM(E9:F9) -> 3.1784667 | H9: ='Master Harga'!J185 -> 28500 | I9: =H9*G9 -> 90586.3 | J9: =E9*H9 -> 90586.3 | K9: =F9*H9 -> 0 | L9: =I9/75.9 -> 1193.4954
C10: - Bibit Pakchong | D10: Pkk | F10: ='SI TB LC Pakchong (FFD)'!O126 -> 560880 | G10: =SUM(E10:F10) -> 560880 | H10: ='Master Harga'!J186 -> 456 | I10: =H10*G10 -> 2.5576128e+08 | J10: =E10*H10 -> 0 | K10: =F10*H10 -> 2.5576128e+08 | L10: =I10/75.9 -> 3369713.8
B11: 2 | C11: Pupuk Organik
C12: - Abu Boiler | D12: Ton | E12: ='SI TB LC Indigofera (FFD)'!O15 -> 139 | F12: ='SI TB LC Pakchong (FFD)'!O15 -> 155.8 | G12: =SUM(E12:F12) -> 294.8 | H12: ='SI TB LC Indigofera (FFD)'!P15 -> 71700 | I12: =H12*G12 -> 21137160 | J12: =E12*H12 -> 9966300 | K12: =F12*H12 -> 11170860 | L12: =I12/75.9 -> 278486.96
C13: - Janjang Kosong | D13: Ton | E13: ='SI TB LC Indigofera (FFD)'!O165 -> 278 | F13: ='SI TB LC Pakchong (FFD)'!O160 -> 311.6 | G13: =SUM(E13:F13) -> 589.6 | H13: ='SI TB LC Indigofera (FFD)'!P165 -> 71700 | I13: =H13*G13 -> 42274320 | J13: =E13*H13 -> 19932600 | K13: =F13*H13 -> 22341720 | L13: =I13/75.9 -> 556973.91
C14: - Pupuk Kandang | D14: Ton | E14: ='SI TB LC Indigofera (FFD)'!O18 -> 139 | F14: ='SI TB LC Pakchong (FFD)'!O18 -> 155.8 | G14: =SUM(E14:F14) -> 294.8 | H14: ='Master Harga'!J148 -> 980000 | I14: =H14*G14 -> 2.88904e+08 | J14: =E14*H14 -> 1.3622e+08 | K14: =F14*H14 -> 1.52684e+08 | L14: =I14/75.9 -> 3806376.8
B15: 3 | C15: Pupuk Anorganik
C16: - NPK 15-15-6-4+TE | D16: Kg | E16: ='SI TB LC Indigofera (FFD)'!O199 -> 6950 | F16: ='SI TB LC Pakchong (FFD)'!O194 -> 13243 | G16: =SUM(E16:F16) -> 20193 | H16: ='Master Harga'!J139 -> 8338.316 | I16: =H16*G16 -> 1.6837561e+08 | J16: =E16*H16 -> 57951296 | K16: =F16*H16 -> 1.1042432e+08 | L16: =I16/75.9 -> 2218387.5
C17: - Rock Phosphate | D17: Kg | E17: ='SI TB LC Indigofera (FFD)'!O123 -> 1362.2 | F17: ='SI TB LC Pakchong (FFD)'!O158 -> 6232 | G17: =SUM(E17:F17) -> 7594.2 | H17: ='Master Harga'!J131 -> 3220 | I17: =H17*G17 -> 24453324 | J17: =E17*H17 -> 4386284 | K17: =F17*H17 -> 20067040 | L17: =I17/75.9 -> 322178.18
B18: 4 | C18: Pestisida
C19: - Glyphosate | D19: Ltr | E19: ='SI TB LC Indigofera (FFD)'!O23 -> 5.8797 | F19: ='SI TB LC Pakchong (FFD)'!O29 -> 6.59034 | G19: =SUM(E19:F19) -> 12.47004 | H19: ='Master Harga'!J103 -> 35343 | I19: =H19*G19 -> 440728.62 | J19: =E19*H19 -> 207806.24 | K19: =F19*H19 -> 232922.39 | L19: =I19/75.9 -> 5806.7012
C20: - Metil Metsulfuron | D20: Kg | E20: ='SI TB LC Indigofera (FFD)'!O24 -> 0.740592 | F20: ='SI TB LC Pakchong (FFD)'!O30 -> 0.8301024 | G20: =SUM(E20:F20) -> 1.5706944 | H20: ='Master Harga'!J104 -> 96390 | I20: =H20*G20 -> 151399.23 | J20: =E20*H20 -> 71385.663 | K20: =F20*H20 -> 80013.57 | L20: =I20/75.9 -> 1994.7198
C21: - Parakuat | D21: Ltr | E21: ='SI TB LC Indigofera (FFD)'!O25 -> 12.51 | F21: ='SI TB LC Pakchong (FFD)'!O31 -> 14.022 | G21: =SUM(E21:F21) -> 26.532 | H21: ='Master Harga'!J106 -> 28381.5 | I21: =H21*G21 -> 753017.96 | J21: =E21*H21 -> 355052.57 | K21: =F21*H21 -> 397965.39 | L21: =I21/75.9 -> 9921.1852
C22: - Perekat | D22: Ltr | E22: ='SI TB LC Indigofera (FFD)'!O26 -> 5.55444 | F22: ='SI TB LC Pakchong (FFD)'!O32 -> 6.225768 | G22: =SUM(E22:F22) -> 11.780208 | H22: ='Master Harga'!J105 -> 44982 | I22: =H22*G22 -> 529897.32 | J22: =E22*H22 -> 249849.82 | K22: =F22*H22 -> 280047.5 | L22: =I22/75.9 -> 6981.5193
B23: 4 | C23: Perlengkapan
C24: - Anak Pancang | D24: Bh | E24: ='SI TB LC Indigofera (FFD)'!O159 -> 222400 | F24: ='SI TB LC Pakchong (FFD)'!O154 -> 84132 | G24: =SUM(E24:F24) -> 306532 | H24: ='SI TB LC Pakchong (FFD)'!P154 -> 50 | I24: =H24*G24 -> 15326600 | J24: =E24*H24 -> 11120000 | K24: =F24*H24 -> 4206600 | L24: =I24/75.9 -> 201931.49
C25: - Baby Bag | D25: Kg | E25: ='SI TB LC Indigofera (FFD)'!O124 -> 272.44 | G25: =SUM(E25:F25) -> 272.44 | H25: ='Master Harga'!J47 -> 26345.76 | I25: =H25*G25 -> 7177638.9 | J25: =E25*H25 -> 7177638.9 | K25: =F25*H25 -> 0 | L25: =I25/75.9 -> 94567.047
C26: - Cangkul | D26: Bh | E26: ='SI TB LC Indigofera (FFD)'!O186+'SI TB LC Indigofera (FFD)'!O188 -> 12.788 | F26: ='SI TB LC Pakchong (FFD)'!O181+'SI TB LC Pakchong (FFD)'!O183 -> 14.3336 | G26: =SUM(E26:F26) -> 27.1216 | H26: ='Master Harga'!J50 -> 84894.6 | I26: =H26*G26 -> 2302477.4 | J26: =E26*H26 -> 1085632.1 | K26: =F26*H26 -> 1216845.2 | L26: =I26/75.9 -> 30335.67
C27: - Celemek | D27: Bh | E27: ='SI TB LC Indigofera (FFD)'!O28 -> 0.695 | F27: ='SI TB LC Pakchong (FFD)'!O34 -> 0.779 | G27: =SUM(E27:F27) -> 1.474 | H27: ='Master Harga'!J52 -> 47980.8 | I27: =H27*G27 -> 70723.699 | J27: =E27*H27 -> 33346.656 | K27: =F27*H27 -> 37377.043 | L27: =I27/75.9 -> 931.80104
C28: - Gorong-Gorong 80 CM | D28: Bh | E28: ='SI TB LC Indigofera (FFD)'!O65 -> 6 | F28: ='SI TB LC Pakchong (FFD)'!O71 -> 6 | G28: =SUM(E28:F28) -> 12 | H28: ='Master Harga'!J177 -> 741000 | I28: =H28*G28 -> 8892000 | J28: =E28*H28 -> 4446000 | K28: =F28*H28 -> 4446000 | L28: =I28/75.9 -> 117154.15
C29: - Kaca mata | D29: Bh | E29: ='SI TB LC Indigofera (FFD)'!O30 -> 0.17375 | F29: ='SI TB LC Pakchong (FFD)'!O36 -> 0.19475 | G29: =SUM(E29:F29) -> 0.3685 | H29: ='Master Harga'!J65 -> 41983.2 | I29: =H29*G29 -> 15470.809 | J29: =E29*H29 -> 7294.581 | K29: =F29*H29 -> 8176.2282 | L29: =I29/75.9 -> 203.83148
C30: - Kawat Duri | D30: Rol | F30: ='SI TB LC Pakchong (FFD)'!O24 -> 0 | G30: =SUM(E30:F30) -> 0 | H30: ='Master Harga'!J95 -> 178071.6 | I30: =H30*G30 -> 0 | J30: =E30*H30 -> 0 | K30: =F30*H30 -> 0 | L30: =I30/75.9 -> 0
C31: - Masker Chemical | D31: Bh | E31: ='SI TB LC Indigofera (FFD)'!O29 -> 2.085 | F31: ='SI TB LC Pakchong (FFD)'!O35 -> 2.337 | G31: =SUM(E31:F31) -> 4.422 | H31: ='Master Harga'!J70 -> 15680 | I31: =H31*G31 -> 69336.96 | J31: =E31*H31 -> 32692.8 | K31: =F31*H31 -> 36644.16 | L31: =I31/75.9 -> 913.53043
C32: - Paku 1" | D32: Kg | F32: ='SI TB LC Pakchong (FFD)'!O25 -> 0 | G32: =SUM(E32:F32) -> 0 | H32: ='Master Harga'!J96 -> 20263.32 | I32: =H32*G32 -> 0 | J32: =E32*H32 -> 0 | K32: =F32*H32 -> 0 | L32: =I32/75.9 -> 0
C33: - Paku 2.5" | D33: Kg | F33: ='SI TB LC Pakchong (FFD)'!O26 -> 0 | G33: =SUM(E33:F33) -> 0 | H33: ='Master Harga'!J97 -> 18421.2 | I33: =H33*G33 -> 0 | J33: =E33*H33 -> 0 | K33: =F33*H33 -> 0 | L33: =I33/75.9 -> 0
C34: - Papan | D34: Bh | E34: ='SI TB LC Indigofera (FFD)'!O129 -> 5.2730323 | G34: =SUM(E34:F34) -> 5.2730323 | H34: ='Master Harga'!J76 -> 2268000 | I34: =H34*G34 -> 11959237 | J34: =E34*H34 -> 11959237 | K34: =F34*H34 -> 0 | L34: =I34/75.9 -> 157565.71
C35: - Patok Kayu | D35: Bh | F35: ='SI TB LC Pakchong (FFD)'!O23 -> 0 | G35: =SUM(E35:F35) -> 0 | H35: ='SI TB LC Pakchong (FFD)'!P23 -> 22400 | I35: =H35*G35 -> 0 | J35: =E35*H35 -> 0 | K35: =F35*H35 -> 0 | L35: =I35/75.9 -> 0
C36: - Plastik Hitam | D36: Mtr | F36: ='SI TB LC Pakchong (FFD)'!O22 -> 60.762 | G36: =SUM(E36:F36) -> 60.762 | H36: ='Master Harga'!J93 -> 3360 | I36: =H36*G36 -> 204160.32 | J36: =E36*H36 -> 0 | K36: =F36*H36 -> 204160.32 | L36: =I36/75.9 -> 2689.8593
C37: - Sarung Tangan Karet | D37: Bh | E37: ='SI TB LC Indigofera (FFD)'!O31 -> 0.3475 | F37: ='SI TB LC Pakchong (FFD)'!O37 -> 0.3895 | G37: =SUM(E37:F37) -> 0.737 | H37: ='Master Harga'!J83 -> 35985.6 | I37: =H37*G37 -> 26521.387 | J37: =E37*H37 -> 12504.996 | K37: =F37*H37 -> 14016.391 | L37: =I37/75.9 -> 349.42539
C38: - Sepatu Boots | D38: Bh | E38: ='SI TB LC Indigofera (FFD)'!O32 -> 0.17375 | F38: ='SI TB LC Pakchong (FFD)'!O38 -> 0.19475 | G38: =SUM(E38:F38) -> 0.3685 | H38: ='Master Harga'!J84 -> 95961.6 | I38: =H38*G38 -> 35361.85 | J38: =E38*H38 -> 16673.328 | K38: =F38*H38 -> 18688.522 | L38: =I38/75.9 -> 465.90052
C39: - Top Soil | D39: Rit | E39: ='SI TB LC Indigofera (FFD)'!O126 -> 77.84 | G39: =SUM(E39:F39) -> 77.84 | H39: ='SI TB LC Indigofera (FFD)'!P126 -> 84360 | I39: =H39*G39 -> 6566582.4 | J39: =E39*H39 -> 6566582.4 | K39: =F39*H39 -> 0 | L39: =I39/75.9 -> 86516.237
B40: Total | I40: =SUM(I9:I39) -> 8.5551744e+08 | J40: =SUM(J9:J39) -> 2.7188876e+08 | K40: =SUM(K9:K39) -> 5.8362868e+08 | L40: =I40/E4 -> 14510133

Sheet KeB.HM Alat Berat (FFD)
B2: Project | E2: : Tanam Pastura
B3: Area | E3: : PT Fass Forest Development
B4: RENCANA KEBUTUHAN HM ALAT BERAT
B5: No | C5: Jenis Alat Berat | D5: HM Alat Berat | I5: Harga Sat (Rp) | J5: Estimasi Biaya (Rp) | K5: Pastura | M5: Rp/Ha
D6: Indigofera | F6: Pakchong | H6: Total | K6: Indigofera | L6: Pakchong
D7: Luas (Ha) | E7: HM | F7: Luas (Ha) | G7: HM | K7: (Rp) | L7: (Rp)
B8: 1 | C8: Buldozer | D8: ='Areal Stmt'!D33 -> 27.8 | E8: ='SI TB LC Indigofera (FFD)'!O12 -> 197.4912 | F8: ='Areal Stmt'!D36 -> 31.16 | G8: ='SI TB LC Pakchong (FFD)'!O12 -> 44.8704 | H8: =E8+G8 -> 242.3616 | I8: ='Master Harga'!J344 -> 1051433.7 | J8: =I8*H8 -> 2.5482715e+08 | K8: =E8*I8 -> 2.076489e+08 | L8: =I8*G8 -> 47178250 | M8: =J8/($D$8+$F$8) -> 4322034.4
B9: 2 | C9: Excavator PC 200 | E9: ='SI TB LC Indigofera (FFD)'!O13+'SI TB LC Indigofera (FFD)'!O70+'SI TB LC Indigofera (FFD)'!O74+'SI TB LC Indigofera (FFD)'!O112+'SI TB LC Indigofera (FFD)'!O113 -> 241.5403 | G9: ='SI TB LC Pakchong (FFD)'!O13+'SI TB LC Pakchong (FFD)'!O76+'SI TB LC Pakchong (FFD)'!O80+'SI TB LC Pakchong (FFD)'!O118+'SI TB LC Pakchong (FFD)'!O119 -> 146.09366 | H9: =E9+G9 -> 387.63396 | I9: ='Master Harga'!J312 -> 720338.07 | J9: =I9*H9 -> 2.792275e+08 | K9: =E9*I9 -> 1.7399067e+08 | L9: =I9*G9 -> 1.0523683e+08 | M9: =J9/($D$8+$F$8) -> 4735880.3
B10: 3 | C10: Greader | E10: ='SI TB LC Indigofera (FFD)'!O38 -> 8.339166 | G10: ='SI TB LC Pakchong (FFD)'!O44 -> 9.3470652 | H10: =E10+G10 -> 17.686231 | I10: ='Master Harga'!J331 -> 715047.83 | J10: =I10*H10 -> 12646501 | K10: =E10*I10 -> 5962902.5 | L10: =I10*G10 -> 6683598.7 | M10: =J10/($D$8+$F$8) -> 214492.9
B11: 4 | C11: TLB | E11: ='SI TB LC Indigofera (FFD)'!O66 -> 3 | G11: ='SI TB LC Pakchong (FFD)'!O72 -> 3 | H11: =E11+G11 -> 6 | I11: ='Master Harga'!J338 -> 680210.07 | J11: =I11*H11 -> 4081260.4 | K11: =E11*I11 -> 2040630.2 | L11: =I11*G11 -> 2040630.2 | M11: =J11/($D$8+$F$8) -> 69220.834
B12: 5 | C12: Farm Traktor | E12: ='SI TB LC Indigofera (FFD)'!O16+'SI TB LC Indigofera (FFD)'!O19+'SI TB LC Indigofera (FFD)'!O20+'SI TB LC Indigofera (FFD)'!O40+'SI TB LC Indigofera (FFD)'!O202 -> 319.7 | G12: ='SI TB LC Pakchong (FFD)'!O16+'SI TB LC Pakchong (FFD)'!O19+'SI TB LC Pakchong (FFD)'!O20+'SI TB LC Pakchong (FFD)'!O46 -> 327.18 | H12: =E12+G12 -> 646.88 | I12: ='Master Harga'!J294 -> 369600 | J12: =I12*H12 -> 2.3908685e+08 | K12: =E12*I12 -> 1.1816112e+08 | L12: =I12*G12 -> 120925728 | M12: =J12/($D$8+$F$8) -> 4055068.7
B13: Total | E13: =SUM(E8:E12) -> 770.07067 | G13: =SUM(G8:G12) -> 530.49113 | H13: =SUM(H8:H12) -> 1300.5618 | J13: =SUM(J8:J12) -> 7.8986926e+08 | K13: =SUM(K8:K12) -> 5.0780423e+08 | L13: =SUM(L8:L12) -> 2.8206503e+08 | M13: =J13/($D$8+$F$8) -> 13396697

Sheet Master Harga
A2: Master Harga
B3: Tenaga Kerja | E3: Nama | F3: Satuan | G3: Harga | R3: Id Budget | S3: AVERAGE 2023-2025 | T3: AVERAGE 2024-2026 | U3: AVERAGE 2025-2027 | V3: AVERAGE 2026-2028
G4: 2023 | H4: 2024 | I4: 2025 | J4: 2026 | K4: 2027 | L4: 2028 | M4: 2029 | N4: 2030 | O4: 2031 | P4: 2032 | Q4: 2033
J5: Forecast BC
A6: Forecast Kenaikkan Upah | I6: Aktual | J6: 1.08 | K6: =J6 -> 1.08 | L6: =K6 -> 1.08 | M6: =L6 -> 1.08 | N6: =M6 -> 1.08 | O6: =N6 -> 1.08 | P6: =O6 -> 1.08 | Q6: =P6 -> 1.08
A7: 1 | B7: TK | C7: 001 | E7: SKU Panen | F7: HK | R7: =A7&"."&B7&"."&C7 -> 1.TK.001
A8: 1 | B8: TK | C8: 002 | E8: Upah PHL | F8: HK | I8: 140008 | J8: =I8*J6 -> 151208.64 | K8: =J8*K6 -> 163305.33 | L8: =K8*L6 -> 176369.76 | M8: =L8*M6 -> 190479.34 | N8: =M8*N6 -> 205717.69 | O8: =N8*O6 -> 222175.1 | P8: =O8*P6 -> 239949.11 | Q8: =P8*Q6 -> 259145.04 | R8: =A8&"."&B8&"."&C8 -> 1.TK.002 | S8: =AVERAGE(H8:J8) -> 145608.32 | T8: =AVERAGE(I8:K8) -> 151507.32 | U8: =AVERAGE(J8:L8) -> 163627.91 | V8: =AVERAGE(K8:M8) -> 176718.14
A9: 1 | B9: TK | C9: 003 | E9: Biaya Konsultan | F9: Rp/Ha | R9: =A9&"."&B9&"."&C9 -> 1.TK.003
A10: 1 | B10: TK | C10: 004 | E10: Muat TBS | F10: Kg | R10: =A10&"."&B10&"."&C10 -> 1.TK.004
A11: 1 | B11: TK | C11: 005 | E11: Upah BM Pupuk Intern | F11: Ton | I11: 19500 | J11: =I11*J6 -> 21060 | K11: =J11*K6 -> 22744.8 | L11: =K11*L6 -> 24564.384 | M11: =L11*M6 -> 26529.535 | N11: =M11*N6 -> 28651.897 | O11: =N11*O6 -> 30944.049 | P11: =O11*P6 -> 33419.573 | Q11: =P11*Q6 -> 36093.139 | R11: =A11&"."&B11&"."&C11 -> 1.TK.005 | S11: =AVERAGE(H11:J11) -> 20280 | T11: =AVERAGE(I11:K11) -> 21101.6 | U11: =AVERAGE(J11:L11) -> 22789.728 | V11: =AVERAGE(K11:M11) -> 24612.906
