Workbook
Name \0: #REF!
Name \0: #REF!
Name \a: #N/A
Name \a: #N/A
Name \b: #N/A
Name \b: #N/A
Name \g: #N/A
Name \g: #N/A
Name \n: #N/A
Name \n: #N/A
Name __kop2: #N/A
Name __s2: #REF!
Name __SKF1: #N/A
Name __SKF2: #N/A
Name _0: #REF!
Name _0: #REF!
Name _10_A_1: #REF!
Name _11_A_1: #REF!
Name _12_A_1: #REF!
Name _13_b_1: #REF!
Name _14_b_1: #REF!
Name _15_b_1: #REF!
Name _16_g_1: #REF!
Name _17_g_1: #REF!
Name _18_g_1: #REF!
Name _19_n_1: #REF!
Name _20_n_1: #REF!
Name _21_n_1: #REF!
Name _22Excel_BuiltIn_Database_1: #REF!
Name _23Excel_BuiltIn_Database_1: #REF!
Name _24Excel_BuiltIn_Print_Area_1: #REF!
Name _25Excel_BuiltIn_Print_Area_1: #REF!
Name _26Excel_BuiltIn_Print_Area_31_1: '[4]Kap Rinci'!#REF!
Name _27Excel_BuiltIn_Print_Area_31_1: '[5]Kap Rinci'!#REF!
Name _28Excel_BuiltIn_Print_Area_31_1: '[6]Kap Rinci'!#REF!
Name _29Excel_BuiltIn_Print_Titles_1: #REF!
Name _30Excel_BuiltIn_Print_Titles_1: #REF!
Name _31Excel_BuiltIn_Print_Titles_1: #REF!
Name _432: 432
Name _8_0_1: #REF!
Name _8311: #REF!
Name _8311: #REF!
Name _8311: #REF!
Name _9_0_1: #REF!
Name _a: #REF!
Name _A: #REF!
Name _A: #REF!
Name _A: #N/A
Name _A_1: #REF!
Name _A_1: #REF!
Name _A_1: #REF!
Name _A_2: #REF!
Name _A_2: #REF!
Name _A_28: #REF!
Name _A_28: #REF!
Name _A_28: #REF!
Name _A_3: #REF!
Name _A_3: #REF!
Name _A_31: #REF!
Name _A_31: #REF!

Sheet Sheet1
C2: jb | D2: bb
A3: 2008 | B3: 1 | E3: =SUM(C3:D3) -> 0
B4: 2 | E4: =SUM(C4:D4) -> 0
B5: 3 | E5: =SUM(C5:D5) -> 0
B6: 4 | C6: 310 | D6: 50 | E6: =SUM(C6:D6) -> 360
B7: ttl | C7: =SUM(C3:C6) -> 310 | D7: =SUM(D3:D6) -> 50 | E7: =SUM(E3:E6) -> 360
A9: =A3+1 -> 2009 | B9: 1 | E9: =SUM(C9:D9) -> 0
B10: 2 | E10: =SUM(C10:D10) -> 0
B11: 3 | E11: =SUM(C11:D11) -> 0
B12: 4 | C12: =50.3+80.23+78.84 -> 209.37 | E12: =SUM(C12:D12) -> 209.37
B13: ttl | C13: =SUM(C9:C12) -> 209.37 | D13: =SUM(D9:D12) -> 0 | E13: =SUM(E9:E12) -> 209.37
A15: =A9+1 -> 2010 | B15: 1 | D15: =52.15+61.73+19.59 -> 133.47 | E15: =SUM(C15:D15) -> 133.47
B16: 2 | D16: =60.74+51.74+45.2 -> 157.68 | E16: =SUM(C16:D16) -> 157.68
B17: 3 | C17: 21.54 | D17: =8.02+54.92+1.62 -> 64.56 | E17: =SUM(C17:D17) -> 86.1
B18: 4 | C18: =26.19+46.62-2.62 -> 70.19 | D18: =22+87.37+141.82 -> 251.19 | E18: =SUM(C18:D18) -> 321.38
B19: ttl | C19: =SUM(C15:C18) -> 91.73 | D19: =SUM(D15:D18) -> 606.9 | E19: =SUM(E15:E18) -> 698.63
H20: 326.6 | I20: 50
A21: =A15+1 -> 2011 | B21: 1 | D21: =68.25+93.06+66.29 -> 227.6 | E21: =SUM(C21:D21) -> 227.6 | H21: 197.2 | I21: 606.9
B22: 2 | D22: =38.5+29.04+4.43+0.03 -> 72 | E22: =SUM(C22:D22) -> 72 | H22: 87.3 | I22: 299.6
B23: 3 | C23: =24.26+15.22 -> 39.48 | E23: =SUM(C23:D23) -> 39.48 | H23: 53.79
B24: 4 | C24: =6.25+8.06 -> 14.31 | E24: =SUM(C24:D24) -> 14.31 | H24: =SUM(H20:H23) -> 664.89 | I24: =SUM(I20:I23) -> 956.5
B25: ttl | C25: =SUM(C21:C24) -> 53.79 | D25: =SUM(D21:D24) -> 299.6 | E25: =SUM(E21:E24) -> 353.39
A27: =A21+1 -> 2012 | B27: 1 | C27: 40.65 | D27: 313.54 | E27: =SUM(C27:D27) -> 354.19 | H27: =200+40.65 -> 240.65 | I27: =600+13.54 -> 613.54
B28: 2 | C28: 200 | D28: 300 | E28: =SUM(C28:D28) -> 500 | I28: 200
B29: 3 | E29: =SUM(C29:D29) -> 0 | H29: =SUM(H27:H28) -> 240.65 | I29: =SUM(I27:I28) -> 813.54
B30: 4 | E30: =SUM(C30:D30) -> 0
B31: ttl | C31: =SUM(C27:C30) -> 240.65 | D31: =SUM(D27:D30) -> 613.54 | E31: =SUM(E27:E30) -> 854.19 | H31: =H29+H24 -> 905.54 | I31: =I29+I24 -> 1770.04
C33: =C7+C13+C19+C25+C31 -> 905.54 | D33: =D7+D13+D19+D25+D31 -> 1570.04 | E33: =E7+E13+E19+E25+E31 -> 2475.58
A36: rencana | D36: 200 | E36: =SUM(C36:D36) -> 200
C38: =C33+C36 -> 905.54 | D38: =D33+D36 -> 1770.04 | E38: =E33+E36 -> 2675.58
C39: =C38-H31 -> 0 | D39: =D38-I31 -> 0

Sheet Cover RKP
B10: RENCANA KERJA PROYEK
B11: KEBUN TELUK PULAI
B21: Tahun 2026 - 2029
C35: ='Tingkat Jalan Mineral'!G20 -> 998942.8
C36: ='Tingkat Jalan Mineral'!Q20 -> 1522646.8
C37: ='Drainase Tnh Mineral '!Q21 -> 581740
C38: =SUM(C35:C37) -> 3103329.6
C39: =C33+C38 -> 3103329.6

Sheet Harga
A1: Daftar Harga Satuan
B3: Item | D3: Harga 2026 | H3: Item | J3: Harga
A4: A | B4: Peralatan | G4: A | H4: Peralatan
A5: 1 | B5: Buldozer | C5: Hm | D5: =[22]Sheet1!$F$7 -> 815200 | F5: 450000 | G5: 1 | H5: Buldozer | I5: Hm | J5: 300000 | K5: =D5-J5 -> 515200 | N5: 380000
A6: 2 | B6: Grader | C6: Hm | D6: =[22]Sheet1!$F$8 -> 663600 | F6: 300000 | G6: 2 | H6: Grader | I6: Hm | J6: 200000 | K6: =D6-J6 -> 463600 | N6: 260000
A7: 3 | B7: Excavator | C7: Hm | D7: =[22]Sheet1!$F$9 -> 691200 | F7: 350000 | G7: 3 | H7: Excavator | I7: Hm | J7: 300000 | K7: =D7-J7 -> 391200 | N7: 350000
A8: 4 | B8: Compactor | C8: Hm | D8: =[22]Sheet1!$F$10 -> 579200 | F8: 300000 | G8: 4 | H8: Compactor | I8: Hm | J8: 190000 | K8: =D8-J8 -> 389200 | N8: 300000
A9: 5 | B9: Farm Tractor | C9: Hm | D9: =[22]Sheet1!$F$11 -> 327000 | F9: 150000 | G9: 5 | H9: Farm Tractor | I9: Hm | J9: 150000 | K9: =D9-J9 -> 177000 | N9: 150000
A10: 6 | B10: Gergaji Rantai | C10: JK | D10: 50490 | F10: 50000 | G10: 6 | H10: Gergaji Rantai | I10: JK | J10: 50000 | K10: =D10-J10 -> 490 | N10: 50000
A11: 7 | B11: Sumi sansui irigasi | C11: Roll | D11: 325000 | F11: 350000 | G11: 7 | H11: Sumi sansui irigasi | I11: Roll | J11: 350000 | K11: =D11-J11 -> -25000 | N11: 350000
A12: 8 | B12: Saringan | C12: Pcs | D12: 50000 | F12: 50000 | G12: 8 | H12: Saringan | I12: Pcs | J12: 50000 | K12: =D12-J12 -> 0 | N12: 50000
A13: 9 | B13: Sprayer (Inter) | C13: Unit | D13: =[22]Sheet1!$F$15 -> 1450770 | F13: 241500 | G13: 9 | H13: Sprayer | I13: Unit | J13: 241500 | K13: =D13-J13 -> 1209270 | N13: 241500
A14: 10 | B14: Ember | C14: Unit | D14: 30000 | F14: 7500 | G14: 10 | H14: Ember | I14: Unit | J14: 7500 | K14: =D14-J14 -> 22500 | N14: 7500
A15: 11 | B15: Pipa Paralon/Slang | C15: Set | D15: 1500000 | F15: 1500000 | G15: 11 | H15: Pipa Paralon/Slang | I15: Set | J15: 1500000 | K15: =D15-J15 -> 0 | N15: 1500000
A16: 12 | B16: Mesin Alkon | C16: Unit | D16: 2112000 | F16: 2112000 | G16: 12 | H16: Mesin Alkon | I16: Unit | J16: 2112000 | K16: =D16-J16 -> 0 | N16: 2112000
A17: 13 | B17: Tiang Pagar - ulin | C17: Unit | D17: 30000 | F17: 30000 | G17: 13 | H17: Tiang Pagar - ulin | I17: Unit | J17: 30000 | K17: =D17-J17 -> 0 | N17: 30000
A18: 14 | B18: Kawat Duri | C18: Gulung | D18: 78843 | F18: 50000 | G18: 14 | H18: Kawat Duri | I18: Gulung | J18: 50000 | K18: =D18-J18 -> 28843 | N18: 50000
A19: 15 | B19: Paku | C19: Kg | D19: 18500 | F19: 17735 | G19: 15 | H19: Paku | I19: Kg | J19: 17735 | K19: =D19-J19 -> 765 | N19: 17735
A20: 16 | B20: Rumah Jaga | C20: Unit | D20: 5000000 | F20: 5000000 | G20: 16 | H20: Rumah Jaga | I20: Unit | J20: 5000000 | K20: =D20-J20 -> 0 | N20: 5000000
K21: =D21-J21 -> 0
A22: B | B22: Bahan-bahan | G22: B | H22: Bahan-bahan | K22: =D22-J22 -> 0
A23: 1 | B23: Kecambah (Socfindo) | C23: Butir | D23: 10000 | F23: 9500 | G23: 1 | H23: Kecambah (Socfindo) | I23: Butir | J23: 9500 | K23: =D23-J23 -> 500 | N23: 9500
A24: 2 | B24: Badan Naungan | C24: Unit | D24: 461201 | F24: 350000 | G24: 2 | H24: Badan Naungan | I24: Unit | J24: 350000 | K24: =D24-J24 -> 111201 | N24: 350000
A25: 3 | B25: Polybag (PN) | C25: Kg | D25: 22500 | F25: 139 | G25: 3 | H25: Polybag (PN) | I25: Lbr | J25: 139 | K25: =D25-J25 -> 22361 | N25: 139
A26: 4 | B26: Polybag (MN) | C26: Kg | D26: 45000 | F26: 1013 | G26: 4 | H26: Polybag (MN) | I26: Lbr | J26: 1013 | K26: =D26-J26 -> 43987 | N26: 1015
A27: 5 | B27: PJ | C27: Kg | D27: 98879 | F27: 260000 | G27: 5 | H27: PJ | I27: Kg | J27: 60360 | K27: =D27-J27 -> 38519 | N27: 200000
A28: 6 | B28: CM | C28: Kg | D28: 27497 | F28: 21000 | G28: 6 | H28: CM | I28: Kg | J28: 8385 | K28: =D28-J28 -> 19112 | N28: 21000
A29: 8 | B29: Rhizobium | C29: Kg | D29: 71654 | F29: 77135 | G29: 8 | H29: Rhizobium | I29: Kg | J29: 77135 | K29: =D29-J29 -> -5481 | N29: 77135
A30: 9 | B30: LCC MB | C30: Kg | D30: =[22]Sheet1!$F$32 -> 702065.43
A31: 10 | B31: Cat | C31: Kg | D31: 66759
A32: 11 | B32: Anak Pancang | C32: Buah | D32: 100
K33: =D33-J33 -> 0
A34: C | B34: Pupuk | G34: C | H34: Pupuk | K34: =D34-J34 -> 0
A35: 1 | B35: NPK 15.15.6.4 | C35: Kg | D35: =[22]Sheet1!$F$37 -> 5561.1 | F35: 4700 | G35: 1 | H35: NPK 15.15.6.4 | I35: Kg | J35: =7100+(7100*10%)+(7100*5%) -> 8165 | K35: =D35-J35 -> -2603.9 | N35: 4700
A36: 2 | B36: NPK 12.12.17.2 | C36: Kg | D36: =[22]Sheet1!$F$38 -> 6277.09 | F36: 4950 | G36: 2 | H36: NPK 12.12.17.2 | I36: Kg | J36: 8682.5 | K36: =D36-J36 -> -2405.41 | N36: 4950
A37: 3 | B37: Suburin | C37: Kg | D37: 7450 | F37: 8521.5 | G37: 3 | H37: Suburin | I37: Kg | J37: 8521.5 | K37: =D37-J37 -> -1071.5 | N37: 8521.5
A38: 4 | B38: Pupuk Kandang | C38: Kg | D38: 1115 | F38: 665 | G38: 4 | H38: Pupuk Kandang | I38: Kg | J38: 665 | K38: =D38-J38 -> 450 | N38: 665
A39: 5 | B39: Bayfolan | C39: Kg | D39: =[22]Sheet1!$F$41 -> 61795.55 | F39: 33925 | G39: 5 | H39: Bayfolan | I39: Ltr | J39: =29500+(29500*10%)+(29500*5%) -> 33925 | K39: =D39-J39 -> 27870.55 | N39: 33925
A40: 6 | B40: Urea | C40: Kg | D40: =[22]Sheet1!$F$42 -> 6444.51 | F40: 5099.6 | G40: 6 | H40: Urea | I40: Kg | J40: =2900+(2900*10%)+(2900*5%) -> 3335 | K40: =D40-J40 -> 3109.51 | N40: 5099.6
A41: 7 | B41: RP | C41: Kg | D41: =[22]Sheet1!$F$43 -> 2008.63 | F41: 2117.5 | G41: 7 | H41: RP | I41: Kg | J41: =1750+(1750*10%)+(1750*5%) -> 2012.5 | K41: =D41-J41 -> -3.87 | N41: 2117.5
...

Sheet RKP 08
B1: RENCANA KERJA PROYEK ( RKP )
B2: PT. KUMAI SENTOSA | I2: =G58*E58 -> 2.1386846e+08
B3: Kebun Teluk Pulai | I3: =F58/E58 -> 611052.75
B5: LUAS : | D5: 350 | E5: Tahun Tanam 2026/2027/2028/2029
B6: No. | C6: Item | E6: Rencana | J6: TAHUN I ( 2026) | R6: TAHUN II ( 2027 ) | AB6: TAHUN III ( 2028 ) | AL6: TAHUN IV ( 2029 ) | AV6: TAHUN V ( 2030 ) | BF6: TAHUN VI ( 2031) | BP6: TAHUN VII ( 2032 )
E7: Proyek 4 Tahun | G7: Harga | H7: Rotasi | I7: Harga | J7: Catur Wulan 1 | L7: Catur Wulan 2 | N7: Catur Wulan 3 | P7: Jumlah Tahun I | R7: Catur Wulan 1 | T7: Catur Wulan 2 | V7: Catur Wulan 3 | X7: Jumlah Tahun II | Z7: Jumlah S/d Tahun II | AB7: Catur Wulan 1 | AD7: Catur Wulan 2 | AF7: Catur Wulan 3 | AH7: Jumlah Tahun III | AJ7: Jumlah S/d Tahun III | AL7: Catur Wulan 1 | AN7: Catur Wulan 2 | AP7: Catur Wulan 3 | AR7: Jumlah Tahun IV | AT7: Jumlah S/d Tahun IV | AV7: Catur Wulan 1 | AX7: Catur Wulan 2 | AZ7: Catur Wulan 3 | BB7: Jumlah Tahun V | BD7: Jumlah S/d Tahun V | BF7: Catur Wulan 1 | BH7: Catur Wulan 2 | BJ7: Catur Wulan 3 | BL7: Jumlah Tahun VI | BN7: Jumlah S/d Tahun VI | BP7: Catur Wulan 1 | BR7: Catur Wulan 2 | BT7: Catur Wulan 3 | BV7: Jumlah Tahun VII | BX7: Jumlah S/d Tahun VII
E8: Volume | F8: Biaya | G8: Satuan | H8: (Periode) | I8: (Rp/Ha/Rot) | J8: Fisik | K8: Biaya | L8: Fisik | M8: Biaya | N8: Fisik | O8: Biaya | P8: Fisik | Q8: Biaya | R8: Fisik | S8: Biaya | T8: Fisik | U8: Biaya | V8: Fisik | W8: Biaya | X8: Fisik | Y8: Biaya | Z8: Fisik | AA8: Biaya | AB8: Fisik | AC8: Biaya | AD8: Fisik | AE8: Biaya | AF8: Fisik | AG8: Biaya | AH8: Fisik | AI8: Biaya | AJ8: Fisik | AK8: Biaya | AL8: Fisik | AM8: Biaya | AN8: Fisik | AO8: Biaya | AP8: Fisik | AQ8: Biaya | AR8: Fisik | AS8: Biaya | AT8: Fisik | AU8: Biaya | AV8: Fisik | AW8: Biaya | AX8: Fisik | AY8: Biaya | AZ8: Fisik | BA8: Biaya | BB8: Fisik | BC8: Biaya | BD8: Fisik | BE8: Biaya | BF8: Fisik | BG8: Biaya | BH8: Fisik | BI8: Biaya | BJ8: Fisik | BK8: Biaya | BL8: Fisik | BM8: Biaya | BN8: Fisik | BO8: Biaya | BP8: Fisik | BQ8: Biaya | BR8: Fisik | BS8: Biaya | BT8: Fisik | BU8: Biaya | BV8: Fisik | BW8: Biaya | BX8: Fisik | BY8: Biaya | CI8: Perbandingan Cost / Ha
E9: ( Ha ) | F9: ( Rp ) | G9: ( Rp / Ha ) | J9: ( Ha ) | K9: ( Rp ) | L9: ( Ha ) | M9: ( Rp ) | N9: ( Ha ) | O9: ( Rp ) | P9: ( Ha ) | Q9: ( Rp ) | R9: ( Ha ) | S9: ( Rp ) | T9: ( Ha ) | U9: ( Rp ) | V9: ( Ha ) | W9: ( Rp ) | X9: ( Ha ) | Y9: ( Rp ) | Z9: ( Ha ) | AA9: ( Rp ) | AB9: ( Ha ) | AC9: ( Rp ) | AD9: ( Ha ) | AE9: ( Rp ) | AF9: ( Ha ) | AG9: ( Rp ) | AH9: ( Ha ) | AI9: ( Rp ) | AJ9: ( Ha ) | AK9: ( Rp ) | AL9: ( Ha ) | AM9: ( Rp ) | AN9: ( Ha ) | AO9: ( Rp ) | AP9: ( Ha ) | AQ9: ( Rp ) | AR9: ( Ha ) | AS9: ( Rp ) | AT9: ( Ha ) | AU9: ( Rp ) | AV9: ( Ha ) | AW9: ( Rp ) | AX9: ( Ha ) | AY9: ( Rp ) | AZ9: ( Ha ) | BA9: ( Rp ) | BB9: ( Ha ) | BC9: ( Rp ) | BD9: ( Ha ) | BE9: ( Rp ) | BF9: ( Ha ) | BG9: ( Rp ) | BH9: ( Ha ) | BI9: ( Rp ) | BJ9: ( Ha ) | BK9: ( Rp ) | BL9: ( Ha ) | BM9: ( Rp ) | BN9: ( Ha ) | BO9: ( Rp ) | BP9: ( Ha ) | BQ9: ( Rp ) | BR9: ( Ha ) | BS9: ( Rp ) | BT9: ( Ha ) | BU9: ( Rp ) | BV9: ( Ha ) | BW9: ( Rp ) | BX9: ( Ha ) | BY9: ( Rp ) | CI9: Mitra | CJ9: Plasma | CK9: Selisih
B10: A. | C10: TANAMAN & INFRASTRUKTUR KEBUN
B11: I | C11: TANAMAN
B12: 1 | C12: Pembukaan Lahan (Land Clearing)
C13: Mekanis | E13: =$D$5 -> 350 | F13: =E13*G13 -> 3.6107051e+09 | G13: ='Rekapitulasi Biaya'!C18 -> 10316300 | H13: 1 | I13: =G13/H13 -> 10316300 | J13: 0 | K13: =J13*$G13 -> 0 | L13: 200 | M13: =L13*$G13 -> 2063260038 | N13: 150 | O13: =N13*$G13 -> 1.547445e+09 | P13: =J13+L13+N13 -> 350 | Q13: =K13+M13+O13 -> 3.6107051e+09 | R13: 0 | S13: =R13*$G13 -> 0 | T13: 0 | U13: =T13*$G13 -> 0 | V13: 0 | W13: =V13*$G13 -> 0 | X13: =R13+T13+V13 -> 0 | Y13: =S13+U13+W13 -> 0 | Z13: =X13+P13 -> 350 | AA13: =Y13+Q13 -> 3.6107051e+09 | AC13: =AB13*$G13 -> 0 | AE13: =AD13*$G13 -> 0 | AG13: =AF13*$G13 -> 0 | AH13: =AB13+AD13+AF13 -> 0 | AI13: =AC13+AE13+AG13 -> 0 | AJ13: =AH13+Z13 -> 350 | AK13: =AI13+AA13 -> 3.6107051e+09 | AM13: =AL13*$G13 -> 0 | AO13: =AN13*$G13 -> 0 | AQ13: =AP13*$G13 -> 0 | AR13: =AL13+AN13+AP13 -> 0 | AS13: =AM13+AO13+AQ13 -> 0 | AT13: =AR13+AJ13 -> 350 | AU13: =AS13+AK13 -> 3.6107051e+09 | AW13: =AV13*$G13 -> 0 | AY13: =AX13*$G13 -> 0 | BA13: =AZ13*$G13 -> 0 | BB13: =AV13+AX13+AZ13 -> 0 | BC13: =AW13+AY13+BA13 -> 0 | BD13: =BB13+AT13 -> 350 | BE13: =BC13+AU13 -> 3.6107051e+09 | BG13: =BF13*$G13 -> 0 | BI13: =BH13*$G13 -> 0 | BK13: =BJ13*$G13 -> 0 | BL13: =BF13+BH13+BJ13 -> 0 | BM13: =BG13+BI13+BK13 -> 0 | BN13: =BL13+BD13 -> 350 | BO13: =BM13+BE13 -> 3.6107051e+09 | BQ13: =BP13*$G13 -> 0 | BS13: =BR13*$G13 -> 0 | BU13: =BT13*$G13 -> 0 | BV13: =BP13+BR13+BT13 -> 0 | BW13: =BQ13+BS13+BU13 -> 0 | BX13: =BV13+BN13 -> 350 | BY13: =BW13+BO13 -> 3.6107051e+09 | CA13: =E13*H13 -> 350 | CB13: =CA13-BX13 -> 0 | CC13: =E13-BX13 -> 0 | CD13: =F13-BY13 -> 0 | CE13: 8.8847695e+09 | CF13: =CE13-BY13 -> 5.2740644e+09 | CG13: =CF13-BZ13 -> 5.2740644e+09 | CI13: 7640840.6 | CJ13: 7640840.6 | CK13: 0
CA14: =E14*H14 -> 0 | CB14: =CA14-BX14 -> 0 | CC14: =E14-BX14 -> 0 | CD14: =F14-BY14 -> 0 | CF14: =CE14-BY14 -> 0 | CG14: =CF14-BZ14 -> 0 | CI14: 0 | CJ14: 0 | CK14: 0
C15: Total Pembukaan Lahan | F15: =SUM(F13:F14) -> 3.6107051e+09 | G15: =SUM(G13:G14) -> 10316300 | I15: =SUM(I13:I14) -> 10316300 | K15: =SUM(K13:K14) -> 0 | M15: =SUM(M13:M14) -> 2063260038 | O15: =SUM(O13:O14) -> 1.547445e+09 | Q15: =SUM(Q13:Q14) -> 3.6107051e+09 | S15: =SUM(S13:S14) -> 0 | U15: =SUM(U13:U14) -> 0 | W15: =SUM(W13:W14) -> 0 | Y15: =SUM(Y13:Y14) -> 0 | AA15: =SUM(AA13:AA14) -> 3.6107051e+09 | AC15: =SUM(AC13:AC14) -> 0 | AE15: =SUM(AE13:AE14) -> 0 | AG15: =SUM(AG13:AG14) -> 0 | AI15: =SUM(AI13:AI14) -> 0 | AK15: =SUM(AK13:AK14) -> 3.6107051e+09 | AM15: =SUM(AM13:AM14) -> 0 | AO15: =SUM(AO13:AO14) -> 0 | AQ15: =SUM(AQ13:AQ14) -> 0 | AS15: =SUM(AS13:AS14) -> 0 | AU15: =SUM(AU13:AU14) -> 3.6107051e+09 | AW15: =SUM(AW13:AW14) -> 0 | AY15: =SUM(AY13:AY14) -> 0 | BA15: =SUM(BA13:BA14) -> 0 | BC15: =SUM(BC13:BC14) -> 0 | BE15: =SUM(BE13:BE14) -> 3.6107051e+09 | BG15: =SUM(BG13:BG14) -> 0 | BI15: =SUM(BI13:BI14) -> 0 | BK15: =SUM(BK13:BK14) -> 0 | BM15: =SUM(BM13:BM14) -> 0 | BO15: =SUM(BO13:BO14) -> 3.6107051e+09 | BQ15: =SUM(BQ13:BQ14) -> 0 | BS15: =SUM(BS13:BS14) -> 0 | BU15: =SUM(BU13:BU14) -> 0 | BW15: =SUM(BW13:BW14) -> 0 | BY15: =SUM(BY13:BY14) -> 3.6107051e+09 | CA15: =E15*H15 -> 0 | CB15: =CA15-BX15 -> 0 | CC15: =E15-BX15 -> 0 | CD15: =F15-BY15 -> 0 | CE15: 8.8847695e+09 | CF15: =CE15-BY15 -> 5.2740644e+09 | CG15: =CF15-BZ15 -> 5.2740644e+09 | CI15: 7640840.6 | CJ15: 7640840.6 | CK15: 0
C16: Harga Satuan Land Clearing | CA16: =E16*H16 -> 0 | CB16: =CA16-BX16 -> 0 | CC16: =E16-BX16 -> 0 | CD16: =F16-BY16 -> 0 | CF16: =CE16-BY16 -> 0 | CG16: =CF16-BZ16 -> 0 | CI16: 0 | CJ16: 0 | CK16: 0
B17: 2 | C17: Persiapan Lahan | CA17: =E17*H17 -> 0 | CB17: =CA17-BX17 -> 0 | CC17: =E17-BX17 -> 0 | CD17: =F17-BY17 -> 0 | CF17: =CE17-BY17 -> 0 | CG17: =CF17-BZ17 -> 0 | CI17: 0 | CJ17: 0 | CK17: 0
C18: a. Nursery | CA18: =E18*H18 -> 0 | CB18: =CA18-BX18 -> 0 | CC18: =E18-BX18 -> 0 | CD18: =F18-BY18 -> 0 | CF18: =CE18-BY18 -> 0 | CG18: =CF18-BZ18 -> 0 | CI18: 0 | CJ18: 0 | CK18: 0
C19: Pre Nursery | E19: =$D$5 -> 350 | F19: =E19*G19 -> 7.3441523e+08 | G19: ='Rekapitulasi Biaya'!C19 -> 2098329.2 | H19: 1 | I19: =G19/H19 -> 2098329.2 | J19: 0 | K19: =J19*$G19 -> 0 | L19: 200 | M19: =L19*$G19 -> 4.1966585e+08 | N19: 150 | O19: =N19*$G19 -> 3.1474939e+08 | P19: =J19+L19+N19 -> 350 | Q19: =K19+M19+O19 -> 7.3441523e+08 | S19: =R19*$G19 -> 0 | U19: =T19*$G19 -> 0 | W19: =V19*$G19 -> 0 | X19: =R19+T19+V19 -> 0 | Y19: =S19+U19+W19 -> 0 | Z19: =X19+P19 -> 350 | AA19: =Y19+Q19 -> 7.3441523e+08 | AC19: =AB19*$G19 -> 0 | AE19: =AD19*$G19 -> 0 | AG19: =AF19*$G19 -> 0 | AH19: =AB19+AD19+AF19 -> 0 | AI19: =AC19+AE19+AG19 -> 0 | AJ19: =AH19+Z19 -> 350 | AK19: =AI19+AA19 -> 7.3441523e+08 | AM19: =AL19*$G19 -> 0 | AO19: =AN19*$G19 -> 0 | AQ19: =AP19*$G19 -> 0 | AR19: =AL19+AN19+AP19 -> 0 | AS19: =AM19+AO19+AQ19 -> 0 | AT19: =AR19+AJ19 -> 350 | AU19: =AS19+AK19 -> 7.3441523e+08 | AW19: =AV19*$G19 -> 0 | AY19: =AX19*$G19 -> 0 | BA19: =AZ19*$G19 -> 0 | BB19: =AV19+AX19+AZ19 -> 0 | BC19: =AW19+AY19+BA19 -> 0 | BD19: =BB19+AT19 -> 350 | BE19: =BC19+AU19 -> 7.3441523e+08 | BG19: =BF19*$G19 -> 0 | BI19: =BH19*$G19 -> 0 | BK19: =BJ19*$G19 -> 0 | BL19: =BF19+BH19+BJ19 -> 0 | BM19: =BG19+BI19+BK19 -> 0 | BN19: =BL19+BD19 -> 350 | BO19: =BM19+BE19 -> 7.3441523e+08 | BQ19: =BP19*$G19 -> 0 | BS19: =BR19*$G19 -> 0 | BU19: =BT19*$G19 -> 0 | BV19: =BP19+BR19+BT19 -> 0 | BW19: =BQ19+BS19+BU19 -> 0 | BX19: =BV19+BN19 -> 350 | BY19: =BW19+BO19 -> 7.3441523e+08 | CA19: =E19*H19 -> 350 | CB19: =CA19-BX19 -> 0 | CC19: =E19-BX19 -> 0 | CD19: =F19-BY19 -> 0 | CE19: 2.6941336e+09 | CF19: =CE19-BY19 -> 1.9597183e+09 | CG19: =CF19-BZ19 -> 1.9597183e+09 | CI19: 2316936.3 | CJ19: 2316936.3 | CK19: 0
C20: Main Nursery | E20: =$D$5 -> 350 | F20: =E20*G20 -> 2.116286e+09 | G20: ='Rekapitulasi Biaya'!C20 -> 6046531.3 | H20: 1 | I20: =G20/H20 -> 6046531.3 | J20: =J19 -> 0 | K20: =J20*$G20 -> 0 | L20: =L19 -> 200 | M20: =L20*$G20 -> 1.2093063e+09 | N20: 150 | O20: =N20*$G20 -> 9.069797e+08 | P20: =J20+L20+N20 -> 350 | Q20: =K20+M20+O20 -> 2.116286e+09 | S20: =R20*$G20 -> 0 | U20: =T20*$G20 -> 0 | W20: =V20*$G20 -> 0 | X20: =R20+T20+V20 -> 0 | Y20: =S20+U20+W20 -> 0 | Z20: =X20+P20 -> 350 | AA20: =Y20+Q20 -> 2.116286e+09 | AC20: =AB20*$G20 -> 0 | AE20: =AD20*$G20 -> 0 | AG20: =AF20*$G20 -> 0 | AH20: =AB20+AD20+AF20 -> 0 | AI20: =AC20+AE20+AG20 -> 0 | AJ20: =AH20+Z20 -> 350 | AK20: =AI20+AA20 -> 2.116286e+09 | AM20: =AL20*$G20 -> 0 | AO20: =AN20*$G20 -> 0 | AQ20: =AP20*$G20 -> 0 | AR20: =AL20+AN20+AP20 -> 0 | AS20: =AM20+AO20+AQ20 -> 0 | AT20: =AR20+AJ20 -> 350 | AU20: =AS20+AK20 -> 2.116286e+09 | AW20: =AV20*$G20 -> 0 | AY20: =AX20*$G20 -> 0 | BA20: =AZ20*$G20 -> 0 | BB20: =AV20+AX20+AZ20 -> 0 | BC20: =AW20+AY20+BA20 -> 0 | BD20: =BB20+AT20 -> 350 | BE20: =BC20+AU20 -> 2.116286e+09 | BG20: =BF20*$G20 -> 0 | BI20: =BH20*$G20 -> 0 | BK20: =BJ20*$G20 -> 0 | BL20: =BF20+BH20+BJ20 -> 0 | BM20: =BG20+BI20+BK20 -> 0 | BN20: =BL20+BD20 -> 350 | BO20: =BM20+BE20 -> 2.116286e+09 | BQ20: =BP20*$G20 -> 0 | BS20: =BR20*$G20 -> 0 | BU20: =BT20*$G20 -> 0 | BV20: =BP20+BR20+BT20 -> 0 | BW20: =BQ20+BS20+BU20 -> 0 | BX20: =BV20+BN20 -> 350 | BY20: =BW20+BO20 -> 2.116286e+09 | CA20: =E20*H20 -> 350 | CB20: =CA20-BX20 -> 0 | CC20: =E20-BX20 -> 0 | CD20: =F20-BY20 -> 0 | CE20: 7.8373505e+09 | CF20: =CE20-BY20 -> 5.7210645e+09 | CG20: =CF20-BZ20 -> 5.7210645e+09 | CI20: 6740067.5 | CJ20: 6740067.5 | CK20: 0
C21: Sub Total Pembibitan | F21: =SUM(F19:F20) -> 2.8507012e+09 | G21: =SUM(G19:G20) -> 8144860.6 | I21: =SUM(I19:I20) -> 8144860.6 | K21: =SUM(K19:K20) -> 0 | M21: =SUM(M19:M20) -> 1.6289721e+09 | O21: =SUM(O19:O20) -> 1.2217291e+09 | Q21: =SUM(Q19:Q20) -> 2.8507012e+09 | S21: =SUM(S19:S20) -> 0 | U21: =SUM(U19:U20) -> 0 | W21: =SUM(W19:W20) -> 0 | Y21: =SUM(Y19:Y20) -> 0 | AA21: =SUM(AA19:AA20) -> 2.8507012e+09 | AC21: =SUM(AC19:AC20) -> 0 | AE21: =SUM(AE19:AE20) -> 0 | AG21: =SUM(AG19:AG20) -> 0 | AI21: =SUM(AI19:AI20) -> 0 | AK21: =SUM(AK19:AK20) -> 2.8507012e+09 | AM21: =SUM(AM19:AM20) -> 0 | AO21: =SUM(AO19:AO20) -> 0 | AQ21: =SUM(AQ19:AQ20) -> 0 | AS21: =SUM(AS19:AS20) -> 0 | AU21: =SUM(AU19:AU20) -> 2.8507012e+09 | AW21: =SUM(AW19:AW20) -> 0 | AY21: =SUM(AY19:AY20) -> 0 | BA21: =SUM(BA19:BA20) -> 0 | BC21: =SUM(BC19:BC20) -> 0 | BE21: =SUM(BE19:BE20) -> 2.8507012e+09 | BG21: =SUM(BG19:BG20) -> 0 | BI21: =SUM(BI19:BI20) -> 0 | BK21: =SUM(BK19:BK20) -> 0 | BM21: =SUM(BM19:BM20) -> 0 | BO21: =SUM(BO19:BO20) -> 2.8507012e+09 | BQ21: =SUM(BQ19:BQ20) -> 0 | BS21: =SUM(BS19:BS20) -> 0 | BU21: =SUM(BU19:BU20) -> 0 | BW21: =SUM(BW19:BW20) -> 0 | BY21: =SUM(BY19:BY20) -> 2.8507012e+09 | CA21: =E21*H21 -> 0 | CB21: =CA21-BX21 -> 0 | CC21: =E21-BX21 -> 0 | CD21: =F21-BY21 -> 0 | CE21: 1.0531484e+10 | CF21: =CE21-BY21 -> 7.6807829e+09 | CG21: =CF21-BZ21 -> 7.6807829e+09 | CI21: 9057003.8 | CJ21: 9057003.8 | CK21: 0
C22: b. Aplikasi Bahan Organik | E22: =$D$5 -> 350 | F22: =E22*G22 -> 9.237438e+08 | G22: ='Rekapitulasi Biaya'!C22 -> 2639268 | H22: 1 | I22: =G22/H22 -> 2639268 | K22: =J22*$G22 -> 0 | L22: 200 | M22: =L22*$G22 -> 5.278536e+08 | N22: 150 | O22: =N22*$G22 -> 3.958902e+08 | P22: =J22+L22+N22 -> 350 | Q22: =K22+M22+O22 -> 9.237438e+08 | R22: 0 | S22: =R22*$G22 -> 0 | T22: 0 | U22: =T22*$G22 -> 0 | V22: 0 | W22: =V22*$G22 -> 0 | X22: 0 | Y22: =S22+U22+W22 -> 0 | Z22: =X22+P22 -> 350 | AA22: =Y22+Q22 -> 9.237438e+08 | AB22: 0 | AC22: =AB22*$G22 -> 0 | AD22: 0 | AE22: =AD22*$G22 -> 0 | AG22: =AF22*$G22 -> 0 | AH22: 0 | AI22: =AC22+AE22+AG22 -> 0 | AJ22: =AH22+Z22 -> 350 | AK22: =AI22+AA22 -> 9.237438e+08 | AM22: =AL22*$G22 -> 0 | AO22: =AN22*$G22 -> 0 | AQ22: =AP22*$G22 -> 0 | AR22: =AL22+AN22+AP22 -> 0 | AS22: =AM22+AO22+AQ22 -> 0 | AT22: =AR22+AJ22 -> 350 | AU22: =AS22+AK22 -> 9.237438e+08 | AW22: =AV22*$G22 -> 0 | AY22: =AX22*$G22 -> 0 | BA22: =AZ22*$G22 -> 0 | BB22: =AV22+AX22+AZ22 -> 0 | BC22: =AW22+AY22+BA22 -> 0 | BD22: =BB22+AT22 -> 350 | BE22: =BC22+AU22 -> 9.237438e+08 | BG22: =BF22*$G22 -> 0 | BI22: =BH22*$G22 -> 0 | BK22: =BJ22*$G22 -> 0 | BL22: =BF22+BH22+BJ22 -> 0 | BM22: =BG22+BI22+BK22 -> 0 | BN22: =BL22+BD22 -> 350 | BO22: =BM22+BE22 -> 9.237438e+08 | BQ22: =BP22*$G22 -> 0 | BS22: =BR22*$G22 -> 0 | BU22: =BT22*$G22 -> 0 | BV22: =BP22+BR22+BT22 -> 0 | BW22: =BQ22+BS22+BU22 -> 0 | BX22: =BV22+BN22 -> 350 | BY22: =BW22+BO22 -> 9.237438e+08 | CA22: =E22*H22 -> 350 | CB22: =CA22-BX22 -> 0 | CC22: =E22-BX22 -> 0 | CD22: =F22-BY22 -> 0 | CE22: 1.7801121e+09 | CF22: =CE22-BY22 -> 8.5636827e+08 | CG22: =CF22-BZ22 -> 8.5636827e+08 | CI22: 1530884.1 | CJ22: 1530884.1 | CK22: 0
C23: Penanaman | E23: =$D$5 -> 350 | K23: =J23*$G23 -> 0 | M23: =L23*$G23 -> 0 | O23: =N23*$G23 -> 0 | P23: =J23+L23+N23 -> 0 | Q23: =K23+M23+O23 -> 0 | S23: =R23*$G23 -> 0 | U23: =T23*$G23 -> 0 | W23: =V23*$G23 -> 0 | X23: =R23+T23+V23 -> 0 | Y23: =S23+U23+W23 -> 0 | Z23: =X23+P23 -> 0 | AA23: =Y23+Q23 -> 0 | AC23: =AB23*$G23 -> 0 | AE23: =AD23*$G23 -> 0 | AG23: =AF23*$G23 -> 0 | AH23: =AB23+AD23+AF23 -> 0 | AI23: =AC23+AE23+AG23 -> 0 | AJ23: =AH23+Z23 -> 0 | AK23: =AI23+AA23 -> 0 | AM23: =AL23*$G23 -> 0 | AO23: =AN23*$G23 -> 0 | AQ23: =AP23*$G23 -> 0 | AR23: =AL23+AN23+AP23 -> 0 | AS23: =AM23+AO23+AQ23 -> 0 | AT23: =AR23+AJ23 -> 0 | AU23: =AS23+AK23 -> 0 | AW23: =AV23*$G23 -> 0 | AY23: =AX23*$G23 -> 0 | BA23: =AZ23*$G23 -> 0 | BB23: =AV23+AX23+AZ23 -> 0 | BC23: =AW23+AY23+BA23 -> 0 | BD23: =BB23+AT23 -> 0 | BE23: =BC23+AU23 -> 0 | BG23: =BF23*$G23 -> 0 | BI23: =BH23*$G23 -> 0 | BK23: =BJ23*$G23 -> 0 | BL23: =BF23+BH23+BJ23 -> 0 | BM23: =BG23+BI23+BK23 -> 0 | BN23: =BL23+BD23 -> 0 | BO23: =BM23+BE23 -> 0 | BQ23: =BP23*$G23 -> 0 | BS23: =BR23*$G23 -> 0 | BU23: =BT23*$G23 -> 0 | BV23: =BP23+BR23+BT23 -> 0 | BW23: =BQ23+BS23+BU23 -> 0 | BX23: =BV23+BN23 -> 0 | BY23: =BW23+BO23 -> 0 | CA23: =E23*H23 -> 0 | CB23: =CA23-BX23 -> 0 | CC23: =E23-BX23 -> 350 | CD23: =F23-BY23 -> 0 | CE23: 0 | CF23: =CE23-BY23 -> 0 | CG23: =CF23-BZ23 -> 0 | CI23: 0 | CJ23: 0 | CK23: 0
C24: Pemeliharaan | E24: =$D$5 -> 350 | P24: =J24+L24+N24 -> 0 | Z24: =X24+P24 -> 0 | AA24: =Y24+Q24 -> 0 | AJ24: =AH24+Z24 -> 0 | AK24: =AI24+AA24 -> 0 | AT24: =AR24+AJ24 -> 0 | AU24: =AS24+AK24 -> 0 | BD24: =BB24+AT24 -> 0 | BE24: =BC24+AU24 -> 0 | BN24: =BL24+BD24 -> 0 | BO24: =BM24+BE24 -> 0 | BX24: =BV24+BN24 -> 0 | BY24: =BW24+BO24 -> 0 | CA24: =E24*H24 -> 0 | CB24: =CA24-BX24 -> 0 | CC24: =E24-BX24 -> 350 | CD24: =F24-BY24 -> 0 | CE24: 0 | CF24: =CE24-BY24 -> 0 | CG24: =CF24-BZ24 -> 0 | CI24: 0 | CJ24: 0 | CK24: 0
C25: Sub Total Tanam LCC | E25: =$D$5 -> 350 | I25: =SUM(I22:I24) -> 2639268 | P25: =J25+L25+N25 -> 0 | Z25: =X25+P25 -> 0 | AA25: =Y25+Q25 -> 0 | AJ25: =AH25+Z25 -> 0 | AK25: =AI25+AA25 -> 0 | AT25: =AR25+AJ25 -> 0 | AU25: =AS25+AK25 -> 0 | BD25: =BB25+AT25 -> 0 | BE25: =BC25+AU25 -> 0 | BN25: =BL25+BD25 -> 0 | BO25: =BM25+BE25 -> 0 | BX25: =BV25+BN25 -> 0 | BY25: =BW25+BO25 -> 0 | CA25: =E25*H25 -> 0 | CB25: =CA25-BX25 -> 0 | CC25: =E25-BX25 -> 350 | CD25: =F25-BY25 -> 0 | CE25: 0 | CF25: =CE25-BY25 -> 0 | CG25: =CF25-BZ25 -> 0 | CI25: 0 | CJ25: 0 | CK25: 0
C26: c. Tanam Kelapa Sawit | E26: =$D$5 -> 350 | F26: =E26*G26 -> 1444166542 | G26: ='Rekapitulasi Biaya'!C23 -> 4126190.1 | H26: 1 | I26: =G26/H26 -> 4126190.1 | J26: 0 | K26: =J26*$G26 -> 0 | L26: 200 | M26: =L26*$G26 -> 825238024 | N26: 150 | O26: =N26*$G26 -> 618928518 | P26: =J26+L26+N26 -> 350 | Q26: =K26+M26+O26 -> 1444166542 | R26: 0 | S26: =R26*$I26 -> 0 | T26: 0 | U26: =T26*$I26 -> 0 | V26: 0 | W26: =V26*$I26 -> 0 | X26: 0 | Y26: =S26+U26+W26 -> 0 | Z26: =X26+P26 -> 350 | AA26: =Y26+Q26 -> 1444166542 | AB26: 0 | AC26: =AB26*$I26 -> 0 | AE26: =AD26*$I26 -> 0 | AG26: =AF26*$I26 -> 0 | AH26: 0 | AI26: =AC26+AE26+AG26 -> 0 | AJ26: =AH26+Z26 -> 350 | AK26: =AI26+AA26 -> 1444166542 | AM26: =AL26*$I26 -> 0 | AO26: =AN26*$I26 -> 0 | AQ26: =AP26*$I26 -> 0 | AR26: =AL26+AN26+AP26 -> 0 | AS26: =AM26+AO26+AQ26 -> 0 | AT26: =AR26+AJ26 -> 350 | AU26: =AS26+AK26 -> 1444166542 | AW26: =AV26*$I26 -> 0 | AY26: =AX26*$I26 -> 0 | BA26: =AZ26*$I26 -> 0 | BB26: =AV26+AX26+AZ26 -> 0 | BC26: =AW26+AY26+BA26 -> 0 | BD26: =BB26+AT26 -> 350 | BE26: =BC26+AU26 -> 1444166542 | BG26: =BF26*$I26 -> 0 | BI26: =BH26*$I26 -> 0 | BK26: =BJ26*$I26 -> 0 | BL26: =BF26+BH26+BJ26 -> 0 | BM26: =BG26+BI26+BK26 -> 0 | BN26: =BL26+BD26 -> 350 | BO26: =BM26+BE26 -> 1444166542 | BQ26: =BP26*$I26 -> 0 | BS26: =BR26*$I26 -> 0 | BU26: =BT26*$I26 -> 0 | BV26: =BP26+BR26+BT26 -> 0 | BW26: =BQ26+BS26+BU26 -> 0 | BX26: =BV26+BN26 -> 350 | BY26: =BW26+BO26 -> 1444166542 | CA26: =E26*H26 -> 350 | CB26: =CA26-BX26 -> 0 | CC26: =E26-BX26 -> 0 | CD26: =F26-BY26 -> 0 | CE26: 5.1506828e+09 | CF26: =CE26-BY26 -> 3.7065162e+09 | CG26: =CF26-BZ26 -> 3.7065162e+09 | CI26: 4429551.7 | CJ26: 4429551.8 | CK26: 0
P27: =J27+L27+N27 -> 0 | Q27: =K27+M27+O27 -> 0 | X27: =R27+T27+V27 -> 0 | Y27: =S27+U27+W27 -> 0 | AH27: =AB27+AD27+AF27 -> 0 | AI27: =AC27+AE27+AG27 -> 0 | AR27: =AL27+AN27+AP27 -> 0 | AS27: =AM27+AO27+AQ27 -> 0 | BB27: =AV27+AX27+AZ27 -> 0 | BC27: =AW27+AY27+BA27 -> 0 | BL27: =BF27+BH27+BJ27 -> 0 | BM27: =BG27+BI27+BK27 -> 0 | BV27: =BP27+BR27+BT27 -> 0 | BW27: =BQ27+BS27+BU27 -> 0 | CA27: =E27*H27 -> 0 | CB27: =CA27-BX27 -> 0 | CC27: =E27-BX27 -> 0 | CD27: =F27-BY27 -> 0 | CF27: =CE27-BY27 -> 0 | CG27: =CF27-BZ27 -> 0 | CI27: 0 | CJ27: 0 | CK27: 0
CA28: =E28*H28 -> 0 | CB28: =CA28-BX28 -> 0 | CC28: =E28-BX28 -> 0 | CD28: =F28-BY28 -> 0 | CF28: =CE28-BY28 -> 0 | CG28: =CF28-BZ28 -> 0 | CI28: 0 | CJ28: 0 | CK28: 0
CA29: =E29*H29 -> 0 | CB29: =CA29-BX29 -> 0 | CC29: =E29-BX29 -> 0 | CD29: =F29-BY29 -> 0 | CF29: =CE29-BY29 -> 0 | CG29: =CF29-BZ29 -> 0 | CI29: 0 | CJ29: 0 | CK29: 0
CA30: =E30*H30 -> 0 | CB30: =CA30-BX30 -> 0 | CC30: =E30-BX30 -> 0 | CD30: =F30-BY30 -> 0 | CF30: =CE30-BY30 -> 0 | CG30: =CF30-BZ30 -> 0 | CI30: 0 | CJ30: 0 | CK30: 0
C31: Total Persiapan Lahan | F31: =F21+F22+F26 -> 5.2186115e+09 | G31: =G21+G22+G26 -> 14910319 | I31: =I21+I22+I26 -> 14910319 | K31: =K21+K22+K26 -> 0 | M31: =M21+M22+M26 -> 2.9820637e+09 | O31: =O21+O22+O26 -> 2.2365478e+09 | Q31: =Q21+Q22+Q26 -> 5.2186115e+09 | S31: =S21+S22+S26 -> 0 | U31: =U21+U22+U26 -> 0 | W31: =W21+W22+W26 -> 0 | Y31: =Y21+Y22+Y26 -> 0 | AA31: =AA21+AA22+AA26 -> 5.2186115e+09 | AC31: =AC21+AC22+AC26 -> 0 | AE31: =AE21+AE22+AE26 -> 0 | AG31: =AG21+AG22+AG26 -> 0 | AI31: =AI21+AI22+AI26 -> 0 | AK31: =AK21+AK22+AK26 -> 5.2186115e+09 | AM31: =AM21+AM22+AM26 -> 0 | AO31: =AO21+AO22+AO26 -> 0 | AQ31: =AQ21+AQ22+AQ26 -> 0 | AS31: =AS21+AS22+AS26 -> 0 | AU31: =AU21+AU22+AU26 -> 5.2186115e+09 | AW31: =AW21+AW22+AW26 -> 0 | AY31: =AY21+AY22+AY26 -> 0 | BA31: =BA21+BA22+BA26 -> 0 | BC31: =BC21+BC22+BC26 -> 0 | BE31: =BE21+BE22+BE26 -> 5.2186115e+09 | BG31: =BG21+BG22+BG26 -> 0 | BI31: =BI21+BI22+BI26 -> 0 | BK31: =BK21+BK22+BK26 -> 0 | BM31: =BM21+BM22+BM26 -> 0 | BO31: =BO21+BO22+BO26 -> 5.2186115e+09 | BQ31: =BQ21+BQ22+BQ26 -> 0 | BS31: =BS21+BS22+BS26 -> 0 | BU31: =BU21+BU22+BU26 -> 0 | BW31: =BW21+BW22+BW26 -> 0 | BY31: =BY21+BY22+BY26 -> 5.2186115e+09 | CA31: =E31*H31 -> 0 | CB31: =CA31-BX31 -> 0 | CC31: =E31-BX31 -> 0 | CD31: =F31-BY31 -> 0 | CE31: 1.7462279e+10 | CF31: =CE31-BY31 -> 1.2243667e+10 | CG31: =CF31-BZ31 -> 1.2243667e+10 | CI31: 15017440 | CJ31: 15017440 | CK31: 0
CA32: =E32*H32 -> 0 | CB32: =CA32-BX32 -> 0 | CC32: =E32-BX32 -> 0 | CD32: =F32-BY32 -> 0 | CF32: =CE32-BY32 -> 0 | CG32: =CF32-BZ32 -> 0 | CI32: 0 | CJ32: 0 | CK32: 0
B33: 3 | C33: Pemeliharaan TBM-1 | E33: =$D$5 -> 350 | F33: =E33*G33 -> 4.915516e+09 | G33: ='Rekapitulasi Biaya'!C24 -> 14044331 | H33: 1 | I33: =G33/H33 -> 14044331 | K33: =J33*$G33 -> 0 | M33: =L33*$G33 -> 0 | O33: =N33*$G33 -> 0 | P33: =J33+L33+N33 -> 0 | Q33: =K33+M33+O33 -> 0 | R33: 200 | S33: =R33*$G33 -> 2.8088663e+09 | T33: 150 | U33: =T33*$G33 -> 2.1066497e+09 | V33: 0 | W33: =V33*$G33 -> 0 | X33: =V33+T33+R33 -> 350 | Y33: =S33+U33+W33 -> 4.915516e+09 | Z33: =X33+P33 -> 350 | AA33: =Y33+Q33 -> 4.915516e+09 | AB33: 0 | AC33: =AB33*$G33 -> 0 | AD33: 0 | AE33: =AD33*$G33 -> 0 | AF33: 0 | AG33: =AF33*$G33 -> 0 | AH33: =AF33+AD33+AB33 -> 0 | AI33: =AC33+AE33+AG33 -> 0 | AJ33: =AH33+Z33 -> 350 | AK33: =AI33+AA33 -> 4.915516e+09 | AL33: 0 | AM33: =AL33*$G33 -> 0 | AN33: =AL33 -> 0 | AO33: =AN33*$G33 -> 0 | AP33: =AN33 -> 0 | AQ33: =AP33*$G33 -> 0 | AR33: 0 | AS33: =AM33+AO33+AQ33 -> 0 | AT33: =AR33+AJ33 -> 350 | AU33: =AS33+AK33 -> 4.915516e+09 | AW33: =AV33*$G33 -> 0 | AY33: =AX33*$G33 -> 0 | BA33: =AZ33*$G33 -> 0 | BB33: =AV33+AX33+AZ33 -> 0 | BC33: =AW33+AY33+BA33 -> 0 | BD33: =BB33+AT33 -> 350 | BE33: =BC33+AU33 -> 4.915516e+09 | BG33: =BF33*$G33 -> 0 | BI33: =BH33*$G33 -> 0 | BK33: =BJ33*$G33 -> 0 | BL33: =BF33+BH33+BJ33 -> 0 | BM33: =BG33+BI33+BK33 -> 0 | BN33: =BL33+BD33 -> 350 | BO33: =BM33+BE33 -> 4.915516e+09 | BQ33: =BP33*$G33 -> 0 | BS33: =BR33*$G33 -> 0 | BU33: =BT33*$G33 -> 0 | BV33: =BP33+BR33+BT33 -> 0 | BW33: =BQ33+BS33+BU33 -> 0 | BX33: =BV33+BN33 -> 350 | BY33: =BW33+BO33 -> 4.915516e+09 | CA33: =E33*H33 -> 350 | CB33: =CA33-BX33 -> 0 | CC33: =E33-BX33 -> 0 | CD33: =F33-BY33 -> 0 | CE33: 1.5604327e+10 | CF33: =CE33-BY33 -> 1.0688811e+10 | CG33: =CF33-BZ33 -> 1.0688811e+10 | CI33: 13419614 | CJ33: 13419614 | CK33: 0
C34: Pembersihan Piringan/Gawangan | E34: =$D$5 -> 350 | P34: =J34+L34+N34 -> 0 | Q34: =K34+M34+O34 -> 0 | X34: =R34+T34+V34 -> 0 | Y34: =S34+U34+W34 -> 0 | Z34: =X34+P34 -> 0 | AA34: =Y34+Q34 -> 0 | AH34: =AF34+AD34+AB34 -> 0 | AI34: =AC34+AE34+AG34 -> 0 | AJ34: =AH34+Z34 -> 0 | AK34: =AI34+AA34 -> 0 | AR34: =AL34+AN34+AP34 -> 0 | AS34: =AM34+AO34+AQ34 -> 0 | AT34: =AR34+AJ34 -> 0 | AU34: =AS34+AK34 -> 0 | BB34: =AV34+AX34+AZ34 -> 0 | BC34: =AW34+AY34+BA34 -> 0 | BD34: =BB34+AT34 -> 0 | BE34: =BC34+AU34 -> 0 | BL34: =BF34+BH34+BJ34 -> 0 | BM34: =BG34+BI34+BK34 -> 0 | BN34: =BL34+BD34 -> 0 | BO34: =BM34+BE34 -> 0 | BV34: =BP34+BR34+BT34 -> 0 | BW34: =BQ34+BS34+BU34 -> 0 | BX34: =BV34+BN34 -> 0 | BY34: =BW34+BO34 -> 0 | CA34: =E34*H34 -> 0 | CB34: =CA34-BX34 -> 0 | CC34: =E34-BX34 -> 350 | CD34: =F34-BY34 -> 0 | CE34: 0 | CF34: =CE34-BY34 -> 0 | CG34: =CF34-BZ34 -> 0 | CI34: 0 | CJ34: 0 | CK34: 0
C35: ='Tingkat Jalan Mineral'!G20 -> 998942.8 | E35: =$D$5 -> 350 | P35: =J35+L35+N35 -> 0 | Q35: =K35+M35+O35 -> 0 | X35: =R35+T35+V35 -> 0 | Y35: =S35+U35+W35 -> 0 | Z35: =X35+P35 -> 0 | AA35: =Y35+Q35 -> 0 | AH35: =AF35+AD35+AB35 -> 0 | AI35: =AC35+AE35+AG35 -> 0 | AJ35: =AH35+Z35 -> 0 | AK35: =AI35+AA35 -> 0 | AR35: =AL35+AN35+AP35 -> 0 | AS35: =AM35+AO35+AQ35 -> 0 | AT35: =AR35+AJ35 -> 0 | AU35: =AS35+AK35 -> 0 | BB35: =AV35+AX35+AZ35 -> 0 | BC35: =AW35+AY35+BA35 -> 0 | BD35: =BB35+AT35 -> 0 | BE35: =BC35+AU35 -> 0 | BL35: =BF35+BH35+BJ35 -> 0 | BM35: =BG35+BI35+BK35 -> 0 | BN35: =BL35+BD35 -> 0 | BO35: =BM35+BE35 -> 0 | BV35: =BP35+BR35+BT35 -> 0 | BW35: =BQ35+BS35+BU35 -> 0 | BX35: =BV35+BN35 -> 0 | BY35: =BW35+BO35 -> 0 | CA35: =E35*H35 -> 0 | CB35: =CA35-BX35 -> 0 | CC35: =E35-BX35 -> 350 | CD35: =F35-BY35 -> 0 | CE35: 0 | CF35: =CE35-BY35 -> 0 | CG35: =CF35-BZ35 -> 0 | CI35: 0 | CJ35: 0 | CK35: 0
C36: ='Tingkat Jalan Mineral'!Q20 -> 1522646.8 | E36: =$D$5 -> 350 | P36: =J36+L36+N36 -> 0 | Q36: =K36+M36+O36 -> 0 | X36: =R36+T36+V36 -> 0 | Y36: =S36+U36+W36 -> 0 | Z36: =X36+P36 -> 0 | AA36: =Y36+Q36 -> 0 | AH36: =AF36+AD36+AB36 -> 0 | AI36: =AC36+AE36+AG36 -> 0 | AJ36: =AH36+Z36 -> 0 | AK36: =AI36+AA36 -> 0 | AR36: =AL36+AN36+AP36 -> 0 | AS36: =AM36+AO36+AQ36 -> 0 | AT36: =AR36+AJ36 -> 0 | AU36: =AS36+AK36 -> 0 | BB36: =AV36+AX36+AZ36 -> 0 | BC36: =AW36+AY36+BA36 -> 0 | BD36: =BB36+AT36 -> 0 | BE36: =BC36+AU36 -> 0 | BL36: =BF36+BH36+BJ36 -> 0 | BM36: =BG36+BI36+BK36 -> 0 | BN36: =BL36+BD36 -> 0 | BO36: =BM36+BE36 -> 0 | BV36: =BP36+BR36+BT36 -> 0 | BW36: =BQ36+BS36+BU36 -> 0 | BX36: =BV36+BN36 -> 0 | BY36: =BW36+BO36 -> 0 | CA36: =E36*H36 -> 0 | CB36: =CA36-BX36 -> 0 | CC36: =E36-BX36 -> 350 | CD36: =F36-BY36 -> 0 | CE36: 0 | CF36: =CE36-BY36 -> 0 | CG36: =CF36-BZ36 -> 0 | CI36: 0 | CJ36: 0 | CK36: 0
C37: ='Drainase Tnh Mineral '!Q21 -> 581740 | E37: =$D$5 -> 350 | P37: =J37+L37+N37 -> 0 | Q37: =K37+M37+O37 -> 0 | X37: =R37+T37+V37 -> 0 | Y37: =S37+U37+W37 -> 0 | Z37: =X37+P37 -> 0 | AA37: =Y37+Q37 -> 0 | AH37: =AF37+AD37+AB37 -> 0 | AI37: =AC37+AE37+AG37 -> 0 | AJ37: =AH37+Z37 -> 0 | AK37: =AI37+AA37 -> 0 | AR37: =AL37+AN37+AP37 -> 0 | AS37: =AM37+AO37+AQ37 -> 0 | AT37: =AR37+AJ37 -> 0 | AU37: =AS37+AK37 -> 0 | BB37: =AV37+AX37+AZ37 -> 0 | BC37: =AW37+AY37+BA37 -> 0 | BD37: =BB37+AT37 -> 0 | BE37: =BC37+AU37 -> 0 | BL37: =BF37+BH37+BJ37 -> 0 | BM37: =BG37+BI37+BK37 -> 0 | BN37: =BL37+BD37 -> 0 | BO37: =BM37+BE37 -> 0 | BV37: =BP37+BR37+BT37 -> 0 | BW37: =BQ37+BS37+BU37 -> 0 | BX37: =BV37+BN37 -> 0 | BY37: =BW37+BO37 -> 0 | CA37: =E37*H37 -> 0 | CB37: =CA37-BX37 -> 0 | CC37: =E37-BX37 -> 350 | CD37: =F37-BY37 -> 0 | CE37: 0 | CF37: =CE37-BY37 -> 0 | CG37: =CF37-BZ37 -> 0 | CI37: 0 | CJ37: 0 | CK37: 0
B38: 4 | C38: Pemeliharaan TBM-2 | E38: =$D$5 -> 350 | F38: =E38*G38 -> 6.5254319e+09 | G38: ='Rekapitulasi Biaya'!C25 -> 18644091 | H38: 1 | I38: =G38/H38 -> 18644091 | K38: =J38*$G38 -> 0 | M38: =L38*$G38 -> 0 | O38: =N38*$G38 -> 0 | P38: =J38+L38+N38 -> 0 | Q38: =K38+M38+O38 -> 0 | S38: =R38*$G38 -> 0 | U38: =T38*$G38 -> 0 | W38: =V38*$G38 -> 0 | X38: =R38+T38+V38 -> 0 | Y38: =S38+U38+W38 -> 0 | Z38: =X38+P38 -> 0 | AA38: =Y38+Q38 -> 0 | AB38: 200 | AC38: =AB38*$G38 -> 3.7288183e+09 | AD38: 150 | AE38: =AD38*$G38 -> 2.7966137e+09 | AF38: 0 | AG38: =AF38*$G38 -> 0 | AH38: =+AD38+AB38 -> 350 | AI38: =AC38+AE38+AG38 -> 6.5254319e+09 | AJ38: =AH38+Z38 -> 350 | AK38: =AI38+AA38 -> 6.5254319e+09 | AL38: 0 | AM38: =AL38*$G38 -> 0 | AN38: 0 | AO38: =AN38*$G38 -> 0 | AP38: 0 | AQ38: =AP38*$G38 -> 0 | AR38: =AL38+AN38+AP38 -> 0 | AS38: =AM38+AO38+AQ38 -> 0 | AT38: =AR38+AJ38 -> 350 | AU38: =AS38+AK38 -> 6.5254319e+09 | AV38: 0 | AW38: =AV38*$G38 -> 0 | AX38: =AV38 -> 0 | AY38: =AX38*$G38 -> 0 | AZ38: =AX38 -> 0 | BA38: =AZ38*$G38 -> 0 | BB38: 0 | BC38: =AW38+AY38+BA38 -> 0 | BD38: =BB38+AT38 -> 350 | BE38: =BC38+AU38 -> 6.5254319e+09 | BG38: =BF38*$G38 -> 0 | BI38: =BH38*$G38 -> 0 | BK38: =BJ38*$G38 -> 0 | BL38: =BF38+BH38+BJ38 -> 0 | BM38: =BG38+BI38+BK38 -> 0 | BN38: =BL38+BD38 -> 350 | BO38: =BM38+BE38 -> 6.5254319e+09 | BQ38: =BP38*$G38 -> 0 | BS38: =BR38*$G38 -> 0 | BU38: =BT38*$G38 -> 0 | BV38: =BP38+BR38+BT38 -> 0 | BW38: =BQ38+BS38+BU38 -> 0 | BX38: =BV38+BN38 -> 350 | BY38: =BW38+BO38 -> 6.5254319e+09 | CA38: =E38*H38 -> 350 | CB38: =CA38-BX38 -> 0 | CC38: =E38-BX38 -> 0 | CD38: =F38-BY38 -> 0 | CE38: 1.5932355e+10 | CF38: =CE38-BY38 -> 9.4069232e+09 | CG38: =CF38-BZ38 -> 9.4069232e+09 | CI38: 13701716 | CJ38: 13701716 | CK38: 0
C39: =C33+C38 -> #VALUE! | E39: =$D$5 -> 350 | K39: =J39*$G39 -> 0 | M39: =L39*$G39 -> 0 | O39: =N39*$G39 -> 0 | P39: =J39+L39+N39 -> 0 | Q39: =K39+M39+O39 -> 0 | S39: =R39*$G39 -> 0 | U39: =T39*$G39 -> 0 | W39: =V39*$G39 -> 0 | X39: =R39+T39+V39 -> 0 | Y39: =S39+U39+W39 -> 0 | Z39: =X39+P39 -> 0 | AA39: =Y39+Q39 -> 0 | AC39: =AB39*$G39 -> 0 | AE39: =AD39*$G39 -> 0 | AG39: =AF39*$G39 -> 0 | AH39: =AB39+AD39+AF39 -> 0 | AI39: =AC39+AE39+AG39 -> 0 | AJ39: =AH39+Z39 -> 0 | AK39: =AI39+AA39 -> 0 | AR39: =AL39+AN39+AP39 -> 0 | AS39: =AM39+AO39+AQ39 -> 0 | AT39: =AR39+AJ39 -> 0 | AU39: =AS39+AK39 -> 0 | BB39: =AV39+AX39+AZ39 -> 0 | BC39: =AW39+AY39+BA39 -> 0 | BD39: =BB39+AT39 -> 0 | BE39: =BC39+AU39 -> 0 | BL39: =BF39+BH39+BJ39 -> 0 | BM39: =BG39+BI39+BK39 -> 0 | BN39: =BL39+BD39 -> 0 | BO39: =BM39+BE39 -> 0 | BV39: =BP39+BR39+BT39 -> 0 | BW39: =BQ39+BS39+BU39 -> 0 | BX39: =BV39+BN39 -> 0 | BY39: =BW39+BO39 -> 0 | CA39: =E39*H39 -> 0 | CB39: =CA39-BX39 -> 0 | CC39: =E39-BX39 -> 350 | CD39: =F39-BY39 -> 0 | CE39: 0 | CF39: =CE39-BY39 -> 0 | CG39: =CF39-BZ39 -> 0 | CI39: 0 | CJ39: 0 | CK39: 0
C40: Pemupukan | E40: =$D$5 -> 350 | K40: =J40*$G40 -> 0 | M40: =L40*$G40 -> 0 | O40: =N40*$G40 -> 0 | P40: =J40+L40+N40 -> 0 | Q40: =K40+M40+O40 -> 0 | S40: =R40*$G40 -> 0 | U40: =T40*$G40 -> 0 | W40: =V40*$G40 -> 0 | X40: =R40+T40+V40 -> 0 | Y40: =S40+U40+W40 -> 0 | Z40: =X40+P40 -> 0 | AA40: =Y40+Q40 -> 0 | AC40: =AB40*$G40 -> 0 | AE40: =AD40*$G40 -> 0 | AG40: =AF40*$G40 -> 0 | AH40: =AB40+AD40+AF40 -> 0 | AI40: =AC40+AE40+AG40 -> 0 | AJ40: =AH40+Z40 -> 0 | AK40: =AI40+AA40 -> 0 | AR40: =AL40+AN40+AP40 -> 0 | AS40: =AM40+AO40+AQ40 -> 0 | AT40: =AR40+AJ40 -> 0 | AU40: =AS40+AK40 -> 0 | BB40: =AV40+AX40+AZ40 -> 0 | BC40: =AW40+AY40+BA40 -> 0 | BD40: =BB40+AT40 -> 0 | BE40: =BC40+AU40 -> 0 | BL40: =BF40+BH40+BJ40 -> 0 | BM40: =BG40+BI40+BK40 -> 0 | BN40: =BL40+BD40 -> 0 | BO40: =BM40+BE40 -> 0 | BV40: =BP40+BR40+BT40 -> 0 | BW40: =BQ40+BS40+BU40 -> 0 | BX40: =BV40+BN40 -> 0 | BY40: =BW40+BO40 -> 0 | CA40: =E40*H40 -> 0 | CB40: =CA40-BX40 -> 0 | CC40: =E40-BX40 -> 350 | CD40: =F40-BY40 -> 0 | CE40: 0 | CF40: =CE40-BY40 -> 0 | CG40: =CF40-BZ40 -> 0 | CI40: 0 | CJ40: 0 | CK40: 0
C41: Pemberantasan Hama Penyakit | E41: =$D$5 -> 350 | K41: =J41*$G41 -> 0 | M41: =L41*$G41 -> 0 | O41: =N41*$G41 -> 0 | P41: =J41+L41+N41 -> 0 | Q41: =K41+M41+O41 -> 0 | S41: =R41*$G41 -> 0 | U41: =T41*$G41 -> 0 | W41: =V41*$G41 -> 0 | X41: =R41+T41+V41 -> 0 | Y41: =S41+U41+W41 -> 0 | Z41: =X41+P41 -> 0 | AA41: =Y41+Q41 -> 0 | AC41: =AB41*$G41 -> 0 | AE41: =AD41*$G41 -> 0 | AG41: =AF41*$G41 -> 0 | AH41: =AB41+AD41+AF41 -> 0 | AI41: =AC41+AE41+AG41 -> 0 | AJ41: =AH41+Z41 -> 0 | AK41: =AI41+AA41 -> 0 | AR41: =AL41+AN41+AP41 -> 0 | AS41: =AM41+AO41+AQ41 -> 0 | AT41: =AR41+AJ41 -> 0 | AU41: =AS41+AK41 -> 0 | BB41: =AV41+AX41+AZ41 -> 0 | BC41: =AW41+AY41+BA41 -> 0 | BD41: =BB41+AT41 -> 0 | BE41: =BC41+AU41 -> 0 | BL41: =BF41+BH41+BJ41 -> 0 | BM41: =BG41+BI41+BK41 -> 0 | BN41: =BL41+BD41 -> 0 | BO41: =BM41+BE41 -> 0 | BV41: =BP41+BR41+BT41 -> 0 | BW41: =BQ41+BS41+BU41 -> 0 | BX41: =BV41+BN41 -> 0 | BY41: =BW41+BO41 -> 0 | CA41: =E41*H41 -> 0 | CB41: =CA41-BX41 -> 0 | CC41: =E41-BX41 -> 350 | CD41: =F41-BY41 -> 0 | CE41: 0 | CF41: =CE41-BY41 -> 0 | CG41: =CF41-BZ41 -> 0 | CI41: 0 | CJ41: 0 | CK41: 0
...

Sheet RKT 18_19 Infra
B2: PT. KUMAI SENTOSA
B3: Rencana Kerja Tahun 2026
D4: satuan m atau unit sheet kuning | GL4: satuan ha warna sheet putih
B5: Uraian | C5: Satuan | D5: Unit Cost | E5: Qty | F5: 2026 | AG5: 2027 | BH5: 2028 | CI5: 2029 | DJ5: 2029 | EK5: 2030 | FL5: 2031 | GL5: 2024 | GR5: 2025 | GT5: 2022 | GZ5: ="Total"&" "&GT5 -> Total 2022 | HB5: 2023 | HH5: ="Total"&" "&HB5 -> Total 2023 | HJ5: 2024 | HP5: ="Total"&" "&HJ5 -> Total 2024 | HR5: 2025 | HX5: ="Total"&" "&HR5 -> Total 2025 | HZ5: 2026 | IF5: 2026 | II5: Total
D6: (Rp/Satuan) | F6: Januari | H6: Pebruari | J6: Maret | L6: April | N6: Mei | P6: Juni | R6: Juli | T6: Agustus | V6: September | X6: Oktober | Z6: Nopember | AB6: Desember | AD6: Total | AG6: Januari | AI6: Pebruari | AK6: Maret | AM6: April | AO6: Mei | AQ6: Juni | AS6: Juli | AU6: Agustus | AW6: September | AY6: Oktober | BA6: Nopember | BC6: Desember | BE6: Total | BH6: Januari | BJ6: Pebruari | BL6: Maret | BN6: April | BP6: Mei | BR6: Juni | BT6: Juli | BV6: Agustus | BX6: September | BZ6: Oktober | CB6: Nopember | CD6: Desember | CF6: Total | CI6: Januari | CK6: Pebruari | CM6: Maret | CO6: April | CQ6: Mei | CS6: Juni | CU6: Juli | CW6: Agustus | CY6: September | DA6: Oktober | DC6: Nopember | DE6: Desember | DG6: Total | DJ6: Januari | DL6: Pebruari | DN6: Maret | DP6: April | DR6: Mei | DT6: Juni | DV6: Juli | DX6: Agustus | DZ6: September | EB6: Oktober | ED6: Nopember | EF6: Desember | EH6: Total | EK6: Januari | EM6: Pebruari | EO6: Maret | EQ6: April | ES6: Mei | EU6: Juni | EW6: Juli | EY6: Agustus | FA6: September | FC6: Oktober | FE6: Nopember | FG6: Desember | FI6: Total | FL6: Januari | FN6: Pebruari | FP6: Maret | FR6: April | FT6: Mei | FV6: Juni | FX6: Juli | FZ6: Agustus | GB6: September | GD6: Oktober | GF6: Nopember | GH6: Desember | GJ6: Total | GL6: Catur Wulan 1 | GN6: Catur Wulan 2 | GP6: Catur Wulan 3 | GT6: Catur Wulan 1 | GV6: Catur Wulan 2 | GX6: Catur Wulan 3 | HB6: Catur Wulan 1 | HD6: Catur Wulan 2 | HF6: Catur Wulan 3 | HJ6: Catur Wulan 1 | HL6: Catur Wulan 2 | HN6: Catur Wulan 3 | HR6: Catur Wulan 1 | HT6: Catur Wulan 2 | HV6: Catur Wulan 3 | HZ6: Catur Wulan 1 | IB6: Catur Wulan 2 | ID6: Catur Wulan 3
F7: Qty | G7: Rp | H7: Qty | I7: Rp | J7: Qty | K7: Rp | L7: Qty | M7: Rp | N7: Qty | O7: Rp | P7: Qty | Q7: Rp | R7: Qty | S7: Rp | T7: Qty | U7: Rp | V7: Qty | W7: Rp | X7: Qty | Y7: Rp | Z7: Qty | AA7: Rp | AB7: Qty | AC7: Rp | AD7: Qty | AE7: Rp | AG7: Qty | AH7: Rp | AI7: Qty | AJ7: Rp | AK7: Qty | AL7: Rp | AM7: Qty | AN7: Rp | AO7: Qty | AP7: Rp | AQ7: Qty | AR7: Rp | AS7: Qty | AT7: Rp | AU7: Qty | AV7: Rp | AW7: Qty | AX7: Rp | AY7: Qty | AZ7: Rp | BA7: Qty | BB7: Rp | BC7: Qty | BD7: Rp | BE7: Qty | BF7: Rp | BH7: Qty | BI7: Rp | BJ7: Qty | BK7: Rp | BL7: Qty | BM7: Rp | BN7: Qty | BO7: Rp | BP7: Qty | BQ7: Rp | BR7: Qty | BS7: Rp | BT7: Qty | BU7: Rp | BV7: Qty | BW7: Rp | BX7: Qty | BY7: Rp | BZ7: Qty | CA7: Rp | CB7: Qty | CC7: Rp | CD7: Qty | CE7: Rp | CF7: Qty | CG7: Rp | CI7: Qty | CJ7: Rp | CK7: Qty | CL7: Rp | CM7: Qty | CN7: Rp | CO7: Qty | CP7: Rp | CQ7: Qty | CR7: Rp | CS7: Qty | CT7: Rp | CU7: Qty | CV7: Rp | CW7: Qty | CX7: Rp | CY7: Qty | CZ7: Rp | DA7: Qty | DB7: Rp | DC7: Qty | DD7: Rp | DE7: Qty | DF7: Rp | DG7: Qty | DH7: Rp | DJ7: Qty | DK7: Rp | DL7: Qty | DM7: Rp | DN7: Qty | DO7: Rp | DP7: Qty | DQ7: Rp | DR7: Qty | DS7: Rp | DT7: Qty | DU7: Rp | DV7: Qty | DW7: Rp | DX7: Qty | DY7: Rp | DZ7: Qty | EA7: Rp | EB7: Qty | EC7: Rp | ED7: Qty | EE7: Rp | EF7: Qty | EG7: Rp | EH7: Qty | EI7: Rp | EK7: Qty | EL7: Rp | EM7: Qty | EN7: Rp | EO7: Qty | EP7: Rp | EQ7: Qty | ER7: Rp | ES7: Qty | ET7: Rp | EU7: Qty | EV7: Rp | EW7: Qty | EX7: Rp | EY7: Qty | EZ7: Rp | FA7: Qty | FB7: Rp | FC7: Qty | FD7: Rp | FE7: Qty | FF7: Rp | FG7: Qty | FH7: Rp | FI7: Qty | FJ7: Rp | FL7: Qty | FM7: Rp | FN7: Qty | FO7: Rp | FP7: Qty | FQ7: Rp | FR7: Qty | FS7: Rp | FT7: Qty | FU7: Rp | FV7: Qty | FW7: Rp | FX7: Qty | FY7: Rp | FZ7: Qty | GA7: Rp | GB7: Qty | GC7: Rp | GD7: Qty | GE7: Rp | GF7: Qty | GG7: Rp | GH7: Qty | GI7: Rp | GJ7: Qty | GK7: Rp | GL7: Qty | GM7: Rp | GN7: Qty | GO7: Rp | GP7: Qty | GQ7: Rp | GR7: Qty | GS7: Rp | GT7: Qty | GU7: Rp | GV7: Qty | GW7: Rp | GX7: Qty | GY7: Rp | GZ7: Qty | HA7: Rp | HB7: Qty | HC7: Rp | HD7: Qty | HE7: Rp | HF7: Qty | HG7: Rp | HH7: Qty | HI7: Rp | HJ7: Qty | HK7: Rp | HL7: Qty | HM7: Rp | HN7: Qty | HO7: Rp | HP7: Qty | HQ7: Rp | HR7: Qty | HS7: Rp | HT7: Qty | HU7: Rp | HV7: Qty | HW7: Rp | HX7: Qty | HY7: Rp | HZ7: Qty | IA7: Rp | IB7: Qty | IC7: Rp | ID7: Qty | IE7: Rp | IF7: Qty | IG7: Rp
B9: PEMBUKAAN LAHAN
B10: - Blok | C10: Ha | D10: =AE10/AD10 -> 110763.54 | E10: =AD10 -> 6511.6 | F10: ='[15]TTL TB'!W14 -> 600 | G10: ='[15]TTL TB'!X21 -> 66458122 | H10: ='[15]TTL TB'!Y14 -> 600 | I10: ='[15]TTL TB'!Z21 -> 66458122 | J10: ='[15]TTL TB'!AA14 -> 407.39 | K10: ='[15]TTL TB'!AB21 -> 45123958 | L10: ='[15]TTL TB'!AC14 -> 600 | M10: ='[15]TTL TB'!AD21 -> 66458122 | N10: ='[15]TTL TB'!AE14 -> 600 | O10: ='[15]TTL TB'!AF21 -> 66458122 | P10: ='[15]TTL TB'!AG14 -> 457.63 | Q10: ='[15]TTL TB'!AH21 -> 50688718 | R10: ='[15]TTL TB'!AI14 -> 600 | S10: ='[15]TTL TB'!AJ21 -> 66458122 | T10: ='[15]TTL TB'!AK14 -> 600 | U10: ='[15]TTL TB'!AL21 -> 66458122 | V10: ='[15]TTL TB'!AM14 -> 414.93 | W10: ='[15]TTL TB'!AN21 -> 45959115 | X10: ='[15]TTL TB'!AO14 -> 600 | Y10: ='[15]TTL TB'!AP21 -> 66458122 | Z10: ='[15]TTL TB'!AQ14 -> 600 | AA10: ='[15]TTL TB'!AR21 -> 66458122 | AB10: ='[15]TTL TB'!AS14 -> 431.65 | AC10: ='[15]TTL TB'!AT21 -> 47811081 | AD10: =F10+H10+J10+L10+N10+P10+R10+T10+V10+X10+Z10+AB10 -> 6511.6 | AE10: =G10+I10+K10+M10+O10+Q10+S10+U10+W10+Y10+AA10+AC10 -> 7.2124785e+08 | BE10: =AG10+AI10+AK10+AM10+AO10+AQ10+AS10+AU10+AW10+AY10+BA10+BC10 -> 0 | BF10: =AH10+AJ10+AL10+AN10+AP10+AR10+AT10+AV10+AX10+AZ10+BB10+BD10 -> 0 | CF10: =BH10+BJ10+BL10+BN10+BP10+BR10+BT10+BV10+BX10+BZ10+CB10+CD10 -> 0 | CG10: =BI10+BK10+BM10+BO10+BQ10+BS10+BU10+BW10+BY10+CA10+CC10+CE10 -> 0 | DG10: =CI10+CK10+CM10+CO10+CQ10+CS10+CU10+CW10+CY10+DA10+DC10+DE10 -> 0 | DH10: =CJ10+CL10+CN10+CP10+CR10+CT10+CV10+CX10+CZ10+DB10+DD10+DF10 -> 0 | EH10: =DJ10+DL10+DN10+DP10+DR10+DT10+DV10+DX10+DZ10+EB10+ED10+EF10 -> 0 | EI10: =DK10+DM10+DO10+DQ10+DS10+DU10+DW10+DY10+EA10+EC10+EE10+EG10 -> 0 | FI10: =EK10+EM10+EO10+EQ10+ES10+EU10+EW10+EY10+FA10+FC10+FE10+FG10 -> 0 | FJ10: =EL10+EN10+EP10+ER10+ET10+EV10+EX10+EZ10+FB10+FD10+FF10+FH10 -> 0 | GJ10: =FL10+FN10+FP10+FR10+FT10+FV10+FX10+FZ10+GB10+GD10+GF10+GH10 -> 0 | GK10: =FM10+FO10+FQ10+FS10+FU10+FW10+FY10+GA10+GC10+GE10+GG10+GI10 -> 0
B11: - Perun Mekanis | C11: Ha | D11: =AE11/AD11 -> 5250000 | E11: =AD11 -> 2500 | F11: ='[15]TTL TB'!W45+'[15]TTL TB'!W47+'[15]TTL TB'!W49 -> 0 | G11: ='[15]TTL TB'!X52 -> 0 | H11: ='[15]TTL TB'!Y45+'[15]TTL TB'!Y47+'[15]TTL TB'!Y49 -> 0 | I11: ='[15]TTL TB'!Z52 -> 0 | J11: ='[15]TTL TB'!AA45+'[15]TTL TB'!AA47+'[15]TTL TB'!AA49 -> 0 | K11: ='[15]TTL TB'!AB52 -> 0 | L11: ='[15]TTL TB'!AC45+'[15]TTL TB'!AC47+'[15]TTL TB'!AC49 -> 0 | M11: ='[15]TTL TB'!AD52 -> 0 | N11: ='[15]TTL TB'!AE45+'[15]TTL TB'!AE47+'[15]TTL TB'!AE49 -> 0 | O11: ='[15]TTL TB'!AF52 -> 0 | P11: ='[15]TTL TB'!AG45+'[15]TTL TB'!AG47+'[15]TTL TB'!AG49 -> 0 | Q11: ='[15]TTL TB'!AH52 -> 0 | R11: ='[15]TTL TB'!AI45+'[15]TTL TB'!AI47+'[15]TTL TB'!AI49 -> 300 | S11: ='[15]TTL TB'!AJ52 -> 1575000000 | T11: ='[15]TTL TB'!AK45+'[15]TTL TB'!AK47+'[15]TTL TB'!AK49 -> 400 | U11: ='[15]TTL TB'!AL52 -> 2100000000 | V11: ='[15]TTL TB'!AM45+'[15]TTL TB'!AM47+'[15]TTL TB'!AM49 -> 400 | W11: ='[15]TTL TB'!AN52 -> 2100000000 | X11: ='[15]TTL TB'!AO45+'[15]TTL TB'!AO47+'[15]TTL TB'!AO49 -> 400 | Y11: ='[15]TTL TB'!AP52 -> 2100000000 | Z11: ='[15]TTL TB'!AQ45+'[15]TTL TB'!AQ47+'[15]TTL TB'!AQ49 -> 500 | AA11: ='[15]TTL TB'!AR52 -> 2625000000 | AB11: ='[15]TTL TB'!AS45+'[15]TTL TB'!AS47+'[15]TTL TB'!AS49 -> 500 | AC11: ='[15]TTL TB'!AT52 -> 2625000000 | AD11: =F11+H11+J11+L11+N11+P11+R11+T11+V11+X11+Z11+AB11 -> 2500 | AE11: =G11+I11+K11+M11+O11+Q11+S11+U11+W11+Y11+AA11+AC11 -> 13125000000 | BE11: =AG11+AI11+AK11+AM11+AO11+AQ11+AS11+AU11+AW11+AY11+BA11+BC11 -> 0 | BF11: =AH11+AJ11+AL11+AN11+AP11+AR11+AT11+AV11+AX11+AZ11+BB11+BD11 -> 0 | CF11: =BH11+BJ11+BL11+BN11+BP11+BR11+BT11+BV11+BX11+BZ11+CB11+CD11 -> 0 | CG11: =BI11+BK11+BM11+BO11+BQ11+BS11+BU11+BW11+BY11+CA11+CC11+CE11 -> 0 | DG11: =CI11+CK11+CM11+CO11+CQ11+CS11+CU11+CW11+CY11+DA11+DC11+DE11 -> 0 | DH11: =CJ11+CL11+CN11+CP11+CR11+CT11+CV11+CX11+CZ11+DB11+DD11+DF11 -> 0 | EH11: =DJ11+DL11+DN11+DP11+DR11+DT11+DV11+DX11+DZ11+EB11+ED11+EF11 -> 0 | EI11: =DK11+DM11+DO11+DQ11+DS11+DU11+DW11+DY11+EA11+EC11+EE11+EG11 -> 0 | FI11: =EK11+EM11+EO11+EQ11+ES11+EU11+EW11+EY11+FA11+FC11+FE11+FG11 -> 0 | FJ11: =EL11+EN11+EP11+ER11+ET11+EV11+EX11+EZ11+FB11+FD11+FF11+FH11 -> 0 | GJ11: =FL11+FN11+FP11+FR11+FT11+FV11+FX11+FZ11+GB11+GD11+GF11+GH11 -> 0 | GK11: =FM11+FO11+FQ11+FS11+FU11+FW11+FY11+GA11+GC11+GE11+GG11+GI11 -> 0
B12: - Pemberantasan Lalang dan Gulma Lainnya | C12: Ha | D12: =AE12/AD12 -> 882733.22 | E12: =AD12 -> 1100 | F12: ='[15]TTL TB'!W53 -> 0 | G12: ='[15]TTL TB'!X61 -> 0 | H12: ='[15]TTL TB'!Y53 -> 0 | I12: ='[15]TTL TB'!Z61 -> 0 | J12: ='[15]TTL TB'!AA53 -> 0 | K12: ='[15]TTL TB'!AB61 -> 0 | L12: ='[15]TTL TB'!AC53 -> 0 | M12: ='[15]TTL TB'!AD61 -> 0 | N12: ='[15]TTL TB'!AE53 -> 0 | O12: ='[15]TTL TB'!AF61 -> 0 | P12: ='[15]TTL TB'!AG53 -> 0 | Q12: ='[15]TTL TB'!AH61 -> 0 | R12: ='[15]TTL TB'!AI53 -> 0 | S12: ='[15]TTL TB'!AJ61 -> 0 | T12: ='[15]TTL TB'!AK53 -> 0 | U12: ='[15]TTL TB'!AL61 -> 0 | V12: ='[15]TTL TB'!AM53 -> 0 | W12: ='[15]TTL TB'!AN61 -> 0 | X12: ='[15]TTL TB'!AO53 -> 300 | Y12: ='[15]TTL TB'!AP61 -> 2.6481997e+08 | Z12: ='[15]TTL TB'!AQ53 -> 400 | AA12: ='[15]TTL TB'!AR61 -> 3.5309329e+08 | AB12: ='[15]TTL TB'!AS53 -> 400 | AC12: ='[15]TTL TB'!AT61 -> 3.5309329e+08 | AD12: =F12+H12+J12+L12+N12+P12+R12+T12+V12+X12+Z12+AB12 -> 1100 | AE12: =G12+I12+K12+M12+O12+Q12+S12+U12+W12+Y12+AA12+AC12 -> 9.7100654e+08 | BE12: =AG12+AI12+AK12+AM12+AO12+AQ12+AS12+AU12+AW12+AY12+BA12+BC12 -> 0 | BF12: =AH12+AJ12+AL12+AN12+AP12+AR12+AT12+AV12+AX12+AZ12+BB12+BD12 -> 0 | CF12: =BH12+BJ12+BL12+BN12+BP12+BR12+BT12+BV12+BX12+BZ12+CB12+CD12 -> 0 | CG12: =BI12+BK12+BM12+BO12+BQ12+BS12+BU12+BW12+BY12+CA12+CC12+CE12 -> 0 | DG12: =CI12+CK12+CM12+CO12+CQ12+CS12+CU12+CW12+CY12+DA12+DC12+DE12 -> 0 | DH12: =CJ12+CL12+CN12+CP12+CR12+CT12+CV12+CX12+CZ12+DB12+DD12+DF12 -> 0 | EH12: =DJ12+DL12+DN12+DP12+DR12+DT12+DV12+DX12+DZ12+EB12+ED12+EF12 -> 0 | EI12: =DK12+DM12+DO12+DQ12+DS12+DU12+DW12+DY12+EA12+EC12+EE12+EG12 -> 0 | FI12: =EK12+EM12+EO12+EQ12+ES12+EU12+EW12+EY12+FA12+FC12+FE12+FG12 -> 0 | FJ12: =EL12+EN12+EP12+ER12+ET12+EV12+EX12+EZ12+FB12+FD12+FF12+FH12 -> 0 | GJ12: =FL12+FN12+FP12+FR12+FT12+FV12+FX12+FZ12+GB12+GD12+GF12+GH12 -> 0 | GK12: =FM12+FO12+FQ12+FS12+FU12+FW12+FY12+GA12+GC12+GE12+GG12+GI12 -> 0
B13: - Pemadatan Tanah | C13: M | D13: =AE13/AD13 -> 6300 | E13: =AD13 -> 239917.8 | F13: ='[15]TTL TB'!W62 -> 0 | G13: ='[15]TTL TB'!X66 -> 0 | H13: ='[15]TTL TB'!Y62 -> 0 | I13: ='[15]TTL TB'!Z66 -> 0 | J13: ='[15]TTL TB'!AA62 -> 0 | K13: ='[15]TTL TB'!AB66 -> 0 | L13: ='[15]TTL TB'!AC62 -> 27200 | M13: ='[15]TTL TB'!AD66 -> 1.7136e+08 | N13: ='[15]TTL TB'!AE62 -> 27200 | O13: ='[15]TTL TB'!AF66 -> 1.7136e+08 | P13: ='[15]TTL TB'!AG62 -> 24725.16 | Q13: ='[15]TTL TB'!AH66 -> 1.5576851e+08 | R13: ='[15]TTL TB'!AI62 -> 27200 | S13: ='[15]TTL TB'!AJ66 -> 1.7136e+08 | T13: ='[15]TTL TB'!AK62 -> 27200 | U13: ='[15]TTL TB'!AL66 -> 1.7136e+08 | V13: ='[15]TTL TB'!AM62 -> 26935.72 | W13: ='[15]TTL TB'!AN66 -> 1.6969504e+08 | X13: ='[15]TTL TB'!AO62 -> 27200 | Y13: ='[15]TTL TB'!AP66 -> 1.7136e+08 | Z13: ='[15]TTL TB'!AQ62 -> 27200 | AA13: ='[15]TTL TB'!AR66 -> 1.7136e+08 | AB13: ='[15]TTL TB'!AS62 -> 25056.92 | AC13: ='[15]TTL TB'!AT66 -> 157858596 | AD13: =F13+H13+J13+L13+N13+P13+R13+T13+V13+X13+Z13+AB13 -> 239917.8 | AE13: =G13+I13+K13+M13+O13+Q13+S13+U13+W13+Y13+AA13+AC13 -> 1.5114821e+09 | BE13: =AG13+AI13+AK13+AM13+AO13+AQ13+AS13+AU13+AW13+AY13+BA13+BC13 -> 0 | BF13: =AH13+AJ13+AL13+AN13+AP13+AR13+AT13+AV13+AX13+AZ13+BB13+BD13 -> 0 | CF13: =BH13+BJ13+BL13+BN13+BP13+BR13+BT13+BV13+BX13+BZ13+CB13+CD13 -> 0 | CG13: =BI13+BK13+BM13+BO13+BQ13+BS13+BU13+BW13+BY13+CA13+CC13+CE13 -> 0 | DG13: =CI13+CK13+CM13+CO13+CQ13+CS13+CU13+CW13+CY13+DA13+DC13+DE13 -> 0 | DH13: =CJ13+CL13+CN13+CP13+CR13+CT13+CV13+CX13+CZ13+DB13+DD13+DF13 -> 0 | EH13: =DJ13+DL13+DN13+DP13+DR13+DT13+DV13+DX13+DZ13+EB13+ED13+EF13 -> 0 | EI13: =DK13+DM13+DO13+DQ13+DS13+DU13+DW13+DY13+EA13+EC13+EE13+EG13 -> 0 | FI13: =EK13+EM13+EO13+EQ13+ES13+EU13+EW13+EY13+FA13+FC13+FE13+FG13 -> 0 | FJ13: =EL13+EN13+EP13+ER13+ET13+EV13+EX13+EZ13+FB13+FD13+FF13+FH13 -> 0 | GJ13: =FL13+FN13+FP13+FR13+FT13+FV13+FX13+FZ13+GB13+GD13+GF13+GH13 -> 0 | GK13: =FM13+FO13+FQ13+FS13+FU13+FW13+FY13+GA13+GC13+GE13+GG13+GI13 -> 0
B14: Total Pembukaan Lahan | G14: =SUM(G10:G13) -> 66458122 | I14: =SUM(I10:I13) -> 66458122 | K14: =SUM(K10:K13) -> 45123958 | M14: =SUM(M10:M13) -> 2.3781812e+08 | O14: =SUM(O10:O13) -> 2.3781812e+08 | Q14: =SUM(Q10:Q13) -> 2.0645723e+08 | S14: =SUM(S10:S13) -> 1.8128181e+09 | U14: =SUM(U10:U13) -> 2.3378181e+09 | W14: =SUM(W10:W13) -> 2.3156542e+09 | Y14: =SUM(Y10:Y13) -> 2.6026381e+09 | AA14: =SUM(AA10:AA13) -> 3.2159114e+09 | AC14: =SUM(AC10:AC13) -> 3.183763e+09 | AE14: =SUM(AE10:AE13) -> 1.6328737e+10 | BF14: =SUM(BF10:BF13) -> 0 | CG14: =SUM(CG10:CG13) -> 0 | DH14: =SUM(DH10:DH13) -> 0 | EI14: =SUM(EI10:EI13) -> 0 | FJ14: =SUM(FJ10:FJ13) -> 0 | GK14: =SUM(GK10:GK13) -> 0
B16: PEMBUATAN SARANA DAN PRASARANA
B17: - Pembuatan Jalan Produksi | C17: M | D17: =24689*105.81% -> 26123.431 | E17: =(300/30)*350 -> 3500 | F17: =E17 -> 3500 | G17: =F17*$D17 -> 91432008 | I17: =H17*$D17 -> 0 | K17: =J17*$D17 -> 0 | M17: =L17*$D17 -> 0 | O17: =N17*$D17 -> 0 | Q17: =P17*$D17 -> 0 | S17: =R17*$D17 -> 0 | U17: =T17*$D17 -> 0 | W17: =V17*$D17 -> 0 | Y17: =X17*$D17 -> 0 | AA17: =Z17*$D17 -> 0 | AC17: =AB17*$D17 -> 0 | AD17: =F17+H17+J17+L17+N17+P17+R17+T17+V17+X17+Z17+AB17 -> 3500 | AE17: =G17+I17+K17+M17+O17+Q17+S17+U17+W17+Y17+AA17+AC17 -> 91432008 | AH17: =AG17*$D17 -> 0 | AJ17: =AI17*$D17 -> 0 | AL17: =AK17*$D17 -> 0 | AN17: =AM17*$D17 -> 0 | AP17: =AO17*$D17 -> 0 | AR17: =AQ17*$D17 -> 0 | AT17: =AS17*$D17 -> 0 | AV17: =AU17*$D17 -> 0 | AX17: =AW17*$D17 -> 0 | AZ17: =AY17*$D17 -> 0 | BB17: =BA17*$D17 -> 0 | BD17: =BC17*$D17 -> 0 | BE17: =AG17+AI17+AK17+AM17+AO17+AQ17+AS17+AU17+AW17+AY17+BA17+BC17 -> 0 | BF17: =AH17+AJ17+AL17+AN17+AP17+AR17+AT17+AV17+AX17+AZ17+BB17+BD17 -> 0 | BI17: =BH17*$D17 -> 0 | BK17: =BJ17*$D17 -> 0 | BM17: =BL17*$D17 -> 0 | BO17: =BN17*$D17 -> 0 | BQ17: =BP17*$D17 -> 0 | BS17: =BR17*$D17 -> 0 | BU17: =BT17*$D17 -> 0 | BW17: =BV17*$D17 -> 0 | BY17: =BX17*$D17 -> 0 | CA17: =BZ17*$D17 -> 0 | CC17: =CB17*$D17 -> 0 | CE17: =CD17*$D17 -> 0 | CF17: =BH17+BJ17+BL17+BN17+BP17+BR17+BT17+BV17+BX17+BZ17+CB17+CD17 -> 0 | CG17: =BI17+BK17+BM17+BO17+BQ17+BS17+BU17+BW17+BY17+CA17+CC17+CE17 -> 0 | CJ17: =CI17*$D17 -> 0 | CL17: =CK17*$D17 -> 0 | CN17: =CM17*$D17 -> 0 | CP17: =CO17*$D17 -> 0 | CR17: =CQ17*$D17 -> 0 | CT17: =CS17*$D17 -> 0 | CV17: =CU17*$D17 -> 0 | CX17: =CW17*$D17 -> 0 | CZ17: =CY17*$D17 -> 0 | DB17: =DA17*$D17 -> 0 | DD17: =DC17*$D17 -> 0 | DF17: =DE17*$D17 -> 0 | DG17: =CI17+CK17+CM17+CO17+CQ17+CS17+CU17+CW17+CY17+DA17+DC17+DE17 -> 0 | DH17: =CJ17+CL17+CN17+CP17+CR17+CT17+CV17+CX17+CZ17+DB17+DD17+DF17 -> 0 | DK17: =DJ17*$D17 -> 0 | DM17: =DL17*$D17 -> 0 | DO17: =DN17*$D17 -> 0 | DQ17: =DP17*$D17 -> 0 | DS17: =DR17*$D17 -> 0 | DU17: =DT17*$D17 -> 0 | DW17: =DV17*$D17 -> 0 | DY17: =DX17*$D17 -> 0 | EA17: =DZ17*$D17 -> 0 | EC17: =EB17*$D17 -> 0 | EE17: =ED17*$D17 -> 0 | EG17: =EF17*$D17 -> 0 | EH17: =DJ17+DL17+DN17+DP17+DR17+DT17+DV17+DX17+DZ17+EB17+ED17+EF17 -> 0 | EI17: =DK17+DM17+DO17+DQ17+DS17+DU17+DW17+DY17+EA17+EC17+EE17+EG17 -> 0 | EL17: =EK17*$D17 -> 0 | EN17: =EM17*$D17 -> 0 | EP17: =EO17*$D17 -> 0 | ER17: =EQ17*$D17 -> 0 | ET17: =ES17*$D17 -> 0 | EV17: =EU17*$D17 -> 0 | EX17: =EW17*$D17 -> 0 | EZ17: =EY17*$D17 -> 0 | FB17: =FA17*$D17 -> 0 | FD17: =FC17*$D17 -> 0 | FF17: =FE17*$D17 -> 0 | FH17: =FG17*$D17 -> 0 | FI17: =EK17+EM17+EO17+EQ17+ES17+EU17+EW17+EY17+FA17+FC17+FE17+FG17 -> 0 | FJ17: =EL17+EN17+EP17+ER17+ET17+EV17+EX17+EZ17+FB17+FD17+FF17+FH17 -> 0 | FM17: =FL17*$D17 -> 0 | FO17: =FN17*$D17 -> 0 | FQ17: =FP17*$D17 -> 0 | FS17: =FR17*$D17 -> 0 | FU17: =FT17*$D17 -> 0 | FW17: =FV17*$D17 -> 0 | FY17: =FX17*$D17 -> 0 | GA17: =FZ17*$D17 -> 0 | GC17: =GB17*$D17 -> 0 | GE17: =GD17*$D17 -> 0 | GG17: =GF17*$D17 -> 0 | GI17: =GH17*$D17 -> 0 | GJ17: =FL17+FN17+FP17+FR17+FT17+FV17+FX17+FZ17+GB17+GD17+GF17+GH17 -> 0 | GK17: =FM17+FO17+FQ17+FS17+FU17+FW17+FY17+GA17+GC17+GE17+GG17+GI17 -> 0 | GL17: =IFERROR(((+F17+H17+J17+L17)/($E17/'RKP 08'!$D$5)),0) -> 350 | GM17: =G17+I17+K17+M17 -> 91432008 | GN17: =IFERROR(((+N17+P17+R17+T17)/($E17/'RKP 08'!$D$5)),0) -> 0 | GO17: =+O17+Q17+S17+U17 -> 0 | GP17: =IFERROR(((V17+X17+Z17+AB17)/($E17/'RKP 08'!$D$5)),0) -> 0 | GQ17: =W17+Y17+AA17+AC17 -> 0 | GR17: =GL17+GN17+GP17 -> 350 | GS17: =GM17+GO17+GQ17 -> 91432008 | GT17: =IFERROR(((AG17+AI17+AK17+AM17)/($E17/'RKP 08'!$D$5)),0) -> 0 | GU17: =AH17+AJ17+AL17+AN17 -> 0 | GV17: =IFERROR(((AO17+AQ17+AS17+AU17)/($E17/'RKP 08'!$D$5)),0) -> 0 | GW17: =AP17+AR17+AT17+AV17 -> 0 | GX17: =IFERROR(((AW17+AY17+BA17+BC17)/($E17/'RKP 08'!$D$5)),0) -> 0 | GY17: =AX17+AZ17+BB17+BD17 -> 0 | GZ17: =GT17+GV17+GX17 -> 0 | HA17: =GU17+GW17+GY17 -> 0 | HB17: =IFERROR(((BH17+BJ17+BL17+BN17)/($E17/'RKP 08'!$D$5)),0) -> 0 | HC17: =BI17+BK17+BM17+BO17 -> 0 | HD17: =IFERROR(((BP17+BR17+BT17+BV17)/($E17/'RKP 08'!$D$5)),0) -> 0 | HE17: =BQ17+BS17+BU17+BW17 -> 0 | HF17: =IFERROR(((BX17+BZ17+CB17+CD17)/($E17/'RKP 08'!$D$5)),0) -> 0 | HG17: =BY17+CA17+CC17+CE17 -> 0 | HH17: =HB17+HD17+HF17 -> 0 | HI17: =HC17+HE17+HG17 -> 0 | HJ17: =IFERROR(((CI17+CK17+CM17+CO17)/($E17/'RKP 08'!$D$5)),0) -> 0 | HK17: =CJ17+CL17+CN17+CP17 -> 0 | HL17: =IFERROR(((CQ17+CS17+CU17+CW17)/($E17/'RKP 08'!$D$5)),0) -> 0 | HM17: =CR17+CT17+CV17+CX17 -> 0 | HN17: =IFERROR(((CY17+DA17+DC17+DE17)/($E17/'RKP 08'!$D$5)),0) -> 0 | HO17: =CZ17+DB17+DD17+DF17 -> 0 | HP17: =HJ17+HL17+HN17 -> 0 | HQ17: =HK17+HM17+HO17 -> 0 | HR17: =IFERROR(((DJ17+DL17+DN17+DP17)/($E17/'RKP 08'!$D$5)),0) -> 0 | HS17: =DK17+DM17+DO17+DQ17 -> 0 | HT17: =IFERROR(((DR17+DT17+DV17+DX17)/($E17/'RKP 08'!$D$5)),0) -> 0 | HU17: =DS17+DU17+DW17+DY17 -> 0 | HV17: =IFERROR(((DZ17+EB17+ED17+EF17)/($E17/'RKP 08'!$D$5)),0) -> 0 | HW17: =EA17+EC17+EE17+EG17 -> 0 | HX17: =HR17+HT17+HV17 -> 0 | HY17: =HS17+HU17+HW17 -> 0 | HZ17: =EK17+EM17+EO17+EQ17 -> 0 | IA17: =EL17+EN17+EP17+ER17 -> 0 | IB17: =((ES17+EU17+EW17+EY17)/($E17/'RKP 08'!$D$5)) -> 0 | IC17: =ET17+EV17+EX17+EZ17 -> 0 | ID17: =((FA17+FC17+FE17+FG17)/($E17/'RKP 08'!$D$5)) -> 0 | IE17: =FB17+FD17+FF17+FH17 -> 0 | IF17: =HZ17+IB17+ID17 -> 0 | IG17: =IA17+IC17+IE17 -> 0 | II17: =GS17+HA17+HI17+HQ17+HY17+IG17 -> 91432008 | IJ17: =II17-(D17*E17) -> 0
