Workbook
Name \0: #REF!
Name \a: #N/A
Name \b: #N/A
Name \g: #N/A
Name \n: #N/A
Name __kop2: #REF!
Name __s2: #REF!
Name __SKF1: #REF!
Name __SKF2: #REF!
Name _0: #REF!
Name _10_b_1: #REF!
Name _11_g_1: #REF!
Name _12_n_1: #REF!
Name _13Excel_BuiltIn_Database_1: #REF!
Name _14Excel_BuiltIn_Print_Area_1: #REF!
Name _15Excel_BuiltIn_Print_Area_31_1: #REF!
Name _16Excel_BuiltIn_Print_Titles_1: #REF!
Name _432: 432
Name _8_0_1: #REF!
Name _8311: #REF!
Name _9_A_1: #REF!
Name _A: #REF!
Name _A_1: #REF!
Name _A_2: #REF!
Name _A_28: #REF!
Name _A_3: #REF!
Name _A_31: #REF!
Name _A_58: #REF!
Name _A_7: #REF!
Name _A_8: #REF!
Name _A_86: #REF!
Name _A_87: #REF!
Name _A_9: #REF!
Name _b: #REF!
Name _g: #REF!
Name _HOME___FR_PGSE: #REF!
Name _HOME___PG_FRSE: #REF!
Name _kop2: #REF!
Name _n: #REF!
Name _PG: #REF!
Name _Regression_Int: 1
Name _s2: #REF!
Name _SKF1: #REF!
Name _SKF2: #REF!
Name A: #N/A
Name aa: #N/A
Name are: #REF!
Name ari: #REF!
Name bln: #N/A
Name capital: #N/A
Name CC: #REF!
Name CC_31: #REF!
Name CC_7: #REF!
Name CCC: #REF!
Name Cetak: #REF!
Name dea: #N/A
Name df: #REF!
Name edar: #N/A
Name er: #REF!
Name Excel_BuiltIn_Database: #REF!

Sheet RKP
C1: RENCANA KERJA PROYEK ( RKP )
C2: PT Buana Karya Bhakti
C3: Kebun Inti BKB
C4: Tahun Tanam Tanaman 1998 & 1999
B5: LUAS : | D5: 192,08 Ha | E5: Periode Proyek : 2025 s.d 2029
B6: No. | C6: Pekerjaan | E6: Rencana | G6: Unit | H6: TAHUN I ( 2026 ) | R6: TAHUN II ( 2027 ) | AB6: TAHUN III ( 2028 ) | AL6: TAHUN IV ( 2029 )
E7: Proyek 4 Tahun | H7: Catur Wulan 1 | J7: Catur Wulan 2 | L7: Catur Wulan 3 | N7: Jumlah Tahun I | P7: Jumlah S/d Tahun I | R7: Catur Wulan 1 | T7: Catur Wulan 2 | V7: Catur Wulan 3 | X7: Jumlah Tahun II | Z7: Jumlah S/d Tahun II | AB7: Catur Wulan 1 | AD7: Catur Wulan 2 | AF7: Catur Wulan 3 | AH7: Jumlah Tahun III | AJ7: Jumlah S/d Tahun III | AL7: Catur Wulan 1 | AN7: Catur Wulan 2 | AP7: Catur Wulan 3 | AR7: Jumlah Tahun IV | AT7: Jumlah S/d Tahun IV
E8: Volume | F8: Biaya | G8: Cost | H8: Fisik | I8: Biaya | J8: Fisik | K8: Biaya | L8: Fisik | M8: Biaya | N8: Fisik | O8: Biaya | P8: Fisik | Q8: Biaya | R8: Fisik | S8: Biaya | T8: Fisik | U8: Biaya | V8: Fisik | W8: Biaya | X8: Fisik | Y8: Biaya | Z8: Fisik | AA8: Biaya | AB8: Fisik | AC8: Biaya | AD8: Fisik | AE8: Biaya | AF8: Fisik | AG8: Biaya | AH8: Fisik | AI8: Biaya | AJ8: Fisik | AK8: Biaya | AL8: Fisik | AM8: Biaya | AN8: Fisik | AO8: Biaya | AP8: Fisik | AQ8: Biaya | AR8: Fisik | AS8: Biaya | AT8: Fisik | AU8: Biaya
E9: ( Ha ) | F9: ( Rp ) | G9: ( Rp / Ha ) | H9: ( Ha ) | I9: ( Rp ) | J9: ( Ha ) | K9: ( Rp ) | L9: ( Ha ) | M9: ( Rp ) | N9: ( Ha ) | O9: ( Rp ) | P9: ( Ha ) | Q9: ( Rp ) | R9: ( Ha ) | S9: ( Rp ) | T9: ( Ha ) | U9: ( Rp ) | V9: ( Ha ) | W9: ( Rp ) | X9: ( Ha ) | Y9: ( Rp ) | Z9: ( Ha ) | AA9: ( Rp ) | AB9: ( Ha ) | AC9: ( Rp ) | AD9: ( Ha ) | AE9: ( Rp ) | AF9: ( Ha ) | AG9: ( Rp ) | AH9: ( Ha ) | AI9: ( Rp ) | AJ9: ( Ha ) | AK9: ( Rp ) | AL9: ( Ha ) | AM9: ( Rp ) | AN9: ( Ha ) | AO9: ( Rp ) | AP9: ( Ha ) | AQ9: ( Rp ) | AR9: ( Ha ) | AS9: ( Rp ) | AT9: ( Ha ) | AU9: ( Rp )
B10: 1 | C10: Replanting TB | E10: 192.08 | F10: =E10*G10 -> 1.02884e+10 | G10: ='REKAP BIAYA'!G48 -> 53563100 | I10: =H10*$G10 -> 0 | K10: =J10*$G10 -> 0 | L10: 192.08 | M10: =L10*$G10 -> 1.02884e+10 | N10: =H10+J10+L10 -> 192.08 | O10: =I10+K10+M10 -> 1.02884e+10 | P10: =N10 -> 192.08 | Q10: =O10 -> 1.02884e+10 | Z10: =P10 -> 192.08 | AA10: =Q10 -> 1.02884e+10 | AJ10: =Z10 -> 192.08 | AK10: =AA10 -> 1.02884e+10 | AT10: =AJ10 -> 192.08 | AU10: =AK10 -> 1.02884e+10
B11: 2 | C11: Pemeliharaan TBM-1 | E11: =E10 -> 192.08 | F11: =E11*G11 -> 1.7835687e+09 | G11: ='REKAP BIAYA'!P42 -> 9285551.2 | I11: =H11*$G11 -> 0 | K11: =J11*$G11 -> 0 | M11: =L11*$G11 -> 0 | N11: =H11+J11+L11 -> 0 | O11: =I11+K11+M11 -> 0 | P11: =N11 -> 0 | Q11: =O11 -> 0 | S11: =R11*$G11 -> 0 | T11: 96.04 | U11: =T11*$G11 -> 8.9178434e+08 | V11: 96.04 | W11: =V11*$G11 -> 8.9178434e+08 | X11: =R11+T11+V11 -> 192.08 | Y11: =S11+U11+W11 -> 1.7835687e+09 | Z11: =X11+P11 -> 192.08 | AA11: =Y11+Q11 -> 1.7835687e+09 | AC11: =AB11*$G11 -> 0 | AE11: =AD11*$G11 -> 0 | AG11: =AF11*$G11 -> 0 | AH11: =AB11+AD11+AF11 -> 0 | AI11: =AC11+AE11+AG11 -> 0 | AJ11: =AH11+Z11 -> 192.08 | AK11: =AI11+AA11 -> 1.7835687e+09 | AM11: =AL11*$G11 -> 0 | AO11: =AN11*$G11 -> 0 | AQ11: =AP11*$G11 -> 0 | AR11: =AL11+AN11+AP11 -> 0 | AS11: =AM11+AO11+AQ11 -> 0 | AT11: =AR11+AJ11 -> 192.08 | AU11: =AS11+AK11 -> 1.7835687e+09
B12: 3 | C12: Pemeliharaan TBM-2 | E12: =E11 -> 192.08 | F12: =E12*G12 -> 2.3939196e+09 | G12: ='REKAP BIAYA'!X41 -> 12463138 | I12: =H12*$G12 -> 0 | K12: =J12*$G12 -> 0 | M12: =L12*$G12 -> 0 | N12: =H12+J12+L12 -> 0 | O12: =I12+K12+M12 -> 0 | P12: =N12 -> 0 | Q12: =O12 -> 0 | R12: =L11/3 -> 0 | S12: =R12*$G12 -> 0 | T12: =R12 -> 0 | U12: =T12*$G12 -> 0 | V12: =T12 -> 0 | W12: =V12*$G12 -> 0 | X12: =R12+T12+V12 -> 0 | Y12: =S12+U12+W12 -> 0 | Z12: =X12+P12 -> 0 | AA12: =Y12+Q12 -> 0 | AB12: =X11/3 -> 64.026667 | AC12: =AB12*$G12 -> 7.9797319e+08 | AD12: =AB12 -> 64.026667 | AE12: =AD12*$G12 -> 7.9797319e+08 | AF12: =AD12 -> 64.026667 | AG12: =AF12*$G12 -> 7.9797319e+08 | AH12: =X11 -> 192.08 | AI12: =AC12+AE12+AG12 -> 2.3939196e+09 | AJ12: =AH12+Z12 -> 192.08 | AK12: =AI12+AA12 -> 2.3939196e+09 | AL12: =AH11/3 -> 0 | AM12: =AL12*$G12 -> 0 | AN12: =AL12 -> 0 | AO12: =AN12*$G12 -> 0 | AP12: =AN12 -> 0 | AQ12: =AP12*$G12 -> 0 | AR12: =AL12+AN12+AP12 -> 0 | AS12: =AM12+AO12+AQ12 -> 0 | AT12: =AR12+AJ12 -> 192.08 | AU12: =AS12+AK12 -> 2.3939196e+09
B13: 4 | C13: Pemeliharaan TBM-3 | E13: =E12 -> 192.08 | F13: =E13*G13 -> 4.0078404e+09 | G13: ='REKAP BIAYA'!AF43 -> 20865475 | I13: =H13*$G13 -> 0 | K13: =J13*$G13 -> 0 | M13: =L13*$G13 -> 0 | N13: =H13+J13+L13 -> 0 | O13: =I13+K13+M13 -> 0 | P13: =N13 -> 0 | Q13: =O13 -> 0 | S13: =R13*$G13 -> 0 | U13: =T13*$G13 -> 0 | W13: =V13*$G13 -> 0 | X13: =R13+T13+V13 -> 0 | Y13: =S13+U13+W13 -> 0 | Z13: =X13+P13 -> 0 | AA13: =Y13+Q13 -> 0 | AB13: =R12 -> 0 | AC13: =AB13*$G13 -> 0 | AD13: =AB13 -> 0 | AE13: =AD13*$G13 -> 0 | AF13: =AD13 -> 0 | AG13: =AF13*$G13 -> 0 | AH13: =AB13+AD13+AF13 -> 0 | AI13: =AC13+AE13+AG13 -> 0 | AJ13: =AH13+Z13 -> 0 | AK13: =AI13+AA13 -> 0 | AL13: =AB12 -> 64.026667 | AM13: =AL13*$G13 -> 1.3359468e+09 | AN13: =AL13 -> 64.026667 | AO13: =AN13*$G13 -> 1.3359468e+09 | AP13: =AN13 -> 64.026667 | AQ13: =AP13*$G13 -> 1.3359468e+09 | AR13: =AL13+AN13+AP13 -> 192.08 | AS13: =AM13+AO13+AQ13 -> 4.0078404e+09 | AT13: =AR13+AJ13 -> 192.08 | AU13: =AS13+AK13 -> 4.0078404e+09
B14: GRAND TOTAL BIAYA | E14: =E10 -> 192.08 | F14: =SUM(F10:F13) -> 1.8473729e+10 | G14: =F14/E14 -> 96177264 | I14: =SUM(I10:I13) -> 0 | K14: =SUM(K10:K13) -> 0 | M14: =SUM(M10:M13) -> 1.02884e+10 | O14: =SUM(O10:O13) -> 1.02884e+10 | Q14: =SUM(Q10:Q13) -> 1.02884e+10 | S14: =SUM(S10:S13) -> 0 | U14: =SUM(U10:U13) -> 8.9178434e+08 | W14: =SUM(W10:W13) -> 8.9178434e+08 | Y14: =SUM(Y10:Y13) -> 1.7835687e+09 | AA14: =SUM(AA10:AA13) -> 1.2071969e+10 | AC14: =SUM(AC10:AC13) -> 7.9797319e+08 | AE14: =SUM(AE10:AE13) -> 7.9797319e+08 | AG14: =SUM(AG10:AG13) -> 7.9797319e+08 | AI14: =SUM(AI10:AI13) -> 2.3939196e+09 | AK14: =SUM(AK10:AK13) -> 1.4465888e+10 | AM14: =SUM(AM10:AM13) -> 1.3359468e+09 | AO14: =SUM(AO10:AO13) -> 1.3359468e+09 | AQ14: =SUM(AQ10:AQ13) -> 1.3359468e+09 | AS14: =SUM(AS10:AS13) -> 4.0078404e+09 | AU14: =SUM(AU10:AU13) -> 1.8473729e+10
B16: Catatan:
B17: *Biaya pemeliharaan kacangan setelah revisi dari gliphosate ke fluroxyphr sebagai pengganti bahan aktif ada penambahan biaya Rp 231.924 per Ha
L18: Satui, 19 September 2025
I19: Disetujui Oleh ; | J19: Diperiksa Oleh ; | L19: Disusun Oleh ; | AS19: Satui, 30 September 2025
N20: Diketahui Oleh ; | X20: Disetujui Oleh ; | AI20: Diperiksa Oleh ; | AS20: Disusun Oleh ;
AS21: Samsir Hadi
I22: Hairul Amri | J22: A r i f | L22: Samsir Hadi
I23: Direktur | J23: Pjs. GM Agronomy | L23: Askep Project Re-Planting & Reklamasi | N23: Imam Satoto Yudiono | X23: Hairul Amri | AI23: A r i f
N24: Direktur Utama | X24: Direktur | AI24: Pjs. GM Agronomy | AS24: Askep Project Re-Planting & Reklamasi

Sheet REKAP BIAYA
A1: CECT | B1: SERAK
A2: 140.98 | B2: 51.1
A3: =A2+B2 -> 192.08 | B3: REKAPITULASI RENCANA BIAYA REPLANTING TB BKB INTI TAHUN TANAM 1998 & 1999 | L3: REKAPITULASI RENCANA BIAYA TBM 01 BKB INTI TAHUN TANAM 1998 & 1999 | T3: REKAPITULASI RENCANA BIAYA TBM 02 BKB INTI TAHUN TANAM 1998 & 1999 | AB3: REKAPITULASI RENCANA BIAYA TBM 03 BKB INTI TAHUN TANAM 1998 & 1999
B4: RENCANA ANGGARAN TANAM BARU | L4: RENCANA ANGGARAN TBM 1 | T4: RENCANA ANGGARAN TBM 2 | AB4: RENCANA ANGGARAN TBM 3
B5: No | C5: Pekerjaan | F5: Jumlah Rp | G5: Total Rp | H5: Rp/Ha | I5: (%) | L5: No | M5: Pekerjaan | O5: Jumlah Rp | P5: Total Rp | Q5: Rp/Ha | R5: Persentase (%) | T5: No | U5: Pekerjaan | W5: Jumlah Rp | X5: Total Rp | Y5: Rp/Ha | Z5: Persentase (%) | AB5: No | AC5: Pekerjaan | AE5: Jumlah Rp | AF5: Total Rp | AG5: Rp/Ha | AH5: Persentase (%)
B7: 1 | C7: Pembukaan Lahan CECT | D7: =IF(C7="",D6,C7) -> Pembukaan Lahan CECT | E7: Identifikasi Blok | F7: ='SI TB CECT'!Q8 -> 5255329.8 | G7: =SUM(F7:F12) -> 4.5034912e+09 | H7: =G7/A2 -> 31944185 | I7: =G7/$G$47*100 -> 43.772511 | L7: 1 | M7: Pembuatan Piringan & Titi Pasar Rintis | N7: Pembuatan Piringan | O7: =SUM('S1 TBM 1'!S38:S40) -> 76597996 | P7: =SUM(O7:O8) -> 1.1585457e+08 | Q7: =P7/A3 -> 603157.9 | R7: =P7/P41*100 -> 6.4956606 | T7: 1 | U7: Pemeliharaan Piringan Gawangan Manual & Chemist | V7: Pemeliharaan Piringan Manual | W7: =SUM('S1 TBM 2'!Q59:Q61) -> 81551022 | X7: =SUM(W7:W10) -> 4.3148202e+08 | Y7: =X7/$A$3 -> 2246366.2 | Z7: =X7/X40*100 -> 18.024082 | AB7: 1 | AC7: Pembuatan TPH, Pemeliharaan Piringan Gawangan Manual & Chemist | AD7: Pembuatan TPH | AE7: =SUM('S1 TBM 3'!Q44:Q46) -> 4679836.7 | AF7: =SUM(AE7:AE12) -> 6.3845249e+08 | AG7: =AF7/$A$3 -> 3323888.4 | AH7: =AF7/AF42*100 -> 15.930088
D8: =IF(C8="",D7,C8) -> Pembukaan Lahan CECT | E8: Pengolahan Tanah (Ripping) | F8: =SUM('SI TB CECT'!Q23:Q25) -> 8.2513491e+08 | N8: Pembuatan Titi Pasar Rintis | O8: =SUM('S1 TBM 1'!S48:S50) -> 39256573 | V8: Pemeliharaan Piringan /Pasar Rintis(Chemist) | W8: =SUM('S1 TBM 2'!Q70:Q81) -> 1.135711e+08 | AD8: Pemeliharaan Piringan Manual | AE8: =SUM('S1 TBM 3'!Q60:Q62) -> 86846764
D9: =IF(C9="",D8,C9) -> Pembukaan Lahan CECT | E9: Tumbang Chipping | F9: =SUM('SI TB CECT'!Q27:Q32) -> 1.3902328e+09 | K9: =SUM(F10:F11) -> 2.112072e+09 | L9: 2 | M9: Pemeliharaan Piringan Gawangan Manual & Chemist | N9: Pemeliharaan Piringan Manual | O9: =SUM('S1 TBM 1'!S61:S63) -> 76578268 | P9: =SUM(O9:O12) -> 2.8807307e+08 | Q9: =P9/A3 -> 1499755.7 | R9: =P9/P41*100 -> 16.151499 | V9: Pemeliharaan Gawangan Manual | W9: =SUM('S1 TBM 2'!Q105:Q107) -> 1.3055068e+08 | AD9: Pemeliharaan Piringan /Pasar Rintis(Chemist) | AE9: =SUM('S1 TBM 3'!Q72:Q83) -> 1.2505902e+08
D10: =IF(C10="",D9,C10) -> Pembukaan Lahan CECT | E10: Parit CECT | F10: =SUM('SI TB CECT'!Q33:Q35) -> 9.7041145e+08 | K10: =SUM(F10:F11)/140.98 -> 14981359 | N10: Pemeliharaan Piringan /Pasar Rintis(Chemist) | O10: =SUM('S1 TBM 1'!S72:S82) -> 29516605 | V10: Pemeliharaan Gawangan Chemist | W10: =SUM('S1 TBM 2'!Q112:Q123) -> 1.0580921e+08 | AD10: Pemeliharaan Pasar Rintis Manual | AE10: =SUM('S1 TBM 3'!Q67:Q69) -> 1.7354011e+08
D11: =IF(C11="",D10,C11) -> Pembukaan Lahan CECT | E11: Tutup Lubang CECT | F11: =SUM('SI TB CECT'!Q36:Q38) -> 1.1416605e+09 | N11: Pemeliharaan Gawangan Manual | O11: =SUM('S1 TBM 1'!S106:S108) -> 1.530934e+08 | T11: 2 | U11: Pemberantasan Lalang | V11: Spot Lalang | W11: =SUM('S1 TBM 2'!Q149:Q158) -> 25652170 | X11: =SUM(W11:W13) -> 91352741 | Y11: =X11/$A$3 -> 475597.36 | Z11: =X11/X40*100 -> 3.8160322 | AD11: Pemeliharaan Gawangan Manual | AE11: =SUM('S1 TBM 3'!Q107:Q109) -> 1.3902732e+08
D12: =IF(C12="",D11,C12) -> Pembukaan Lahan CECT | E12: Lubang Tanam Mekanis Auger | F12: =SUM('SI TB CECT'!Q40:Q43) -> 1.7079611e+08 | N12: Pemeliharaan Gawangan Chemist | O12: =SUM('S1 TBM 1'!S113:S124) -> 28884795 | V12: Wipping | W12: =SUM('S1 TBM 2'!Q159:Q167) -> 48090995 | AD12: Pemeliharaan Gawangan Chemist | AE12: =SUM('S1 TBM 3'!Q114:Q125) -> 1.0929943e+08
B13: 2 | C13: Pembukaan Lahan Serak | D13: =IF(C13="",D12,C13) -> Pembukaan Lahan Serak | E13: Identifikasi Blok | F13: ='SI TB SERAK'!Q7 -> 1904861.3 | G13: =SUM(F13:F17) -> 1.1142139e+09 | H13: =G13/B2 -> 21804577 | I13: =G13/G47*100 -> 10.829807 | L13: 3 | M13: Pemberantasan Lalang | N13: Spot Lalang | O13: =SUM('S1 TBM 1'!S150:S159) -> 24162279 | P13: =SUM(O13:O15) -> 89814717 | Q13: =P13/A3 -> 467590.15 | R13: =P13/P41*100 -> 5.0356747 | V13: Transport Air | W13: =SUM('S1 TBM 2'!Q170) -> 17609576 | AB13: 2 | AC13: Pemberantasan Lalang | AD13: Wipping | AE13: =SUM('S1 TBM 3'!Q161:Q169) -> 51095729 | AF13: =SUM(AE13:AE14) -> 69585784 | AG13: =AF13/$A$3 -> 362275.01 | AH13: =AF13/AF42*100 -> 1.7362414
D14: =IF(C14="",D13,C14) -> Pembukaan Lahan Serak | E14: Pengolahan Tanah (Ripping) | F14: =SUM('SI TB SERAK'!Q22:Q24) -> 3.3230959e+08 | K14: =F14/B2 -> 6503123.1 | N14: Wipping | O14: =SUM('S1 TBM 1'!S160:S169) -> 48881413 | T14: 3 | U14: Pemeliharaan Pokok | V14: Kastrasi | W14: =SUM('S1 TBM 2'!Q178:Q182) -> 1.9584936e+08 | X14: =SUM(W14:W16) -> 2.7354357e+08 | Y14: =X14/$A$3 -> 1424112.7 | Z14: =X14/X40*100 -> 11.426598 | AD14: Transport Air | AE14: =SUM('S1 TBM 3'!Q172) -> 18490055
D15: =IF(C15="",D14,C15) -> Pembukaan Lahan Serak | E15: Tumbang Chipping | F15: =SUM('SI TB SERAK'!Q26:Q31) -> 5.9808744e+08 | N15: Transport Air | O15: =SUM('S1 TBM 1'!S172) -> 16771025 | V15: Penyisipan | W15: =SUM('S1 TBM 2'!Q185:Q188) -> 45074613 | AB15: 3 | AC15: Pemeliharaan Pokok | AD15: Sanitasi | AE15: =SUM('S1 TBM 3'!Q176:Q179) -> 69312728 | AF15: =SUM(AE15:AE18) -> 1.3881149e+08 | AG15: =AF15/$A$3 -> 722675.42 | AH15: =AF15/AF42*100 -> 3.4634985
D16: =IF(C16="",D15,C16) -> Pembukaan Lahan Serak | E16: Tutup Lubang | F16: =SUM('SI TB SERAK'!Q32:Q34) -> 1.2000473e+08 | L16: 4 | M16: Pemeliharaan Pokok | N16: Penyisipan | O16: =SUM('S1 TBM 1'!S186:S189) -> 64138248 | P16: =SUM(O16:O18) -> 1.318754e+08 | Q16: =P16/A3 -> 686564.98 | R16: =P16/P41*100 -> 7.3939066 | V16: Survey dan Sensus | W16: =SUM('S1 TBM 2'!Q193:Q194) -> 32619597 | AD16: Kastrasi | AE16: =SUM('S1 TBM 3'!Q181:Q185) -> 34760914
D17: =IF(C17="",D16,C17) -> Pembukaan Lahan Serak | E17: Lubang Tanam Mekanis Auger | F17: =SUM('SI TB SERAK'!Q36:Q39) -> 61907228 | N17: Konsolidasi | O17: =SUM('S1 TBM 1'!S191:S192) -> 55408068 | T17: 4 | U17: Pemeliharaan Prasarana | V17: Jalan Utama / Jalan Akses | W17: =SUM('S1 TBM 2'!Q199:Q204) -> 0 | X17: =SUM(W17:W25) -> 0 | Y17: =X17/$A$3 -> 0 | Z17: =X17/X40*100 -> 0 | AD17: Penyisipan | AE17: =SUM('S1 TBM 3'!Q188:Q191) -> 0
B18: 3 | C18: Penyemprotan Lalang Gulma & Pasar Rintis | D18: =IF(C18="",D17,C18) -> Penyemprotan Lalang Gulma & Pasar Rintis | E18: Penyemprotan Pasar Rintis | F18: =SUM('SI TB CECT'!Q57:Q67) -> 76291985 | G18: =SUM(F18) -> 76291985 | H18: =G18/A3 -> 397188.59 | I18: =G18/G47*100 -> 0.74153399 | N18: Survey dan Sensus | O18: =SUM('S1 TBM 1'!S194:S195) -> 12329085 | V18: Jalan Produksi | W18: =SUM('S1 TBM 2'!Q205:Q210) -> 0 | AD18: Survey dan Sensus | AE18: =SUM('S1 TBM 3'!Q196:Q197) -> 34737853
D19: =IF(C19="",D18,C19) -> Penyemprotan Lalang Gulma & Pasar Rintis | E19: Pemberantasan Lalang | F19: =SUM('SI TB CECT'!Q44:Q56) -> 69784788 | G19: =SUM(F19) -> 69784788 | H19: =G19/A3 -> 363311.06 | I19: =G19/G47*100 -> 0.6782861 | L19: 5 | M19: Pemeliharaan Prasarana | N19: Jalan Utama / Jalan Akses | O19: =SUM('S1 TBM 1'!S200:S205) -> 0 | P19: =SUM(O19:O27) -> 0 | Q19: =P19/A3 -> 0 | R19: =P19/P41*100 -> 0 | V19: Jalan Koleksi | W19: =SUM('S1 TBM 2'!Q211:Q216) -> 0 | AB19: 4 | AC19: Pemeliharaan Prasarana | AD19: Jalan Utama / Jalan Akses | AE19: =SUM('S1 TBM 3'!Q202:Q207) -> 1.2094304e+08 | AF19: =SUM(AE19:AE27) -> 7.6503344e+08 | AG19: =AF19/$A$3 -> 3982889.6 | AH19: =AF19/AF42*100 -> 19.088421
B20: 4 | C20: Pembuatan Sarana & Prasarana | D20: =IF(C20="",D19,C20) -> Pembuatan Sarana & Prasarana | E20: Pembuatan Parit Tersier (1x1) | F20: =SUM('SI TB CECT'!Q119:Q120) -> 0 | G20: =SUM(F20:F24) -> 3.3662443e+08 | H20: =F20/A2 -> 0 | I20: =G20/G47*100 -> 3.2718831 | N20: Jalan Produksi | O20: =SUM('S1 TBM 1'!S206:S211) -> 0 | V20: Jalan Pringgan / Ring | W20: =SUM('S1 TBM 2'!Q217:Q222) -> 0 | AD20: Jalan Produksi | AE20: =SUM('S1 TBM 3'!Q208:Q213) -> 1.7610393e+08
D21: =IF(C21="",D20,C21) -> Pembuatan Sarana & Prasarana | E21: Cuci Parit Alam (1x1) Parit Alam | F21: =SUM('SI TB CECT'!Q127:Q128) -> 44955330 | H21: =F21/A3 -> 234044.82 | N21: Jalan Koleksi | O21: =SUM('S1 TBM 1'!S212:S217) -> 0 | V21: Jalan Liung | W21: =SUM('S1 TBM 2'!Q223:Q227) -> 0 | AD21: Jalan Koleksi | AE21: =SUM('S1 TBM 3'!Q214:Q219) -> 9940521
D22: =IF(C22="",D21,C22) -> Pembuatan Sarana & Prasarana | E22: Cuci Parit Sekunder (2X2) Parit Alam | F22: =SUM('SI TB CECT'!Q125:Q126) -> 59583909 | H22: =F22/46.1 -> 1292492.6 | N22: Jalan Pringgan / Ring | O22: =SUM('S1 TBM 1'!S218:S223) -> 0 | V22: Jembatan Permanen | W22: =SUM('S1 TBM 2'!Q237:Q248) -> 0 | AD22: Jalan Pringgan / Ring | AE22: =SUM('S1 TBM 3'!Q220:Q225) -> 1.5702897e+08
D23: =IF(C23="",D22,C23) -> Pembuatan Sarana & Prasarana | E23: Pembuatan Kontur Teras | F23: =SUM('SI TB SERAK'!Q124:Q126) -> 2.3208519e+08 | H23: =F23/11.1 -> 20908576 | N23: Jalan Liung | O23: =SUM('S1 TBM 1'!S224:S228) -> 0 | V23: Gorong-gorong 40 cm | W23: =SUM('S1 TBM 2'!Q252:Q254) -> 0 | AD23: Jalan Liung | AE23: =SUM('S1 TBM 3'!Q226:Q230) -> 31043155
D24: =IF(C24="",D23,C24) -> Pembuatan Sarana & Prasarana | E24: Pembuatan Pasar Pikul Mekanis | F24: =SUM('SI TB SERAK'!Q142) -> 0 | H24: =F24/51.1 -> 0 | N24: Jembatan Permanen | O24: =SUM('S1 TBM 1'!S237:S249) -> 0 | V24: Gorong-gorong 60 CM | W24: =SUM('S1 TBM 2'!Q255:Q257) -> 0 | AD24: Jembatan Permanen | AE24: =SUM('S1 TBM 3'!Q233:Q245) -> 2.5378344e+08
B25: 5 | C25: Tanam Kacangan | D25: =IF(C25="",D24,C25) -> Tanam Kacangan | E25: Penanaman Kacangan | F25: =SUM('SI TB CECT'!Q163:Q174) -> 5.9462617e+08 | G25: =SUM(F25:F32) -> 1.5079398e+09 | H25: =G25/A3 -> 7850582.1 | I25: =G25/G47*100 -> 14.656699 | N25: Gorong-gorong 40 cm | O25: =SUM('S1 TBM 1'!S253:S255) -> 0 | V25: Gorong-gorong 80 CM | W25: =SUM('S1 TBM 2'!Q258:Q260) -> 0 | AD25: Gorong-gorong 40 cm | AE25: =SUM('S1 TBM 3'!Q249:Q251) -> 8610502.6
D26: =IF(C26="",D25,C26) -> Tanam Kacangan | E26: Pembuatan Bedengan | F26: =SUM('SI TB CECT'!Q175:Q176) -> 21275591 | N26: Gorong-gorong 60 CM | O26: =SUM('S1 TBM 1'!S256:S258) -> 0 | T26: 6 | U26: Pengawetan Tanah | V26: Tapak Kuda | W26: =SUM('S1 TBM 2'!Q283) -> 0 | X26: =SUM(W26:W27) -> 0 | Y26: =X26/$A$3 -> 0 | Z26: =X26/X40*100 -> 0 | AD26: Gorong-gorong 60 CM | AE26: =SUM('S1 TBM 3'!Q252:Q254) -> 4572709.8
D27: =IF(C27="",D26,C27) -> Tanam Kacangan | E27: Perakitan Instalasi Air | F27: =SUM('SI TB CECT'!Q186:Q187) -> 6451237.9 | N27: Gorong-gorong 80 CM | O27: =SUM('S1 TBM 1'!S259:S261) -> 0 | V27: Tapak Timbun | W27: =SUM('S1 TBM 2'!Q284) -> 0 | AD27: Gorong-gorong 80 CM | AE27: =SUM('S1 TBM 3'!Q255:Q257) -> 3007163.9
D28: =IF(C28="",D27,C28) -> Tanam Kacangan | E28: Pemeliharaan Weeding Atas | F28: =SUM('SI TB CECT'!Q177) -> 8592229.4 | L28: 6 | M28: Pengawetan Tanah | N28: Tapak Kuda | O28: =SUM('S1 TBM 1'!S283:S283) -> 69138806 | P28: =SUM(O28:O29) -> 1.3827761e+08 | Q28: =P28/A3 -> 719895.93 | R28: =P28/P41*100 -> 7.7528616 | T28: 7 | U28: Pengendalian Hama dan Penyakit | V28: Hama Tikus | W28: =SUM('S1 TBM 2'!Q289:Q290) -> 52777414 | X28: =SUM(W28:W30) -> 1.8349378e+08 | Y28: =X28/$A$3 -> 955298.71 | Z28: =X28/X40*100 -> 7.6649934 | AB28: 6 | AC28: Pengawetan Tanah | AD28: Tapak Kuda | AE28: =SUM('S1 TBM 3'!Q277) -> 0 | AF28: =SUM(AE28:AE29) -> 0 | AG28: =AF28/$A$3 -> 0 | AH28: =AF28/AF42*100 -> 0
D29: =IF(C29="",D28,C29) -> Tanam Kacangan | E29: PHPT Insek | F29: =SUM('SI TB CECT'!Q178:Q181) -> 9179405.5 | N29: Tapak Timbun | O29: =SUM('S1 TBM 1'!S284:S284) -> 69138806 | V29: Hama Ulat Api | W29: =SUM('S1 TBM 2'!Q294:Q302) -> 2457942.9 | AD29: Tapak Timbun | AE29: =SUM('S1 TBM 3'!Q278) -> 0
D30: =IF(C30="",D29,C30) -> Tanam Kacangan | E30: PHPT Fungi | F30: =SUM('SI TB CECT'!Q182:Q184) -> 0 | L30: 7 | M30: Pengendalian Hama dan Penyakit | N30: Hama Tikus | O30: =SUM('S1 TBM 1'!S289:S290) -> 49610581 | P30: =SUM(O30:O32) -> 1.5914269e+08 | Q30: =P30/A3 -> 828522.97 | R30: =P30/P41*100 -> 8.9227117 | V30: Hama (Oryctes) | W30: =SUM('S1 TBM 2'!Q306:Q319) -> 1.2825842e+08 | AB30: 7 | AC30: Pengendalian Hama dan Penyakit | AD30: Hama Tikus | AE30: =SUM('S1 TBM 3'!Q283:Q284) -> 56147199 | AF30: =SUM(AE30:AE32) -> 3.3048236e+08 | AG30: =AF30/$A$3 -> 1720545.4 | AH30: =AF30/AF42*100 -> 8.245896
D31: =IF(C31="",D30,C31) -> Tanam Kacangan | E31: Penyiraman Bibit | F31: =SUM('SI TB CECT'!Q185) -> 8592229.4 | N31: Hama Ulat Api | O31: =SUM('S1 TBM 1'!S293:S301) -> 3448080.8 | T31: 8 | U31: Pemupukkan Kelapa Sawit | V31: Pemupukkan Hayati | W31: =SUM('S1 TBM 2'!Q330:Q338) -> 0 | X31: =SUM(W31:W37) -> 1.3090863e+09 | Y31: =X31/$A$3 -> 6815318.1 | Z31: =X31/X40*100 -> 54.683805 | AD31: Hama Ulat Api | AE31: =SUM('S1 TBM 3'!Q287:Q295) -> 2610849.2
D32: =IF(C32="",D31,C32) -> Tanam Kacangan | E32: Pemeliharaan Kacangan | F32: =SUM('SI TB CECT'!Q188) -> 8.5922294e+08 | N32: Hama (Oryctes) | O32: =SUM('S1 TBM 1'!S305:S316) -> 1.0608403e+08 | V32: Pemupukkan NPK 12-12-17-2+0,65B | W32: =SUM('S1 TBM 2'!Q350:Q358) -> 8.3571973e+08 | AD32: Hama (Oryctes) | AE32: =SUM('S1 TBM 3'!Q299:Q313) -> 2.7172431e+08
B33: 6 | C33: Pemupukkan Kacangan | D33: =IF(C33="",D32,C33) -> Pemupukkan Kacangan | E33: Pemupukkan NPK Granule & RP | F33: =SUM('SI TB CECT'!Q213:Q222) -> 1.4627326e+08 | G33: =SUM(F33:F33) -> 1.4627326e+08 | H33: =G33/A3 -> 761522.61 | I33: =G33/G47*100 -> 1.4217299 | L33: 8 | M33: Pemupukkan Kelapa Sawit | N33: Pemupukkan NPK 12-12-17-2+0,65B | O33: =SUM('S1 TBM 1'!S327:S335) -> 6.2589557e+08 | P33: =SUM(O33:O38) -> 7.6187485e+08 | Q33: =P33/A3 -> 3966445.5 | R33: =P33/P41*100 -> 42.716317 | V33: Pemupukkan Dolomite | W33: =SUM('S1 TBM 2'!Q340:Q348) -> 97842104 | AB33: 8 | AC33: Pemupukkan Kelapa Sawit | AD33: Pemupukkan Hayati | AE33: =SUM('S1 TBM 3'!Q324:Q332) -> 0 | AF33: =SUM(AE33:AE39) -> 1.9538038e+09 | AG33: =AF33/$A$3 -> 10171823 | AH33: =AF33/AF42*100 -> 48.749541
B34: 7 | C34: Angkutan Pupuk | D34: =IF(C34="",D33,C34) -> Angkutan Pupuk | E34: Angkutan Pupuk Intern | F34: =SUM('SI TB CECT'!Q227:Q229) -> 2172198.8 | G34: =SUM(F34:F35) -> 7207453.3 | H34: =G34/A3 -> 37523.185 | I34: =G34/G47*100 -> 0.070054169 | N34: Pemupukkan Dolomite | O34: =SUM('S1 TBM 1'!S337:S345) -> 1.0424336e+08 | V34: Pemupukkan Borate | W34: =SUM('S1 TBM 2'!Q360:Q368) -> 30016684 | AD34: Pemupukkan NPK 12-12-17-2+0,65B | AE34: =SUM('S1 TBM 3'!Q344:Q352) -> 1.0299211e+09
D35: =IF(C35="",D34,C35) -> Angkutan Pupuk | E35: Angkutan Pupuk Ekstern | F35: =SUM('SI TB CECT'!Q230:Q231) -> 5035254.5 | N35: Pemupukkan Borate | O35: =SUM('S1 TBM 1'!S347:S355) -> 19029669 | V35: Janjang Kosong | W35: =SUM('S1 TBM 2'!Q370:Q374) -> 3.2647469e+08 | AD35: Pemupukkan Dolomite | AE35: =SUM('S1 TBM 3'!Q334:Q342) -> 1.293058e+08
B36: 8 | C36: Tanam Pokok Sawit | D36: =IF(C36="",D35,C36) -> Tanam Pokok Sawit | E36: Memancang | F36: =SUM('SI TB CECT'!Q235:Q236) -> 88665196 | G36: =SUM(F36:F38) -> 2.1125503e+09 | H36: =G36/A3 -> 10998283 | I36: =G36/G47*100 -> 20.533321 | N36: Janjang Kosong | O36: =SUM('S1 TBM 1'!S357:S361) -> 0 | V36: Pengangkutan Pupuk Intern | W36: =SUM('S1 TBM 2'!Q378:Q380) -> 13681341 | AD36: Pemupukkan Borate | AE36: =SUM('S1 TBM 3'!Q354:Q362) -> 31080141
D37: =IF(C37="",D36,C37) -> Tanam Pokok Sawit | E37: Pupuk Lubang Tanam | F37: =SUM('SI TB CECT'!Q237:Q245) -> 4.1602438e+08 | N37: Pengangkutan Pupuk Intern | O37: =SUM('S1 TBM 1'!S365:S367) -> 9070148.2 | V37: Pengangkutan Pupuk Ekstern | W37: =SUM('S1 TBM 2'!Q381) -> 5351748.9 | AD37: Janjang Kosong | AE37: =SUM('S1 TBM 3'!Q364:Q368) -> 7.3614578e+08
D38: =IF(C38="",D37,C38) -> Tanam Pokok Sawit | E38: Penanaman Kelapa Sawit | F38: =SUM('SI TB CECT'!Q246:Q250) -> 1.6078607e+09 | N38: Pengangkutan Pupuk Ekstern | O38: =SUM('S1 TBM 1'!S368) -> 3636098.3 | T38: 9 | U38: Pengawasan dan Administrasi | V38: Pengawasan | W38: =SUM('S1 TBM 2'!Q395:Q397) -> 81200874 | X38: =SUM(W38:W39) -> 1.0496116e+08 | Y38: =X38/$A$3 -> 546445.04 | Z38: =X38/X40*100 -> 4.38449 | AD38: Pengangkutan Pupuk Intern | AE38: =SUM('S1 TBM 3'!Q372:Q374) -> 19796360
B39: 9 | C39: Pemupukkan Kelapa Sawit | D39: =IF(C39="",D38,C39) -> Pemupukkan Kelapa Sawit | E39: Pemupukkan Urea | F39: =SUM('SI TB CECT'!Q277:Q285) -> 31464495 | G39: =SUM(F39) -> 31464495 | H39: =G39/A3 -> 163809.32 | I39: =G39/G47*100 -> 0.30582495 | L39: 9 | M39: Pengawasan dan Administrasi | N39: Pengawasan | O39: =SUM('S1 TBM 1'!S382:S384) -> 76288368 | P39: =SUM(O39:O40) -> 98655766 | Q39: =P39/A3 -> 513618.11 | R39: =P39/P41*100 -> 5.5313691 | V39: Administrasi | W39: =SUM('S1 TBM 2'!Q398:Q399) -> 23760290 | AD39: Pengangkutan Pupuk Ekstern | AE39: =SUM('S1 TBM 3'!Q375) -> 7554675.1
B40: 10 | C40: Pemeliharaan Pokok Sawit | D40: =IF(C40="",D39,C40) -> Pemeliharaan Pokok Sawit | E40: PHPT Tikus | F40: =SUM('SI TB CECT'!Q257:Q258) -> 28644916 | G40: =SUM(F40:F44) -> 55106910 | H40: =G40/A3 -> 286895.62 | I40: =G40/G47*100 -> 0.53562176 | N40: Administrasi | O40: =SUM('S1 TBM 1'!S385:S386) -> 22367398 | T40: Total | X40: =SUM(X5:X39) -> 2.3939196e+09 | AB40: 9 | AC40: Pengawasan dan Administrasi | AD40: Pengawasan | AE40: =SUM('S1 TBM 3'!Q389:Q391) -> 86430380 | AF40: =SUM(AE40:AE41) -> 1.1167105e+08 | AG40: =AF40/$A$3 -> 581377.81 | AH40: =AF40/AF42*100 -> 2.7863148
D41: =IF(C41="",D40,C41) -> Pemeliharaan Pokok Sawit | E41: PHPT Kumbang Tanduk | F41: =SUM('SI TB CECT'!Q259:Q263) -> 500000 | L41: Total | P41: =SUM(P5:P40) -> 1.7835687e+09 | T41: Rp/HA | X41: =X40/$A$3 -> 12463138 | AD41: Administrasi | AE41: =SUM('S1 TBM 3'!Q392:Q393) -> 25240670
...

Sheet SI TB CECT
C1: CECT: | D1: 140.98 | E1: RENCANA BIAYA REPLANTING TANAM BARU DENGAN CECT
C2: Total: | D2: 192.08
B3: Pekerjaan | F3: Material | H3: Rotasi APD | J3: TB/LC | P3: 2026 | R3: 2026 | T3: 2027 | V3: Rata-rata | X3: Keterangan | Y3: BIAYA/HA | Z3: Biaya/pkk | AA3: Rp/Ha | AB3: (%)
F4: Jenis | G4: Sat | J4: Sat | K4: Vol | M4: Norma | N4: Rotasi | O4: Jumlah Unit | P4: Rp Sat | Q4: Jumlah RP | R4: Rp Sat | S4: Jumlah RP | T4: Rp Sat | U4: Jumlah RP | V4: Rp Sat | W4: Jumlah RP
K5: % | L5: Luas/Mtr/Pkk/Unit
B6: PEMBUKAAN LAHAN
C7: IMAS,TUMBANG, PERUN
D8: Identifikasi Blok | F8: Upah PHL | G8: HK | J8: Ha | K8: 1 | L8: 140.98 | M8: 0.25 | N8: 1 | O8: =K8*L8*M8*N8 -> 35.245 | P8: 149108.52 | Q8: =P8*$O8 -> 5255329.8 | R8: 149108.52 | S8: =R8*$O8 -> 5255329.8 | T8: 158800.57 | U8: =T8*$O8 -> 5596926.2 | V8: =W8/O8 -> 152339.2 | W8: =AVERAGEIF($P$4:$U$4,W$4,$P8:$U8) -> 5369195.3 | AA8: =Q8/$D$1 -> 37277.13
F9: Cat | G9: Kg | N9: 1
F10: Kuas | G10: Buah | N10: 1
F11: Kompas | G11: Buah | M11: 0.0007 | N11: 1
F12: GPS | G12: Buah | M12: 0.0013 | N12: 1
D13: Imas | E13: Hutan Primer | F13: Upah PHL | G13: HK | M13: 10 | N13: 1 | X13: Vol sesuai kondisi
E14: Hutan Sekunder | F14: Upah PHL | G14: HK | M14: 10 | N14: 1
E15: Semak Belukar | F15: Upah PHL | G15: HK
D16: Tumbang | E16: Hutan Primer | F16: Upah PHL | G16: HK | M16: 20 | N16: 1 | X16: Vol sesuai kondisi
E17: Hutan Sekunder | F17: Upah PHL | G17: HK | M17: 12 | N17: 1
D18: Cincang | E18: Hutan Primer | F18: Upah PHL | G18: HK
E19: Hutan Sekunder | F19: Upah PHL | G19: HK
D20: Perun Mekanis | E20: Hutan Primer | F20: Buldozer 1 | G20: HM | M20: 6 | N20: 1 | X20: Vol sesuai kondisi
E21: Hutan Sekunder | F21: Buldozer 1 | G21: HM | M21: 5 | N21: 1
E22: Semak Belukar | F22: Buldozer 1 | G22: HM | M22: 4 | N22: 1
D23: Pengolahan Tanah (Ripping) | F23: Buldozer 1 | G23: HM | J23: HM/Ha | K23: 1 | L23: =D1*(1-0.12) -> 124.0624 | M23: =2.85*2 -> 5.7 | N23: 1 | O23: =K23*L23*M23*N23 -> 707.15568 | P23: 1051433.7 | Q23: =P23*$O23 -> 7.435273e+08 | R23: 1051433.7 | S23: =R23*$O23 -> 7.435273e+08 | T23: 1113470.8 | U23: =T23*$O23 -> 7.8739718e+08 | V23: =W23/O23 -> 1072112.7 | W23: =AVERAGEIF($P$4:$U$4,W$4,$P23:$U23) -> 7.5815059e+08 | X23: 3 HM/HA Penggemburan Tanah dan Pemutusan Akar, total rupiah sudah termasuk harga sewa alat dan BBM | Y23: =Q23/L23 -> 5993172 | AA23: =(Q23+Q24+Q25)/35.245 -> 23411403 | AD23: =92518125/35.245 -> 2625000
F24: Upah PHL | G24: HK | J24: Ha | K24: 1 | L24: =O23/10 -> 70.715568 | M24: =3*2 -> 6 | N24: 1 | O24: =K24*L24*M24*N24 -> 424.29341 | P24: 149108.52 | Q24: =P24*$O24 -> 63265762 | X24: Waker Alat
F25: Angkutan Material | G25: RIT | K25: 1 | L25: =(O23*25)/400 -> 44.19723 | M25: 2 | N25: 1 | O25: =K25*L25*M25*N25 -> 88.39446 | P25: 207500 | Q25: =P25*$O25 -> 18341850 | X25: Angkut BBM
D26: Tumbang Chipping
E27: Pancang Chiping | F27: Upah PHL | G27: HK | J27: Ha | K27: 1 | L27: 140.98 | M27: 1 | N27: 1 | O27: =K27*L27*M27*N27 -> 140.98 | P27: 149108.52 | Q27: =P27*$O27 -> 21021319 | R27: 149108.52 | S27: =R27*$O27 -> 21021319 | T27: 158800.57 | U27: =T27*$O27 -> 22387705 | V27: =W27/O27 -> 152339.2 | W27: =AVERAGEIF($P$4:$U$4,W$4,$P27:$U27) -> 21476781 | X27: Pemancangan Titik Rumpuk Hasil Chippingan | AA27: =Q27/$D$1 -> 149108.52
E28: Tumbang Chiping | F28: Excavator 1 | G28: HM | J28: HM/Ha | K28: 1 | L28: 140.98 | M28: 10.8 | N28: 1 | O28: =K28*L28*M28*N28 -> 1522.584 | P28: 720338.07 | Q28: =P28*$O28 -> 1.0967752e+09 | R28: 720338.07 | S28: =R28*$O28 -> 1.0967752e+09 | T28: 761671.7 | U28: =T28*$O28 -> 1.1597091e+09 | V28: =W28/O28 -> 734115.95 | W28: =AVERAGEIF($P$4:$U$4,W$4,$P28:$U28) -> 1.1177532e+09 | X28: 12 Pokok/HM, Total rupiah sudah termasuk harga sewa alat dan BBM | Y28: =Q28/192.08 -> 5709991.8 | Z28: =Y28/122 -> 46803.211 | AA28: =Q28/$D$1 -> 7779651.2 | AD28: =AA28/136 -> 57203.318
F29: Upah PHL | G29: HK | J29: Ha | K29: 1 | L29: =O28/10 -> 152.2584 | M29: =3*4 -> 12 | N29: 1 | O29: =K29*L29*M29*N29 -> 1827.1008 | P29: 149108.52 | Q29: =P29*$O29 -> 2.724363e+08 | X29: Waker Alat 4 Orang, 2 Alat | AA29: =Q29/$D$1 -> 1932446.4
F30: Angkutan Material | G30: RIT | K30: 0 | L30: =(O28*18)/400 -> 68.51628 | M30: 2 | N30: 1 | O30: =K30*L30*M30*N30 -> 0 | P30: 207500 | Q30: =P30*$O30 -> 0 | X30: Angkut Solar
E31: Aplikasi Metharizium | F31: Upah PHL | G31: HK | J31: Ha | K31: 0 | L31: 140.98 | M31: 0.5 | N31: 1 | O31: =K31*L31*M31*N31 -> 0 | P31: 149108.52 | Q31: =P31*$O31 -> 0 | AA31: =Q31/35.245 -> 0
F32: Metharizium | G32: Kg | J32: Kg | K32: 0 | L32: 140.98 | M32: 24 | N32: 1 | O32: =K32*L32*M32*N32 -> 0 | P32: 70350 | Q32: =P32*$O32 -> 0 | R32: 70350 | S32: =R32*$O32 -> 0 | T32: 73867.5 | U32: =T32*$O32 -> 0 | V32: =W32/O32 -> #DIV/0! | W32: =AVERAGEIF($P$4:$U$4,W$4,$P32:$U32) -> 0 | AA32: =Q32/35.245 -> 0
D33: Parit CECT | F33: Excavator 1 | G33: HM | J33: HM/Ha | K33: 1 | L33: 140.98 | M33: 8.5 | N33: 1 | O33: =K33*L33*M33*N33 -> 1198.33 | P33: 720338.07 | Q33: =P33*$O33 -> 8.6320272e+08 | X33: Total rupiah sudah termasuk harga sewa alat, dan BBM | AA33: =Q33/$D$1 -> 6122873.6 | AE33: =AB33/600 -> 0
F34: Upah PHL | G34: HK | J34: Ha | K34: 1 | L34: =O33/10 -> 119.833 | M34: =3*2 -> 6 | N34: 1 | O34: =K34*L34*M34*N34 -> 718.998 | P34: 149108.52 | Q34: =P34*$O34 -> 1.0720873e+08 | X34: Waker Alat | AA34: =Q34/$D$1 -> 760453.45
F35: Angkutan Material | G35: RIT | J35: RIT | K35: 0 | L35: =(O33*18)/400 -> 53.92485 | M35: 2 | N35: 1 | O35: =K35*L35*M35*N35 -> 0 | P35: 207500 | Q35: =P35*$O35 -> 0 | X35: Angkut Solar | AA35: =Q35/$D$1 -> 0
D36: Tutup Lubang CECT dan Perataan Tanah | F36: Excavator 1 | G36: HM | J36: HM/Ha | K36: 1 | L36: 140.98 | M36: =600/60 -> 10 | N36: 1 | O36: =K36*L36*M36*N36 -> 1409.8 | P36: 720338.07 | Q36: =P36*$O36 -> 1.0155326e+09 | R36: 720338.07 | S36: =R36*$O36 -> 1.0155326e+09 | T36: 761671.7 | U36: =T36*$O36 -> 1.0738048e+09 | V36: =W36/O36 -> 734115.95 | W36: =AVERAGEIF($P$4:$U$4,W$4,$P36:$U36) -> 1.0349567e+09 | X36: Total rupiah sudah termasuk harga sewa alat, dan BBM | AA36: =Q36/$D$1 -> 7203380.7 | AE36: =AA36/600 -> 12005.635
F37: Upah PHL | G37: HK | J37: Ha | K37: 1 | L37: =O36/10 -> 140.98 | M37: =3*2 -> 6 | N37: 1 | O37: =K37*L37*M37*N37 -> 845.88 | P37: 149108.52 | Q37: =P37*$O37 -> 1.2612791e+08 | X37: Waker Alat 2 Orang | AA37: =Q37/$D$1 -> 894651.12
F38: Angkutan Material | G38: RIT | J38: RIT | K38: 0 | L38: =(O36*18)/400 -> 63.441 | M38: 2 | N38: 1 | O38: =K38*L38*M38*N38 -> 0 | P38: 207500 | Q38: =P38*$O38 -> 0 | X38: Angkut Solar
D39: Lubang Tanam Mekanis/Auger
E40: Pancang Kepala | F40: Upah PHL | G40: HK | K40: 1 | L40: =140.98 -> 140.98 | M40: 0.25 | N40: 1 | O40: =K40*L40*M40*N40 -> 35.245 | P40: 149108.52 | Q40: =P40*$O40 -> 5255329.8 | R40: 149108.52 | S40: =R40*$O40 -> 5255329.8 | T40: 158800.57 | U40: =T40*$O40 -> 5596926.2 | V40: =W40/O40 -> 152339.2 | W40: =AVERAGEIF($P$4:$U$4,W$4,$P40:$U40) -> 5369195.3 | X40: Pancang Kepala 1 HK = 4 HA | Y40: =Q40/L40 -> 37277.13 | AA40: =Q40/$D$1 -> 37277.13
...

Sheet SI TB SERAK
D1: Serak : | E1: 51.1 | F1: RENCANA BIAYA REPLANTING TANAM BARU DENGAN CIPPING SERAK DAN TERAS BERSAMBUNG
B2: Pekerjaan | F2: Material | H2: Rotasi APD | J2: TB/LC | P2: 2026 | R2: 2026 | T2: 2027 | V2: Rata-rata | X2: Keterangan | Y2: BIAYA/HA | Z2: Biaya/pkk | AA2: Rp/Ha | AB2: (%)
F3: Jenis | G3: Sat | J3: Sat | K3: Vol | M3: Norma | N3: Rotasi | O3: Jumlah Unit | P3: Rp Sat | Q3: Jumlah RP | R3: Rp Sat | S3: Jumlah RP | T3: Rp Sat | U3: Jumlah RP | V3: Rp Sat | W3: Jumlah RP
K4: % | L4: Luas/Mtr/Pkk/Unit
B5: PEMBUKAAN LAHAN
C6: IMAS,TUMBANG, PERUN
D7: Identifikasi Blok | F7: Upah PHL | G7: HK | J7: Ha | K7: 1 | L7: 51.1 | M7: 0.25 | N7: 1 | O7: =K7*L7*M7*N7 -> 12.775 | P7: 149108.52 | Q7: =P7*$O7 -> 1904861.3 | R7: 149108.52 | S7: =R7*$O7 -> 1904861.3 | T7: 158800.57 | U7: =T7*$O7 -> 2028677.3 | V7: =W7/O7 -> 152339.2 | W7: =AVERAGEIF($P$3:$U$3,W$3,$P7:$U7) -> 1946133.3 | AA7: =Q7/$E$1 -> 37277.13
F8: Cat | G8: Kg | N8: 1 | P8: 69079.5 | AA8: =Q8/L8 -> #DIV/0!
F9: Kuas | G9: Buah | N9: 1 | P9: 0 | AA9: =Q9/L9 -> #DIV/0!
F10: Kompas | G10: Buah | M10: 0.0007 | N10: 1 | P10: 0 | AA10: =Q10/L10 -> #DIV/0!
F11: GPS | G11: Buah | M11: 0.0013 | N11: 1 | P11: 0 | AA11: =Q11/L11 -> #DIV/0!
D12: Imas | E12: Hutan Primer | F12: Upah PHL | G12: HK | M12: 10 | N12: 1 | P12: 149108.52 | X12: Vol sesuai kondisi | AA12: =Q12/L12 -> #DIV/0!
E13: Hutan Sekunder | F13: Upah PHL | G13: HK | M13: 10 | N13: 1 | P13: 149108.52 | AA13: =Q13/L13 -> #DIV/0!
E14: Semak Belukar | F14: Upah PHL | G14: HK | P14: 149108.52 | AA14: =Q14/L14 -> #DIV/0!
D15: Tumbang | E15: Hutan Primer | F15: Upah PHL | G15: HK | M15: 20 | N15: 1 | P15: 149108.52 | X15: Vol sesuai kondisi | AA15: =Q15/L15 -> #DIV/0!
E16: Hutan Sekunder | F16: Upah PHL | G16: HK | M16: 12 | N16: 1 | P16: 149108.52 | AA16: =Q16/L16 -> #DIV/0!
D17: Cincang | E17: Hutan Primer | F17: Upah PHL | G17: HK | P17: 149108.52 | AA17: =Q17/L17 -> #DIV/0!
E18: Hutan Sekunder | F18: Upah PHL | G18: HK | P18: 149108.52 | AA18: =Q18/L18 -> #DIV/0!
D19: Perun Mekanis | E19: Hutan Primer | F19: Buldozer 1 | G19: HM | M19: 6 | N19: 1 | P19: 1051433.7 | X19: Vol sesuai kondisi | AA19: =Q19/L19 -> #DIV/0!
E20: Hutan Sekunder | F20: Buldozer 1 | G20: HM | M20: 5 | N20: 1 | P20: 1051433.7 | AA20: =Q20/L20 -> #DIV/0!
E21: Semak Belukar | F21: Buldozer 1 | G21: HM | M21: 4 | N21: 1 | P21: 1051433.7 | AA21: =Q21/L21 -> #DIV/0!
D22: Pengolahan Tanah (Ripping) | F22: Buldozer 1 | G22: HM | J22: HM/Ha | K22: 1 | L22: 51.1 | M22: =2.85*2 -> 5.7 | N22: 1 | O22: =K22*L22*M22*N22 -> 291.27 | P22: 1051433.7 | Q22: =P22*$O22 -> 3.0625109e+08 | R22: 1051433.7 | S22: =R22*$O22 -> 3.0625109e+08 | T22: 1113470.8 | U22: =T22*$O22 -> 3.2432063e+08 | V22: =W22/O22 -> 1072112.7 | W22: =AVERAGEIF($P$3:$U$3,W$3,$P22:$U22) -> 3.1227427e+08 | X22: 2,85 HM/HA Penggemburan Tanah dan Pemutusan Akar | Y22: =Q22/L22 -> 5993172 | AA22: =Q22/$E$1 -> 5993172
F23: Upah PHL | G23: HK | J23: Ha | K23: 1 | L23: =O22/10 -> 29.127 | M23: =3*2 -> 6 | N23: 1 | O23: =K23*L23*M23*N23 -> 174.762 | P23: 149108.52 | Q23: =P23*$O23 -> 26058503 | AA23: =Q23/$E$1 -> 509951.14
F24: Angkutan Material | G24: RIT | K24: 0 | L24: =(O22*25)/400 -> 18.204375 | M24: 2 | N24: 1 | O24: =K24*L24*M24*N24 -> 0 | P24: 207500 | Q24: =P24*$O24 -> 0
D25: Tumbang Chipping
E26: Pancang Chiping | F26: Upah PHL | G26: HK | J26: Ha | K26: 1 | L26: 51.1 | M26: 1 | N26: 1 | O26: =K26*L26*M26*N26 -> 51.1 | P26: 149108.52 | Q26: =P26*$O26 -> 7619445.4 | R26: 149108.52 | S26: =R26*$O26 -> 7619445.4 | T26: 158800.57 | U26: =T26*$O26 -> 8114709.3 | V26: =W26/O26 -> 152339.2 | W26: =AVERAGEIF($P$3:$U$3,W$3,$P26:$U26) -> 7784533.4 | AA26: =Q26/$E$1 -> 149108.52
E27: Tumbang Chiping | F27: Excavator 1 | G27: HM | J27: HM/Ha | K27: 1 | L27: 51.1 | M27: 12 | N27: 1 | O27: =K27*L27*M27*N27 -> 613.2 | P27: 720338.07 | Q27: =P27*$O27 -> 4.4171131e+08 | R27: 720338.07 | S27: =R27*$O27 -> 4.4171131e+08 | T27: 761671.7 | U27: =T27*$O27 -> 4.6705709e+08 | V27: =W27/O27 -> 734115.95 | W27: =AVERAGEIF($P$3:$U$3,W$3,$P27:$U27) -> 4.501599e+08 | X27: 12 Pokok/HM | Y27: =Q27/192.08 -> 2299621.5 | Z27: =Y27/122 -> 18849.357 | AA27: =Q27/$E$1 -> 8644056.9 | AC27: =AA27/136 -> 63559.242
F28: Upah PHL | G28: HK | J28: Ha | K28: 1 | L28: =O27/10 -> 61.32 | M28: =3*2 -> 6 | N28: 1 | O28: =K28*L28*M28*N28 -> 367.92 | P28: 149108.52 | Q28: =P28*$O28 -> 54860007 | AA28: =Q28/$E$1 -> 1073581.3
F29: Angkutan Material | G29: RIT | K29: 0 | L29: =(O27*18)/400 -> 27.594 | M29: 2 | N29: 1 | O29: =K29*L29*M29*N29 -> 0 | P29: 207500 | Q29: =P29*$O29 -> 0
E30: Aplikasi Metharizium | F30: Upah PHL | G30: HK | K30: 1 | L30: 51.1 | M30: 1 | N30: 1 | O30: =K30*L30*M30*N30 -> 51.1 | P30: 149108.52 | Q30: =P30*$O30 -> 7619445.4 | AA30: =Q30/$E$1 -> 149108.52
F31: Metharizium | G31: Kg | J31: Kg | K31: 1 | L31: 51.1 | M31: 24 | N31: 1 | O31: =K31*L31*M31*N31 -> 1226.4 | P31: 70350 | Q31: =P31*$O31 -> 86277240 | R31: 70350 | S31: =R31*$O31 -> 86277240 | T31: 73867.5 | U31: =T31*$O31 -> 90591102 | V31: =W31/O31 -> 71522.5 | W31: =AVERAGEIF($P$3:$U$3,W$3,$P31:$U31) -> 87715194 | AA31: =Q31/$E$1 -> 1688400
D32: Tutup Lubang | F32: Excavator 1 | G32: HM | J32: HM/Ha | K32: 1 | L32: 51.1 | M32: 2.9 | N32: 1 | O32: =K32*L32*M32*N32 -> 148.19 | P32: 720338.07 | Q32: =P32*$O32 -> 1.067469e+08 | R32: 720338.07 | S32: =R32*$O32 -> 1.067469e+08 | T32: 761671.7 | U32: =T32*$O32 -> 1.1287213e+08 | V32: =W32/O32 -> 734115.95 | W32: =AVERAGEIF($P$3:$U$3,W$3,$P32:$U32) -> 1.0878864e+08 | AA32: =Q32/$E$1 -> 2088980.4
F33: Upah PHL | G33: HK | J33: Ha | K33: 1 | L33: =O32/10 -> 14.819 | M33: =3*2 -> 6 | N33: 1 | O33: =K33*L33*M33*N33 -> 88.914 | P33: 149108.52 | Q33: =P33*$O33 -> 13257835 | AA33: =Q33/$E$1 -> 259448.82
F34: Angkutan Material | G34: RIT | K34: 0 | L34: =(O32*18)/400 -> 6.66855 | M34: 2 | N34: 1 | O34: =K34*L34*M34*N34 -> 0 | P34: 207500 | Q34: =P34*$O34 -> 0
D35: Lubang Tanam Mekanis/Auger
E36: Pancang Kepala | F36: Upah PHL | G36: HK | K36: 1 | L36: =51.1 -> 51.1 | M36: 0.25 | N36: 1 | O36: =K36*L36*M36*N36 -> 12.775 | P36: 149108.52 | Q36: =P36*$O36 -> 1904861.3 | R36: 149108.52 | S36: =R36*$O36 -> 1904861.3 | T36: 158800.57 | U36: =T36*$O36 -> 2028677.3 | V36: =W36/O36 -> 152339.2 | W36: =AVERAGEIF($P$3:$U$3,W$3,$P36:$U36) -> 1946133.3 | X36: Pancang Kepala 1 HK = 4 HA | Y36: =Q36/L36 -> 37277.13 | AA36: =Q36/$E$1 -> 37277.13
E37: Lubang Tanah Mekanis/Auger | F37: Excavator 1 | G37: HM | J37: HM/Ha | K37: 1 | L37: 51.1 | M37: 1.45 | N37: 1 | O37: =K37*L37*M37*N37 -> 74.095 | P37: 720338.07 | Q37: =P37*$O37 -> 53373450 | R37: 720338.07 | S37: =R37*$O37 -> 53373450 | T37: 761671.7 | U37: =T37*$O37 -> 56436065 | V37: =W37/O37 -> 734115.95 | W37: =AVERAGEIF($P$3:$U$3,W$3,$P37:$U37) -> 54394321 | X37: 1 HM 90 Lubang, 10 HM 900 Lubang | Y37: =Q37/192.08 -> 277870.94 | AA37: =Q37/$E$1 -> 1044490.2
F38: Upah PHL | G38: HK | J38: Ha | K38: 1 | L38: =O37/10 -> 7.4095 | M38: =3*2 -> 6 | N38: 1 | O38: =K38*L38*M38*N38 -> 44.457 | P38: 149108.52 | Q38: =P38*$O38 -> 6628917.5 | AA38: =Q38/$E$1 -> 129724.41
F39: Angkutan Material | G39: RIT | K39: 0 | L39: =(O37*18)/400 -> 3.334275 | M39: 2 | N39: 1 | O39: =K39*L39*M39*N39 -> 0 | P39: 207500 | Q39: =P39*$O39 -> 0
D40: Pemberantasan Lalang dan Gulma Lainnya | F40: Upah PHL | G40: HK | J40: Ha | K40: 1 | M40: 1.5 | N40: 1 | O40: =K40*L40*M40*N40 -> 0 | P40: 149108.52 | Q40: =P40*$O40 -> 0 | R40: 149108.52 | S40: =R40*$O40 -> 0 | T40: 158800.57 | U40: =T40*$O40 -> 0 | V40: =W40/O40 -> #DIV/0! | W40: =AVERAGEIF($P$3:$U$3,W$3,$P40:$U40) -> 0
...

Sheet S1 TBM 1
B1: Luas: | C1: 192.08
B2: Pekerjaan | F2: Material | H2: Rotasi APD | J2: TBM 1 | P2: 2025 | R2: 2027 | T2: 2027 | V2: Rata-rata | Y2: Rp/Ha | Z2: (%)
F3: Jenis | G3: Sat | J3: Sat | K3: Vol | M3: Norma | N3: Rotasi | O3: Jumlah Unit | P3: Rp Sat | Q3: Jumlah RP | R3: Rp Sat | S3: Jumlah RP | T3: Rp Sat | U3: Jumlah RP | V3: Rp Sat | W3: Jumlah RP | X3: Keterangan
K4: % | L4: Luas/Mtr/Pkk/Unit
B5: TANAM KACANGAN
C6: Tanam Kacangan | F6: Upah PHL | G6: HK | M6: 6.5 | N6: 1
F7: PJ | G7: Kg | M7: 3 | N7: 1
F8: CM | G8: Kg | M8: 6 | N8: 1
F9: MB (Mocuna Bracteata) | G9: Kg | M9: 0.25 | N9: 1
F10: Rizhobium | G10: Kg | M10: 0.01 | N10: 1
F11: Rock Phosphate | G11: Kg | M11: 2 | N11: 1
F12: Sepatu Boots | G12: Buah | H12: 1 | I12: X | M12: =((M$6*N$6)/240*($H12/N12)) -> 0.027083333 | N12: 1
C13: Pemeliharaan Kacangan | F13: Upah PHL | G13: HK | M13: 4 | N13: 3
C14: Bongkar Tumbuhan Pengganggu | F14: Upah PHL | G14: HK | M14: 2 | N14: 1
F15: Glyphosate | G15: Liter | M15: 1.2 | N15: 1
F16: Metil Metsulfuron | G16: Kg | M16: =48/1000 -> 0.048 | N16: 1
F17: Perekat | G17: Liter | M17: 0.288 | N17: 1
F18: Sprayer | G18: Buah | M18: 0.007 | N18: 1
F19: Premi Extra Fooding | G19: HK | M19: 2 | N19: 1
F20: Celemek | G20: Buah | H20: 4 | I20: X | M20: =((M$14*N$14)/240*($H20/N20)) -> 0.033333333 | N20: 1
F21: Masker Chemical | G21: Buah | H21: 12 | I21: X | M21: =((M$14*N$14)/240*($H21/N21)) -> 0.1 | N21: 1
F22: Kaca mata | G22: Buah | H22: 1 | I22: X | M22: =((M$14*N$14)/240*($H22/N22)) -> 0.0083333333 | N22: 1
F23: Sarung Tangan Karet | G23: Buah | H23: 2 | I23: X | M23: =((M$14*N$14)/240*($H23/N23)) -> 0.016666667 | N23: 1
F24: Sepatu Boots | G24: Buah | H24: 1 | I24: X | M24: =((M$14*N$14)/240*($H24/N24)) -> 0.0083333333 | N24: 1
C25: Pemberantasan Lalang | F25: Upah PHL | G25: HK | M25: 1 | N25: 1
F26: Glyphosate | G26: Liter | M26: 1.08 | N26: 1
F27: Perekat | G27: Liter | M27: 0.18 | N27: 1
F28: Sprayer | G28: Buah | M28: 0.004 | N28: 1
F29: Premi Extra Fooding | G29: HK | M29: 1 | N29: 1
F30: Celemek | G30: Buah | H30: 4 | I30: X | M30: =((M$25*N$25)/240*($H30/N30)) -> 0.016666667 | N30: 1
F31: Masker | G31: Buah | H31: 12 | I31: X | M31: =((M$25*N$25)/240*($H31/N31)) -> 0.05 | N31: 1
F32: Kaca mata | G32: Buah | H32: 1 | I32: X | M32: =((M$25*N$25)/240*($H32/N32)) -> 0.0041666667 | N32: 1
F33: Sarung Tangan Karet | G33: Buah | H33: 2 | I33: X | M33: =((M$25*N$25)/240*($H33/N33)) -> 0.0083333333 | N33: 1
F34: Sepatu Boots | G34: Buah | H34: 1 | I34: X | M34: =((M$25*N$25)/240*($H34/N34)) -> 0.0041666667 | N34: 1
B35: SUB TOTAL TANAMAN KACANGAN | S35: =SUM(S6:S34) -> 0
B36: TANAMAN BELUM MENGHASILKAN
B37: PEMBUATAN PIRINGAN, PASAR RINTIS, TPH DAN TITI PASAR RINTIS
C38: Pembuatan Piringan | F38: Upah PHL | G38: HK | J38: Ha | K38: 1 | L38: 192.08 | M38: 2.5 | N38: 1 | O38: =K38*L38*M38*N38 -> 480.2 | P38: 140008 | Q38: =P38*$O38 -> 67231842 | R38: 158800.57 | S38: =R38*$O38 -> 76256036 | T38: 163305.33 | U38: =$O38*T38 -> 78419220 | V38: =W38/O38 -> 154037.97 | W38: =AVERAGEIF($P$3:$U$3,W$3,$P38:$U38) -> 73969032 | Y38: =S38/$C$1 -> 397001.43
F39: Cangkul | G39: Buah | K39: 1 | L39: 192.08 | M39: 0.01 | N39: 1 | O39: =K39*L39*M39*N39 -> 1.9208 | R39: 83568.122 | S39: =R39*$O39 -> 160517.65 | Y39: =S39/$C$1 -> 835.68122
F40: Sepatu Boots | G40: Buah | K40: 1 | L40: 192.08 | M40: 0.01 | N40: 1 | O40: =K40*L40*M40*N40 -> 1.9208 | R40: 94462.2 | S40: =R40*$O40 -> 181442.99 | Y40: =S40/$C$1 -> 944.622
...

Sheet S1 TBM 2
B1: Luas: | C1: 192.08
B2: Pekerjaan | F2: Material | H2: Rotasi APD | J2: TBM 2 | P2: 2028 | R2: 2028 | T2: 2029 | V2: Rata-rata | Y2: Rp/Ha | Z2: (%)
F3: Jenis | G3: Sat | J3: Sat | K3: Vol | M3: Norma | N3: Rotasi | O3: Jumlah Unit | P3: Rp Sat | Q3: Jumlah RP | R3: Rp Sat | S3: Jumlah RP | T3: Rp Sat | U3: Jumlah RP | V3: Rp Sat | W3: Jumlah RP | X3: Keterangan
K4: % | L4: Luas/Mtr/Pkk/Unit
B5: TANAM KACANGAN
C6: Tanam Kacangan | F6: Upah PHL | G6: HK
F7: PJ | G7: Kg
F8: CM | G8: Kg
F9: MB (Mocuna Bracteata) | G9: Kg
F10: Rizhobium | G10: Kg
F11: Rock Phosphate | G11: Kg
F12: Sepatu Boots | G12: Buah | H12: 1 | I12: X
C13: Pemeliharaan Kacangan | F13: Upah PHL | G13: HK
C14: Bongkar Tumbuhan Pengganggu | F14: Upah PHL | G14: HK
F15: Glyphosate | G15: Liter
F16: Metil Metsulfuron | G16: Kg
F17: Perekat | G17: Liter
F18: Sprayer | G18: Buah
F19: Premi Extra Fooding | G19: HK
F20: Celemek | G20: Buah | H20: 4 | I20: X
F21: Masker Chemical | G21: Buah | H21: 12 | I21: X
F22: Kaca mata | G22: Buah | H22: 1 | I22: X
F23: Sarung Tangan Karet | G23: Buah | H23: 2 | I23: X
F24: Sepatu Boots | G24: Buah | H24: 1 | I24: X
C25: Pemberantasan Lalang | F25: Upah PHL | G25: HK
F26: Glyphosate | G26: Liter
F27: Perekat | G27: Liter
F28: Sprayer | G28: Buah
F29: Premi Extra Fooding | G29: HK
F30: Celemek | G30: Buah | H30: 4 | I30: X
F31: Masker | G31: Buah | H31: 12 | I31: X
F32: Kaca mata | G32: Buah | H32: 1 | I32: X
F33: Sarung Tangan Karet | G33: Buah | H33: 2 | I33: X
F34: Sepatu Boots | G34: Buah | H34: 1 | I34: X
B35: SUB TOTAL TANAMAN KACANGAN | Q35: =SUM(Q6:Q34) -> 0 | S35: =SUM(S6:S34) -> 0
B36: TANAMAN BELUM MENGHASILKAN
B37: PEMBUATAN PIRINGAN, PASAR RINTIS, TPH DAN TITI PASAR RINTIS
C38: Pembuatan Piringan | F38: Upah PHL | G38: HK | O38: =K38*L38*M38*N38 -> 0 | P38: 151208.64 | Q38: =P38*$O38 -> 0 | R38: 163305.33 | S38: =R38*$O38 -> 0 | T38: 179635.86 | U38: =$O38*T38 -> 0 | V38: =W38/O38 -> #DIV/0! | W38: =AVERAGEIF($P$3:$U$3,W$3,$P38:$U38) -> 0
F39: Cangkul | G39: Buah
F40: Sepatu Boots | G40: Buah
...

Sheet S1 TBM 3
B1: Luas : | C1: 192.08
B2: Pekerjaan | F2: Material | H2: Rotasi APD | J2: TBM 3 | P2: 2029 | R2: 2029 | T2: 2029 | V2: Rata-rata | Y2: Rp/Ha | Z2: (%)
F3: Jenis | G3: Sat | J3: Sat | K3: Vol | M3: Norma | N3: Rotasi | O3: Jumlah Unit | P3: Rp Sat | Q3: Jumlah RP | R3: Rp Sat | S3: Jumlah RP | T3: Rp Sat | U3: Jumlah RP | V3: Rp Sat | W3: Jumlah RP | X3: Keterangan
K4: % | L4: Luas/Mtr/Pkk/Unit
B5: TANAM KACANGAN
C6: Tanam Kacangan | F6: Upah PHL | G6: HK
F7: PJ | G7: Kg
F8: CM | G8: Kg
F9: MB (Mocuna Bracteata) | G9: Kg
F10: Rizhobium | G10: Kg
F11: Rock Phosphate | G11: Kg
F12: Sepatu Boots | G12: Buah | H12: 1 | I12: X
C13: Pemeliharaan Kacangan | F13: Upah PHL | G13: HK
C14: Bongkar Tumbuhan Pengganggu | F14: Upah PHL | G14: HK
F15: Glyphosate | G15: Liter
F16: Metil Metsulfuron | G16: Kg
F17: Perekat | G17: Liter
F18: Sprayer | G18: Buah
F19: Premi Extra Fooding | G19: HK
F20: Celemek | G20: Buah | H20: 4 | I20: X
F21: Masker Chemical | G21: Buah | H21: 12 | I21: X
F22: Kaca mata | G22: Buah | H22: 1 | I22: X
F23: Sarung Tangan Karet | G23: Buah | H23: 2 | I23: X
F24: Sepatu Boots | G24: Buah | H24: 1 | I24: X
C25: Pemberantasan Lalang | F25: Upah PHL | G25: HK
F26: Glyphosate | G26: Liter
F27: Perekat | G27: Liter
F28: Sprayer | G28: Buah
F29: Premi Extra Fooding | G29: HK
F30: Celemek | G30: Buah | H30: 4 | I30: X
F31: Masker | G31: Buah | H31: 12 | I31: X
F32: Kaca mata | G32: Buah | H32: 1 | I32: X
F33: Sarung Tangan Karet | G33: Buah | H33: 2 | I33: X
F34: Sepatu Boots | G34: Buah | H34: 1 | I34: X
B35: SUB TOTAL TANAM KACANGAN | Q35: =SUM(Q6:Q34) -> 0 | R35: =SUM(R6:R34) -> 0 | S35: =SUM(S6:S34) -> 0 | T35: =SUM(T6:T34) -> 0 | U35: =SUM(U6:U34) -> 0 | V35: =SUM(V6:V34) -> 0 | W35: =SUM(W6:W34) -> 0 | X35: =SUM(X6:X34) -> 0 | ... AA35: =SUM(AA6:AA34) -> 0
B36: TANAMAN BELUM MENGHASILKAN
B37: PEMBUATAN PIRINGAN, PASAR RINTIS, TPH DAN TITI PASAR RINTIS
C38: Pembuatan Piringan | F38: Upah PHL | G38: HK | O38: =K38*L38*M38*N38 -> 0 | P38: 169122.61 | Q38: =P38*$O38 -> 0 | R38: 179635.86 | S38: =R38*$O38 -> 0 | T38: 197599.45 | U38: =$O38*T38 -> 0 | V38: =W38/O38 -> #DIV/0! | W38: =AVERAGEIF($P$3:$U$3,W$3,$P38:$U38) -> 0
F39: Cangkul | G39: Buah
F40: Sepatu Boots | G40: Buah
...
