Workbook
Name \0: #REF!
Name \a: #N/A
Name \b: #N/A
Name \g: #N/A
Name \n: #N/A
Name __kop2: #REF!
Name __s2: #REF!
Name __SKF1: #REF!
Name __SKF2: #REF!
Name _0: #REF!
Name _10_b_1: #REF!
Name _11_g_1: #REF!
Name _12_n_1: #REF!
Name _13Excel_BuiltIn_Database_1: #REF!
Name _14Excel_BuiltIn_Print_Area_1: #REF!
Name _15Excel_BuiltIn_Print_Area_31_1: '[6]Kap Rinci'!#REF!
Name _16Excel_BuiltIn_Print_Titles_1: #REF!
Name _432: 432
Name _8_0_1: #REF!
Name _8311: #REF!
Name _9_A_1: #REF!
Name _A: #REF!
Name _A_1: #REF!
Name _A_2: #REF!
Name _A_28: #REF!
Name _A_3: #REF!
Name _A_31: #REF!
Name _A_58: #REF!
Name _A_7: #REF!
Name _A_8: #REF!
Name _A_86: #REF!
Name _A_87: #REF!
Name _A_9: #REF!
Name _b: #REF!
Name _g: #REF!
Name _HOME___FR_PGSE: #REF!
Name _HOME___PG_FRSE: #REF!
Name _kop2: #REF!
Name _n: #REF!
Name _PG: [7]XXXXXXXXXXXX!#REF!
Name _Regression_Int: 1
Name _s2: #REF!
Name _SKF1: #REF!
Name _SKF2: #REF!
Name A: #N/A
Name aa: #N/A
Name are: #REF!
Name ari: #REF!
Name bln: #N/A
Name capital: #N/A
Name CC: #REF!
Name CC_31: #REF!
Name CC_7: #REF!
Name CCC: #REF!
Name Cetak: '[9]Pk prod'!#REF!
Name dea: #N/A
Name df: '[10]GRFK BJR_SBH_02'!#REF!
Name edar: #N/A
Name er: #REF!
Name Excel_BuiltIn_Database: #REF!

Sheet RKP
B1: RENCANA KERJA PROYEK ( RKP )
B2: PT. BUANA KARYA BHAKTI
B3: KEBUN SATUI TIMUR
A5: 400.8 | B5: LUAS : | D5: 400.8 Ha | E5: Tahun Tanam 2025/2026/2027/2028/202-29 | S5: 400.8
B6: No. | C6: Pekerjaan | E6: Rencana | G6: Harga Satuan (Per/Ha) | H6: Prosentase (%) | I6: TAHUN I ( 2025 ) | S6: TAHUN II ( 2026 ) | AC6: TAHUN III ( 2027 ) | AM6: TAHUN IV ( 2028 ) | AW6: TAHUN IV ( 2029 )
E7: Proyek 4 Tahun | I7: Catur Wulan 1 | K7: Catur Wulan 2 | M7: Catur Wulan 3 | O7: Jumlah Tahun I | Q7: Jumlah S/d Tahun I | S7: Catur Wulan 1 | U7: Catur Wulan 2 | W7: Catur Wulan 3 | Y7: Jumlah Tahun II | AA7: Jumlah S/d Tahun II | AC7: Catur Wulan 1 | AE7: Catur Wulan 2 | AG7: Catur Wulan 3 | AI7: Jumlah Tahun III | AK7: Jumlah S/d Tahun III | AM7: Catur Wulan 1 | AO7: Catur Wulan 2 | AQ7: Catur Wulan 3 | AS7: Jumlah Tahun IV | AU7: Jumlah S/d Tahun IV | AW7: Catur Wulan 1 | AY7: Catur Wulan 2 | BA7: Catur Wulan 3 | BC7: Jumlah Tahun IV | BE7: Jumlah S/d Tahun IV
E8: Volume | F8: Biaya | I8: Fisik | J8: Biaya | K8: Fisik | L8: Biaya | M8: Fisik | N8: Biaya | O8: Fisik | P8: Biaya | Q8: Fisik | R8: Biaya | S8: Fisik | T8: Biaya | U8: Fisik | V8: Biaya | W8: Fisik | X8: Biaya | Y8: Fisik | Z8: Biaya | AA8: Fisik | AB8: Biaya | AC8: Fisik | AD8: Biaya | AE8: Fisik | AF8: Biaya | AG8: Fisik | AH8: Biaya | AI8: Fisik | AJ8: Biaya | AK8: Fisik | AL8: Biaya | AM8: Fisik | AN8: Biaya | AO8: Fisik | AP8: Biaya | AQ8: Fisik | AR8: Biaya | AS8: Fisik | AT8: Biaya | AU8: Fisik | AV8: Biaya | AW8: Fisik | AX8: Biaya | AY8: Fisik | AZ8: Biaya | BA8: Fisik | BB8: Biaya | BC8: Fisik | BD8: Biaya | BE8: Fisik | BF8: Biaya
E9: ( Ha ) | F9: ( Rp ) | I9: ( Ha ) | J9: ( Rp ) | K9: ( Ha ) | L9: ( Rp ) | M9: ( Ha ) | N9: ( Rp ) | O9: ( Ha ) | P9: ( Rp ) | Q9: ( Ha ) | R9: ( Rp ) | S9: ( Ha ) | T9: ( Rp ) | U9: ( Ha ) | V9: ( Rp ) | W9: ( Ha ) | X9: ( Rp ) | Y9: ( Ha ) | Z9: ( Rp ) | AA9: ( Ha ) | AB9: ( Rp ) | AC9: ( Ha ) | AD9: ( Rp ) | AE9: ( Ha ) | AF9: ( Rp ) | AG9: ( Ha ) | AH9: ( Rp ) | AI9: ( Ha ) | AJ9: ( Rp ) | AK9: ( Ha ) | AL9: ( Rp ) | AM9: ( Ha ) | AN9: ( Rp ) | AO9: ( Ha ) | AP9: ( Rp ) | AQ9: ( Ha ) | AR9: ( Rp ) | AS9: ( Ha ) | AT9: ( Rp ) | AU9: ( Ha ) | AV9: ( Rp ) | AW9: ( Ha ) | AX9: ( Rp ) | AY9: ( Ha ) | AZ9: ( Rp ) | BA9: ( Ha ) | BB9: ( Rp ) | BC9: ( Ha ) | BD9: ( Rp ) | BE9: ( Ha ) | BF9: ( Rp )
B10: 1 | C10: Perizinan & lainnya | E10: =$A$5 -> 400.8 | F10: ='[1]By Pra Operasional'!Q16 -> 8.3963675e+09 | G10: ='[1]By Pra Operasional'!R16 -> 20949021 | H10: =G10/$G$16*100 -> 17.38031 | I10: 0 | J10: =I10*$G10 -> 0 | K10: 0 | L10: =K10*$G10 -> 0 | M10: 300 | N10: =M10*G10 -> 6.2847062e+09 | O10: =I10+K10+M10 -> 300 | P10: =J10+L10+N10 -> 6.2847062e+09 | Q10: ='[1]By Pra Operasional'!K16 -> 333.4 | R10: ='[1]By Pra Operasional'!L16 -> 6.9883554e+09 | S10: ='[1]By Pra Operasional'!N16 -> 67.4 | T10: ='[1]By Pra Operasional'!O16 -> 1.4080122e+09 | U10: 0 | V10: =U10*$G10 -> 0 | W10: 0 | X10: =W10*$G10 -> 0 | Y10: =S10+U10+W10 -> 67.4 | Z10: =T10+V10+X10 -> 1.4080122e+09 | AA10: =Q10+Y10 -> 400.8 | AB10: =Z10+R10 -> 8.3963675e+09 | AC10: 0 | AD10: =AC10*$G10 -> 0 | AE10: 0 | AF10: =AE10*$G10 -> 0 | AG10: 0 | AH10: =AG10*$G10 -> 0 | AK10: =AA10+AI10 -> 400.8 | AL10: =AJ10+AB10 -> 8.3963675e+09 | AM10: 0 | AN10: =AM10*$G10 -> 0 | AO10: 0 | AP10: =AO10*$G10 -> 0 | AQ10: 0 | AR10: =AQ10*$G10 -> 0 | AS10: =AM10+AO10+AQ10 -> 0 | AT10: =AN10+AP10+AR10 -> 0 | AU10: =AK10+AS10 -> 400.8 | AV10: =AT10+AL10 -> 8.3963675e+09 | AW10: 0 | AX10: =AW10*$G10 -> 0 | AY10: 0 | AZ10: =AY10*$G10 -> 0 | BA10: 0 | BB10: =BA10*$G10 -> 0 | BC10: =AW10+AY10+BA10 -> 0 | BD10: =AX10+AZ10+BB10 -> 0 | BE10: =AU10+BC10 -> 400.8 | BF10: =BD10+AV10 -> 8.3963675e+09
B11: =B10+1 -> 2 | C11: Biaya Non Tanaman | E11: =$A$5 -> 400.8 | F11: ='[1]By Non Tanaman'!H21+'[1]By Non Tanaman'!I21 -> 1206950000 | G11: ='[1]By Non Tanaman'!J21 -> 3011352.3 | H11: =G11/$G$16*100 -> 2.498362 | O11: =I11+K11+M11 -> 0 | P11: =J11+L11+N11 -> 0 | U11: 200 | V11: ='[1]By Non Tanaman'!H21 -> 533950000 | Y11: =S11+U11+W11 -> 200 | Z11: =T11+V11+X11 -> 533950000 | AA11: =Q11+Y11 -> 200 | AB11: =Z11+R11 -> 533950000 | AC11: 200.8 | AD11: ='[1]By Non Tanaman'!I21 -> 673000000 | AI11: =AC11+AE11+AG11 -> 200.8 | AJ11: =AD11+AF11+AH11 -> 673000000 | AK11: =AA11+AI11 -> 400.8 | AL11: =AJ11+AB11 -> 1206950000 | AU11: =AK11+AS11 -> 400.8 | AV11: =AT11+AL11 -> 1206950000 | BE11: =AU11+BC11 -> 400.8 | BF11: =BD11+AV11 -> 1206950000
B12: =B11+1 -> 3 | C12: Land Clearing & TB | E12: =$A$5 -> 400.8 | F12: ='REKAP BIAYA'!F46 -> 1.9876409e+10 | G12: ='REKAP BIAYA'!F47 -> 49591840 | H12: =G12/$G$16*100 -> 41.143764 | I12: 0 | J12: =I12*$G12 -> 0 | K12: 0 | L12: =K12*$G12 -> 0 | M12: 0 | N12: =M12*$G12 -> 0 | O12: =I12+K12+M12 -> 0 | P12: =J12+L12+N12 -> 0 | Q12: =O12 -> 0 | R12: =P12 -> 0 | S12: 200 | T12: =S12*$G12 -> 9.918368e+09 | U12: 200.8 | V12: =U12*$G12 -> 9.9580415e+09 | W12: 0 | X12: =W12*$G12 -> 0 | Y12: =S12+U12+W12 -> 400.8 | Z12: =T12+V12+X12 -> 1.9876409e+10 | AA12: =Q12+Y12 -> 400.8 | AB12: =Z12+R12 -> 1.9876409e+10 | AC12: 0 | AD12: =AC12*$G12 -> 0 | AE12: 0 | AF12: =AE12*$G12 -> 0 | AG12: 0 | AH12: =AG12*$G12 -> 0 | AK12: =AA12+AI12 -> 400.8 | AL12: =AJ12+AB12 -> 1.9876409e+10 | AM12: 0 | AN12: =AM12*$G12 -> 0 | AO12: 0 | AP12: =AO12*$G12 -> 0 | AQ12: 0 | AR12: =AQ12*$G12 -> 0 | AS12: =AM12+AO12+AQ12 -> 0 | AT12: =AN12+AP12+AR12 -> 0 | AU12: =AK12+AS12 -> 400.8 | AV12: =AT12+AL12 -> 1.9876409e+10 | AW12: 0 | AX12: =AW12*$G12 -> 0 | AY12: 0 | AZ12: =AY12*$G12 -> 0 | BA12: 0 | BB12: =BA12*$G12 -> 0 | BC12: =AW12+AY12+BA12 -> 0 | BD12: =AX12+AZ12+BB12 -> 0 | BE12: =AU12+BC12 -> 400.8 | BF12: =BD12+AV12 -> 1.9876409e+10
B13: =B12+1 -> 4 | C13: Pemeliharaan TBM-1 | E13: =$A$5 -> 400.8 | F13: ='REKAP BIAYA'!N45 -> 5.7674185e+09 | G13: ='REKAP BIAYA'!N46 -> 14389767 | H13: =G13/$G$16*100 -> 11.938439 | I13: 0 | J13: =I13*$G13 -> 0 | K13: 0 | L13: =K13*$G13 -> 0 | M13: 0 | N13: =M13*$G13 -> 0 | O13: =I13+K13+M13 -> 0 | P13: =J13+L13+N13 -> 0 | Q13: =O13 -> 0 | R13: =P13 -> 0 | S13: =Q12 -> 0 | T13: =S13*$G13 -> 0 | U13: 0 | V13: =U13*$G13 -> 0 | W13: 0 | X13: =W13*$G13 -> 0 | Y13: =S13+U13+W13 -> 0 | Z13: =T13+V13+X13 -> 0 | AA13: =Q13+Y13 -> 0 | AB13: =Z13+R13 -> 0 | AC13: =E13/3 -> 133.6 | AD13: =AC13*$G13 -> 1.9224728e+09 | AE13: =AC13 -> 133.6 | AF13: =AE13*$G13 -> 1.9224728e+09 | AG13: =AE13 -> 133.6 | AH13: =AG13*$G13 -> 1.9224728e+09 | AI13: =AC13+AE13+AG13 -> 400.8 | AJ13: =AD13+AF13+AH13 -> 5.7674185e+09 | AK13: =AA13+AI13 -> 400.8 | AL13: =AJ13+AB13 -> 5.7674185e+09 | AM13: 0 | AN13: =AM13*$G13 -> 0 | AO13: 0 | AP13: =AO13*$G13 -> 0 | AQ13: 0 | AR13: =AQ13*$G13 -> 0 | AS13: =AM13+AO13+AQ13 -> 0 | AT13: =AN13+AP13+AR13 -> 0 | AU13: =AK13+AS13 -> 400.8 | AV13: =AT13+AL13 -> 5.7674185e+09 | AW13: 0 | AX13: =AW13*$G13 -> 0 | AY13: 0 | AZ13: =AY13*$G13 -> 0 | BA13: 0 | BB13: =BA13*$G13 -> 0 | BC13: =AW13+AY13+BA13 -> 0 | BD13: =AX13+AZ13+BB13 -> 0 | BE13: =AU13+BC13 -> 400.8 | BF13: =BD13+AV13 -> 5.7674185e+09
B14: =B13+1 -> 5 | C14: Pemeliharaan TBM-2 | E14: =$A$5 -> 400.8 | F14: ='REKAP BIAYA'!V44 -> 5.553982e+09 | G14: ='REKAP BIAYA'!V45 -> 13857240 | H14: =G14/$G$16*100 -> 11.49663 | I14: 0 | J14: =I14*$G14 -> 0 | K14: 0 | L14: =K14*$G14 -> 0 | M14: =K13 -> 0 | N14: =M14*$G14 -> 0 | O14: =I14+K14+M14 -> 0 | P14: =J14+L14+N14 -> 0 | Q14: =O14 -> 0 | R14: =P14 -> 0 | S14: =M13/3 -> 0 | T14: =S14*$G14 -> 0 | U14: 0 | V14: =U14*$G14 -> 0 | W14: =U14 -> 0 | X14: =W14*$G14 -> 0 | Y14: =S14+U14+W14 -> 0 | Z14: =T14+V14+X14 -> 0 | AA14: =Y14+Q14 -> 0 | AB14: =Z14+R14 -> 0 | AC14: =AA13 -> 0 | AD14: =AC14*$G14 -> 0 | AE14: 0 | AF14: =AE14*$G14 -> 0 | AG14: 0 | AH14: =AG14*$G14 -> 0 | AI14: =Y13 -> 0 | AJ14: =AD14+AF14+AH14 -> 0 | AK14: =AI14+AA14 -> 0 | AL14: =AJ14+AB14 -> 0 | AM14: =E14/3 -> 133.6 | AN14: =AM14*$G14 -> 1.8513273e+09 | AO14: =AM14 -> 133.6 | AP14: =AO14*$G14 -> 1.8513273e+09 | AQ14: =AO14 -> 133.6 | AR14: =AQ14*$G14 -> 1.8513273e+09 | AS14: =AM14+AO14+AQ14 -> 400.8 | AT14: =AN14+AP14+AR14 -> 5.553982e+09 | AU14: =AS14+AK14 -> 400.8 | AV14: =AT14+AL14 -> 5.553982e+09 | AW14: =O14/3 -> 0 | AX14: =AW14*$G14 -> 0 | AY14: =AW14 -> 0 | AZ14: =AY14*$G14 -> 0 | BA14: =AY14 -> 0 | BB14: =BA14*$G14 -> 0 | BC14: =AW14+AY14+BA14 -> 0 | BD14: =AX14+AZ14+BB14 -> 0 | BE14: =BC14+AU14 -> 400.8 | BF14: =BD14+AV14 -> 5.553982e+09
B15: =B14+1 -> 6 | C15: Pemeliharaan TBM-3 | E15: =$A$5 -> 400.8 | F15: ='REKAP BIAYA'!AD46 -> 7.508525e+09 | G15: ='REKAP BIAYA'!AD47 -> 18733845 | H15: =G15/$G$16*100 -> 15.542494 | I15: 0 | J15: =I15*$G15 -> 0 | K15: 0 | L15: =K15*$G15 -> 0 | M15: 0 | N15: =M15*$G15 -> 0 | O15: =I15+K15+M15 -> 0 | P15: =J15+L15+N15 -> 0 | Q15: =O15 -> 0 | R15: =P15 -> 0 | S15: 0 | T15: =S15*$G15 -> 0 | U15: 0 | V15: =U15*$G15 -> 0 | W15: 0 | X15: =W15*$G15 -> 0 | Y15: =S15+U15+W15 -> 0 | Z15: =T15+V15+X15 -> 0 | AA15: =Y15+Q15 -> 0 | AB15: =Z15+R15 -> 0 | AC15: =S14 -> 0 | AD15: =AC15*$G15 -> 0 | AE15: =AC15 -> 0 | AF15: =AE15*$G15 -> 0 | AG15: =AE15 -> 0 | AH15: =AG15*$G15 -> 0 | AI15: =AC15+AE15+AG15 -> 0 | AJ15: =AD15+AF15+AH15 -> 0 | AK15: =AI15+AA15 -> 0 | AL15: =AJ15+AB15 -> 0 | AM15: =AI14 -> 0 | AN15: =AM15*$G15 -> 0 | AO15: 0 | AP15: =AO15*$G15 -> 0 | AQ15: 0 | AR15: =AQ15*$G15 -> 0 | AS15: =AM15+AO15+AQ15 -> 0 | AT15: =AN15+AP15+AR15 -> 0 | AU15: =AS15+AK15 -> 0 | AV15: =AT15+AL15 -> 0 | AW15: =E15/3 -> 133.6 | AX15: =AW15*$G15 -> 2.5028417e+09 | AY15: =AW15 -> 133.6 | AZ15: =AY15*$G15 -> 2.5028417e+09 | BA15: =AY15 -> 133.6 | BB15: =BA15*$G15 -> 2.5028417e+09 | BC15: =AW15+AY15+BA15 -> 400.8 | BD15: =AX15+AZ15+BB15 -> 7.508525e+09 | BE15: =BC15+AU15 -> 400.8 | BF15: =BD15+AV15 -> 7.508525e+09
B16: GRAND TOTAL BIAYA | E16: =$A$5 -> 400.8 | F16: =SUM(F10:F15) -> 4.8309652e+10 | G16: =F16/E16 -> 1.2053307e+08 | H16: =SUM(H10:H15) -> 100 | I16: =SUM(I10:I15) -> 0 | J16: =SUM(J10:J15) -> 0 | K16: =SUM(K10:K15) -> 0 | L16: =SUM(L10:L15) -> 0 | M16: =SUM(M10:M15) -> 300 | N16: =SUM(N10:N15) -> 6.2847062e+09 | O16: =SUM(O10:O15) -> 300 | ... BD16: =SUM(BD10:BD15) -> 7.508525e+09 | BE16: 400.8 | BF16: =SUM(BF10:BF15) -> 4.8309652e+10
BC19: Satui, 30 September 2025
Y20: Diketahui Oleh ; | AI20: Disetujui Oleh ; | AS20: Diperiksa Oleh ; | BC20: Disusun Oleh ;
Y22: Imam Satoto Yudiono | AI22: Hairul Amri | AS22: A r i f | BC22: Joko Purwoto
Y23: Direktur Utama | AI23: Direktur | AS23: Pjs. GM Agronomy | BC23: Manager Kebun Inti BKB

Sheet REKAP BIAYA
A2: 400.8 | B2: 400.8
A3: 400.8 | B3: REKAPITULASI RENCANA BIAYA LAND CLEARING DAN TANAM BARU AFD9 - SATUI TIMUR | J3: REKAPITULASI RENCANA BIAYA TBM 1 AFD9 - SATUI TIMUR | R3: REKAPITULASI RENCANA BIAYA TBM 2 AFD9 - SATUI TIMUR | Z3: REKAPITULASI RENCANA BIAYA TBM 3 AFD9 - SATUI TIMUR
B4: TB | J4: TBM 1 | R4: TBM 2 | Z4: TBM 3
B5: No | C5: Pekerjaan | E5: Jumlah Rp | F5: Total Rp | G5: Rp/Ha | H5: Persentase (%) | J5: No | K5: Pekerjaan | M5: Jumlah Rp | N5: Total Rp | O5: Rp/Ha | P5: Persentase (%) | R5: No | S5: Pekerjaan | U5: Jumlah Rp | V5: Total Rp | W5: Rp/Ha | X5: Persentase (%) | Z5: No | AA5: Pekerjaan | AC5: Jumlah Rp | AD5: Total Rp | AE5: Rp/Ha | AF5: Persentase (%)
B6: 1 | C6: Imas Tumbang Perun | D6: Identifikasi Blok | E6: ='SI TB LC'!Q7 -> 29881347 | F6: =SUM(E6:E11) -> 6.6739411e+09 | G6: =F6/A2 -> 16651550 | H6: =F6/$F$46*100 -> 33.577197 | J6: 1 | K6: Tanam Kacangan | L6: Tanam kacangan | M6: =SUM('S1 TBM 1'!S6:S12) -> 0 | N6: =SUM(M6:M9) -> 2.5903448e+08 | O6: =N6/A2 -> 646293.62 | P6: =N6/N45*100 -> 4.4913419 | R6: 1 | S6: Pembuatan Piringan,Pasar Rintis,Dan Titi Pasar Rintis | T6: Pembuatan Piringan | U6: =SUM('S1 TBM 2'!Q38:Q40) -> 0 | V6: =SUM(U6:U10) -> 67591255 | W6: =V6/A3 -> 168640.86 | X6: =V6/V44*100 -> 1.2169873 | Z6: 1 | AA6: Pembuatan Piringan,Pasar Rintis,Dan Titi Pasar Rintis | AB6: Pembuatan Piringan | AC6: =SUM('S1 TBM 3'!Q38:Q40) -> 0 | AD6: =SUM(AC6:AC10) -> 71300386 | AE6: =AD6/A3 -> 177895.18 | AF6: =AD6/AD46*100 -> 0.94959245
D7: Imas | E7: =SUM('SI TB LC'!Q13) -> 2.9881347e+08 | L7: Pemeliharaan Kacangan | M7: ='S1 TBM 1'!S13 -> 1.7928808e+08 | T7: Pembuatan Pasar Rintis | U7: =SUM('S1 TBM 2'!Q41:Q43) -> 30417544 | AB7: Pembuatan Pasar Rintis | AC7: =SUM('S1 TBM 3'!Q41:Q43) -> 0
D8: Perun Mekanis | E8: =SUM('SI TB LC'!Q20:Q23) -> 6.1273536e+09 | I8: 3018.49 | L8: Bongkar tanaman pengganggu | M8: =SUM('S1 TBM 1'!S14:S24) -> 38170998 | T8: Pembuatan TPH | U8: =SUM('S1 TBM 2'!Q44:Q46) -> 0 | AB8: Pembuatan TPH | AC8: =SUM('S1 TBM 3'!Q44:Q46) -> 9179042.6
D9: Lubang Tanam Mekanis Auger | E9: =SUM('SI TB LC'!Q43:Q46) -> 0 | L9: Pemberantasan lalang | M9: =SUM('S1 TBM 1'!S25:S34) -> 41575399 | T9: Pembuatan Titi Pasar Rintis | U9: =SUM('S1 TBM 2'!Q47:Q49) -> 32375053 | AB9: Pembuatan Titi Pasar Rintis | AC9: =SUM('S1 TBM 3'!Q48:Q50) -> 56997700
D10: Pemberantasan Lalang & Gulma | E10: =SUM('SI TB LC'!Q47:Q60) -> 2.1789271e+08 | J10: =J6+1 -> 2 | K10: Pembuatan Piringan & Titi Pasar Rintis | L10: Pembuatan Piringan | M10: =SUM('S1 TBM 1'!S38:S40) -> 1.4997078e+08 | N10: =SUM(M10:M11) -> 2.1988472e+08 | O10: =N10/A3 -> 548614.56 | P10: =N10/N45*100 -> 3.8125327 | T10: Pembuatan Pasar Tengah | U10: =SUM('S1 TBM 2'!Q50:Q52) -> 4798658.8 | AB10: Pembuatan Pasar Tengah | AC10: =SUM('S1 TBM 3'!Q51:Q53) -> 5123644.2
L11: Pembuatan Pasar Rintis & Titi Pasar Rintis | M11: =SUM('S1 TBM 1'!S42:S50) -> 69913938 | R11: 2 | S11: Pemeliharaan Piringan Gawangan Manual & Chemist | T11: Pemeliharaan Piringan Manual | U11: =SUM('S1 TBM 2'!Q59:Q65) -> 2.870851e+08 | V11: =SUM(U11:U14) -> 1.0937067e+09 | W11: =V11/$A$3 -> 2728809 | X11: =V11/V44*100 -> 19.692298 | Z11: 2 | AA11: Pemeliharaan Piringan Gawangan Manual & Chemist | AB11: Pemeliharaan Piringan Manual | AC11: =SUM('S1 TBM 3'!Q60:Q62) -> 1.7016686e+08 | AD11: =SUM(AC11:AC15) -> 8.6004711e+08 | AE11: =AD11/$A$3 -> 2145826.1 | AF11: =AD11/AD46*100 -> 11.454275
B12: 2 | C12: Pembuatan Sarana & Prasarana | D12: Pembuatan Jalan | E12: =SUM('SI TB LC'!Q97) -> 7.4545357e+08 | F12: =SUM(E12:E17) -> 7.7890708e+09 | G12: =F12/B2 -> 19433809 | H12: =F12/F46*100 -> 39.187514 | J12: =J10+1 -> 3 | K12: Pemeliharaan Piringan Gawangan Manual & Chemist | L12: Pemeliharaan Piringan Manual | M12: =SUM('S1 TBM 1'!S61:S63) -> 1.500471e+08 | N12: =SUM(M12:M15) -> 8.7051522e+08 | O12: =N12/A3 -> 2171944.2 | P12: =N12/N45*100 -> 15.093672 | T12: Pemeliharaan Piringan /Pasar Rintis(Chemist) | U12: =SUM('S1 TBM 2'!Q71:Q82) -> 1.6430654e+08 | AB12: Pemeliharaan Piringan /Pasar Rintis(Chemist) | AC12: =SUM('S1 TBM 3'!Q73:Q84) -> 1.8966026e+08
D13: Pembuatan Jembatan | E13: =SUM('SI TB LC'!$Q$125) -> 1.3877226e+09 | L13: Pemeliharaan Piringan /Pasar Rintis(Chemist) | M13: =SUM('S1 TBM 1'!S73:S83) -> 56233730 | T13: Pemeliharaan Gawangan Manual | U13: =SUM('S1 TBM 2'!Q106:Q108) -> 2.5580211e+08 | AB13: Pemeliharaan TPH & Pasar Rintis Manual | AC13: =SUM('S1 TBM 3'!Q64:Q69) -> 1.6010489e+08
D14: Pembuatan Parit | E14: =SUM('SI TB LC'!$Q$135) -> 4.7375096e+09 | L14: Pemeliharaan Gawangan Manual | M14: =SUM('S1 TBM 1'!S107:S109) -> 2.9996874e+08 | T14: Pemeliharaan Gawangan Chemist | U14: =SUM('S1 TBM 2'!Q126:Q137) -> 3.8651292e+08 | AB14: Pemeliharaan Gawangan Manual | AC14: =SUM('S1 TBM 3'!Q108:Q110) -> 1.3607066e+08
D15: Pemeliharaan Titi Pasar Rintis | E15: =SUM('SI TB LC'!Q169:Q173) -> 252504000 | L15: Pemeliharaan Gawangan Chemist | M15: =SUM('S1 TBM 1'!S127:S138) -> 3.6426565e+08 | R15: 3 | S15: Pemberantasan Lalang | T15: Spot Lalang | U15: =SUM('S1 TBM 2'!Q150:Q159) -> 25214646 | V15: =SUM(U15:U17) -> 1.0678259e+08 | W15: =V15/$A$3 -> 266423.62 | X15: =V15/V44*100 -> 1.9226312 | AB15: Pemeliharaan Gawangan Chemist | AC15: =SUM('S1 TBM 3'!Q128:Q139) -> 2.0404444e+08
D16: Pengawetan Tanah | E16: =SUM('SI TB LC'!$Q$159) -> 2.6893213e+08 | J16: 4 | K16: Pemberantasan Lalang | L16: Sheet Lalang | M16: =SUM('S1 TBM 1'!S141:S150) -> 31677097 | N16: =SUM(M16:M19) -> 1.9478603e+08 | O16: =N16/A3 -> 485993.08 | P16: =N16/N45*100 -> 3.377352 | T16: Wipping | U16: =SUM('S1 TBM 2'!Q160:Q168) -> 47236405
D17: Pemeliharaan Pintu Air | E17: =SUM('SI TB LC'!$Q$148) -> 3.969489e+08 | L17: Spot Lalang | M17: =SUM('S1 TBM 1'!S151:S160) -> 23757822 | T17: Transport Air | U17: =SUM('S1 TBM 2'!Q171) -> 34331537 | Z17: 3 | AA17: Pemberantasan Lalang | AB17: Wipping | AC17: =SUM('S1 TBM 3'!Q162:Q170) -> 50022313 | AD17: =SUM(AC17:AC18) -> 1.0357951e+08 | AE17: =AD17/$A$3 -> 258431.91 | AF17: =AD17/AD46*100 -> 1.3794921
B18: 3 | C18: Tanam Kacangan & Pemeliharaan | D18: Penanaman Kacangan | E18: =SUM('SI TB LC'!Q179:Q190) -> 87302717 | F18: =SUM(E18:E27) -> 6.6925975e+08 | G18: =F18/A3 -> 1669809.7 | H18: =F18/F46*100 -> 3.3671059 | L18: Wipping | M18: =SUM('S1 TBM 1'!S161:S170) -> 24034477 | R18: 4 | S18: Pemeliharaan Pokok | T18: Kastrasi | U18: =SUM('S1 TBM 2'!Q179:Q183) -> 3.8374953e+08 | V18: =SUM(U18:U20) -> 5.363867e+08 | W18: =V18/$A$3 -> 1338290.2 | X18: =V18/V44*100 -> 9.6576961 | AB18: Transport Air | AC18: =SUM('S1 TBM 3'!Q173) -> 53557198
D19: Pembuatan Bedengan | E19: =SUM('SI TB LC'!Q191:Q192) -> 2382841.1 | L19: Transport Air | M19: =SUM('S1 TBM 1'!S171:S173) -> 1.1531663e+08 | T19: Penyisipan | U19: =SUM('S1 TBM 2'!Q186:Q189) -> 88722568 | Z19: 4 | AA19: Pemeliharaan Pokok | AB19: Sanitasi & Kastrasi | AC19: =SUM('S1 TBM 3'!Q181+'S1 TBM 3'!Q187) -> 68110876 | AD19: =SUM(AC19:AC22) -> 99098100 | AE19: =AD19/$A$3 -> 247250.75 | AF19: =AD19/AD46*100 -> 1.3198078
D20: Perakitan Instalasi Air | E20: =SUM('SI TB LC'!Q203:Q204) -> 2855830 | J20: 5 | K20: Pemeliharaan Pokok | L20: Sanitasi & Kastrasi | M20: =SUM('S1 TBM 1'!S177:S185) -> 1.2011774e+08 | N20: =SUM(M20:M22) -> 3.4942603e+08 | O20: =N20/A3 -> 871821.43 | P20: =N20/N45*100 -> 6.058621 | T20: Survey dan Sensus | U20: =SUM('S1 TBM 2'!Q194:Q195) -> 63914609 | AB20: Penyisipan & Konsolidasi | AC20: ='S1 TBM 3'!Q194+'S1 TBM 3'!Q195+'S1 TBM 3'!Q196 -> 3395078.6
D21: Pemeliharaan Weeding Atas | E21: =SUM('SI TB LC'!Q193) -> 598224.58 | L21: Penyisipan & Konsolidasi | M21: =SUM('S1 TBM 1'!S187:S193) -> 2.051486e+08 | R21: 5 | S21: Pemeliharaan Prasarana | T21: Jalan Utama / Jalan Akses | U21: =SUM('S1 TBM 2'!Q200:Q205) -> 63034281 | V21: =SUM(U21:U29) -> 1.1011197e+09 | W21: =V21/$A$3 -> 2747304.7 | X21: =V21/V44*100 -> 19.825771 | AB21: Survey dan Sensus | AC21: =SUM('S1 TBM 3'!Q197:Q198) -> 27592146
D22: PHPT Insek | E22: =SUM('SI TB LC'!Q194:Q197) -> 639515.3 | L22: Survey dan Sensus | M22: =SUM('S1 TBM 1'!S195:S196) -> 24159686 | T22: Jalan Produksi | U22: =SUM('S1 TBM 2'!Q206:Q211) -> 1.8720506e+08
D23: PHPT Fungi | E23: =SUM('SI TB LC'!Q198:Q200) -> 740821.37 | J23: 6 | K23: Pemeliharaan Prasarana | L23: Jalan Utama / Jalan Akses | M23: =SUM('S1 TBM 1'!S201:S206) -> 19474239 | N23: =SUM(M23:M31) -> 1.1590544e+09 | O23: =N23/A3 -> 2891852.4 | P23: =N23/N45*100 -> 20.09659 | T23: Jalan Koleksi | U23: =SUM('S1 TBM 2'!Q212:Q217) -> 6.2395447e+08 | Z23: 5 | AA23: Pemeliharaan Prasarana | AB23: Jalan Utama / Jalan Akses | AC23: =SUM('S1 TBM 3'!Q203:Q208) -> 87551360 | AD23: =SUM(AC23:AC31) -> 2.4906888e+09 | AE23: =AD23/$A$3 -> 6214293.4 | AF23: =AD23/AD46*100 -> 33.171479
D24: Penyiraman Bibit | E24: =SUM('SI TB LC'!Q202) -> 598224.58 | L24: Jalan Produksi | M24: =SUM('S1 TBM 1'!S207:S212) -> 1.6915714e+08 | T24: Jalan Pringgan / Ring | U24: =SUM('S1 TBM 2'!Q218:Q223) -> 2.2692593e+08 | AB24: Jalan Produksi | AC24: =SUM('S1 TBM 3'!Q209:Q214) -> 2.1124741e+08
D25: Pemeliharaan Semai Kacangan | E25: =SUM('SI TB LC'!Q205) -> 1.7928808e+08 | L25: Jalan Koleksi | M25: =SUM('S1 TBM 1'!S213:S218) -> 4.6420623e+08 | T25: Jalan Liung | U25: =SUM('S1 TBM 2'!Q224:Q228) -> 0 | AB25: Jalan Koleksi | AC25: =SUM('S1 TBM 3'!Q215:Q220) -> 7.0408762e+08
D26: Tanam Kacangan | E26: =SUM('SI TB LC'!Q227:Q233) -> 3.3509079e+08 | L26: Jalan Pringgan / Ring | M26: =SUM('S1 TBM 1'!S219:S224) -> 3.5633909e+08 | T26: Jembatan Permanen | U26: =SUM('S1 TBM 2'!Q238:Q249) -> 0 | AB26: Jalan Pringgan / Ring | AC26: =SUM('S1 TBM 3'!Q221:Q226) -> 3.9409342e+08
D27: Pemeliharaan Kacangan | E27: ='SI TB LC'!Q234 -> 59762695 | L27: Jalan Liung | M27: =SUM('S1 TBM 1'!S225:S229) -> 0 | T27: Gorong-gorong 40 cm | U27: =SUM('S1 TBM 2'!Q253:Q255) -> 0 | AB27: Jalan Liung | AC27: =SUM('S1 TBM 3'!Q227:Q231) -> 0
B28: 4 | C28: Pemupukkan Kacangan | D28: Pemupukkan NPK Granule & RP | E28: =SUM('SI TB LC'!Q238:Q247) -> 49568780 | F28: =SUM(E28:E28) -> 49568780 | G28: =F28/A3 -> 123674.6 | H28: =F28/F46*100 -> 0.24938498 | L28: Jembatan Permanen | M28: =SUM('S1 TBM 1'!S238:S250) -> 1.4987773e+08 | T28: Gorong-gorong 60 CM | U28: =SUM('S1 TBM 2'!Q256:Q258) -> 0 | AB28: Jembatan Permanen | AC28: =SUM('S1 TBM 3'!Q234:Q246) -> 8.0934592e+08
B29: 5 | C29: Angkutan Pupuk | D29: Angkutan Pupuk Intern | E29: =SUM('SI TB LC'!Q252:Q254) -> 33880.626 | F29: =SUM(E29:E30) -> 99154.914 | G29: =F29/A3 -> 247.3925 | H29: =F29/F46*100 -> 0.00049885727 | L29: Gorong-gorong 40 cm | M29: =SUM('S1 TBM 1'!S254:S256) -> 0 | T29: Gorong-gorong 80 CM | U29: =SUM('S1 TBM 2'!Q259:Q261) -> 0 | AB29: Parit 2x2 | AC29: =SUM('S1 TBM 3'!Q263:Q264) -> 2.6034575e+08
D30: Angkutan Pupuk Ekstern | E30: =SUM('SI TB LC'!Q255:Q256) -> 65274.288 | L30: Gorong-gorong 60 CM | M30: =SUM('S1 TBM 1'!S257:S259) -> 0 | R30: 6 | S30: Pengawetan Tanah | T30: Tapak Kuda | U30: =SUM('S1 TBM 2'!Q286) -> 0 | V30: =SUM(U30:U31) -> 4243151.3 | W30: =V30/$A$3 -> 10586.705 | X30: =V30/V44*100 -> 0.076398363 | AB30: Parit 1x1 | AC30: =SUM('S1 TBM 3'!Q265:Q266) -> 0
B31: 6 | C31: Tanam Pokok Sawit | D31: Memancang | E31: =SUM('SI TB LC'!$Q$260:$Q$261) -> 1.853061e+08 | F31: =SUM(E31:E34) -> 4.0175879e+09 | G31: =F31/A3 -> 10023922 | H31: =F31/F46*100 -> 20.212846 | L31: Gorong-gorong 80 CM | M31: =SUM('S1 TBM 1'!S260:S262) -> 0 | T31: Tapak Timbun | U31: =SUM('S1 TBM 2'!Q288) -> 4243151.3 | AB31: Pintu Air | AC31: =SUM('S1 TBM 3'!Q267:Q269) -> 24017308
D32: Perbaikkan Struktur Tanah Titik Tanam | E32: =SUM('SI TB LC'!$Q$262:$Q$263) -> 0 | J32: 7 | K32: Pengawetan Tanah | L32: Tapak Kuda | M32: =SUM('S1 TBM 1'!S287:S288) -> 0 | N32: =SUM(M32:M33) -> 5.6973769e+08 | O32: =N32/A3 -> 1421501.2 | P32: =N32/N45*100 -> 9.8785564 | R32: 7 | S32: Pengendalian Hama dan Penyakit | T32: Hama Tikus | U32: =SUM('S1 TBM 2'!Q296:Q297) -> 35636917 | V32: =SUM(U32:U34) -> 1.0162715e+08 | W32: =V32/$A$3 -> 253560.74 | X32: =V32/V44*100 -> 1.8298069 | Z32: 6 | AA32: Pengawetan Tanah | AB32: Tapak Kuda | AC32: =SUM('S1 TBM 3'!Q278) -> 0 | AD32: =SUM(AC32:AC33) -> 3.0969101e+08 | AE32: =AD32/$A$3 -> 772682.16 | AF32: =AD32/AD46*100 -> 4.1245253
D33: Pupuk Lubang Tanam | E33: =SUM('SI TB LC'!$Q$264:$Q$271) -> 3.8065478e+08 | L33: Tapak Timbun | M33: =SUM('S1 TBM 1'!S289:S290) -> 5.6973769e+08 | T33: Hama Ulat Api | U33: =SUM('S1 TBM 2'!Q301:Q310) -> 20667452 | AB33: Tapak Timbun | AC33: =SUM('S1 TBM 3'!Q280) -> 3.0969101e+08
D34: Penanaman Kelapa Sawit | E34: =SUM('SI TB LC'!$Q$273:$Q$277) -> 3.4516271e+09 | J34: 8 | K34: Pengendalian Hama dan Penyakit | L34: Hama Tikus | M34: =SUM('S1 TBM 1'!S297:S298) -> 33619764 | N34: =SUM(M34:M36) -> 86196285 | O34: =N34/A3 -> 215060.59 | P34: =N34/N45*100 -> 1.4945384 | T34: Hama (Oryctes) | U34: =SUM('S1 TBM 2'!Q314:Q327) -> 45322777 | Z34: 7 | AA34: Pengendalian Hama dan Penyakit | AB34: Hama Tikus | AC34: =SUM('S1 TBM 3'!Q288:Q289) -> 18770698 | AD34: =SUM(AC34:AC36) -> 1.9857106e+08 | AE34: =AD34/$A$3 -> 495436.78 | AF34: =AD34/AD46*100 -> 2.6446081
B35: 7 | C35: Pemeliharaan Pokok Sawit | D35: PHPT Tikus | E35: =SUM('SI TB LC'!Q284:Q285) -> 29885678 | F35: =SUM(E35:E39) -> 1.2071074e+08 | G35: =F35/A3 -> 301174.51 | H35: =F35/F46*100 -> 0.60730658 | L35: Hama Ulat Api | M35: =SUM('S1 TBM 1'!S303:S311) -> 19437081 | R35: 8 | S35: Pemupukkan Kelapa Sawit | T35: Pemupukkan Hayati | U35: =SUM('S1 TBM 2'!Q340:Q348) -> 0 | V35: =SUM(U35:U41) -> 2.3234189e+09 | W35: =V35/$A$3 -> 5796953.5 | X35: =V35/V44*100 -> 41.83339 | AB35: Hama Ulat Api | AC35: =SUM('S1 TBM 3'!Q292:Q300) -> 21983306
D36: PHPT Kumbang Tanduk | E36: =SUM('SI TB LC'!Q286:Q290) -> 63931851 | L36: Hama (Oryctes) | M36: =SUM('S1 TBM 1'!S316:S327) -> 33139439 | T36: Pemupukkan NPK 12-12-17-2+0,65B | U36: =SUM('S1 TBM 2'!Q360:Q368) -> 1.7374382e+09 | AB36: Hama (Oryctes) | AC36: =SUM('S1 TBM 3'!Q304:Q318) -> 1.5781706e+08
D37: Konsolidasi Pokok | E37: =SUM('SI TB LC'!Q297:Q298) -> 26893213 | J37: 9 | K37: Pemupukkan Kelapa Sawit | L37: Pemupukkan NPK 12-12-17-2+0,65B | M37: =SUM('S1 TBM 1'!S341:S349) -> 1.296816e+09 | N37: =SUM(M37:M42) -> 1.8526727e+09 | O37: =N37/A3 -> 4622436.9 | P37: =N37/N45*100 -> 32.123084 | T37: Pemupukkan Dolomite | U37: =SUM('S1 TBM 2'!Q350:Q358) -> 1.9265873e+08 | Z37: 8 | AA37: Pemupukkan Kelapa Sawit | AB37: Pemupukkan Hayati | AC37: =SUM('S1 TBM 3'!Q329:Q337) -> 0 | AD37: =SUM(AC37:AC43) -> 3.1426238e+09 | AE37: =AD37/$A$3 -> 7840877.8 | AF37: =AD37/AD46*100 -> 41.854077
D38: Pembuatan Piringan | E38: =SUM('SI TB LC'!Q299:Q300) -> 0 | L38: Pemupukkan Dolomite | M38: =SUM('S1 TBM 1'!S351:S359) -> 2.1041438e+08 | T38: Pemupukkan Borate | U38: =SUM('S1 TBM 2'!Q370:Q378) -> 59351498 | AB38: Pemupukkan NPK 12-12-17-2+0,65B | AC38: =SUM('S1 TBM 3'!Q349:Q357) -> 2.1045206e+09
L39: Pemupukkan Borate | M39: =SUM('S1 TBM 1'!S361:S369) -> 37080726 | T39: Janjang Kosong | U39: =SUM('S1 TBM 2'!Q381:Q385) -> 2.9697285e+08 | AB39: Pemupukkan Dolomite | AC39: =SUM('S1 TBM 3'!Q339:Q347) -> 2.5293056e+08
B40: 8 | C40: Pemupukkan Sawit | D40: Pemupukkan Urea | E40: =SUM('SI TB LC'!Q304:Q312) -> 85692630 | F40: =SUM(E40:E43) -> 2.5713876e+08 | G40: =F40/A3 -> 641563.78 | H40: =F40/F46*100 -> 1.2936882 | L40: Janjang Kosong | M40: =SUM('S1 TBM 1'!S371:S375) -> 2.7640663e+08 | T40: Pengangkutan Pupuk Intern | U40: =SUM('S1 TBM 2'!Q392:Q394) -> 26280771 | AB40: Pemupukkan Borate | AC40: =SUM('S1 TBM 3'!Q359:Q367) -> 60770382
D41: Pemupukan Dolomit | E41: =SUM('SI TB LC'!Q326:Q328) -> 37360877 | L41: Pengangkutan Pupuk Intern | M41: =SUM('S1 TBM 1'!S382:S384) -> 22720954 | T41: Pengangkutan Pupuk Ekstern | U41: =SUM('S1 TBM 2'!Q395) -> 10716876 | AB41: Janjang Kosong | AC41: =SUM('S1 TBM 3'!Q369:Q373) -> 6.7303396e+08
...

Sheet SI TB LC
AA1: Luas : | AB1: 400.8 | AC1: Ha
B2: Pekerjaan | F2: Material | H2: Rotasi APD | J2: TB/LC | P2: 2026 | R2: 2026 | T2: 2027 | V2: Rata-rata | X2: Keterangan | Y2: Rp/Ha | Z2: Persentase (%)
F3: Jenis | G3: Sat | J3: Sat | K3: Vol | M3: Norma | N3: Rotasi | O3: Jumlah Unit | P3: Rp Sat | Q3: Jumlah RP | R3: Rp Sat | S3: Jumlah RP | T3: Rp Sat | U3: Jumlah RP | V3: Rp Sat | W3: Jumlah RP
K4: % | L4: Luas/Mtr/Pkk/Unit | AC4: 174.95 | AG4: 52.64 | AK4: =+AC4+AG4 -> 227.59
B5: PEMBUKAAN LAHAN | AB5: 2025 | AF5: s/d Feb'26 | AJ5: Total
C6: IMAS,TUMBANG, PERUN | AB6: Ha | AC6: Biaya | AD6: Rp/Ha | AF6: Ha | AG6: Biaya | AH6: Rp/Ha | AJ6: Ha | AK6: Biaya | AL6: Rp/Ha
D7: Identifikasi Blok | F7: Upah PHL | G7: HK | J7: Ha | K7: 1 | L7: =$AB$1 -> 400.8 | M7: 0.5 | N7: 1 | O7: =K7*L7*M7*N7 -> 200.4 | P7: =VLOOKUP($F7,'[1]Master Harga'!$E$5:$L$351,6,FALSE) -> 149108.52 | Q7: =P7*$O7 -> 29881347 | R7: =VLOOKUP($F7,'[1]Master Harga'!$E$5:$L$351,6,FALSE) -> 149108.52 | S7: =R7*$O7 -> 29881347 | T7: =VLOOKUP($F7,'[1]Master Harga'!$E$5:$L$351,7,FALSE) -> 158800.57 | U7: =T7*$O7 -> 31823635 | V7: =W7/O7 -> 152339.2 | W7: =AVERAGEIF($P$3:$U$3,W$3,$P7:$U7) -> 30528777 | Y7: =Q7/$AB$1 -> 74554.26
F8: Cat | G8: Kg | N8: 1 | Y8: =Q8/$AB$1 -> 0
F9: Kuas | G9: Buah | N9: 1 | Y9: =Q9/$AB$1 -> 0
F10: Kompas | G10: Buah | M10: 0.0007 | N10: 1 | Y10: =Q10/$AB$1 -> 0
F11: GPS | G11: Buah | M11: 0.0013 | N11: 1 | Y11: =Q11/$AB$1 -> 0
D12: Imas | E12: Hutan Primer | F12: Upah PHL | G12: HK | M12: 10 | N12: 1 | Y12: =Q12/$AB$1 -> 0
D13: Imas | E13: Hutan Sekunder | F13: Upah PHL | G13: HK | J13: Ha | K13: 1 | L13: =$AB$1 -> 400.8 | M13: 5 | N13: 1 | O13: =K13*L13*M13*N13 -> 2004 | P13: =VLOOKUP($F13,'[1]Master Harga'!$E$5:$L$351,6,FALSE) -> 149108.52 | Q13: =O13*P13 -> 2.9881347e+08 | Y13: =Q13/$AB$1 -> 745542.6
E14: Semak Belukar | F14: Upah PHL | G14: HK | Y14: =Q14/$AB$1 -> 0
D15: Tumbang | E15: Hutan Primer | F15: Upah PHL | G15: HK | M15: 20 | N15: 1 | Y15: =Q15/$AB$1 -> 0
E16: Hutan Sekunder | F16: Upah PHL | G16: HK | M16: 12 | N16: 1 | Y16: =Q16/$AB$1 -> 0
D17: Cincang | E17: Hutan Primer | F17: Upah PHL | G17: HK | Y17: =Q17/$AB$1 -> 0
E18: Hutan Sekunder | F18: Upah PHL | G18: HK | Y18: =Q18/$AB$1 -> 0
D19: Perun Mekanis | E19: Hutan Primer | F19: Buldozer 1 | G19: HM | M19: 6 | N19: 1 | Y19: =Q19/$AB$1 -> 0
D20: Perun Mekanis | E20: Hutan Sekunder | F20: Excavator 2 | G20: HM | K20: 1 | L20: =($AB$1*70%) -> 280.56 | M20: =9.5 -> 9.5 | N20: 1 | O20: =K20*L20*M20*N20 -> 2665.32 | P20: =VLOOKUP($F20,'[1]Master Harga'!$E$5:$L$351,6,FALSE) -> 766238.07 | Q20: =P20*$O20 -> 2.0422697e+09 | Y20: =Q20/$AB$1 -> 5095483.2
F21: Excavator 2 | G21: HM | K21: 1 | L21: =($AB$1*30%) -> 120.24 | M21: 13.54 | N21: 1 | O21: =K21*L21*M21*N21 -> 1628.0496 | P21: =VLOOKUP($F21,'[1]Master Harga'!$E$5:$L$351,6,FALSE) -> 766238.07 | Q21: =P21*$O21 -> 1.2474736e+09 | Y21: =Q21/$AB$1 -> 3112459.1
F22: Matting | G22: Bh | K22: 1 | L22: =$AB$1 -> 400.8 | M22: 13.54 | N22: 1 | O22: =K22*L22*M22*N22 -> 5426.832 | P22: 500000 | Q22: =P22*$O22 -> 2.713416e+09 | Y22: =Q22/$AB$1 -> 6770000
F23: Upah PHL | G23: HK | J23: HK | K23: 1 | L23: =O20/8*125% -> 416.45625 | M23: 2 | N23: 1 | O23: =K23*L23*M23*N23 -> 832.9125 | P23: =VLOOKUP($F23,'[1]Master Harga'!$E$5:$L$351,6,FALSE) -> 149108.52 | Q23: =O23*P23 -> 1.2419435e+08 | Y23: =Q23/$AB$1 -> 309866.14
E24: Semak Belukar | F24: Buldozer 1 | G24: HM | M24: 4 | N24: 1 | Y24: =Q24/$AB$1 -> 0
E25: Reklamasi | F25: Buldozer 1 | G25: HM | K25: 1 | M25: 10 | N25: 1 | O25: =K25*L25*M25*N25 -> 0 | P25: =VLOOKUP($F25,'[1]Master Harga'!$E$5:$L$351,6,FALSE) -> 1051433.7 | Q25: =O25*P25 -> 0 | Y25: =Q25/$AB$1 -> 0
D26: Pengolahan Tanah (Ripping) | F26: Buldozer 1 | G26: HM | J26: HM/Ha | K26: 0 | M26: 2.5 | N26: 1 | O26: =K26*L26*M26*N26 -> 0 | P26: =VLOOKUP($F26,'[1]Master Harga'!$E$5:$L$351,6,FALSE) -> 1051433.7 | Q26: =P26*$O26 -> 0 | R26: =VLOOKUP($F26,'[1]Master Harga'!$E$5:$L$351,6,FALSE) -> 1051433.7 | S26: =R26*$O26 -> 0 | T26: =VLOOKUP($F26,'[1]Master Harga'!$E$5:$L$351,7,FALSE) -> 1113470.8 | U26: =T26*$O26 -> 0 | V26: =W26/O26 -> #DIV/0! | W26: =AVERAGEIF($P$3:$U$3,W$3,$P26:$U26) -> 0 | Y26: =Q26/$AB$1 -> 0
F27: Upah PHL | G27: HK | J27: Ha | K27: 1 | L27: =O26/10 -> 0 | M27: =3*2 -> 6 | N27: 1 | O27: =K27*L27*M27*N27 -> 0 | P27: =VLOOKUP($F27,'[1]Master Harga'!$E$5:$L$351,6,FALSE) -> 149108.52 | Q27: =P27*$O27 -> 0 | Y27: =Q27/$AB$1 -> 0
F28: Angkutan Material | G28: RIT | K28: 1 | L28: =(O26*25)/400 -> 0 | M28: 2 | N28: 1 | O28: =K28*L28*M28*N28 -> 0 | P28: =VLOOKUP($F28,'[1]Master Harga'!$E$5:$L$351,6,FALSE) -> 207500 | Q28: =P28*$O28 -> 0 | Y28: =Q28/$AB$1 -> 0
D29: Tumbang Chipping | Y29: =Q29/$AB$1 -> 0
E30: Pancang Chiping | F30: Upah PHL | G30: HK | J30: Ha | K30: 1 | L30: 0 | M30: 1 | N30: 1 | O30: =K30*L30*M30*N30 -> 0 | P30: =VLOOKUP($F30,'[1]Master Harga'!$E$5:$L$351,6,FALSE) -> 149108.52 | Q30: =P30*$O30 -> 0 | R30: =VLOOKUP($F30,'[1]Master Harga'!$E$5:$L$351,6,FALSE) -> 149108.52 | S30: =R30*$O30 -> 0 | T30: =VLOOKUP($F30,'[1]Master Harga'!$E$5:$L$351,7,FALSE) -> 158800.57 | U30: =T30*$O30 -> 0 | V30: =W30/O30 -> #DIV/0! | W30: =AVERAGEIF($P$3:$U$3,W$3,$P30:$U30) -> 0 | Y30: =Q30/$AB$1 -> 0
E31: Tumbang Chiping | F31: Excavator 1 | G31: HM | J31: HM/Ha | K31: 1 | L31: 0 | M31: 10.8 | N31: 1 | O31: =K31*L31*M31*N31 -> 0 | P31: =VLOOKUP($F31,'[1]Master Harga'!$E$5:$L$351,6,FALSE) -> 720338.07 | Q31: =P31*$O31 -> 0 | R31: =VLOOKUP($F31,'[1]Master Harga'!$E$5:$L$351,6,FALSE) -> 720338.07 | S31: =R31*$O31 -> 0 | T31: =VLOOKUP($F31,'[1]Master Harga'!$E$5:$L$351,7,FALSE) -> 761671.7 | U31: =T31*$O31 -> 0 | V31: =W31/O31 -> #DIV/0! | W31: =AVERAGEIF($P$3:$U$3,W$3,$P31:$U31) -> 0 | Y31: =Q31/$AB$1 -> 0
F32: Upah PHL | G32: HK | J32: Ha | K32: 1 | L32: =O31/10 -> 0 | M32: =3*4 -> 12 | N32: 1 | O32: =K32*L32*M32*N32 -> 0 | P32: =VLOOKUP($F32,'[1]Master Harga'!$E$5:$L$351,6,FALSE) -> 149108.52 | Q32: =P32*$O32 -> 0 | Y32: =Q32/$AB$1 -> 0
F33: Angkutan Material | G33: RIT | K33: 1 | L33: =(O31*18)/400 -> 0 | M33: 2 | N33: 1 | O33: =K33*L33*M33*N33 -> 0 | P33: =VLOOKUP($F33,'[1]Master Harga'!$E$5:$L$351,6,FALSE) -> 207500 | Q33: =P33*$O33 -> 0 | Y33: =Q33/$AB$1 -> 0
E34: Aplikasi Metharizium | F34: Upah PHL | G34: HK | J34: Ha | K34: 0 | L34: 0 | M34: 0.5 | N34: 1 | O34: =K34*L34*M34*N34 -> 0 | P34: =VLOOKUP($F34,'[1]Master Harga'!$E$5:$L$351,6,FALSE) -> 149108.52 | Q34: =P34*$O34 -> 0 | Y34: =Q34/$AB$1 -> 0
F35: Metharizium | G35: Kg | J35: Kg | K35: 0 | L35: 0 | M35: 24 | N35: 1 | O35: =K35*L35*M35*N35 -> 0 | P35: =VLOOKUP($F35,'[1]Master Harga'!$E$5:$L$351,6,FALSE) -> 24097.5 | Q35: =P35*$O35 -> 0 | R35: =VLOOKUP($F35,'[1]Master Harga'!$E$5:$L$351,6,FALSE) -> 24097.5 | S35: =R35*$O35 -> 0 | T35: =VLOOKUP($F35,'[1]Master Harga'!$E$5:$L$351,7,FALSE) -> 25302.375 | U35: =T35*$O35 -> 0 | V35: =W35/O35 -> #DIV/0! | W35: =AVERAGEIF($P$3:$U$3,W$3,$P35:$U35) -> 0 | Y35: =Q35/$AB$1 -> 0
D36: Parit CECT | F36: Excavator 1 | G36: HM | J36: HM/Ha | K36: 1 | L36: 0 | M36: 8.5 | N36: 1 | O36: =K36*L36*M36*N36 -> 0 | P36: =VLOOKUP($F36,'[1]Master Harga'!$E$5:$L$351,6,FALSE) -> 720338.07 | Q36: =P36*$O36 -> 0 | Y36: =Q36/$AB$1 -> 0
F37: Upah PHL | G37: HK | J37: Ha | K37: 1 | L37: =O36/10 -> 0 | M37: =3*2 -> 6 | N37: 1 | O37: =K37*L37*M37*N37 -> 0 | P37: =VLOOKUP($F37,'[1]Master Harga'!$E$5:$L$351,6,FALSE) -> 149108.52 | Q37: =P37*$O37 -> 0 | Y37: =Q37/$AB$1 -> 0
F38: Angkutan Material | G38: RIT | J38: RIT | K38: 1 | L38: =(O36*18)/400 -> 0 | M38: 2 | N38: 1 | O38: =K38*L38*M38*N38 -> 0 | P38: =VLOOKUP($F38,'[1]Master Harga'!$E$5:$L$351,6,FALSE) -> 207500 | Q38: =P38*$O38 -> 0 | Y38: =Q38/$AB$1 -> 0
D39: Tutup Lubang CECT dan Perataan Tanah | F39: Excavator 1 | G39: HM | J39: HM/Ha | K39: 1 | L39: 0 | M39: =600/60 -> 10 | N39: 1 | O39: =K39*L39*M39*N39 -> 0 | P39: =VLOOKUP($F39,'[1]Master Harga'!$E$5:$L$351,6,FALSE) -> 720338.07 | Q39: =P39*$O39 -> 0 | R39: =VLOOKUP($F39,'[1]Master Harga'!$E$5:$L$351,6,FALSE) -> 720338.07 | S39: =R39*$O39 -> 0 | T39: =VLOOKUP($F39,'[1]Master Harga'!$E$5:$L$351,7,FALSE) -> 761671.7 | U39: =T39*$O39 -> 0 | V39: =W39/O39 -> #DIV/0! | W39: =AVERAGEIF($P$3:$U$3,W$3,$P39:$U39) -> 0 | Y39: =Q39/$AB$1 -> 0
F40: Upah PHL | G40: HK | J40: Ha | K40: 1 | L40: =O39/10 -> 0 | M40: =3*2 -> 6 | N40: 1 | O40: =K40*L40*M40*N40 -> 0 | P40: =VLOOKUP($F40,'[1]Master Harga'!$E$5:$L$351,6,FALSE) -> 149108.52 | Q40: =P40*$O40 -> 0 | Y40: =Q40/$AB$1 -> 0
...

Sheet S1 TBM 1
AB1: Luas : | AC1: 400.8 | AD1: Ha
B2: Pekerjaan | F2: Material | H2: Rotasi APD | J2: TBM 1 | P2: 2025 | R2: 2027 | T2: 2027 | V2: Rata-rata | Y2: Rp/Ha | Z2: Persentase (%)
F3: Jenis | G3: Sat | J3: Sat | K3: Vol | M3: Norma | N3: Rotasi | O3: Jumlah Unit | P3: Rp Sat | Q3: Jumlah RP | R3: Rp Sat | S3: Jumlah RP | T3: Rp Sat | U3: Jumlah RP | V3: Rp Sat | W3: Jumlah RP | X3: Keterangan
K4: % | L4: Luas/Mtr/Pkk/Unit
B5: TANAM KACANGAN
C6: Tanam Kacangan | F6: Upah PHL | G6: HK | K6: 0 | L6: =$AC$1 -> 400.8 | M6: 4 | N6: 1 | O6: =K6*L6*M6*N6 -> 0 | R6: =VLOOKUP($F6,'[1]Master Harga'!$E$5:$L$351,6,FALSE) -> 149108.52 | S6: =O6*R6 -> 0 | Y6: =S6/$AC$1 -> 0
F7: PJ | G7: Kg | K7: 0 | L7: =$L$6 -> 400.8 | M7: 3 | N7: 1 | O7: =K7*L7*M7*N7 -> 0 | R7: =VLOOKUP($F7,'[1]Master Harga'!$E$5:$L$351,6,FALSE) -> 0 | S7: =O7*R7 -> 0 | Y7: =S7/$AC$1 -> 0
F8: CM | G8: Kg | K8: 0 | L8: =$L$6 -> 400.8 | M8: 6 | N8: 1 | O8: =K8*L8*M8*N8 -> 0 | R8: =VLOOKUP($F8,'[1]Master Harga'!$E$5:$L$351,6,FALSE) -> 0 | S8: =O8*R8 -> 0 | Y8: =S8/$AC$1 -> 0
F9: MB (Mocuna Bracteata) | G9: Kg | K9: 0 | L9: =$L$6 -> 400.8 | M9: 0.25 | N9: 1 | O9: =K9*L9*M9*N9 -> 0 | R9: =VLOOKUP($F9,'[1]Master Harga'!$E$5:$L$351,6,FALSE) -> 535500 | S9: =O9*R9 -> 0 | Y9: =S9/$AC$1 -> 0
F10: Rizhobium | G10: Kg | K10: 0 | L10: =$L$6 -> 400.8 | M10: 0.01 | N10: 1 | O10: =K10*L10*M10*N10 -> 0 | R10: =VLOOKUP($F10,'[1]Master Harga'!$E$5:$L$351,6,FALSE) -> 0 | S10: =O10*R10 -> 0 | Y10: =S10/$AC$1 -> 0
F11: Rock Phosphate | G11: Kg | K11: 0 | L11: =$L$6 -> 400.8 | M11: 2 | N11: 1 | O11: =K11*L11*M11*N11 -> 0 | R11: =VLOOKUP($F11,'[1]Master Harga'!$E$5:$L$351,6,FALSE) -> 2300 | S11: =O11*R11 -> 0 | Y11: =S11/$AC$1 -> 0
F12: Sepatu Boots | G12: Buah | H12: 1 | I12: X | K12: 0 | L12: =$L$6 -> 400.8 | M12: =((M$6*N$6)/240*($H12/N12)) -> 0.016666667 | N12: 1 | O12: =K12*L12*M12*N12 -> 0 | R12: =VLOOKUP($F12,'[1]Master Harga'!$E$5:$L$351,6,FALSE) -> 89964 | S12: =O12*R12 -> 0 | Y12: =S12/$AC$1 -> 0
C13: Pemeliharaan Kacangan | F13: Upah PHL | G13: HK | K13: 0.5 | L13: =$L$6 -> 400.8 | M13: 2 | N13: 3 | O13: =K13*L13*M13*N13 -> 1202.4 | R13: =VLOOKUP($F13,'[1]Master Harga'!$E$5:$L$351,6,FALSE) -> 149108.52 | S13: =O13*R13 -> 1.7928808e+08 | Y13: =S13/$AC$1 -> 447325.56
C14: Bongkar Tumbuhan Pengganggu | F14: Upah PHL | G14: HK | K14: 0.25 | L14: =$L$6 -> 400.8 | M14: 2 | N14: 1 | O14: =K14*L14*M14*N14 -> 200.4 | R14: =VLOOKUP($F14,'[1]Master Harga'!$E$5:$L$351,6,FALSE) -> 149108.52 | S14: =O14*R14 -> 29881347 | Y14: =S14/$AC$1 -> 74554.26
F15: Glyphosate | G15: Liter | K15: 0.25 | L15: =$L$6 -> 400.8 | M15: 1.2 | N15: 1 | O15: =K15*L15*M15*N15 -> 120.24 | R15: =VLOOKUP($F15,'[1]Master Harga'!$E$5:$L$351,6,FALSE) -> 35343 | S15: =O15*R15 -> 4249642.3 | Y15: =S15/$AC$1 -> 10602.9
F16: Metil Metsulfuron | G16: Kg | K16: 0.25 | L16: =$L$6 -> 400.8 | M16: =48/1000 -> 0.048 | N16: 1 | O16: =K16*L16*M16*N16 -> 4.8096 | R16: =VLOOKUP($F16,'[1]Master Harga'!$E$5:$L$351,6,FALSE) -> 96390 | S16: =O16*R16 -> 463597.34 | Y16: =S16/$AC$1 -> 1156.68
F17: Perekat | G17: Liter | K17: 0.25 | L17: =$L$6 -> 400.8 | M17: 0.288 | N17: 1 | O17: =K17*L17*M17*N17 -> 28.8576 | R17: =VLOOKUP($F17,'[1]Master Harga'!$E$5:$L$351,6,FALSE) -> 44982 | S17: =O17*R17 -> 1298072.6 | Y17: =S17/$AC$1 -> 3238.704
F18: Sprayer (Inter) | G18: Buah | K18: 0.25 | L18: =$L$6 -> 400.8 | M18: 0.007 | N18: 1 | O18: =K18*L18*M18*N18 -> 0.7014 | R18: =VLOOKUP($F18,'[1]Master Harga'!$E$5:$L$351,6,FALSE) -> 1434791.9 | S18: =O18*R18 -> 1006363.1 | Y18: =S18/$AC$1 -> 2510.8859
F19: Premi Extra Fooding | G19: HK | K19: 0.25 | L19: =$L$6 -> 400.8 | M19: 2 | N19: 1 | O19: =K19*L19*M19*N19 -> 200.4 | R19: =VLOOKUP($F19,'[1]Master Harga'!$E$5:$L$351,6,FALSE) -> 4042.5 | S19: =O19*R19 -> 810117 | Y19: =S19/$AC$1 -> 2021.25
F20: Celemek | G20: Buah | H20: 4 | I20: X | K20: 0.25 | L20: =$L$6 -> 400.8 | M20: =((M$14*N$14)/240*($H20/N20)) -> 0.033333333 | N20: 1 | O20: =K20*L20*M20*N20 -> 3.34 | R20: =VLOOKUP($F20,'[1]Master Harga'!$E$5:$L$351,6,FALSE) -> 44982 | S20: =O20*R20 -> 150239.88 | Y20: =S20/$AC$1 -> 374.85
F21: Masker Chemical | G21: Buah | H21: 12 | I21: X | K21: 0.25 | L21: =$L$6 -> 400.8 | M21: =((M$14*N$14)/240*($H21/N21)) -> 0.1 | N21: 1 | O21: =K21*L21*M21*N21 -> 10.02 | R21: =VLOOKUP($F21,'[1]Master Harga'!$E$5:$L$351,6,FALSE) -> 14700 | S21: =O21*R21 -> 147294 | Y21: =S21/$AC$1 -> 367.5
F22: Kaca mata | G22: Buah | H22: 1 | I22: X | K22: 0.25 | L22: =$L$6 -> 400.8 | M22: =((M$14*N$14)/240*($H22/N22)) -> 0.0083333333 | N22: 1 | O22: =K22*L22*M22*N22 -> 0.835 | R22: =VLOOKUP($F22,'[1]Master Harga'!$E$5:$L$351,6,FALSE) -> 39359.25 | S22: =O22*R22 -> 32864.974 | Y22: =S22/$AC$1 -> 81.998437
F23: Sarung Tangan Karet | G23: Buah | H23: 2 | I23: X | K23: 0.25 | L23: =$L$6 -> 400.8 | M23: =((M$14*N$14)/240*($H23/N23)) -> 0.016666667 | N23: 1 | O23: =K23*L23*M23*N23 -> 1.67 | R23: =VLOOKUP($F23,'[1]Master Harga'!$E$5:$L$351,6,FALSE) -> 33736.5 | S23: =O23*R23 -> 56339.955 | Y23: =S23/$AC$1 -> 140.56875
F24: Sepatu Boots | G24: Buah | H24: 1 | I24: X | K24: 0.25 | L24: =$L$6 -> 400.8 | M24: =((M$14*N$14)/240*($H24/N24)) -> 0.0083333333 | N24: 1 | O24: =K24*L24*M24*N24 -> 0.835 | R24: =VLOOKUP($F24,'[1]Master Harga'!$E$5:$L$351,6,FALSE) -> 89964 | S24: =O24*R24 -> 75119.94 | Y24: =S24/$AC$1 -> 187.425
C25: Pemberantasan Lalang | F25: Upah PHL | G25: HK | K25: 0.5 | L25: =$L$6 -> 400.8 | M25: 1 | N25: 1 | O25: =K25*L25*M25*N25 -> 200.4 | R25: =VLOOKUP($F25,'[1]Master Harga'!$E$5:$L$351,6,FALSE) -> 149108.52 | S25: =O25*R25 -> 29881347 | Y25: =S25/$AC$1 -> 74554.26
F26: Glyphosate | G26: Liter | K26: 0.5 | L26: =$L$6 -> 400.8 | M26: 1.08 | N26: 1 | O26: =K26*L26*M26*N26 -> 216.432 | R26: =VLOOKUP($F26,'[1]Master Harga'!$E$5:$L$351,6,FALSE) -> 35343 | S26: =O26*R26 -> 7649356.2 | Y26: =S26/$AC$1 -> 19085.22
F27: Perekat | G27: Liter | K27: 0.5 | L27: =$L$6 -> 400.8 | M27: 0.18 | N27: 1 | O27: =K27*L27*M27*N27 -> 36.072 | R27: =VLOOKUP($F27,'[1]Master Harga'!$E$5:$L$351,6,FALSE) -> 44982 | S27: =O27*R27 -> 1622590.7 | Y27: =S27/$AC$1 -> 4048.38
F28: Sprayer (Inter) | G28: Buah | K28: 0.5 | L28: =$L$6 -> 400.8 | M28: 0.004 | N28: 1 | O28: =K28*L28*M28*N28 -> 0.8016 | R28: =VLOOKUP($F28,'[1]Master Harga'!$E$5:$L$351,6,FALSE) -> 1434791.9 | S28: =O28*R28 -> 1150129.2 | Y28: =S28/$AC$1 -> 2869.5838
F29: Premi Extra Fooding | G29: HK | K29: 0.5 | L29: =$L$6 -> 400.8 | M29: 1 | N29: 1 | O29: =K29*L29*M29*N29 -> 200.4 | R29: =VLOOKUP($F29,'[1]Master Harga'!$E$5:$L$351,6,FALSE) -> 4042.5 | S29: =O29*R29 -> 810117 | Y29: =S29/$AC$1 -> 2021.25
F30: Celemek | G30: Buah | H30: 4 | I30: X | K30: 0.5 | L30: =$L$6 -> 400.8 | M30: =((M$25*N$25)/240*($H30/N30)) -> 0.016666667 | N30: 1 | O30: =K30*L30*M30*N30 -> 3.34 | R30: =VLOOKUP($F30,'[1]Master Harga'!$E$5:$L$351,6,FALSE) -> 44982 | S30: =O30*R30 -> 150239.88 | Y30: =S30/$AC$1 -> 374.85
F31: Masker Chemical | G31: Buah | H31: 12 | I31: X | K31: 0.5 | L31: =$L$6 -> 400.8 | M31: =((M$25*N$25)/240*($H31/N31)) -> 0.05 | N31: 1 | O31: =K31*L31*M31*N31 -> 10.02 | R31: =VLOOKUP($F31,'[1]Master Harga'!$E$5:$L$351,6,FALSE) -> 14700 | S31: =O31*R31 -> 147294 | Y31: =S31/$AC$1 -> 367.5
F32: Kaca mata | G32: Buah | H32: 1 | I32: X | K32: 0.5 | L32: =$L$6 -> 400.8 | M32: =((M$25*N$25)/240*($H32/N32)) -> 0.0041666667 | N32: 1 | O32: =K32*L32*M32*N32 -> 0.835 | R32: =VLOOKUP($F32,'[1]Master Harga'!$E$5:$L$351,6,FALSE) -> 39359.25 | S32: =O32*R32 -> 32864.974 | Y32: =S32/$AC$1 -> 81.998437
F33: Sarung Tangan Karet | G33: Buah | H33: 2 | I33: X | K33: 0.5 | L33: =$L$6 -> 400.8 | M33: =((M$25*N$25)/240*($H33/N33)) -> 0.0083333333 | N33: 1 | O33: =K33*L33*M33*N33 -> 1.67 | R33: =VLOOKUP($F33,'[1]Master Harga'!$E$5:$L$351,6,FALSE) -> 33736.5 | S33: =O33*R33 -> 56339.955 | Y33: =S33/$AC$1 -> 140.56875
F34: Sepatu Boots | G34: Buah | H34: 1 | I34: X | K34: 0.5 | L34: =$L$6 -> 400.8 | M34: =((M$25*N$25)/240*($H34/N34)) -> 0.0041666667 | N34: 1 | O34: =K34*L34*M34*N34 -> 0.835 | R34: =VLOOKUP($F34,'[1]Master Harga'!$E$5:$L$351,6,FALSE) -> 89964 | S34: =O34*R34 -> 75119.94 | Y34: =S34/$AC$1 -> 187.425
B35: SUB TOTAL TANAMAN KACANGAN | S35: =SUM(S6:S34) -> 2.5903448e+08 | Y35: =S35/$AC$1 -> 646293.62
B36: TANAMAN BELUM MENGHASILKAN | Y36: =S36/$AC$1 -> 0
B37: PEMBUATAN PIRINGAN, PASAR RINTIS, TPH DAN TITI PASAR RINTIS | Y37: =S37/$AC$1 -> 0
C38: Pembuatan Piringan | F38: Upah PHL | G38: HK | J38: Ha | K38: 1 | L38: =AC1 -> 400.8 | M38: 2.5 | N38: 1 | O38: =K38*L38*M38*N38 -> 1002 | P38: =VLOOKUP($F38,'[1]Master Harga'!$E$5:$L$351,5,FALSE) -> 140008 | Q38: =P38*$O38 -> 140288016 | R38: =VLOOKUP($F38,'[1]Master Harga'!$E$5:$L$351,6,FALSE) -> 149108.52 | S38: =R38*$O38 -> 1.4940674e+08 | T38: =VLOOKUP($F38,'[2]Master Harga'!$E$5:$L$348,7,FALSE) -> 163305.33 | U38: =$O38*T38 -> 1.6363194e+08 | V38: =W38/O38 -> 150807.28 | W38: =AVERAGEIF($P$3:$U$3,W$3,$P38:$U38) -> 1.511089e+08 | Y38: =S38/$AC$1 -> 372771.3
F39: Cangkul | G39: Buah | K39: 1 | L39: =$L$38 -> 400.8 | M39: 0.0083 | N39: 1 | O39: =K39*L39*M39*N39 -> 3.32664 | R39: =VLOOKUP($F39,'[1]Master Harga'!$E$5:$L$351,6,FALSE) -> 79588.688 | S39: =R39*$O39 -> 264762.91 | Y39: =S39/$AC$1 -> 660.58611
F40: Sepatu Boots | G40: Buah | K40: 1 | L40: =$L$38 -> 400.8 | M40: 0.0083 | N40: 1 | O40: =K40*L40*M40*N40 -> 3.32664 | R40: =VLOOKUP($F40,'[1]Master Harga'!$E$5:$L$351,6,FALSE) -> 89964 | S40: =R40*$O40 -> 299277.84 | Y40: =S40/$AC$1 -> 746.7012
...

Sheet S1 TBM 2
B2: Pekerjaan | F2: Material | H2: Rotasi APD | J2: TBM 2 | P2: 2028 | R2: 2028 | T2: 2029 | V2: Rata-rata | Y2: Rp/Ha | Z2: Persentase (%) | AB2: Luas : | AC2: 400.8 | AD2: Ha
F3: Jenis | G3: Sat | J3: Sat | K3: Vol | M3: Norma | N3: Rotasi | O3: Jumlah Unit | P3: Rp Sat | Q3: Jumlah RP | R3: Rp Sat | S3: Jumlah RP | T3: Rp Sat | U3: Jumlah RP | V3: Rp Sat | W3: Jumlah RP | X3: Keterangan
K4: % | L4: Luas/Mtr/Pkk/Unit
B5: TANAM KACANGAN
C6: Tanam Kacangan | F6: Upah PHL | G6: HK | Y6: =Q6/$AC$2 -> 0
F7: PJ | G7: Kg | Y7: =Q7/$AC$2 -> 0
F8: CM | G8: Kg | Y8: =Q8/$AC$2 -> 0
F9: MB (Mocuna Bracteata) | G9: Kg | Y9: =Q9/$AC$2 -> 0
F10: Rizhobium | G10: Kg | Y10: =Q10/$AC$2 -> 0
F11: Rock Phosphate | G11: Kg | Y11: =Q11/$AC$2 -> 0
F12: Sepatu Boots | G12: Buah | H12: 1 | I12: X | Y12: =Q12/$AC$2 -> 0
C13: Pemeliharaan Kacangan | F13: Upah PHL | G13: HK | Y13: =Q13/$AC$2 -> 0
C14: Bongkar Tumbuhan Pengganggu | F14: Upah PHL | G14: HK | Y14: =Q14/$AC$2 -> 0
F15: Glyphosate | G15: Liter | Y15: =Q15/$AC$2 -> 0
F16: Metil Metsulfuron | G16: Kg | Y16: =Q16/$AC$2 -> 0
F17: Perekat | G17: Liter | Y17: =Q17/$AC$2 -> 0
F18: Sprayer | G18: Buah | Y18: =Q18/$AC$2 -> 0
F19: Premi Extra Fooding | G19: HK | Y19: =Q19/$AC$2 -> 0
F20: Celemek | G20: Buah | H20: 4 | I20: X | Y20: =Q20/$AC$2 -> 0
F21: Masker Chemical | G21: Buah | H21: 12 | I21: X | Y21: =Q21/$AC$2 -> 0
F22: Kaca mata | G22: Buah | H22: 1 | I22: X | Y22: =Q22/$AC$2 -> 0
F23: Sarung Tangan Karet | G23: Buah | H23: 2 | I23: X | Y23: =Q23/$AC$2 -> 0
F24: Sepatu Boots | G24: Buah | H24: 1 | I24: X | Y24: =Q24/$AC$2 -> 0
C25: Pemberantasan Lalang | F25: Upah PHL | G25: HK | Y25: =Q25/$AC$2 -> 0
F26: Glyphosate | G26: Liter | Y26: =Q26/$AC$2 -> 0
F27: Perekat | G27: Liter | Y27: =Q27/$AC$2 -> 0
F28: Sprayer | G28: Buah | Y28: =Q28/$AC$2 -> 0
F29: Premi Extra Fooding | G29: HK | Y29: =Q29/$AC$2 -> 0
F30: Celemek | G30: Buah | H30: 4 | I30: X | Y30: =Q30/$AC$2 -> 0
F31: Masker | G31: Buah | H31: 12 | I31: X | Y31: =Q31/$AC$2 -> 0
F32: Kaca mata | G32: Buah | H32: 1 | I32: X | Y32: =Q32/$AC$2 -> 0
F33: Sarung Tangan Karet | G33: Buah | H33: 2 | I33: X | Y33: =Q33/$AC$2 -> 0
F34: Sepatu Boots | G34: Buah | H34: 1 | I34: X | Y34: =Q34/$AC$2 -> 0
B35: SUB TOTAL TANAMAN KACANGAN | Q35: =SUM(Q6:Q34) -> 0 | S35: =SUM(S6:S34) -> 0 | Y35: =Q35/$AC$2 -> 0
B36: TANAMAN BELUM MENGHASILKAN | Y36: =Q36/$AC$2 -> 0
B37: PEMBUATAN PIRINGAN, PASAR RINTIS, TPH DAN TITI PASAR RINTIS | Y37: =Q37/$AC$2 -> 0
C38: Pembuatan Piringan | F38: Upah PHL | G38: HK | O38: =K38*L38*M38*N38 -> 0 | P38: =VLOOKUP($F38,'[2]Master Harga'!$E$5:$L$348,6,FALSE) -> 151208.64 | Q38: =P38*$O38 -> 0 | R38: =VLOOKUP($F38,'[2]Master Harga'!$E$5:$L$348,7,FALSE) -> 163305.33 | S38: =R38*$O38 -> 0 | T38: =VLOOKUP($F38,'[2]Master Harga'!$E$5:$L$348,8,FALSE) -> 179635.86 | U38: =$O38*T38 -> 0 | V38: =W38/O38 -> #DIV/0! | W38: =AVERAGEIF($P$3:$U$3,W$3,$P38:$U38) -> 0 | Y38: =Q38/$AC$2 -> 0
F39: Cangkul | G39: Buah | Y39: =Q39/$AC$2 -> 0
F40: Sepatu Boots | G40: Buah | Y40: =Q40/$AC$2 -> 0
C41: Pembuatan Pasar Rintis | F41: Upah PHL | G41: HK | K41: 0.5 | L41: =$L$59 -> 400.8 | M41: 1 | N41: 1 | O41: =K41*L41*M41*N41 -> 200.4 | P41: =VLOOKUP($F41,'[2]Master Harga'!$E$5:$L$348,6,FALSE) -> 151208.64 | Q41: =P41*$O41 -> 30302211 | Y41: =Q41/$AC$2 -> 75604.32
...

Sheet S1 TBM 3
B2: Pekerjaan | F2: Material | H2: Rotasi APD | J2: TBM 3 | P2: 2029 | R2: 2029 | T2: 2029 | V2: Rata-rata | Y2: Rp/Ha | Z2: Persentase (%)
F3: Jenis | G3: Sat | J3: Sat | K3: Vol | M3: Norma | N3: Rotasi | O3: Jumlah Unit | P3: Rp Sat | Q3: Jumlah RP | R3: Rp Sat | S3: Jumlah RP | T3: Rp Sat | U3: Jumlah RP | V3: Rp Sat | W3: Jumlah RP | X3: Keterangan | AB3: Luas : | AC3: 400.8 | AD3: Ha
K4: % | L4: Luas/Mtr/Pkk/Unit
B5: TANAM KACANGAN
C6: Tanam Kacangan | F6: Upah PHL | G6: HK | Y6: =Q6/$AC$3 -> 0
F7: PJ | G7: Kg | Y7: =Q7/$AC$3 -> 0
F8: CM | G8: Kg | Y8: =Q8/$AC$3 -> 0
F9: MB (Mocuna Bracteata) | G9: Kg | Y9: =Q9/$AC$3 -> 0
F10: Rizhobium | G10: Kg | Y10: =Q10/$AC$3 -> 0
F11: Rock Phosphate | G11: Kg | Y11: =Q11/$AC$3 -> 0
F12: Sepatu Boots | G12: Buah | H12: 1 | I12: X | Y12: =Q12/$AC$3 -> 0
C13: Pemeliharaan Kacangan | F13: Upah PHL | G13: HK | Y13: =Q13/$AC$3 -> 0
C14: Bongkar Tumbuhan Pengganggu | F14: Upah PHL | G14: HK | Y14: =Q14/$AC$3 -> 0
F15: Glyphosate | G15: Liter | Y15: =Q15/$AC$3 -> 0
F16: Metil Metsulfuron | G16: Kg | Y16: =Q16/$AC$3 -> 0
F17: Perekat | G17: Liter | Y17: =Q17/$AC$3 -> 0
F18: Sprayer | G18: Buah | Y18: =Q18/$AC$3 -> 0
F19: Premi Extra Fooding | G19: HK | Y19: =Q19/$AC$3 -> 0
F20: Celemek | G20: Buah | H20: 4 | I20: X | Y20: =Q20/$AC$3 -> 0
F21: Masker Chemical | G21: Buah | H21: 12 | I21: X | Y21: =Q21/$AC$3 -> 0
F22: Kaca mata | G22: Buah | H22: 1 | I22: X | Y22: =Q22/$AC$3 -> 0
F23: Sarung Tangan Karet | G23: Buah | H23: 2 | I23: X | Y23: =Q23/$AC$3 -> 0
F24: Sepatu Boots | G24: Buah | H24: 1 | I24: X | Y24: =Q24/$AC$3 -> 0
C25: Pemberantasan Lalang | F25: Upah PHL | G25: HK | Y25: =Q25/$AC$3 -> 0
F26: Glyphosate | G26: Liter | Y26: =Q26/$AC$3 -> 0
F27: Perekat | G27: Liter | Y27: =Q27/$AC$3 -> 0
F28: Sprayer | G28: Buah | Y28: =Q28/$AC$3 -> 0
F29: Premi Extra Fooding | G29: HK | Y29: =Q29/$AC$3 -> 0
F30: Celemek | G30: Buah | H30: 4 | I30: X | Y30: =Q30/$AC$3 -> 0
F31: Masker | G31: Buah | H31: 12 | I31: X | Y31: =Q31/$AC$3 -> 0
F32: Kaca mata | G32: Buah | H32: 1 | I32: X | Y32: =Q32/$AC$3 -> 0
F33: Sarung Tangan Karet | G33: Buah | H33: 2 | I33: X | Y33: =Q33/$AC$3 -> 0
F34: Sepatu Boots | G34: Buah | H34: 1 | I34: X | Y34: =Q34/$AC$3 -> 0
B35: SUB TOTAL TANAM KACANGAN | Q35: =SUM(Q6:Q34) -> 0 | S35: =SUM(S24:S34) -> 0 | Y35: =Q35/$AC$3 -> 0
B36: TANAMAN BELUM MENGHASILKAN | Y36: =Q36/$AC$3 -> 0
B37: PEMBUATAN PIRINGAN, PASAR RINTIS, TPH DAN TITI PASAR RINTIS | Y37: =Q37/$AC$3 -> 0
C38: Pembuatan Piringan | F38: Upah PHL | G38: HK | O38: =K38*L38*M38*N38 -> 0 | P38: =VLOOKUP($F38,'[1]Master Harga'!$E$5:$L$351,8,FALSE) -> 169122.61 | Q38: =P38*$O38 -> 0 | R38: =VLOOKUP($F38,'[2]Master Harga'!$E$5:$M$348,8,FALSE) -> 179635.86 | S38: =R38*$O38 -> 0 | T38: =VLOOKUP($F38,'[2]Master Harga'!$E$5:$M$348,9,FALSE) -> 197599.45 | U38: =$O38*T38 -> 0 | V38: =W38/O38 -> #DIV/0! | W38: =AVERAGEIF($P$3:$U$3,W$3,$P38:$U38) -> 0 | Y38: =Q38/$AC$3 -> 0
F39: Cangkul | G39: Buah | Y39: =Q39/$AC$3 -> 0
F40: Sepatu Boots | G40: Buah | Y40: =Q40/$AC$3 -> 0
C41: Pembuatan Pasar Rintis | F41: Upah PHL | G41: HK | Y41: =Q41/$AC$3 -> 0
...
