Workbook
Name db_Bln: db!$I:$I
Name db_Kode: db!$J:$J
Name db_Sum: db!$H:$H

Sheet Lembar Pengesahan
C2: LAMBAR PENGESAHAN
C3: RENCANA KERJA PROYEK (RKP)
C4: ='RKP Dermaga T2 Global - Nex'!B4 -> PEKERJAAN DERMAGA SITE SATUI - TAHAP II
C5: PT BUANA KARYA BHAKTI
C7: NO | D7: URAIAN | F7: BIAYA
D9: BIAYA UMUM DAN ADMINISTRASI
C10: I | D10: KARYAWAN | F10: ='RKP Dermaga T2 Global - Nex'!F11 -> 0
C11: II | D11: ADMINISTRASI KANTOR | F11: ='RKP Dermaga T2 Global - Nex'!F28 -> 470000000
C12: III | D12: PEMELIHARAAN | F12: ='RKP Dermaga T2 Global - Nex'!F95 -> 0
C13: IV | D13: PENGEMBANGAN KARYAWAN | F13: ='RKP Dermaga T2 Global - Nex'!F126 -> 0
C14: V | D14: PERJALANAN DINAS | F14: ='RKP Dermaga T2 Global - Nex'!F134 -> 22000000
C15: VI | D15: PENYUSUTAN/ AMORTISASI | F15: ='RKP Dermaga T2 Global - Nex'!F143 -> 0
C16: VII | D16: BEBAN BANK | F16: ='RKP Dermaga T2 Global - Nex'!F171 -> 0
C17: VIII | D17: BEBAN UMUM & ADM. LAINNYA | F17: ='RKP Dermaga T2 Global - Nex'!F174 -> 0
D18: TOTAL BIAYA UMUM DAN ADMINISTRASI | F18: =SUM(F10:F17) -> 492000000
D20: BIAYA KONSTRUKSI
C21: I | D21: CIVIL WORK | F21: ='RKP Dermaga T2 Global - Nex'!F189 -> 14242000000
C22: II | D22: MEKANIKAL | F22: ='RKP Dermaga T2 Global - Nex'!F247 -> 0
C23: III | D23: ELEKTRIKAL | F23: ='RKP Dermaga T2 Global - Nex'!F264 -> 115000000
D24: TOTAL BIAYA KONSTRUKSI | F24: =SUM(F21:F23) -> 14357000000
D26: GRAND TOTAL RKP | F26: =F18+F24 -> 14849000000
C28: * Lampiran adalah lembar yang tidak terpisahkan dari lembar pengesahan ini
E34: Banjarmasin, 20 Mei 2026
C35: Disahkan Oleh, | F35: Dibuat Oleh,
C40: ( Imam Satoto Yudiono ) | F40: ( Herry Munazar )
C41: Direktur Utama | F41: Manager Engineering & Mill Opr

Sheet RKP Dermaga T2 Global - Nex
B1: ESTIMASI BIAYA | I1: REALISASI
B3: RENCANA KERJA PROYEK (RKP)
B4: PEKERJAAN DERMAGA SITE SATUI - TAHAP II
B6: NO | C6: COA | D6: URAIAN | E6: KONTRAKTOR/ SUPPLIER | F6: BUDGET RKP | G6: NO. SPK | H6: KONTRAKTOR/ SUPPLIER | I6: REALISASI BIAYA | R6: CATATAN | T6: RENCANA SEBARAN BIAYA & TIME SCHEDULE
I7: BUDGET RAB | J7: PEKERJAAN UTAMA | N7: PEKERJAAN TAMBAHAN
J8: NILAI KONTRAK | K8: REALISASI KONTRAK | M8: SISA KONTRAK | N8: NILAI KONTRAK | O8: REALISASI PEK. TAMBAH | Q8: SISA KONTRAK | T8: TAHUN 2024 | Y8: TAHUN 2025
K9: Bi | L9: s/d Bi | O9: Bi | P9: s/d Bi | T9: AGT | U9: SEPT | V9: OKT | W9: NOV | X9: DES | Y9: JAN | Z9: FEB | AA9: MAR | AB9: APR | AC9: MEI | AD9: JUN | AE9: JUL | AF9: AGT | AG9: SEPT | AH9: OKT | AI9: NOV | AJ9: DES
B10: A | C10: 512xx00-???^ | D10: BIAYA UMUM DAN ADMINISTRASI | F10: =F11+F28+F95+F126+F129+F134+F143+F171+F174 -> 492000000 | G10: =G11+G28+G95+G126+G129+G134+G143+G171+G174 -> #REF! | H10: =H11+H28+H95+H126+H129+H134+H143+H171+H174 -> #REF! | I10: =I11+I28+I95+I126+I129+I134+I143+I171+I174 -> 0 | J10: =J11+J28+J95+J126+J129+J134+J143+J171+J174 -> 0 | K10: =K11+K28+K95+K126+K129+K134+K143+K171+K174 -> 0 | L10: =L11+L28+L95+L126+L129+L134+L143+L171+L174 -> 0 | M10: =M11+M28+M95+M126+M129+M134+M143+M171+M174 -> 0 | ... AJ10: =AJ11+AJ28+AJ95+AJ126+AJ129+AJ134+AJ143+AJ171+AJ174 -> 0
B11: I | C11: 1??^ | D11: KARYAWAN | F11: =F27 -> 0 | G11: =G27 -> 0 | H11: =H27 -> 0 | I11: =I27 -> 0 | J11: =J27 -> 0 | K11: =K27 -> 0 | L11: =L27 -> 0 | M11: =M27 -> 0 | ... AJ11: =AJ27 -> 0
C12: 51201001012 | D12: Gaji | F12: 0
C13: 51201001022 | D13: Tunjangan Cuti | F13: 0
C14: 51201001032 | D14: Tunjangan Uang Makan | F14: 0
C15: 51201001042 | D15: Tunjangan Transport | F15: 0
C16: 51201001052 | D16: Tunjangan Pengobatan | F16: 0
C17: 51201001062 | D17: Tunjangan Telekomunikasi | F17: 0
C18: 51201001072 | D18: Tunjangan Perumahan | F18: 0
C19: 51201001082 | D19: Tunjangan Hari Raya & Bonus | F19: 0
C20: 51201001092 | D20: Tunjangan Lainnya : | F20: =SUM(F21:F25) -> 0 | G20: =SUM(G21:G25) -> 0 | H20: =SUM(H21:H25) -> 0 | I20: =SUM(I21:I25) -> 0 | J20: =SUM(J21:J25) -> 0 | K20: =SUM(K21:K25) -> 0 | L20: =SUM(L21:L25) -> 0 | M20: =SUM(M21:M25) -> 0 | ... AJ20: =SUM(AJ21:AJ25) -> 0
C21: 51201002 | D21: - BPJS Ketenagakerjaan | F21: 0
C22: 51201002 | D22: - BPJS Kesehatan | F22: 0
C23: 51201002 | D23: - Subsidi BBM/Perawatan | F23: 0
C24: 51201002 | D24: - Lembur Karyawan | F24: 0
C25: 51201002 | D25: - Tunjangan lain-lain | F25: 0
C26: 51201001102 | D26: Imbalan Kerja | F26: 0
D27: TOTAL KARYAWAN | F27: =F12+F13+F14+F15+F16+F17+F18+F19+F20+F26 -> 0 | G27: =G12+G13+G14+G15+G16+G17+G18+G19+G20+G26 -> 0 | H27: =H12+H13+H14+H15+H16+H17+H18+H19+H20+H26 -> 0 | I27: =I12+I13+I14+I15+I16+I17+I18+I19+I20+I26 -> 0 | J27: =J12+J13+J14+J15+J16+J17+J18+J19+J20+J26 -> 0 | K27: =K12+K13+K14+K15+K16+K17+K18+K19+K20+K26 -> 0 | L27: =L12+L13+L14+L15+L16+L17+L18+L19+L20+L26 -> 0 | M27: =M12+M13+M14+M15+M16+M17+M18+M19+M20+M26 -> 0 | ... AJ27: =AJ12+AJ13+AJ14+AJ15+AJ16+AJ17+AJ18+AJ19+AJ20+AJ26 -> 0
B28: II | C28: 2??^ | D28: ADMINISTRASI KANTOR | F28: =F38+F43+F47+F51+F64+F84+F89+F94 -> 470000000 | G28: =G38+G43+G47+G51+G64+G84+G89+G94 -> #REF! | H28: =H38+H43+H47+H51+H64+H84+H89+H94 -> #REF! | I28: =I38+I43+I47+I51+I64+I84+I89+I94 -> 0 | J28: =J38+J43+J47+J51+J64+J84+J89+J94 -> 0 | K28: =K38+K43+K47+K51+K64+K84+K89+K94 -> 0 | L28: =L38+L43+L47+L51+L64+L84+L89+L94 -> 0 | M28: =M38+M43+M47+M51+M64+M84+M89+M94 -> 0 | ... AJ28: =AJ38+AJ43+AJ47+AJ51+AJ64+AJ84+AJ89+AJ94 -> 0
C29: 21?^ | D29: ADMINISTRASI | F29: =F38 -> 0 | G29: =G38 -> 0 | H29: =H38 -> 0 | I29: =I38 -> 0 | J29: =J38 -> 0 | K29: =K38 -> 0 | L29: =L38 -> 0 | M29: =M38 -> 0 | ... AJ29: =AJ38 -> 0
C30: 51201002112 | D30: Alat Tulis Kantor | F30: 0
C31: 51201002122 | D31: Materai | F31: 0
C32: 51201002132 | D32: Pengiriman Surat/Dokumen | F32: 0
C33: 51201002142 | D33: Cetakan/Formulir | F33: 0
C34: 51201002152 | D34: Fotocopy & Jilid | F34: 0
C35: 51201002162 | D35: Iuran & Langganan | F35: 0
C36: 51201002172 | D36: Pakaian Seragam | F36: 0
C37: 51201002182 | D37: Pengiriman Droping / Jasa Pengawalan | F37: 0
D38: SUB TOTAL ADMINISTRASI | F38: =SUM(F30:F37) -> 0 | G38: =SUM(G30:G37) -> 0 | H38: =SUM(H30:H37) -> 0 | I38: =SUM(I30:I37) -> 0 | J38: =SUM(J30:J37) -> 0 | K38: =SUM(K30:K37) -> 0 | L38: =SUM(L30:L37) -> 0 | M38: =SUM(M30:M37) -> 0 | ... AJ38: =SUM(AJ30:AJ37) -> 0
C39: 22?^ | D39: KOMUNIKASI | F39: =F43 -> 0 | G39: =G43 -> 0 | H39: =H43 -> 0 | I39: =I43 -> 0 | J39: =J43 -> 0 | K39: =K43 -> 0 | L39: =L43 -> 0 | M39: =M43 -> 0 | ... AJ39: =AJ43 -> 0
C40: 51201002212 | D40: Radio Komunikasi | F40: 0
C41: 51201002222 | D41: Telekomunikasi | F41: 0
C42: 51201002232 | D42: Vsat | F42: 0
...

Sheet RKP CIVIL WORK
A1: RKP CIVIL WORK
A3: RENCANA KERJA PROYEK (RKP)
A4: PENAMBAHAN KAPASITAS PKS BATULAKI - LINE 3 | Q4: Analisa Kebutuhan Tiang Pancang
A6: NO | B6: URAIAN | C6: VOLUME | J6: HARGA SATUAN | K6: TOTAL | N6: Tiang Pancang uk. 25/25
C7: Panjang | D7: Lebar | E7: Tebal | F7: Jumlah | G7: Jam Kerja | H7: Hari | O7: Sat | P7: Harga KCE | Q7: Harga NBS
A9: 1 | B9: Cut & Fill | K9: =SUM(K10:K11) -> 1080000000 | N9: Tiang Pancang uk. 25/25
B10: Excavator | F10: 2 | G10: 8 | H10: 90 | J10: 500000 | K10: =F10*G10*H10*J10 -> 720000000 | N10: Middle | O10: m' | P10: 270000 | Q10: =230000 -> 230000
B11: Buldozer | F11: 1 | G11: 8 | H11: 90 | J11: 500000 | K11: =F11*G11*H11*J11 -> 360000000 | N11: Bottom | O11: m' | P11: 235000 | Q11: 200000
N12: Harga Tiang Avg | O12: m' | P12: =(P10+P11)/2 -> 252500 | Q12: =(Q10+Q11)/2 -> 215000
A13: 2 | B13: Alat Berat Konstruksi | K13: =K14 -> 720000000 | N13: By Transport Material | O13: m' | P13: 85000 | Q13: 100000
B14: Excavator | F14: 1 | G14: 8 | H14: =12*15 -> 180 | J14: 500000 | K14: =F14*G14*H14*J14 -> 720000000 | N14: Biaya Pemancangan | O14: m' | P14: 200500 | Q14: 75000
N15: By Transport Alat Pancang | Q15: =55000000/(212*8) -> 32429.245
A16: 3 | B16: Pekerjaan Tiang Pancang | C16: 8 | F16: 212 | J16: =P18 -> 538000 | K16: =C16*F16*J16 -> 912448000 | N16: Biaya Las | O16: joint | Q16: =35000/8 -> 4375
B17: Loading Ramp | N17: Handling | O17: m' | Q17: 5000
B18: Main Building I | P18: =SUM(P12:P17) -> 538000 | Q18: =SUM(Q12:Q17) -> 431804.25
B19: Main Building II
P20: =P18*C16*F16 -> 912448000 | Q20: =Q18*C16*F16 -> 732340000
A21: 4 | B21: Beton Bertulang | K21: =K22+K30 -> 16451044400
B22: Beton | F22: =SUM(F23:F28) -> 1678.678 | J22: 6000000 | K22: =F22*J22 -> 10072068000
B23: Loading Ramp | C23: 53.2 | D23: 33.8 | E23: 0.3 | F23: =C23*D23*E23 -> 539.448
B24: Main Building I | C24: 64 | D24: 14.3 | E24: 0.25 | F24: =C24*D24*E24 -> 228.8
B25: Main Building II | C25: 44 | D25: 19.3 | E25: 0.25 | F25: =C25*D25*E25 -> 212.3
B26: Pat Pit | C26: 11 | D26: 8.1 | E26: 0.3 | F26: =C26*D26*E26 -> 26.73
B27: Open Plate Concrete | E27: 0.3 | F27: =140*E27 -> 42
B28: Poer Plat, Pedestal & Balok | F28: =H28 -> 629.4 | H28: =I28*0.6 -> 629.4 | I28: 1049
B30: Besi | F30: =SUM(F31:F36) -> 335735.6 | J30: 19000 | K30: =F30*J30 -> 6378976400
F31: =F23*200 -> 107889.6
F32: =F24*200 -> 45760
F33: =F25*200 -> 42460
F34: =F26*200 -> 5346
F35: =F27*200 -> 8400
F36: =F28*200 -> 125880
A38: 5 | B38: Main Building & Supporting | K38: =K39+K40 -> 8880000000
B39: Main Building I | C39: 60 | D39: 12 | F39: =C39*D39 -> 720 | J39: 6000000 | K39: =F39*J39 -> 4320000000
B40: Main Building II | C40: 40 | D40: 19 | F40: =C40*D40 -> 760 | J40: 6000000 | K40: =F40*J40 -> 4560000000
P42: =C16*F16*P10 -> 457920000
B43: Pos Grading | C43: 4 | D43: 4 | F43: =C43*D43 -> 16 | J43: 4500000 | K43: =F43*J43 -> 72000000 | P43: 340000000
P44: =C16*F16 -> 1696
B45: Kantor Proses | C45: 3 | D45: 6 | F45: =C45*D45 -> 18 | J45: 4500000 | K45: =F45*J45 -> 81000000 | P45: =P43/P44 -> 200471.7
B47: KM/WC | C47: 3 | D47: 8 | F47: =C47*D47 -> 24 | J47: 4500000 | K47: =F47*J47 -> 108000000
...

Sheet RKP Mekanikal
D1: PT KUMAI SENTOSA
D2: ENGINEERING MILL OPERATIONAL
B4: PEMBANGUNAN PABRIK KELAPA SAWIT LINE 3 PT BUANA KARYA BHAKTI
B5: KAPASITAS 30 TON TBS/JAM
B8: No | C8: URAIAN PEKERJAAN | E8: SPESIFIKASI | F8: JUMLAH | H8: HARGA SATUAN FABRIKASI | I8: JUMAH HARGA & INSTAL MESIN | J8: HARGA SUPPLY OWNER | K8: TOTAL HARGA | N8: ELMO & GEARMOTOR | O8: CHAIN | P8: SPROCKET
F9: QTY | G9: SAT
B11: 1 | C11: GENERAL WORKS
C12: A | D12: GA & MOBDEMOB | F12: 1 | G12: LOT | I12: 1200000000 | J12: 750000000 | K12: =I12+J12 -> 1950000000
H14: =SUM(H12:H13) -> 0 | I14: =SUM(I12:I13) -> 1200000000 | J14: =SUM(J12:J13) -> 750000000 | K14: =SUM(K12:K13) -> 1950000000
B15: 2 | C15: MECHANICAL WORKS
C16: A | D16: Fruit Reception
C17: 2 | D17: Fruit Loading Ramp No.1 dan 2 | E17: 25 Pintu, Kapasitas 15 ton/pintu lengkap dengan Hydrolik dan atap conveyor | F17: 1 | G17: Lot | H17: 2500000000 | I17: =H17*F17 -> 2500000000 | K17: =I17+J17 -> 2500000000
C18: 3 | D18: FFB Horizontal Conveyor 1 | E18: Model Scrapper. L 1200x T 1400x P 26,000mm,c/w Platform Operasional & Atap sampai platform penggerak | F18: 26 | G18: m' | H18: 23000000 | I18: =H18*F18 -> 598000000 | J18: =SUM(N18:P18) -> 343000000 | K18: =I18+J18 -> 941000000 | N18: 147000000 | O18: 135000000 | P18: 61000000
C19: 4 | D19: FFB Horizontal Conveyor 2 | E19: Model Scrapper. L 1200x T 1400x P 56,000mm,c/w Platform Operasional & Atap sampai platform penggerak | F19: 56 | G19: m' | H19: 23000000 | I19: =H19*F19 -> 1288000000 | J19: =SUM(N19:P19) -> 476000000 | K19: =I19+J19 -> 1764000000 | N19: 147000000 | O19: 268000000 | P19: 61000000
I20: =SUM(I17:I19) -> 4386000000 | J20: =SUM(J17:J19) -> 819000000 | K20: =SUM(K17:K19) -> 5205000000
C21: B | D21: Sterilizer Station
C22: 1 | D22: FFB Inclined Conveyor | E22: Model Scrapper.L 1200x T 1400x P 44,400mm, c/w Platform Operasional | F22: 44.4 | G22: m' | H22: 23000000 | I22: =H22*F22 -> 1021200000 | J22: =SUM(N22:P22) -> 426000000 | K22: =I22+J22 -> 1447200000 | N22: 147000000 | O22: 218000000 | P22: 61000000
C23: 2 | D23: FFB Distributing Conveyor c/w Chute Hydraulic | E23: Model Scrapper. L 1200x T 1400x P 22,850mm c/w Platform operasional | F23: 22.85 | G23: m' | H23: 23000000 | I23: =H23*F23 -> 5.2555e+08 | J23: =SUM(N23:P23) -> 328000000 | K23: =I23+J23 -> 853550000 | N23: 147000000 | O23: 120000000 | P23: 61000000
C24: 3 | D24: Vertical Sterilizer Cap. 27-30 Ton TBS | E24: Cap. 50M3 , Dia. 3200mm, Tebal Plate, 12mm | F24: 4 | G24: SET | H24: 120000000 | I24: =H24*F24 -> 480000000 | J24: =2050000000*4 -> 8200000000 | K24: =I24+J24 -> 8680000000
C25: 4 | D25: Vacuum Tank (Condensate Tank) | E25: Material Ms Plate.Dia.1200mm,Panjang 3000mm,Kap.11,3 M3 | F25: 4 | G25: Unit | H25: 80000000 | I25: =H25*F25 -> 320000000 | K25: =I25+J25 -> 320000000
C26: 5 | D26: Sterilizer Catwalk for 4 Sterilizer | E26: H Beam 200 x 200 | F26: 1 | G26: LOT | H26: 680000000 | I26: =H26*F26 -> 680000000 | K26: =I26+J26 -> 680000000
C27: 6 | D27: Blow Down and Blow off Chamber | E27: Matr.SUS 306 Tebal 6 6mm,.Dia.1800,Panjang.7500mm | F27: 1 | G27: Unit | H27: 300000000 | I27: =H27*F27 -> 300000000 | K27: =I27+J27 -> 300000000
C28: 7 | D28: Blow Down Exchaust Chamber | E28: Matr.SUS 306 Tebal 6 mm.Dia.1800,Panjang.7500mm | F28: 1 | G28: Unit | H28: 300000000 | I28: =H28*F28 -> 300000000 | K28: =I28+J28 -> 300000000
I30: =SUM(I22:I29) -> 3626750000 | J30: =SUM(J22:J29) -> 8954000000 | K30: =SUM(K22:K29) -> 12580750000
C31: C | D31: Threshing Station
C32: 1 | D32: SFB Auto Feeder for 4 units Sterilizer | E32: Model Scrapper. L 1800x T 1400x P 25.500mm,c/w Platform Operasional | F32: 1 | G32: Unit | H32: 765000000 | I32: =H32*F32 -> 765000000 | J32: =SUM(N32:P32) -> 340000000 | K32: =I32+J32 -> 1105000000 | N32: 147000000 | O32: 132000000 | P32: 61000000
C33: 3 | D33: Inclined Sterilized Fruit Bunch (SFB) Scrapper Conveyor | E33: Model Scrapper. L 1200x T 1400x P 23.500mm,c/w Platform Operasional | F33: 23.5 | G33: m' | H33: 23000000 | I33: =H33*F33 -> 540500000 | J33: =SUM(N33:P33) -> 331000000 | K33: =I33+J33 -> 871500000 | N33: 147000000 | O33: 123000000 | P33: 61000000
C34: 4 | D34: Distributing SFB (Chute Damper) | E34: Untuk Thresher 1 dan 2 | F34: 1 | G34: lot | H34: 55000000 | I34: =H34*F34 -> 55000000 | K34: =I34+J34 -> 55000000
C35: 5 | D35: Structure Thresher | E35: Struktur uk. 2300x5700x6000mm | F35: 2 | G35: Units | H35: 233000000 | I35: =H35*F35 -> 466000000 | K35: =I35+J35 -> 466000000
C36: 6 | D36: Thresher Drum 1&2 | E36: Dimensi 2100 x 4800 mm | F36: 2 | G36: Units | H36: 400000000 | I36: =H36*F36 -> 800000000 | J36: =SUM(N36:P36) -> 240000000 | K36: =I36+J36 -> 1040000000 | N36: =120000000*2 -> 240000000
C37: 7 | D37: Under Thresher Conveyor no. 1 & 2 | E37: Model Screw,Dia.600mm,Panjang 6.000mm | F37: 12 | G37: m' | H37: 12000000 | I37: =H37*F37 -> 144000000 | J37: =SUM(N37:P37) -> 74000000 | K37: =I37+J37 -> 218000000 | N37: =37000000*2 -> 74000000
C38: 8 | D38: Bottom Cross Conveyor | E38: Model Screw,Dia.600mm,Panjang 10,000mm | F38: 10 | G38: Unit | H38: 12000000 | I38: =H38*F38 -> 120000000 | J38: =SUM(N38:P38) -> 21000000 | K38: =I38+J38 -> 141000000 | N38: 21000000
C39: 9 | D39: Horizontal Empty Bunch Scrapper Conveyor c/w Structure, Cat Walk dan Roofing | E39: Model Scrapper. Top Deck, L 750x T 650x P 12,000mm | F39: 12 | G39: m' | H39: 21000000 | I39: =H39*F39 -> 252000000 | J39: =SUM(N39:P39) -> 79500000 | K39: =I39+J39 -> 331500000 | N39: 28000000 | O39: 38500000 | P39: 13000000
C40: 10 | D40: Inclined Empty Bunch Scrapper Conveyor No 1 c/w Structure, Cat Walk dan Roofing | E40: Model Scrapper.Bottom Deck, L 750x T 650x P 26,000mm | F40: 26 | G40: m' | H40: 21000000 | I40: =H40*F40 -> 546000000 | J40: =SUM(N40:P40) -> 129500000 | K40: =I40+J40 -> 675500000 | N40: 46000000 | O40: 70500000 | P40: 13000000
I42: =SUM(I32:I41) -> 3688500000 | J42: =SUM(J32:J41) -> 1215000000 | K42: =SUM(K32:K41) -> 4903500000
C43: D | D43: Empty Bunch Press
C44: 1 | D44: Empty Bunch Press | E44: Sinaco : Model- SBP 125-13/2 | F44: 3 | G44: Unit | H44: 20000000 | I44: =H44*F44 -> 60000000 | J44: =1323000000*3 -> 3969000000 | K44: =I44+J44 -> 4029000000
C45: 2 | D45: Empty Bunch Press Structure | E45: Dimensi 8000 mm x 8000 mm x t 3000 mm | F45: 1 | G45: Lot | H45: 250000000 | I45: =H45*F45 -> 250000000 | K45: =I45+J45 -> 250000000
C46: 3 | D46: Liquor EB Tank | E46: SS 304 6mm, Dimensi 2500mmx1500mmx t 1500mm | F46: 1 | G46: Unit | H46: 115000000 | I46: =H46*F46 -> 115000000 | K46: =I46+J46 -> 115000000
C47: 4 | D47: Liquor EB Pump | E47: Centrifugal Pump, Kap. 30 M3/Jam, Head : 30M', Ukuran Pompa 80 x 50 mm/ Motor 7.5 kw | F47: 2 | G47: Units | H47: 1500000 | I47: =H47*F47 -> 3000000 | J47: =SUM(N47:P47) -> 54000000 | K47: =I47+J47 -> 57000000 | N47: =27000000*2 -> 54000000
...

Sheet RKP Elektrikal
C1: PT BUANA KARYA BHAKTI
C2: ENGINEERING MILL OPERATIONAL
B5: PEMBANGUNAN PABRIK KELAPA SAWIT LINE 3 PT BUANA KARYA BHAKTI
C6: KAPASITAS 30 TON TBS/JAM | L6: KABEL POWER TO MCC
B7: NO | C7: DESCRIPTION | D7: QUANTITY | F7: MERK | G7: SPECIFICATION | H7: UNIT PRICE | I7: TOTAL PRICE | L7: Item | M7: Description | N7: HP | O7: KW | P7: KHA | Q7: MCCB (A) | R7: Qty | T7: TYPE | W7: Merek | X7: Unit Price | Y7: Total Price | Z7: Merek | AA7: Unit Price | AB7: Total Price | AD7: 1 | AE7: LVMDP
AD8: NO | AE8: DESCRIPTION | AF8: Q T Y | AH8: BRAND
B9: I | C9: OWNER SUPPLY | L9: =1 -> 1 | M9: Kabel Power Loading Ramp | N9: =N46 -> 73.756215 | O9: =O46 -> 55 | P9: =P46 -> 130.625 | Q9: 160 | R9: =115*T9 -> 460 | S9: mtr | T9: 4 | U9: x | V9: NYY - 1 x 95 mm | Z9: Supreme | AA9: 171861 | AB9: =AA9*R9 -> 79056060 | AD9: 1 | AE9: Dimensi : 2100(H) x 8000(W) x 1000(D)mm Steel Sheet 2mm, Marine Coating RAL 7032 | AF9: 1 | AG9: UNIT | AH9: SERION
B10: A | C10: General Work & Mob | L10: =L9+1 -> 2 | M10: Kabel Power Sterilizer Station | N10: =N71 -> 211.21098 | O10: =O71 -> 157.5 | P10: =P71 -> 374.0625 | Q10: 500 | R10: =(102+15+4)*T10 -> 484 | S10: mtr | T10: 4 | U10: x | V10: NYY - 1 x 240 mm | Z10: Supreme | AA10: 433894 | AB10: =AA10*R10 -> 210004696 | AH10: Add LVMDP
B11: 1 | C11: General Work & Mob | D11: 1 | E11: LOT | H11: 180000000 | I11: =H11 -> 180000000 | L11: =L10+1 -> 3 | M11: Kabel Power Press & Digester & Thresher | N11: =N97 -> 365.42852 | O11: =O97 -> 272.5 | P11: =P97 -> 647.1875 | Q11: 800 | R11: =(10+82+35+12)*T11 -> 973 | S11: mtr | T11: 7 | U11: x | V11: NYY - 1 x 240 mm | Z11: Supreme | AA11: 433894 | AB11: =AA11*R11 -> 422178862
C12: SUB TOTAL | I12: =I11 -> 180000000 | L12: =L11+1 -> 4 | M12: Kabel Power EFB Press | N12: =N112 -> 386.61667 | O12: =O112 -> 288.3 | P12: =P112 -> 684.7125 | Q12: 800 | R12: =(102+20+55+4)*T12 -> 1267 | S12: mtr | T12: 7 | U12: x | V12: NYY - 1 x 240 mm | Z12: Supreme | AA12: 433894 | AB12: =AA12*R12 -> 549743698 | AD12: 2 | AE12: BUSBAR & SUPPORT & WIRING CONTROL | AF12: 1 | AG12: LOT | AH12: IMPORT
L13: =L12+1 -> 5 | M13: Kabel Power Kernel & Depericarper | N13: =N165 -> 509.9907 | O13: =O165 -> 380.3 | P13: =P165 -> 903.2125 | Q13: 1000 | R13: 812 | S13: mtr | T13: 7 | U13: x | V13: NYY - 1 x 300 mm | Z13: Supreme | AA13: 522477 | AB13: =AA13*R13 -> 424251324 | AD13: F | AE13: OUTGOING FEEDER :
B14: II | C14: PABRIKASI DAN INSTALASI | L14: =L13+1 -> 6 | M14: Kabel Power Klarifikasi | N14: =N210 -> 448.03548 | O14: =O210 -> 334.1 | P14: =P210 -> 793.4875 | Q14: 800 | R14: 1057 | S14: mtr | T14: 7 | U14: x | V14: NYY - 1 x 240 mm | Z14: Supreme | AA14: 433894 | AB14: =AA14*R14 -> 458625958 | AD14: 1 | AE14: MCCB+TM200D (140-200)A 3P 50kA CVS250N, (LV525452) MCC-1 ST.Loading Ramp & S | AF14: 1 | AG14: pc | AH14: Schneider
B15: A | C15: General Work & Mob | L15: =L14+1 -> 7 | M15: Kabel Power Main Ligthting | N15: - | O15: - | P15: - | Q15: 60 | R15: 130 | S15: mtr | T15: 1 | U15: x | V15: NYY - 4 x 10 mm | Z15: Supreme | AA15: 512292 | AB15: =AA15*R15 -> 66597960 | AD15: 2 | AE15: Ampere Meter Via CT(0-200)A, 96x96mm (FT-96-A) | AF15: 1 | AG15: pc | AH15: FORT
B16: 1 | C16: Transportasi Akomodasi | D16: 1 | E16: LOT | H16: 600000000 | I16: =H16 -> 600000000 | L16: =L15+1 -> 8 | M16: Kabel Power to HSS 01 | N16: =N190 -> 60.345994 | O16: =O190 -> 45 | P16: =P190 -> 106.875 | Q16: 125 | R16: 25 | S16: mtr | T16: 1 | U16: x | V16: NYY - 4 x 35 mm | Z16: Supreme | AA16: 272006 | AB16: =AA16*R16 -> 6800150 | AD16: 3 | AE16: CT. 200/5A MSY-30, Burden 2,5 VA (Class 0,5) | AF16: 1 | AG16: pc | AH16: FORT
B17: 2 | C17: Jasa dan Consumable | D17: 1 | E17: LOT | H17: 1300000000 | I17: =H17 -> 1300000000 | L17: =L16+1 -> 9 | M17: Kabel Power to HSS 02 | N17: =N192 -> 60.345994 | O17: =O192 -> 45 | P17: =P192 -> 106.875 | Q17: 125 | R17: 25 | S17: mtr | T17: 1 | U17: x | V17: NYY - 4 x 35 mm | Z17: Supreme | AA17: 272006 | AB17: =AA17*R17 -> 6800150 | AD17: 4 | AE17: MCCB+TM500D (350-500)A 3P 50kA CVS630N (LV563315) MCC-2 STERILIZER | AF17: 1 | AG17: pc | AH17: Schneider
C18: SUB TOTAL | I18: =SUM(I16:I17) -> 1900000000 | L18: =L17+1 -> 10 | M18: Kabel Power to HSS 03 | N18: =N194 -> 60.345994 | O18: =O194 -> 45 | P18: =P194 -> 106.875 | Q18: 125 | R18: 25 | S18: mtr | T18: 1 | U18: x | V18: NYY - 4 x 35 mm | Z18: Supreme | AA18: 272006 | AB18: =AA18*R18 -> 6800150 | AD18: 5 | AE18: Ampere Meter Via CT(0-500)A, 96x96mm (FT-96-A) | AF18: 1 | AG18: pc | AH18: FORT
L19: =L18+1 -> 11 | M19: Kabel Workshop | N19: - | O19: - | P19: - | Q19: 125 | R19: 21 | S19: mtr | T19: 1 | U19: x | V19: NYY - 4 x 35 mm | Z19: Supreme | AA19: 272006 | AB19: =AA19*R19 -> 5712126 | AD19: 6 | AE19: CT. 500/5A MSY-40, Burden 5 VA (Class 0,5) | AF19: 1 | AG19: pc | AH19: FORT
B20: B | C20: Pekerjaan | L20: =L19+1 -> 12 | M20: O/G from MCC-3 to Panel B. Press 01 | N20: =N100 -> 120.69199 | O20: =O100 -> 90 | P20: =P100 -> 213.75 | Q20: 250 | R20: 6 | S20: mtr | T20: 4 | U20: x | V20: NYY - 1 x 95 mm | Z20: Supreme | AA20: 171861 | AB20: =AA20*R20 -> 1031166 | AD20: 7 | AE20: MCCB 800A 3P 50kA NS800N, (33472) + Mic 2.0 Manual Operated MCC-3 ST. Thresher & Press | AF20: 1 | AG20: pc | AH20: Schneider
B21: 1 | C21: Panel LVMDP dan MCC All Stasiun | D21: 1 | E21: LOT | I21: 2500000000 | L21: =L20+1 -> 13 | M21: O/G from MCC-3 to Panel B. Press 02 | N21: =N102 -> 120.69199 | O21: =O102 -> 90 | P21: =P102 -> 213.75 | Q21: 250 | R21: 5 | S21: mtr | T21: 4 | U21: x | V21: NYY - 1 x 95 mm | Z21: Supreme | AA21: 171861 | AB21: =AA21*R21 -> 859305 | AD21: 8 | AE21: Ampere Meter Via CT(0-800)A, 96x96mm (FT-96-A) | AF21: 1 | AG21: pc | AH21: FORT
B22: 2 | C22: Add Busbar LVMDP Existing | D22: 1 | E22: LOT | I22: 1630000000 | L22: =L21+1 -> 14 | M22: O/G from MCC-3 to Panel B. Press 03 | N22: =N104 -> 120.69199 | O22: =O104 -> 90 | P22: =P104 -> 213.75 | Q22: 250 | R22: 6 | S22: mtr | T22: 4 | U22: x | V22: NYY - 1 x 95 mm | Z22: Supreme | AA22: 171861 | AB22: =AA22*R22 -> 1031166 | AD22: 9 | AE22: CT. 800/5A MSY-60, Burden 10 VA (Class 0,5) | AF22: 1 | AG22: pc | AH22: FORT
B23: 3 | C23: Kabel Power to MCC | D23: 1 | E23: LOT | F23: Supreme | H23: =AA31 -> 3000000000 | I23: =H23 -> 3000000000 | L23: =L22+1 -> 15 | M23: O/G from MLDB ke LDB-1 Loading Ramp | N23: - | O23: - | P23: - | Q23: 32 | R23: 75 | S23: mtr | T23: 1 | U23: x | V23: NYY - 4 x 4 mm | Z23: Supreme | AA23: 38801.5 | AB23: =AA23*R23 -> 2910112.5 | AD23: 10 | AE23: MCCB 800A 3P 50kA NS800N, (33472) + Mic 2.0 Manual Operated MCC-4 ST. Bunch Press | AF23: 1 | AG23: pc | AH23: Schneider
B24: 4 | C24: Kabel Power Electromotor | D24: 1 | E24: LOT | F24: Supreme | H24: =AA214 -> 4e+08 | I24: =H24 -> 4e+08 | L24: =L23+1 -> 16 | M24: O/G from MLDB ke LDB-2 Sterilizer | N24: - | O24: - | P24: - | Q24: 32 | R24: 60 | S24: mtr | T24: 1 | U24: x | V24: NYY - 4 x 4 mm | Z24: Supreme | AA24: 38801.5 | AB24: =AA24*R24 -> 2328090 | AD24: 11 | AE24: Ampere Meter Via CT(0-800)A, 96x96mm (FT-96-A) | AF24: 1 | AG24: pc | AH24: FORT
B25: 5 | C25: Penerangan Pabrik | D25: 1 | E25: LOT | H25: =V229 -> 180000000 | I25: =H25 -> 180000000 | L25: =L24+1 -> 17 | M25: O/G from MLDB ke LDB-3 Thresher & Press | N25: - | O25: - | P25: - | Q25: 32 | R25: 25 | S25: mtr | T25: 1 | U25: x | V25: NYY - 4 x 4 mm | Z25: Supreme | AA25: 38801.5 | AB25: =AA25*R25 -> 970037.5 | AD25: 12 | AE25: CT. 800/5A MSY-60, Burden 10 VA (Class 0,5) | AF25: 1 | AG25: pc | AH25: FORT
B26: 6 | C26: Lighting Protection (Penyalur Petir) | D26: 1 | E26: LOT | H26: =V244 -> 60000000 | I26: =H26 -> 60000000 | L26: =L25+1 -> 18 | M26: O/G from MLDB ke LDB-4 Bunch Press | N26: - | O26: - | P26: - | Q26: 32 | R26: 80 | S26: mtr | T26: 1 | U26: x | V26: NYY - 4 x 4 mm | Z26: Supreme | AA26: 38801.5 | AB26: =AA26*R26 -> 3104120 | AD26: 13 | AE26: MCCB (400-1000)A 3P 50kA NS1000N, (33472) + Mic 2.0 Manual Operated MCC- 5 ST. NUT & KERNEL | AF26: 1 | AG26: pc | AH26: Schneider
B27: 7 | C27: Earthing System (Grounding) | D27: 1 | E27: LOT | H27: =V305 -> 80000000 | I27: =H27 -> 80000000 | L27: =L26+1 -> 19 | M27: O/G from MLDB ke LDB-5 (Nut & Kernel) | N27: - | O27: - | P27: - | Q27: 32 | R27: 30 | S27: mtr | T27: 1 | U27: x | V27: NYY - 4 x 4 mm | Z27: Supreme | AA27: 38801.5 | AB27: =AA27*R27 -> 1164045 | AD27: 14 | AE27: Ampere Meter Via CT(0-1000)A, 96x96mm (FT-96-A) | AF27: 1 | AG27: pc | AH27: FORT
B28: 8 | C28: Supply Tray Cable | D28: 1 | E28: LOT | H28: =V292 -> 250000000 | I28: =H28 -> 250000000 | L28: =L27+1 -> 20 | M28: O/G from MLDB ke LDB-6 (Klarifikasi) | N28: - | O28: - | P28: - | Q28: 32 | R28: 15 | S28: mtr | T28: 1 | U28: x | V28: NYY - 4 x 4 mm | Z28: Supreme | AA28: 38801.5 | AB28: =AA28*R28 -> 582022.5 | AD28: 15 | AE28: CT. 1000/5A MSY-60, Burden 10 VA (Class 0,5) | AF28: 1 | AG28: pc | AH28: FORT
B29: 9 | C29: Steam Kontrol | D29: 1 | E29: LOT | H29: =V318 -> 150000000 | I29: =H29 -> 150000000 | L29: =L28+1 -> 21 | M29: Kabel Ground NYA 50, 16,10 mm | R29: 1 | S29: LOT | AA29: 105000000 | AB29: =AA29*R29 -> 105000000 | AD29: 19 | AE29: MCCB 800A 3P 50kA NS800N, (33472) + Mic 2.0 Manual Operated MCC- 6 ST. KLARIFIKASI | AF29: 1 | AG29: pc | AH29: Schneider
L30: TOTAL | AA30: =SUM(AB9:AB29) -> 2.3555512e+09 | AD30: 20 | AE30: Ampere Meter Via CT(0-800)A, 96x96mm (FT-96-A) | AF30: 1 | AG30: pc | AH30: FORT
C31: SUB TOTAL | I31: =SUM(I21:I29) -> 8250000000 | L31: TOTAL PEMBULATAN + KENAIKAN HARGA 10% + PPn 11% | AA31: =AA30*121%+149783049.815 -> 3000000000 | AD31: 21 | AE31: CT. 800/5A MSY-60, Burden 10 VA (Class 0,5) | AF31: 1 | AG31: pc | AH31: FORT
AD32: 55 | AE32: MCCB 60A 3P 25kA EZC250N3200 SDB - 03 MAIN LIGHTING DISTRIBUTION BOARD | AF32: 1 | AG32: pc | AH32: Schneider
B33: TOTAL | I33: =SUM(I12,I18,I31) -> 10330000000 | L33: KABEL POWER ELECTROMOTOR | AD33: 56 | AE33: Ampere Meter Via CT(0-200)A, 96x96mm (FT-96-A) | AF33: 1 | AG33: pc | AH33: FORT
L34: Item | M34: Description | N34: HP | O34: KW | P34: KHA | Q34: Starter | R34: Qty | T34: TYPE | W34: Merek | X34: Unit Price | Y34: Total Price | Z34: Merek | AA34: Unit Price | AB34: Total Price | AD34: 57 | AE34: CT. 60/5A MSY-30, Burden 2,5 VA (Class 0,5) | AF34: 1 | AG34: pc | AH34: FORT
L36: 1 | M36: Loading Ramp
AE37: 1 (Satu) Unit Panel CAPACITOR BANK, 700kVAR/400VAC, 14 STEP (1, 1, 1, 1, 1, 1, 1, 1, 1, 1, 1, 1, 1, 1.)
L38: 1.1 | M38: Pompa Hidrolic Power Pack No. 1 | N38: =1.34102209*O38 -> 7.3756215 | O38: 5.5 | P38: =O38*1.9*1.25 -> 13.0625 | Q38: DOL | R38: 10 | S38: mtr | T38: 1 | U38: x | V38: NYY - 4 x 2,5 mm | W38: Voksel | X38: 25695.6 | Y38: =X38*R38 -> 256956 | Z38: Supreme | AA38: 24920.4 | AB38: =AA38*R38 -> 249204
L39: 1.2 | M39: Pompa Hidrolic Power Pack No. 2 | N39: =1.34102209*O39 -> 7.3756215 | O39: 5.5 | P39: =O39*1.9*1.25 -> 13.0625 | Q39: DOL | R39: 60 | S39: mtr | T39: 1 | U39: x | V39: NYY - 4 x 2,5 mm | W39: Voksel | X39: 25695.6 | Y39: =X39*R39 -> 1541736 | Z39: Supreme | AA39: 24920.4 | AB39: =AA39*R39 -> 1495224 | AE39: Komposisi Komponen :
L40: 1.3 | M40: FFB Horizontal Conveyor No..1 | N40: =1.34102209*O40 -> 29.502486 | O40: 22 | P40: =O40*1.9*1.25 -> 52.25 | Q40: SD | R40: 20 | S40: mtr | T40: 1 | U40: x | V40: NYY - 4 x 10 mm | W40: Voksel | X40: 56011.9 | Y40: =X40*R40 -> 1120238 | Z40: Supreme | AA40: 54322.1 | AB40: =AA40*R40 -> 1086442 | AD40: 1 | AE40: LBS 800A 3P, GGL-800/3 | AF40: 1 | AG40: pc | AH40: FORT
R41: 20 | S41: mtr | T41: 1 | U41: x | V41: NYY - 3 x 10 mm | W41: Voksel | X41: 69310.5 | Y41: =X41*R41 -> 1386210 | Z41: Supreme | AA41: 67219.5 | AB41: =AA41*R41 -> 1344390 | AD41: 2 | AE41: MCCB 100A 3P 18kA EZC250F3125 | AF41: 28 | AG41: pcs | AH41: Schneider
L42: 1.4 | M42: FFB Horizontal Conveyor No..2 | N42: =1.34102209*O42 -> 29.502486 | O42: 22 | P42: =O42*1.9*1.25 -> 52.25 | Q42: SD | R42: 25 | S42: mtr | T42: 1 | U42: x | V42: NYY - 4 x 10 mm | W42: Voksel | X42: 56011.9 | Y42: =X42*R42 -> 1400297.5 | Z42: Supreme | AA42: 86674.9 | AB42: =AA42*R42 -> 2166872.5 | AD42: 3 | AE42: Contactor 3P AC220V LC1-D100M7 For 50 kVAR | AF42: 28 | AG42: pcs | AH42: Schneider
R43: 25 | S43: mtr | T43: 1 | U43: x | V43: NYY - 3 x 10 mm | W43: Voksel | X43: 69310.5 | Y43: =X43*R43 -> 1732762.5 | Z43: Supreme | AA43: 67219.5 | AB43: =AA43*R43 -> 1680487.5 | AD43: 4 | AE43: Aux. Contact LAD8N11 | AF43: 28 | AG43: pcs | AH43: Schneider
...

Sheet Realisasi (2)
B3: TIME SCHEDULE PAYMENT PEMBANGUNAN PKS PT. KUMAI SENTOSA
B4: Sd Juni 2024 | L4: Ket: | N4: Sudah Lunas
N5: Belum Lunas
O6: 2017 | Q6: 2018 | R6: 2019 | S6: 2020 | T6: 0121 | U6: 0221 | V6: 0321 | W6: 0421 | X6: 0521 | Y6: 0621 | Z6: 0721 | AA6: 0821 | AB6: 0921 | AC6: 1021 | AD6: 1121 | AE6: 1221 | AG6: 0122 | AH6: 0222 | AI6: 0322 | AJ6: 0422 | AK6: 0522 | AL6: 0622 | AM6: 0722 | AN6: 0822 | AO6: 0922 | AP6: 1022 | AQ6: 1122 | AR6: 1222 | AT6: 0123 | AU6: 0223 | AV6: 0323 | AW6: 0423 | AX6: 0523 | AY6: 0623 | AZ6: 0723 | BA6: 0823 | BB6: 0923 | BC6: 1023 | BD6: 1123 | BE6: 1223 | BG6: 0124 | BH6: 0224 | BI6: 0324 | BJ6: 0424 | BK6: 0524 | BL6: 0624 | BM6: 0724 | BN6: 0824 | BO6: 0924 | BP6: 1024 | BQ6: 1124 | BR6: 1224
B7: NO | C7: URAIAN | D7: KONTRAKTOR/ SUPPLIER | E7: BUDGET RKP | F7: NO. SPK | G7: KONTRAKTOR/ SUPPLIER | H7: VARIAN BUDGET | I7: BUDGET RAB | J7: NILAI KONTRAK | K7: REALISASI KONTRAK | L7: PEKERJAAN TAMBAHAN | M7: SISA KONTRAK | N7: CATATAN | O7: 2017 | P7: TOTAL | Q7: 2018 | R7: 2019 | S7: 2020 | T7: TAHUN 2021 | AF7: 2021 | AG7: TAHUN 2022 | AS7: 2022 | AT7: 2023 | BG7: 2024 | BT7: SD INI | BU7: CONTROL
Q8: JUMLAH | R8: JUMLAH | S8: JUMLAH | T8: JANUARI | U8: FEBRUARI | V8: MARET | W8: APRIL | X8: MEI | Y8: JUNI | Z8: JULI | AA8: AGUSTUS | AB8: SEPTEMBER | AC8: OKTOBER | AD8: NOPEMBER | AE8: DESEMBER | AF8: JUMLAH | AG8: JANUARI | AH8: FEBRUARI | AI8: MARET | AJ8: APRIL | AK8: MEI | AL8: JUNI | AM8: JULI | AN8: AGUSTUS | AO8: SEPTEMBER | AP8: OKTOBER | AQ8: NOPEMBER | AR8: DESEMBER | AS8: JUMLAH | AT8: JANUARI | AU8: FEBRUARI | AV8: MARET | AW8: APRIL | AX8: MEI | AY8: JUNI | AZ8: JULI | BA8: AGUSTUS | BB8: SEPTEMBER | BC8: OKTOBER | BD8: NOPEMBER | BE8: DESEMBER | BF8: JUMLAH | BG8: JANUARI | BH8: FEBRUARI | BI8: MARET | BJ8: APRIL | BK8: MEI | BL8: JUNI | BM8: JULI | BN8: AGUSTUS | BO8: SEPTEMBER | BP8: OKTOBER | BQ8: NOPEMBER | BR8: DESEMBER | BS8: JUMLAH | BT8: JUMLAH
B9: I | C9: CIVIL WORK
B10: A | C10: PERSIAPAN & PENGUJIAN
A11: A1 | B11: 1 | C11: Konsultan Civil Work | D11: PT. Drei Meta Dinamika | E11: 749250000 | F11: 010/SPK/KS-HO/PIPS/V/2021 | G11: PT. Drei Meta Dinamika | H11: =+IF(E11>K11,E11-K11,0) -> 4159000 | I11: 745091000 | J11: 745091000 | K11: =+O11+Q11+R11+S11+AF11+AS11+BF11+BS11 -> 745091000 | L11: 0 | M11: =J11-K11 -> 0 | N11: -Sudah Lunas | O11: =+SUMIFS(db_Sum,db_Bln,O$6,db_Kode,$A11) -> 0 | P11: =+IF(H11=0,E11-K11,0) -> 0 | Q11: =+SUMIFS(db_Sum,db_Bln,Q$6,db_Kode,$A11) -> 0 | R11: =+SUMIFS(db_Sum,db_Bln,R$6,db_Kode,$A11) -> 0 | S11: =+SUMIFS(db_Sum,db_Bln,S$6,db_Kode,$A11) -> 0 | T11: =+SUMIFS(db_Sum,db_Bln,T$6,db_Kode,$A11) -> 0 | U11: =+SUMIFS(db_Sum,db_Bln,U$6,db_Kode,$A11) -> 0 | V11: =+SUMIFS(db_Sum,db_Bln,V$6,db_Kode,$A11) -> 0 | W11: =+SUMIFS(db_Sum,db_Bln,W$6,db_Kode,$A11) -> 0 | X11: =+SUMIFS(db_Sum,db_Bln,X$6,db_Kode,$A11) -> 0 | ... AE11: =+SUMIFS(db_Sum,db_Bln,AE$6,db_Kode,$A11) -> 76010000 | AF11: =+SUM(T11:AE11) -> 304040000 | AG11: =+SUMIFS(db_Sum,db_Bln,AG$6,db_Kode,$A11) -> 153450000 | AH11: =+SUMIFS(db_Sum,db_Bln,AH$6,db_Kode,$A11) -> 0 | AJ11: =+SUMIFS(db_Sum,db_Bln,AJ$6,db_Kode,$A11) -> 0 | AK11: =+SUMIFS(db_Sum,db_Bln,AK$6,db_Kode,$A11) -> 0 | AL11: =+SUMIFS(db_Sum,db_Bln,AL$6,db_Kode,$A11) -> 0 | AM11: =+SUMIFS(db_Sum,db_Bln,AM$6,db_Kode,$A11) -> 287601000 | AN11: =+SUMIFS(db_Sum,db_Bln,AN$6,db_Kode,$A11) -> 0 | AO11: =+SUMIFS(db_Sum,db_Bln,AO$6,db_Kode,$A11) -> 0 | AP11: =+SUMIFS(db_Sum,db_Bln,AP$6,db_Kode,$A11) -> 0 | AQ11: =+SUMIFS(db_Sum,db_Bln,AQ$6,db_Kode,$A11) -> 0 | AR11: =+SUMIFS(db_Sum,db_Bln,AR$6,db_Kode,$A11) -> 0 | AS11: =+SUM(AG11:AR11) -> 441051000 | AT11: =+SUMIFS(db_Sum,db_Bln,AT$6,db_Kode,$A11) -> 0 | AU11: =+SUMIFS(db_Sum,db_Bln,AU$6,db_Kode,$A11) -> 0 | AV11: =+SUMIFS(db_Sum,db_Bln,AV$6,db_Kode,$A11) -> 0 | AW11: =+SUMIFS(db_Sum,db_Bln,AW$6,db_Kode,$A11) -> 0 | AX11: =+SUMIFS(db_Sum,db_Bln,AX$6,db_Kode,$A11) -> 0 | AY11: =+SUMIFS(db_Sum,db_Bln,AY$6,db_Kode,$A11) -> 0 | AZ11: =+SUMIFS(db_Sum,db_Bln,AZ$6,db_Kode,$A11) -> 0 | BA11: =+SUMIFS(db_Sum,db_Bln,BA$6,db_Kode,$A11) -> 0 | ... BE11: =+SUMIFS(db_Sum,db_Bln,BE$6,db_Kode,$A11) -> 0 | BF11: =+SUM(AT11:BE11) -> 0 | BG11: =+SUMIFS(db_Sum,db_Bln,BG$6,db_Kode,$A11) -> 0 | BH11: =+SUMIFS(db_Sum,db_Bln,BH$6,db_Kode,$A11) -> 0 | BI11: =+SUMIFS(db_Sum,db_Bln,BI$6,db_Kode,$A11) -> 0 | BJ11: =+SUMIFS(db_Sum,db_Bln,BJ$6,db_Kode,$A11) -> 0 | BK11: =+SUMIFS(db_Sum,db_Bln,BK$6,db_Kode,$A11) -> 0 | BL11: =+SUMIFS(db_Sum,db_Bln,BL$6,db_Kode,$A11) -> 0 | BS11: =+SUM(BG11:BR11) -> 0 | BT11: =+SUM(O11,Q11,R11,S11,AF11,AS11,BF11+BS11) -> 745091000 | BU11: =+IF(K11-BT11=0,"OK","ERROR") -> OK
A12: A2 | B12: 2 | C12: PDA Test | D12: PT. Testindo | E12: 50505000 | F12: 10/SPK/KS-PKS/MILL-HO/V/2022 | G12: PT. Testindo | H12: =+IF(E12>K12,E12-K12,0) -> 2775000 | I12: 47730000 | J12: 47730000 | K12: =+O12+Q12+R12+S12+AF12+AS12+BF12+BS12 -> 47730000 | L12: 0 | M12: =J12-K12 -> 0 | N12: -Sudah Lunas | O12: =+SUMIFS(db_Sum,db_Bln,O$6,db_Kode,$A12) -> 0 | P12: =H12 -> 2775000 | Q12: =+SUMIFS(db_Sum,db_Bln,Q$6,db_Kode,$A12) -> 0 | R12: =+SUMIFS(db_Sum,db_Bln,R$6,db_Kode,$A12) -> 0 | S12: =+SUMIFS(db_Sum,db_Bln,S$6,db_Kode,$A12) -> 0 | T12: =+SUMIFS(db_Sum,db_Bln,T$6,db_Kode,$A12) -> 0 | U12: =+SUMIFS(db_Sum,db_Bln,U$6,db_Kode,$A12) -> 0 | V12: =+SUMIFS(db_Sum,db_Bln,V$6,db_Kode,$A12) -> 0 | W12: =+SUMIFS(db_Sum,db_Bln,W$6,db_Kode,$A12) -> 0 | X12: =+SUMIFS(db_Sum,db_Bln,X$6,db_Kode,$A12) -> 0 | ... AE12: =+SUMIFS(db_Sum,db_Bln,AE$6,db_Kode,$A12) -> 0 | AF12: =+SUM(T12:AE12) -> 0 | AG12: =+SUMIFS(db_Sum,db_Bln,AG$6,db_Kode,$A12) -> 0 | AH12: =+SUMIFS(db_Sum,db_Bln,AH$6,db_Kode,$A12) -> 0 | AI12: =+SUMIFS(db_Sum,db_Bln,AI$6,db_Kode,$A12) -> 0 | AJ12: =+SUMIFS(db_Sum,db_Bln,AJ$6,db_Kode,$A12) -> 0 | AK12: =+SUMIFS(db_Sum,db_Bln,AK$6,db_Kode,$A12) -> 47730000 | AL12: =+SUMIFS(db_Sum,db_Bln,AL$6,db_Kode,$A12) -> 0 | AM12: =+SUMIFS(db_Sum,db_Bln,AM$6,db_Kode,$A12) -> 0 | AN12: =+SUMIFS(db_Sum,db_Bln,AN$6,db_Kode,$A12) -> 0 | ... AR12: =+SUMIFS(db_Sum,db_Bln,AR$6,db_Kode,$A12) -> 0 | AS12: =+SUM(AG12:AR12) -> 47730000 | AT12: =+SUMIFS(db_Sum,db_Bln,AT$6,db_Kode,$A12) -> 0 | AU12: =+SUMIFS(db_Sum,db_Bln,AU$6,db_Kode,$A12) -> 0 | AV12: =+SUMIFS(db_Sum,db_Bln,AV$6,db_Kode,$A12) -> 0 | AW12: =+SUMIFS(db_Sum,db_Bln,AW$6,db_Kode,$A12) -> 0 | AX12: =+SUMIFS(db_Sum,db_Bln,AX$6,db_Kode,$A12) -> 0 | AY12: =+SUMIFS(db_Sum,db_Bln,AY$6,db_Kode,$A12) -> 0 | AZ12: =+SUMIFS(db_Sum,db_Bln,AZ$6,db_Kode,$A12) -> 0 | BA12: =+SUMIFS(db_Sum,db_Bln,BA$6,db_Kode,$A12) -> 0 | ... BE12: =+SUMIFS(db_Sum,db_Bln,BE$6,db_Kode,$A12) -> 0 | BF12: =+SUM(AT12:BE12) -> 0 | BG12: =+SUMIFS(db_Sum,db_Bln,BG$6,db_Kode,$A12) -> 0 | BH12: =+SUMIFS(db_Sum,db_Bln,BH$6,db_Kode,$A12) -> 0 | BI12: =+SUMIFS(db_Sum,db_Bln,BI$6,db_Kode,$A12) -> 0 | BJ12: =+SUMIFS(db_Sum,db_Bln,BJ$6,db_Kode,$A12) -> 0 | BK12: =+SUMIFS(db_Sum,db_Bln,BK$6,db_Kode,$A12) -> 0 | BS12: =+SUM(BG12:BR12) -> 0 | BT12: =+SUM(O12,Q12,R12,S12,AF12,AS12,BF12+BS12) -> 47730000 | BU12: =+IF(K12-BT12=0,"OK","ERROR") -> OK
A13: A3 | B13: 3 | C13: Soil Investigasi | D13: PT. Tiyasa Total Rekayasa | E13: 295548600 | F13: 18/SPK/KS-PKS/MILL-HO/VII/2022 | G13: PT. Tiyasa Total Rekayasa | H13: =E13-K13 -> 39638100 | I13: 295548600 | J13: 295548600 | K13: 255910500 | L13: 0 | M13: 0 | N13: -Pekerjaan Final pada 86,59% (Sudah Lunas) | O13: =+SUMIFS(db_Sum,db_Bln,O$6,db_Kode,$A13) -> 0 | P13: =+IF(H13=0,E13-K13,0) -> 0 | Q13: =+SUMIFS(db_Sum,db_Bln,Q$6,db_Kode,$A13) -> 0 | R13: =+SUMIFS(db_Sum,db_Bln,R$6,db_Kode,$A13) -> 0 | S13: =+SUMIFS(db_Sum,db_Bln,S$6,db_Kode,$A13) -> 0 | T13: =+SUMIFS(db_Sum,db_Bln,T$6,db_Kode,$A13) -> 0 | U13: =+SUMIFS(db_Sum,db_Bln,U$6,db_Kode,$A13) -> 0 | V13: =+SUMIFS(db_Sum,db_Bln,V$6,db_Kode,$A13) -> 0 | W13: =+SUMIFS(db_Sum,db_Bln,W$6,db_Kode,$A13) -> 0 | X13: =+SUMIFS(db_Sum,db_Bln,X$6,db_Kode,$A13) -> 0 | ... AE13: =+SUMIFS(db_Sum,db_Bln,AE$6,db_Kode,$A13) -> 0 | AF13: =+SUM(T13:AE13) -> 0 | AG13: =+SUMIFS(db_Sum,db_Bln,AG$6,db_Kode,$A13) -> 0 | AH13: =+SUMIFS(db_Sum,db_Bln,AH$6,db_Kode,$A13) -> 0 | AI13: =+SUMIFS(db_Sum,db_Bln,AI$6,db_Kode,$A13) -> 0 | AJ13: =+SUMIFS(db_Sum,db_Bln,AJ$6,db_Kode,$A13) -> 0 | AK13: =+SUMIFS(db_Sum,db_Bln,AK$6,db_Kode,$A13) -> 0 | AL13: =+SUMIFS(db_Sum,db_Bln,AL$6,db_Kode,$A13) -> 0 | AM13: =+SUMIFS(db_Sum,db_Bln,AM$6,db_Kode,$A13) -> 147774300 | AN13: =+SUMIFS(db_Sum,db_Bln,AN$6,db_Kode,$A13) -> 0 | ... AR13: =+SUMIFS(db_Sum,db_Bln,AR$6,db_Kode,$A13) -> 0 | AS13: =+SUM(AG13:AR13) -> 262470500 | AT13: =+SUMIFS(db_Sum,db_Bln,AT$6,db_Kode,$A13) -> 0 | AU13: =+SUMIFS(db_Sum,db_Bln,AU$6,db_Kode,$A13) -> 0 | AV13: =+SUMIFS(db_Sum,db_Bln,AV$6,db_Kode,$A13) -> 0 | AW13: =+SUMIFS(db_Sum,db_Bln,AW$6,db_Kode,$A13) -> 0 | AX13: =+SUMIFS(db_Sum,db_Bln,AX$6,db_Kode,$A13) -> 0 | AY13: =+SUMIFS(db_Sum,db_Bln,AY$6,db_Kode,$A13) -> 0 | AZ13: =+SUMIFS(db_Sum,db_Bln,AZ$6,db_Kode,$A13) -> 0 | BA13: =+SUMIFS(db_Sum,db_Bln,BA$6,db_Kode,$A13) -> 0 | ... BE13: =+SUMIFS(db_Sum,db_Bln,BE$6,db_Kode,$A13) -> 0 | BF13: =+SUM(AT13:BE13) -> 0 | BG13: =+SUMIFS(db_Sum,db_Bln,BG$6,db_Kode,$A13) -> 0 | BH13: =+SUMIFS(db_Sum,db_Bln,BH$6,db_Kode,$A13) -> 0 | BI13: =+SUMIFS(db_Sum,db_Bln,BI$6,db_Kode,$A13) -> 0 | BJ13: =+SUMIFS(db_Sum,db_Bln,BJ$6,db_Kode,$A13) -> 0 | BK13: =+SUMIFS(db_Sum,db_Bln,BK$6,db_Kode,$A13) -> 0 | BS13: =+SUM(BG13:BR13) -> 0 | BT13: =+SUM(O13,Q13,R13,S13,AF13,AS13,BF13+BS13) -> 262470500 | BU13: =+IF(K13-BT13=0,"OK","ERROR") -> ERROR
C14: -Konsumsi Soil Investigasi | E14: 0 | H14: =E14-K14 -> -6560000 | I14: 0 | J14: 6560000 | K14: 6560000 | L14: 0
A15: A4 | B15: 4 | C15: Core Drill | D15: CV. Teknik Perdana | E15: 13875000 | F15: 19/SPK/KS-PKS/MILL-HO/VII/2022 | G15: CV. Teknik Perdana | H15: =E15-K15 -> -11453750 | I15: 25328750 | J15: 25328750 | K15: =+O15+Q15+R15+S15+AF15+AS15+BF15+BS15 -> 25328750 | L15: 0 | M15: =J15-K15 -> 0 | N15: -Sudah Lunas | O15: =+SUMIFS(db_Sum,db_Bln,O$6,db_Kode,$A15) -> 0 | P15: =+IF(H15=0,E15-K15,0) -> 0 | Q15: =+SUMIFS(db_Sum,db_Bln,Q$6,db_Kode,$A15) -> 0 | R15: =+SUMIFS(db_Sum,db_Bln,R$6,db_Kode,$A15) -> 0 | S15: =+SUMIFS(db_Sum,db_Bln,S$6,db_Kode,$A15) -> 0 | T15: =+SUMIFS(db_Sum,db_Bln,T$6,db_Kode,$A15) -> 0 | U15: =+SUMIFS(db_Sum,db_Bln,U$6,db_Kode,$A15) -> 0 | V15: =+SUMIFS(db_Sum,db_Bln,V$6,db_Kode,$A15) -> 0 | W15: =+SUMIFS(db_Sum,db_Bln,W$6,db_Kode,$A15) -> 0 | X15: =+SUMIFS(db_Sum,db_Bln,X$6,db_Kode,$A15) -> 0 | ... AE15: =+SUMIFS(db_Sum,db_Bln,AE$6,db_Kode,$A15) -> 0 | AF15: =+SUM(T15:AE15) -> 0 | AG15: =+SUMIFS(db_Sum,db_Bln,AG$6,db_Kode,$A15) -> 0 | AH15: =+SUMIFS(db_Sum,db_Bln,AH$6,db_Kode,$A15) -> 0 | AI15: =+SUMIFS(db_Sum,db_Bln,AI$6,db_Kode,$A15) -> 0 | AJ15: =+SUMIFS(db_Sum,db_Bln,AJ$6,db_Kode,$A15) -> 0 | AK15: =+SUMIFS(db_Sum,db_Bln,AK$6,db_Kode,$A15) -> 0 | AL15: =+SUMIFS(db_Sum,db_Bln,AL$6,db_Kode,$A15) -> 0 | AM15: =+SUMIFS(db_Sum,db_Bln,AM$6,db_Kode,$A15) -> 0 | AN15: =+SUMIFS(db_Sum,db_Bln,AN$6,db_Kode,$A15) -> 6937500 | ... AR15: =+SUMIFS(db_Sum,db_Bln,AR$6,db_Kode,$A15) -> 0 | AS15: =+SUM(AG15:AR15) -> 25328750 | AT15: =+SUMIFS(db_Sum,db_Bln,AT$6,db_Kode,$A15) -> 0 | AU15: =+SUMIFS(db_Sum,db_Bln,AU$6,db_Kode,$A15) -> 0 | AV15: =+SUMIFS(db_Sum,db_Bln,AV$6,db_Kode,$A15) -> 0 | AW15: =+SUMIFS(db_Sum,db_Bln,AW$6,db_Kode,$A15) -> 0 | AX15: =+SUMIFS(db_Sum,db_Bln,AX$6,db_Kode,$A15) -> 0 | AY15: =+SUMIFS(db_Sum,db_Bln,AY$6,db_Kode,$A15) -> 0 | AZ15: =+SUMIFS(db_Sum,db_Bln,AZ$6,db_Kode,$A15) -> 0 | BA15: =+SUMIFS(db_Sum,db_Bln,BA$6,db_Kode,$A15) -> 0 | ... BE15: =+SUMIFS(db_Sum,db_Bln,BE$6,db_Kode,$A15) -> 0 | BF15: =+SUM(AT15:BE15) -> 0 | BG15: =+SUMIFS(db_Sum,db_Bln,BG$6,db_Kode,$A15) -> 0 | BH15: =+SUMIFS(db_Sum,db_Bln,BH$6,db_Kode,$A15) -> 0 | BI15: =+SUMIFS(db_Sum,db_Bln,BI$6,db_Kode,$A15) -> 0 | BJ15: =+SUMIFS(db_Sum,db_Bln,BJ$6,db_Kode,$A15) -> 0 | BK15: =+SUMIFS(db_Sum,db_Bln,BK$6,db_Kode,$A15) -> 0 | BS15: =+SUM(BG15:BR15) -> 0 | BT15: =+SUM(O15,Q15,R15,S15,AF15,AS15,BF15+BS15) -> 25328750 | BU15: =+IF(K15-BT15=0,"OK","ERROR") -> OK
A16: A5 | B16: 5 | C16: PDA Test | D16: PT. Klaton Jaya Mandiri | E16: 39960000 | F16: 20/SPK/KS-PKS/MILL-HO/VII/2022 | G16: PT. Klaton Jaya Mandiri | H16: =E16-K16 -> 0 | I16: 39960000 | J16: 39960000 | K16: =+O16+Q16+R16+S16+AF16+AS16+BF16+BS16 -> 39960000 | L16: 0 | M16: =J16-K16 -> 0 | N16: -Sudah Lunas | O16: =+SUMIFS(db_Sum,db_Bln,O$6,db_Kode,$A16) -> 0 | P16: =+IF(H16=0,E16-K16,0) -> 0 | Q16: =+SUMIFS(db_Sum,db_Bln,Q$6,db_Kode,$A16) -> 0 | R16: =+SUMIFS(db_Sum,db_Bln,R$6,db_Kode,$A16) -> 0 | S16: =+SUMIFS(db_Sum,db_Bln,S$6,db_Kode,$A16) -> 0 | T16: =+SUMIFS(db_Sum,db_Bln,T$6,db_Kode,$A16) -> 0 | U16: =+SUMIFS(db_Sum,db_Bln,U$6,db_Kode,$A16) -> 0 | V16: =+SUMIFS(db_Sum,db_Bln,V$6,db_Kode,$A16) -> 0 | W16: =+SUMIFS(db_Sum,db_Bln,W$6,db_Kode,$A16) -> 0 | X16: =+SUMIFS(db_Sum,db_Bln,X$6,db_Kode,$A16) -> 0 | ... AE16: =+SUMIFS(db_Sum,db_Bln,AE$6,db_Kode,$A16) -> 0 | AF16: =+SUM(T16:AE16) -> 0 | AG16: =+SUMIFS(db_Sum,db_Bln,AG$6,db_Kode,$A16) -> 0 | AH16: =+SUMIFS(db_Sum,db_Bln,AH$6,db_Kode,$A16) -> 0 | AI16: =+SUMIFS(db_Sum,db_Bln,AI$6,db_Kode,$A16) -> 0 | AJ16: =+SUMIFS(db_Sum,db_Bln,AJ$6,db_Kode,$A16) -> 0 | AK16: =+SUMIFS(db_Sum,db_Bln,AK$6,db_Kode,$A16) -> 0 | AL16: =+SUMIFS(db_Sum,db_Bln,AL$6,db_Kode,$A16) -> 0 | AM16: =+SUMIFS(db_Sum,db_Bln,AM$6,db_Kode,$A16) -> 0 | AN16: =+SUMIFS(db_Sum,db_Bln,AN$6,db_Kode,$A16) -> 39960000 | ... AR16: =+SUMIFS(db_Sum,db_Bln,AR$6,db_Kode,$A16) -> 0 | AS16: =+SUM(AG16:AR16) -> 39960000 | AT16: =+SUMIFS(db_Sum,db_Bln,AT$6,db_Kode,$A16) -> 0 | AU16: =+SUMIFS(db_Sum,db_Bln,AU$6,db_Kode,$A16) -> 0 | AV16: =+SUMIFS(db_Sum,db_Bln,AV$6,db_Kode,$A16) -> 0 | AW16: =+SUMIFS(db_Sum,db_Bln,AW$6,db_Kode,$A16) -> 0 | AX16: =+SUMIFS(db_Sum,db_Bln,AX$6,db_Kode,$A16) -> 0 | AY16: =+SUMIFS(db_Sum,db_Bln,AY$6,db_Kode,$A16) -> 0 | AZ16: =+SUMIFS(db_Sum,db_Bln,AZ$6,db_Kode,$A16) -> 0 | BA16: =+SUMIFS(db_Sum,db_Bln,BA$6,db_Kode,$A16) -> 0 | ... BE16: =+SUMIFS(db_Sum,db_Bln,BE$6,db_Kode,$A16) -> 0 | BF16: =+SUM(AT16:BE16) -> 0 | BG16: =+SUMIFS(db_Sum,db_Bln,BG$6,db_Kode,$A16) -> 0 | BH16: =+SUMIFS(db_Sum,db_Bln,BH$6,db_Kode,$A16) -> 0 | BI16: =+SUMIFS(db_Sum,db_Bln,BI$6,db_Kode,$A16) -> 0 | BJ16: =+SUMIFS(db_Sum,db_Bln,BJ$6,db_Kode,$A16) -> 0 | BK16: =+SUMIFS(db_Sum,db_Bln,BK$6,db_Kode,$A16) -> 0 | BS16: =+SUM(BG16:BR16) -> 0 | BT16: =+SUM(O16,Q16,R16,S16,AF16,AS16,BF16+BS16) -> 39960000 | BU16: =+IF(K16-BT16=0,"OK","ERROR") -> OK
A17: A6 | B17: 6 | C17: Static Load Test | D17: PT. Geotes Regio Inti | E17: 111000000 | G17: PT. Geotes Regio Inti | H17: =E17-K17 -> -37740000 | I17: 148740000 | J17: 148740000 | K17: =+O17+Q17+R17+S17+AF17+AS17+BF17+BS17 -> 148740000 | L17: 0 | M17: =J17-K17 -> 0 | N17: -Sudah Lunas+Transport | O17: =+SUMIFS(db_Sum,db_Bln,O$6,db_Kode,$A17) -> 0 | P17: =+IF(H17=0,E17-K17,0) -> 0 | Q17: =+SUMIFS(db_Sum,db_Bln,Q$6,db_Kode,$A17) -> 0 | R17: =+SUMIFS(db_Sum,db_Bln,R$6,db_Kode,$A17) -> 0 | S17: =+SUMIFS(db_Sum,db_Bln,S$6,db_Kode,$A17) -> 0 | T17: =+SUMIFS(db_Sum,db_Bln,T$6,db_Kode,$A17) -> 0 | U17: =+SUMIFS(db_Sum,db_Bln,U$6,db_Kode,$A17) -> 0 | V17: =+SUMIFS(db_Sum,db_Bln,V$6,db_Kode,$A17) -> 0 | W17: =+SUMIFS(db_Sum,db_Bln,W$6,db_Kode,$A17) -> 0 | X17: =+SUMIFS(db_Sum,db_Bln,X$6,db_Kode,$A17) -> 0 | ... AE17: =+SUMIFS(db_Sum,db_Bln,AE$6,db_Kode,$A17) -> 0 | AF17: =+SUM(T17:AE17) -> 0 | AG17: =+SUMIFS(db_Sum,db_Bln,AG$6,db_Kode,$A17) -> 0 | AH17: =+SUMIFS(db_Sum,db_Bln,AH$6,db_Kode,$A17) -> 0 | AI17: =+SUMIFS(db_Sum,db_Bln,AI$6,db_Kode,$A17) -> 0 | AJ17: =+SUMIFS(db_Sum,db_Bln,AJ$6,db_Kode,$A17) -> 0 | AK17: =+SUMIFS(db_Sum,db_Bln,AK$6,db_Kode,$A17) -> 0 | AL17: =+SUMIFS(db_Sum,db_Bln,AL$6,db_Kode,$A17) -> 0 | AM17: =+SUMIFS(db_Sum,db_Bln,AM$6,db_Kode,$A17) -> 0 | AN17: =+SUMIFS(db_Sum,db_Bln,AN$6,db_Kode,$A17) -> 36075000 | ... AR17: =+SUMIFS(db_Sum,db_Bln,AR$6,db_Kode,$A17) -> 0 | AS17: =+SUM(AG17:AR17) -> 148740000 | AT17: =+SUMIFS(db_Sum,db_Bln,AT$6,db_Kode,$A17) -> 0 | AU17: =+SUMIFS(db_Sum,db_Bln,AU$6,db_Kode,$A17) -> 0 | AV17: =+SUMIFS(db_Sum,db_Bln,AV$6,db_Kode,$A17) -> 0 | AW17: =+SUMIFS(db_Sum,db_Bln,AW$6,db_Kode,$A17) -> 0 | AX17: =+SUMIFS(db_Sum,db_Bln,AX$6,db_Kode,$A17) -> 0 | AY17: =+SUMIFS(db_Sum,db_Bln,AY$6,db_Kode,$A17) -> 0 | AZ17: =+SUMIFS(db_Sum,db_Bln,AZ$6,db_Kode,$A17) -> 0 | BA17: =+SUMIFS(db_Sum,db_Bln,BA$6,db_Kode,$A17) -> 0 | ... BE17: =+SUMIFS(db_Sum,db_Bln,BE$6,db_Kode,$A17) -> 0 | BF17: =+SUM(AT17:BE17) -> 0 | BG17: =+SUMIFS(db_Sum,db_Bln,BG$6,db_Kode,$A17) -> 0 | BH17: =+SUMIFS(db_Sum,db_Bln,BH$6,db_Kode,$A17) -> 0 | BI17: =+SUMIFS(db_Sum,db_Bln,BI$6,db_Kode,$A17) -> 0 | BJ17: =+SUMIFS(db_Sum,db_Bln,BJ$6,db_Kode,$A17) -> 0 | BK17: =+SUMIFS(db_Sum,db_Bln,BK$6,db_Kode,$A17) -> 0 | BS17: =+SUM(BG17:BR17) -> 0 | BT17: =+SUM(O17,Q17,R17,S17,AF17,AS17,BF17+BS17) -> 148740000 | BU17: =+IF(K17-BT17=0,"OK","ERROR") -> OK
A18: A7 | B18: 7 | C18: Konsultan Lainnya | O18: =+SUMIFS(db_Sum,db_Bln,O$6,db_Kode,$A18) -> 0 | P18: =+IF(H18=0,E18-K18,0) -> 0 | Q18: =+SUMIFS(db_Sum,db_Bln,Q$6,db_Kode,$A18) -> 0 | R18: =+SUMIFS(db_Sum,db_Bln,R$6,db_Kode,$A18) -> 0 | S18: =+SUMIFS(db_Sum,db_Bln,S$6,db_Kode,$A18) -> 50000000 | T18: =+SUMIFS(db_Sum,db_Bln,T$6,db_Kode,$A18) -> 0 | U18: =+SUMIFS(db_Sum,db_Bln,U$6,db_Kode,$A18) -> 23650000 | V18: =+SUMIFS(db_Sum,db_Bln,V$6,db_Kode,$A18) -> 0 | W18: =+SUMIFS(db_Sum,db_Bln,W$6,db_Kode,$A18) -> 23650000 | X18: =+SUMIFS(db_Sum,db_Bln,X$6,db_Kode,$A18) -> 0 | ... AE18: =+SUMIFS(db_Sum,db_Bln,AE$6,db_Kode,$A18) -> 10000000 | AF18: =+SUM(T18:AE18) -> 87300000 | AG18: =+SUMIFS(db_Sum,db_Bln,AG$6,db_Kode,$A18) -> 0 | AH18: =+SUMIFS(db_Sum,db_Bln,AH$6,db_Kode,$A18) -> 0 | AI18: =+SUMIFS(db_Sum,db_Bln,AI$6,db_Kode,$A18) -> 0 | AJ18: =+SUMIFS(db_Sum,db_Bln,AJ$6,db_Kode,$A18) -> 0 | AK18: =+SUMIFS(db_Sum,db_Bln,AK$6,db_Kode,$A18) -> 10000000 | AL18: =+SUMIFS(db_Sum,db_Bln,AL$6,db_Kode,$A18) -> 0 | AM18: =+SUMIFS(db_Sum,db_Bln,AM$6,db_Kode,$A18) -> 0 | AN18: =+SUMIFS(db_Sum,db_Bln,AN$6,db_Kode,$A18) -> 11100000 | ... AR18: =+SUMIFS(db_Sum,db_Bln,AR$6,db_Kode,$A18) -> 0 | AS18: =+SUM(AG18:AR18) -> 32200000 | AT18: =+SUMIFS(db_Sum,db_Bln,AT$6,db_Kode,$A18) -> 0 | AU18: =+SUMIFS(db_Sum,db_Bln,AU$6,db_Kode,$A18) -> 15000000 | AV18: =+SUMIFS(db_Sum,db_Bln,AV$6,db_Kode,$A18) -> 0 | AW18: =+SUMIFS(db_Sum,db_Bln,AW$6,db_Kode,$A18) -> 15000000 | AX18: =+SUMIFS(db_Sum,db_Bln,AX$6,db_Kode,$A18) -> 0 | AY18: =+SUMIFS(db_Sum,db_Bln,AY$6,db_Kode,$A18) -> 0 | AZ18: =+SUMIFS(db_Sum,db_Bln,AZ$6,db_Kode,$A18) -> 0 | BA18: =+SUMIFS(db_Sum,db_Bln,BA$6,db_Kode,$A18) -> 0 | ... BE18: =+SUMIFS(db_Sum,db_Bln,BE$6,db_Kode,$A18) -> 0 | BF18: =+SUM(AT18:BE18) -> 30000000 | BG18: =+SUMIFS(db_Sum,db_Bln,BG$6,db_Kode,$A18) -> 0 | BH18: =+SUMIFS(db_Sum,db_Bln,BH$6,db_Kode,$A18) -> 0 | BI18: =+SUMIFS(db_Sum,db_Bln,BI$6,db_Kode,$A18) -> 0 | BJ18: =+SUMIFS(db_Sum,db_Bln,BJ$6,db_Kode,$A18) -> 0 | BK18: =+SUMIFS(db_Sum,db_Bln,BK$6,db_Kode,$A18) -> 0 | BS18: =+SUM(BG18:BR18) -> 0 | BT18: =+SUM(O18,Q18,R18,S18,AF18,AS18,BF18+BS18) -> 199500000 | BU18: =+IF(K18-BT18=0,"OK","ERROR") -> ERROR
C19: -Dr. Rusdiansyah, ST., MT. | H19: =E19-K19 -> -55000000 | I19: 55000000 | J19: 55000000 | K19: 55000000 | M19: 0 | N19: -Sudah Lunas
C20: -Joni Irawan, ST., MT. | H20: =E20-K20 -> -25000000 | I20: 25000000 | J20: 25000000 | K20: 25000000 | M20: 0 | N20: -Sudah Lunas
C21: -Said Abdurahman | H21: =E21-K21 -> -50000000 | I21: 50000000 | J21: 50000000 | K21: 50000000 | M21: 0 | N21: -Sudah Lunas
C22: -KJPP MPBRU & Rekan | H22: =E22-K22 -> -69500000 | I22: 69500000 | J22: =69500000 -> 69500000 | K22: 69500000 | M22: 0 | N22: -Sudah Lunas
A23: A8 | B23: 8 | C23: Perizinan HGB | H23: =E23-K23 -> -61580600 | J23: 61580600 | K23: =+O23+Q23+R23+S23+AF23+AS23+BF23+BS23 -> 61580600 | L23: 0 | M23: =J23-K23 -> 0 | N23: -Sudah Lunas | O23: =+SUMIFS(db_Sum,db_Bln,O$6,db_Kode,$A23) -> 0 | P23: =+IF(H23=0,E23-K23,0) -> 0 | Q23: =+SUMIFS(db_Sum,db_Bln,Q$6,db_Kode,$A23) -> 0 | R23: =+SUMIFS(db_Sum,db_Bln,R$6,db_Kode,$A23) -> 61580600 | S23: =+SUMIFS(db_Sum,db_Bln,S$6,db_Kode,$A23) -> 0 | T23: =+SUMIFS(db_Sum,db_Bln,T$6,db_Kode,$A23) -> 0 | U23: =+SUMIFS(db_Sum,db_Bln,U$6,db_Kode,$A23) -> 0 | V23: =+SUMIFS(db_Sum,db_Bln,V$6,db_Kode,$A23) -> 0 | W23: =+SUMIFS(db_Sum,db_Bln,W$6,db_Kode,$A23) -> 0 | X23: =+SUMIFS(db_Sum,db_Bln,X$6,db_Kode,$A23) -> 0 | ... AE23: =+SUMIFS(db_Sum,db_Bln,AE$6,db_Kode,$A23) -> 0 | AF23: =+SUM(T23:AE23) -> 0 | AG23: =+SUMIFS(db_Sum,db_Bln,AG$6,db_Kode,$A23) -> 0 | AH23: =+SUMIFS(db_Sum,db_Bln,AH$6,db_Kode,$A23) -> 0 | AI23: =+SUMIFS(db_Sum,db_Bln,AI$6,db_Kode,$A23) -> 0 | AJ23: =+SUMIFS(db_Sum,db_Bln,AJ$6,db_Kode,$A23) -> 0 | AK23: =+SUMIFS(db_Sum,db_Bln,AK$6,db_Kode,$A23) -> 0 | AL23: =+SUMIFS(db_Sum,db_Bln,AL$6,db_Kode,$A23) -> 0 | AM23: =+SUMIFS(db_Sum,db_Bln,AM$6,db_Kode,$A23) -> 0 | AN23: =+SUMIFS(db_Sum,db_Bln,AN$6,db_Kode,$A23) -> 0 | ... AR23: =+SUMIFS(db_Sum,db_Bln,AR$6,db_Kode,$A23) -> 0 | AS23: =+SUM(AG23:AR23) -> 0 | AT23: =+SUMIFS(db_Sum,db_Bln,AT$6,db_Kode,$A23) -> 0 | AU23: =+SUMIFS(db_Sum,db_Bln,AU$6,db_Kode,$A23) -> 0 | AV23: =+SUMIFS(db_Sum,db_Bln,AV$6,db_Kode,$A23) -> 0 | AW23: =+SUMIFS(db_Sum,db_Bln,AW$6,db_Kode,$A23) -> 0 | AX23: =+SUMIFS(db_Sum,db_Bln,AX$6,db_Kode,$A23) -> 0 | AY23: =+SUMIFS(db_Sum,db_Bln,AY$6,db_Kode,$A23) -> 0 | AZ23: =+SUMIFS(db_Sum,db_Bln,AZ$6,db_Kode,$A23) -> 0 | BA23: =+SUMIFS(db_Sum,db_Bln,BA$6,db_Kode,$A23) -> 0 | ... BE23: =+SUMIFS(db_Sum,db_Bln,BE$6,db_Kode,$A23) -> 0 | BF23: =+SUM(AT23:BE23) -> 0 | BG23: =+SUMIFS(db_Sum,db_Bln,BG$6,db_Kode,$A23) -> 0 | BH23: =+SUMIFS(db_Sum,db_Bln,BH$6,db_Kode,$A23) -> 0 | BI23: =+SUMIFS(db_Sum,db_Bln,BI$6,db_Kode,$A23) -> 0 | BJ23: =+SUMIFS(db_Sum,db_Bln,BJ$6,db_Kode,$A23) -> 0 | BK23: =+SUMIFS(db_Sum,db_Bln,BK$6,db_Kode,$A23) -> 0 | BS23: =+SUM(BG23:BR23) -> 0 | BT23: =+SUM(O23,Q23,R23,S23,AF23,AS23,BF23+BS23) -> 61580600 | BU23: =+IF(K23-BT23=0,"OK","ERROR") -> OK
A24: A9 | B24: 9 | C24: Dokumen Tender Mekanikal | D24: PT. Pasifik Arta Indonesia | E24: 0 | H24: =E24-K24 -> -187000000 | I24: 1.87e+08 | J24: 1.87e+08 | K24: =+O24+Q24+R24+S24+AF24+AS24+BF24+BS24 -> 187000000 | L24: 0 | M24: =J24-K24 -> 0 | N24: -Sudah Lunas | Q24: =+SUMIFS(db_Sum,db_Bln,Q$6,db_Kode,$A24) -> 0 | R24: =+SUMIFS(db_Sum,db_Bln,R$6,db_Kode,$A24) -> 0 | S24: =+SUMIFS(db_Sum,db_Bln,S$6,db_Kode,$A24) -> 0 | T24: =+SUMIFS(db_Sum,db_Bln,T$6,db_Kode,$A24) -> 0 | U24: =+SUMIFS(db_Sum,db_Bln,U$6,db_Kode,$A24) -> 0 | V24: =+SUMIFS(db_Sum,db_Bln,V$6,db_Kode,$A24) -> 0 | W24: =+SUMIFS(db_Sum,db_Bln,W$6,db_Kode,$A24) -> 0 | X24: =+SUMIFS(db_Sum,db_Bln,X$6,db_Kode,$A24) -> 0 | ... AE24: =+SUMIFS(db_Sum,db_Bln,AE$6,db_Kode,$A24) -> 0 | AF24: =+SUM(T24:AE24) -> 0 | AG24: =+SUMIFS(db_Sum,db_Bln,AG$6,db_Kode,$A24) -> 0 | AH24: =+SUMIFS(db_Sum,db_Bln,AH$6,db_Kode,$A24) -> 0 | AI24: =+SUMIFS(db_Sum,db_Bln,AI$6,db_Kode,$A24) -> 187000000 | AJ24: =+SUMIFS(db_Sum,db_Bln,AJ$6,db_Kode,$A24) -> 0 | AK24: =+SUMIFS(db_Sum,db_Bln,AK$6,db_Kode,$A24) -> 0 | AL24: =+SUMIFS(db_Sum,db_Bln,AL$6,db_Kode,$A24) -> 0 | AM24: =+SUMIFS(db_Sum,db_Bln,AM$6,db_Kode,$A24) -> 0 | AN24: =+SUMIFS(db_Sum,db_Bln,AN$6,db_Kode,$A24) -> 0 | ... AR24: =+SUMIFS(db_Sum,db_Bln,AR$6,db_Kode,$A24) -> 0 | AS24: =+SUM(AG24:AR24) -> 187000000 | AT24: =+SUMIFS(db_Sum,db_Bln,AT$6,db_Kode,$A24) -> 0 | AU24: =+SUMIFS(db_Sum,db_Bln,AU$6,db_Kode,$A24) -> 0 | AV24: =+SUMIFS(db_Sum,db_Bln,AV$6,db_Kode,$A24) -> 0 | AW24: =+SUMIFS(db_Sum,db_Bln,AW$6,db_Kode,$A24) -> 0 | AX24: =+SUMIFS(db_Sum,db_Bln,AX$6,db_Kode,$A24) -> 0 | AY24: =+SUMIFS(db_Sum,db_Bln,AY$6,db_Kode,$A24) -> 0 | AZ24: =+SUMIFS(db_Sum,db_Bln,AZ$6,db_Kode,$A24) -> 0 | BA24: =+SUMIFS(db_Sum,db_Bln,BA$6,db_Kode,$A24) -> 0 | ... BE24: =+SUMIFS(db_Sum,db_Bln,BE$6,db_Kode,$A24) -> 0 | BF24: =+SUM(AT24:BE24) -> 0 | BG24: =+SUMIFS(db_Sum,db_Bln,BG$6,db_Kode,$A24) -> 0 | BH24: =+SUMIFS(db_Sum,db_Bln,BH$6,db_Kode,$A24) -> 0 | BI24: =+SUMIFS(db_Sum,db_Bln,BI$6,db_Kode,$A24) -> 0 | BJ24: =+SUMIFS(db_Sum,db_Bln,BJ$6,db_Kode,$A24) -> 0 | BK24: =+SUMIFS(db_Sum,db_Bln,BK$6,db_Kode,$A24) -> 0 | BS24: =+SUM(BG24:BR24) -> 0
A25: A10 | B25: 10 | C25: Soil Investigasi | D25: PT. Tiyasa Total Rekayasa | E25: 0 | H25: =E25-K25 -> -77880000 | I25: 77880000 | J25: 77880000 | K25: =+O25+Q25+R25+S25+AF25+AS25+BF25+BS25 -> 77880000 | L25: 0 | M25: 0 | N25: -Sudah Lunas | Q25: =+SUMIFS(db_Sum,db_Bln,Q$6,db_Kode,$A25) -> 0 | R25: =+SUMIFS(db_Sum,db_Bln,R$6,db_Kode,$A25) -> 0 | S25: =+SUMIFS(db_Sum,db_Bln,S$6,db_Kode,$A25) -> 0 | T25: =+SUMIFS(db_Sum,db_Bln,T$6,db_Kode,$A25) -> 0 | U25: =+SUMIFS(db_Sum,db_Bln,U$6,db_Kode,$A25) -> 0 | V25: =+SUMIFS(db_Sum,db_Bln,V$6,db_Kode,$A25) -> 0 | W25: =+SUMIFS(db_Sum,db_Bln,W$6,db_Kode,$A25) -> 38940000 | X25: =+SUMIFS(db_Sum,db_Bln,X$6,db_Kode,$A25) -> 0 | ... AE25: =+SUMIFS(db_Sum,db_Bln,AE$6,db_Kode,$A25) -> 0 | AF25: =+SUM(T25:AE25) -> 77880000 | AG25: =+SUMIFS(db_Sum,db_Bln,AG$6,db_Kode,$A25) -> 0 | AH25: =+SUMIFS(db_Sum,db_Bln,AH$6,db_Kode,$A25) -> 0 | AI25: =+SUMIFS(db_Sum,db_Bln,AI$6,db_Kode,$A25) -> 0 | AJ25: =+SUMIFS(db_Sum,db_Bln,AJ$6,db_Kode,$A25) -> 0 | AK25: =+SUMIFS(db_Sum,db_Bln,AK$6,db_Kode,$A25) -> 0 | AL25: =+SUMIFS(db_Sum,db_Bln,AL$6,db_Kode,$A25) -> 0 | AM25: =+SUMIFS(db_Sum,db_Bln,AM$6,db_Kode,$A25) -> 0 | AN25: =+SUMIFS(db_Sum,db_Bln,AN$6,db_Kode,$A25) -> 0 | ... AR25: =+SUMIFS(db_Sum,db_Bln,AR$6,db_Kode,$A25) -> 0 | AS25: =+SUM(AG25:AR25) -> 0 | AT25: =+SUMIFS(db_Sum,db_Bln,AT$6,db_Kode,$A25) -> 0 | AU25: =+SUMIFS(db_Sum,db_Bln,AU$6,db_Kode,$A25) -> 0 | AV25: =+SUMIFS(db_Sum,db_Bln,AV$6,db_Kode,$A25) -> 0 | AW25: =+SUMIFS(db_Sum,db_Bln,AW$6,db_Kode,$A25) -> 0 | AX25: =+SUMIFS(db_Sum,db_Bln,AX$6,db_Kode,$A25) -> 0 | AY25: =+SUMIFS(db_Sum,db_Bln,AY$6,db_Kode,$A25) -> 0 | AZ25: =+SUMIFS(db_Sum,db_Bln,AZ$6,db_Kode,$A25) -> 0 | BA25: =+SUMIFS(db_Sum,db_Bln,BA$6,db_Kode,$A25) -> 0 | ... BE25: =+SUMIFS(db_Sum,db_Bln,BE$6,db_Kode,$A25) -> 0 | BF25: =+SUM(AT25:BE25) -> 0 | BG25: =+SUMIFS(db_Sum,db_Bln,BG$6,db_Kode,$A25) -> 0 | BH25: =+SUMIFS(db_Sum,db_Bln,BH$6,db_Kode,$A25) -> 0 | BI25: =+SUMIFS(db_Sum,db_Bln,BI$6,db_Kode,$A25) -> 0 | BJ25: =+SUMIFS(db_Sum,db_Bln,BJ$6,db_Kode,$A25) -> 0 | BK25: =+SUMIFS(db_Sum,db_Bln,BK$6,db_Kode,$A25) -> 0
A26: A11 | B26: 11 | C26: Survey Penyelidikan Tanah | D26: PT. Geo Inti Perkasa | E26: 0 | H26: =E26-K26 -> -385000000 | I26: 385000000 | J26: 385000000 | K26: =+O26+Q26+R26+S26+AF26+AS26+BF26+BS26 -> 385000000 | L26: 0 | M26: 0 | N26: -Sudah Lunas | Q26: =+SUMIFS(db_Sum,db_Bln,Q$6,db_Kode,$A26) -> 0 | R26: =+SUMIFS(db_Sum,db_Bln,R$6,db_Kode,$A26) -> 385000000 | S26: =+SUMIFS(db_Sum,db_Bln,S$6,db_Kode,$A26) -> 0 | T26: =+SUMIFS(db_Sum,db_Bln,T$6,db_Kode,$A26) -> 0 | U26: =+SUMIFS(db_Sum,db_Bln,U$6,db_Kode,$A26) -> 0 | V26: =+SUMIFS(db_Sum,db_Bln,V$6,db_Kode,$A26) -> 0 | W26: =+SUMIFS(db_Sum,db_Bln,W$6,db_Kode,$A26) -> 0 | X26: =+SUMIFS(db_Sum,db_Bln,X$6,db_Kode,$A26) -> 0 | ... AE26: =+SUMIFS(db_Sum,db_Bln,AE$6,db_Kode,$A26) -> 0 | AF26: =+SUM(T26:AE26) -> 0 | AG26: =+SUMIFS(db_Sum,db_Bln,AG$6,db_Kode,$A26) -> 0 | AH26: =+SUMIFS(db_Sum,db_Bln,AH$6,db_Kode,$A26) -> 0 | AI26: =+SUMIFS(db_Sum,db_Bln,AI$6,db_Kode,$A26) -> 0 | AJ26: =+SUMIFS(db_Sum,db_Bln,AJ$6,db_Kode,$A26) -> 0 | AK26: =+SUMIFS(db_Sum,db_Bln,AK$6,db_Kode,$A26) -> 0 | AL26: =+SUMIFS(db_Sum,db_Bln,AL$6,db_Kode,$A26) -> 0 | AM26: =+SUMIFS(db_Sum,db_Bln,AM$6,db_Kode,$A26) -> 0 | AN26: =+SUMIFS(db_Sum,db_Bln,AN$6,db_Kode,$A26) -> 0 | ... AR26: =+SUMIFS(db_Sum,db_Bln,AR$6,db_Kode,$A26) -> 0 | AS26: =+SUM(AG26:AR26) -> 0 | AT26: =+SUMIFS(db_Sum,db_Bln,AT$6,db_Kode,$A26) -> 0 | AU26: =+SUMIFS(db_Sum,db_Bln,AU$6,db_Kode,$A26) -> 0 | AV26: =+SUMIFS(db_Sum,db_Bln,AV$6,db_Kode,$A26) -> 0 | AW26: =+SUMIFS(db_Sum,db_Bln,AW$6,db_Kode,$A26) -> 0 | AX26: =+SUMIFS(db_Sum,db_Bln,AX$6,db_Kode,$A26) -> 0 | AY26: =+SUMIFS(db_Sum,db_Bln,AY$6,db_Kode,$A26) -> 0 | AZ26: =+SUMIFS(db_Sum,db_Bln,AZ$6,db_Kode,$A26) -> 0 | BA26: =+SUMIFS(db_Sum,db_Bln,BA$6,db_Kode,$A26) -> 0 | ... BE26: =+SUMIFS(db_Sum,db_Bln,BE$6,db_Kode,$A26) -> 0 | BF26: =+SUM(AT26:BE26) -> 0 | BG26: =+SUMIFS(db_Sum,db_Bln,BG$6,db_Kode,$A26) -> 0 | BH26: =+SUMIFS(db_Sum,db_Bln,BH$6,db_Kode,$A26) -> 0 | BI26: =+SUMIFS(db_Sum,db_Bln,BI$6,db_Kode,$A26) -> 0 | BJ26: =+SUMIFS(db_Sum,db_Bln,BJ$6,db_Kode,$A26) -> 0 | BK26: =+SUMIFS(db_Sum,db_Bln,BK$6,db_Kode,$A26) -> 0
A27: C5 | B27: 12 | C27: Pengukuran Base Meter | D27: PT. JBP | E27: 0 | H27: =E27-K27 -> -164755855 | I27: 164755855 | J27: 164755855 | K27: =+O27+Q27+R27+S27+AF27+AS27+BF27+BS27-1 -> 164755855 | L27: 0 | M27: =J27-K27 -> 0 | N27: -Sudah Lunas | Q27: =+SUMIFS(db_Sum,db_Bln,Q$6,db_Kode,$A27) -> 0 | R27: =+SUMIFS(db_Sum,db_Bln,R$6,db_Kode,$A27) -> 0 | S27: =+SUMIFS(db_Sum,db_Bln,S$6,db_Kode,$A27) -> 0 | T27: =+SUMIFS(db_Sum,db_Bln,T$6,db_Kode,$A27) -> 0 | U27: =+SUMIFS(db_Sum,db_Bln,U$6,db_Kode,$A27) -> 0 | V27: =+SUMIFS(db_Sum,db_Bln,V$6,db_Kode,$A27) -> 0 | W27: =+SUMIFS(db_Sum,db_Bln,W$6,db_Kode,$A27) -> 0 | X27: =+SUMIFS(db_Sum,db_Bln,X$6,db_Kode,$A27) -> 0 | ... AE27: =+SUMIFS(db_Sum,db_Bln,AE$6,db_Kode,$A27) -> 156446950 | AF27: =+SUM(T27:AE27) -> 156446950 | AG27: =+SUMIFS(db_Sum,db_Bln,AG$6,db_Kode,$A27) -> 0 | AH27: =+SUMIFS(db_Sum,db_Bln,AH$6,db_Kode,$A27) -> 0 | AI27: =+SUMIFS(db_Sum,db_Bln,AI$6,db_Kode,$A27) -> 0 | AJ27: =+SUMIFS(db_Sum,db_Bln,AJ$6,db_Kode,$A27) -> 0 | AK27: =+SUMIFS(db_Sum,db_Bln,AK$6,db_Kode,$A27) -> 0 | AL27: =+SUMIFS(db_Sum,db_Bln,AL$6,db_Kode,$A27) -> 0 | AM27: =+SUMIFS(db_Sum,db_Bln,AM$6,db_Kode,$A27) -> 0 | AN27: =+SUMIFS(db_Sum,db_Bln,AN$6,db_Kode,$A27) -> 0 | ... AR27: =+SUMIFS(db_Sum,db_Bln,AR$6,db_Kode,$A27) -> 0 | AS27: =+SUM(AG27:AR27) -> 0 | AT27: =+SUMIFS(db_Sum,db_Bln,AT$6,db_Kode,$A27) -> 0 | AU27: =+SUMIFS(db_Sum,db_Bln,AU$6,db_Kode,$A27) -> 0 | AV27: =+SUMIFS(db_Sum,db_Bln,AV$6,db_Kode,$A27) -> 8308906 | AW27: =+SUMIFS(db_Sum,db_Bln,AW$6,db_Kode,$A27) -> 0 | AX27: =+SUMIFS(db_Sum,db_Bln,AX$6,db_Kode,$A27) -> 0 | AY27: =+SUMIFS(db_Sum,db_Bln,AY$6,db_Kode,$A27) -> 0 | AZ27: =+SUMIFS(db_Sum,db_Bln,AZ$6,db_Kode,$A27) -> 0 | BA27: =+SUMIFS(db_Sum,db_Bln,BA$6,db_Kode,$A27) -> 0 | ... BE27: =+SUMIFS(db_Sum,db_Bln,BE$6,db_Kode,$A27) -> 0 | BF27: =+SUM(AT27:BE27) -> 8308906 | BG27: =+SUMIFS(db_Sum,db_Bln,BG$6,db_Kode,$A27) -> 0 | BH27: =+SUMIFS(db_Sum,db_Bln,BH$6,db_Kode,$A27) -> 0 | BI27: =+SUMIFS(db_Sum,db_Bln,BI$6,db_Kode,$A27) -> 0 | BJ27: =+SUMIFS(db_Sum,db_Bln,BJ$6,db_Kode,$A27) -> 0 | BK27: =+SUMIFS(db_Sum,db_Bln,BK$6,db_Kode,$A27) -> 0
