Workbook
Name \0: #REF!
Name \a: #N/A
Name \b: #N/A
Name \g: #N/A
Name \n: #N/A
Name __kop2: #REF!
Name __s2: #REF!
Name __SKF1: #REF!
Name __SKF2: #REF!
Name _0: #REF!
Name _10_b_1: #REF!
Name _11_g_1: #REF!
Name _12_n_1: #REF!
Name _13Excel_BuiltIn_Database_1: #REF!
Name _14Excel_BuiltIn_Print_Area_1: #REF!
Name _15Excel_BuiltIn_Print_Area_31_1: #REF!
Name _16Excel_BuiltIn_Print_Titles_1: #REF!
Name _432: 432
Name _8_0_1: #REF!
Name _8311: #REF!
Name _9_A_1: #REF!
Name _A: #REF!
Name _A_1: #REF!
Name _A_2: #REF!
Name _A_28: #REF!
Name _A_3: #REF!
Name _A_31: #REF!
Name _A_58: #REF!
Name _A_7: #REF!
Name _A_8: #REF!
Name _A_86: #REF!
Name _A_87: #REF!
Name _A_9: #REF!
Name _b: #REF!
Name _g: #REF!
Name _HOME___FR_PGSE: #REF!
Name _HOME___PG_FRSE: #REF!
Name _kop2: #REF!
Name _n: #REF!
Name _PG: #REF!
Name _Regression_Int: 1
Name _s2: #REF!
Name _SKF1: #REF!
Name _SKF2: #REF!
Name A: #N/A
Name aa: #N/A
Name are: #REF!
Name ari: #REF!
Name bln: #N/A
Name capital: #N/A
Name CC: #REF!
Name CC_31: #REF!
Name CC_7: #REF!
Name CCC: #REF!
Name Cetak: #REF!
Name dea: #N/A
Name df: #REF!
Name edar: #N/A
Name er: #REF!
Name Excel_BuiltIn_Database: #REF!

Sheet RKP
B1: RENCANA KERJA PROYEK ( RKP )
B2: PT. FAST FOREST DEVELOPMENT
B3: KEBUN FFD INTI
B5: LUAS : | D5: 45,36 Ha | E5: Tahun 2026/2027/2028/2029
B6: No. | C6: Pekerjaan | E6: Rencana | H6: TAHUN I ( 2026 ) | R6: TAHUN II ( 2027 ) | AB6: TAHUN III ( 2028 ) | AL6: TAHUN IV ( 2029 )
E7: Proyek 4 Tahun | G7: Harga | H7: Catur Wulan 1 | J7: Catur Wulan 2 | L7: Catur Wulan 3 | N7: Jumlah Tahun I | P7: Jumlah S/d Tahun I | R7: Catur Wulan 1 | T7: Catur Wulan 2 | V7: Catur Wulan 3 | X7: Jumlah Tahun II | Z7: Jumlah S/d Tahun II | AB7: Catur Wulan 1 | AD7: Catur Wulan 2 | AF7: Catur Wulan 3 | AH7: Jumlah Tahun III | AJ7: Jumlah S/d Tahun III | AL7: Catur Wulan 1 | AN7: Catur Wulan 2 | AP7: Catur Wulan 3 | AR7: Jumlah Tahun IV | AT7: Jumlah S/d Tahun IV
E8: Volume | F8: Biaya | G8: Satuan | H8: Fisik | I8: Biaya | J8: Fisik | K8: Biaya | L8: Fisik | M8: Biaya | N8: Fisik | O8: Biaya | P8: Fisik | Q8: Biaya | R8: Fisik | S8: Biaya | T8: Fisik | U8: Biaya | V8: Fisik | W8: Biaya | X8: Fisik | Y8: Biaya | Z8: Fisik | AA8: Biaya | AB8: Fisik | AC8: Biaya | AD8: Fisik | AE8: Biaya | AF8: Fisik | AG8: Biaya | AH8: Fisik | AI8: Biaya | AJ8: Fisik | AK8: Biaya | AL8: Fisik | AM8: Biaya | AN8: Fisik | AO8: Biaya | AP8: Fisik | AQ8: Biaya | AR8: Fisik | AS8: Biaya | AT8: Fisik | AU8: Biaya
E9: ( Ha ) | F9: ( Rp ) | G9: ( Rp / Ha ) | H9: ( Ha ) | I9: ( Rp ) | J9: ( Ha ) | K9: ( Rp ) | L9: ( Ha ) | M9: ( Rp ) | N9: ( Ha ) | O9: ( Rp ) | P9: ( Ha ) | Q9: ( Rp ) | R9: ( Ha ) | S9: ( Rp ) | T9: ( Ha ) | U9: ( Rp ) | V9: ( Ha ) | W9: ( Rp ) | X9: ( Ha ) | Y9: ( Rp ) | Z9: ( Ha ) | AA9: ( Rp ) | AB9: ( Ha ) | AC9: ( Rp ) | AD9: ( Ha ) | AE9: ( Rp ) | AF9: ( Ha ) | AG9: ( Rp ) | AH9: ( Ha ) | AI9: ( Rp ) | AJ9: ( Ha ) | AK9: ( Rp ) | AL9: ( Ha ) | AM9: ( Rp ) | AN9: ( Ha ) | AO9: ( Rp ) | AP9: ( Ha ) | AQ9: ( Rp ) | AR9: ( Ha ) | AS9: ( Rp ) | AT9: ( Ha ) | AU9: ( Rp )
B10: 1 | C10: Reklamasi TB | E10: 45.36 | F10: =E10*G10 -> 3.7711084e+09 | G10: ='REKAP BIAYA'!F50 -> 83137310 | H10: =$E$10/3 -> 15.12 | I10: =H10*$G10 -> 1.2570361e+09 | J10: =$E$10/3 -> 15.12 | K10: =J10*$G10 -> 1.2570361e+09 | L10: =$E$10/3 -> 15.12 | M10: =L10*$G10 -> 1.2570361e+09 | N10: =H10+J10+L10 -> 45.36 | O10: =I10+K10+M10 -> 3.7711084e+09 | P10: =N10 -> 45.36 | Q10: =O10 -> 3.7711084e+09 | Z10: =P10 -> 45.36 | AA10: =Q10 -> 3.7711084e+09 | AJ10: =Z10 -> 45.36 | AK10: =AA10 -> 3.7711084e+09 | AT10: =AJ10 -> 45.36 | AU10: =AK10 -> 3.7711084e+09
B11: 2 | C11: Pemeliharaan TBM-1 | E11: =E10 -> 45.36 | F11: =E11*G11 -> 5.0081171e+08 | G11: ='REKAP BIAYA'!N41 -> 11040823 | I11: =H11*$G11 -> 0 | K11: =J11*$G11 -> 0 | M11: =L11*$G11 -> 0 | N11: =H11+J11+L11 -> 0 | O11: =I11+K11+M11 -> 0 | P11: =N11 -> 0 | Q11: =O11 -> 0 | R11: =$E$11/3 -> 15.12 | S11: =R11*$G11 -> 1.6693724e+08 | T11: =$E$11/3 -> 15.12 | U11: =T11*$G11 -> 1.6693724e+08 | V11: =$E$11/3 -> 15.12 | W11: =V11*$G11 -> 1.6693724e+08 | X11: =R11+T11+V11 -> 45.36 | Y11: =S11+U11+W11 -> 5.0081171e+08 | Z11: =X11+P11 -> 45.36 | AA11: =Y11+Q11 -> 5.0081171e+08 | AC11: =AB11*$G11 -> 0 | AE11: =AD11*$G11 -> 0 | AG11: =AF11*$G11 -> 0 | AH11: =AB11+AD11+AF11 -> 0 | AI11: =AC11+AE11+AG11 -> 0 | AJ11: =AH11+Z11 -> 45.36 | AK11: =AI11+AA11 -> 5.0081171e+08 | AM11: =AL11*$G11 -> 0 | AO11: =AN11*$G11 -> 0 | AQ11: =AP11*$G11 -> 0 | AR11: =AL11+AN11+AP11 -> 0 | AS11: =AM11+AO11+AQ11 -> 0 | AT11: =AR11+AJ11 -> 45.36 | AU11: =AS11+AK11 -> 5.0081171e+08
B12: 3 | C12: Pemeliharaan TBM-2 | E12: =E11 -> 45.36 | F12: =E12*G12 -> 5.9017324e+08 | G12: ='REKAP BIAYA'!V40 -> 13010874 | I12: =H12*$G12 -> 0 | K12: =J12*$G12 -> 0 | M12: =L12*$G12 -> 0 | N12: =H12+J12+L12 -> 0 | O12: =I12+K12+M12 -> 0 | P12: =N12 -> 0 | Q12: =O12 -> 0 | R12: =L11/3 -> 0 | S12: =R12*$G12 -> 0 | T12: =R12 -> 0 | U12: =T12*$G12 -> 0 | V12: =T12 -> 0 | W12: =V12*$G12 -> 0 | X12: =R12+T12+V12 -> 0 | Y12: =S12+U12+W12 -> 0 | Z12: =X12+P12 -> 0 | AA12: =Y12+Q12 -> 0 | AB12: =$E$12/3 -> 15.12 | AC12: =AB12*$G12 -> 1.9672441e+08 | AD12: =$E$12/3 -> 15.12 | AE12: =AD12*$G12 -> 1.9672441e+08 | AF12: =$E$12/3 -> 15.12 | AG12: =AF12*$G12 -> 1.9672441e+08 | AH12: =X11 -> 45.36 | AI12: =AC12+AE12+AG12 -> 5.9017324e+08 | AJ12: =AH12+Z12 -> 45.36 | AK12: =AI12+AA12 -> 5.9017324e+08 | AL12: =AH11/3 -> 0 | AM12: =AL12*$G12 -> 0 | AN12: =AL12 -> 0 | AO12: =AN12*$G12 -> 0 | AP12: =AN12 -> 0 | AQ12: =AP12*$G12 -> 0 | AR12: =AL12+AN12+AP12 -> 0 | AS12: =AM12+AO12+AQ12 -> 0 | AT12: =AR12+AJ12 -> 45.36 | AU12: =AS12+AK12 -> 5.9017324e+08
B13: 4 | C13: Pemeliharaan TBM-3 | E13: =E12 -> 45.36 | F13: =E13*G13 -> 8.4939897e+08 | G13: ='REKAP BIAYA'!AD42 -> 18725727 | I13: =H13*$G13 -> 0 | K13: =J13*$G13 -> 0 | M13: =L13*$G13 -> 0 | N13: =H13+J13+L13 -> 0 | O13: =I13+K13+M13 -> 0 | P13: =N13 -> 0 | Q13: =O13 -> 0 | S13: =R13*$G13 -> 0 | U13: =T13*$G13 -> 0 | W13: =V13*$G13 -> 0 | X13: =R13+T13+V13 -> 0 | Y13: =S13+U13+W13 -> 0 | Z13: =X13+P13 -> 0 | AA13: =Y13+Q13 -> 0 | AB13: =R12 -> 0 | AC13: =AB13*$G13 -> 0 | AD13: =AB13 -> 0 | AE13: =AD13*$G13 -> 0 | AF13: =AD13 -> 0 | AG13: =AF13*$G13 -> 0 | AH13: =AB13+AD13+AF13 -> 0 | AI13: =AC13+AE13+AG13 -> 0 | AJ13: =AH13+Z13 -> 0 | AK13: =AI13+AA13 -> 0 | AL13: =$E$13/3 -> 15.12 | AM13: =AL13*$G13 -> 2.8313299e+08 | AN13: =$E$13/3 -> 15.12 | AO13: =AN13*$G13 -> 2.8313299e+08 | AP13: =$E$13/3 -> 15.12 | AQ13: =AP13*$G13 -> 2.8313299e+08 | AR13: =AL13+AN13+AP13 -> 45.36 | AS13: =AM13+AO13+AQ13 -> 8.4939897e+08 | AT13: =AR13+AJ13 -> 45.36 | AU13: =AS13+AK13 -> 8.4939897e+08
B14: GRAND TOTAL BIAYA | E14: =E10 -> 45.36 | F14: =SUM(F10:F13) -> 5.7114923e+09 | G14: =F14/E14 -> 1.2591473e+08 | I14: =SUM(I10:I13) -> 1.2570361e+09 | K14: =SUM(K10:K13) -> 1.2570361e+09 | M14: =SUM(M10:M13) -> 1.2570361e+09 | O14: =SUM(O10:O13) -> 3.7711084e+09 | Q14: =SUM(Q10:Q13) -> 3.7711084e+09 | S14: =SUM(S10:S13) -> 1.6693724e+08 | U14: =SUM(U10:U13) -> 1.6693724e+08 | W14: =SUM(W10:W13) -> 1.6693724e+08 | Y14: =SUM(Y10:Y13) -> 5.0081171e+08 | AA14: =SUM(AA10:AA13) -> 4.2719201e+09 | AC14: =SUM(AC10:AC13) -> 1.9672441e+08 | AE14: =SUM(AE10:AE13) -> 1.9672441e+08 | AG14: =SUM(AG10:AG13) -> 1.9672441e+08 | AI14: =SUM(AI10:AI13) -> 5.9017324e+08 | AK14: =SUM(AK10:AK13) -> 4.8620933e+09 | AM14: =SUM(AM10:AM13) -> 2.8313299e+08 | AO14: =SUM(AO10:AO13) -> 2.8313299e+08 | AQ14: =SUM(AQ10:AQ13) -> 2.8313299e+08 | AS14: =SUM(AS10:AS13) -> 8.4939897e+08 | AU14: =SUM(AU10:AU13) -> 5.7114923e+09
I18: Disetujui Oleh ; | J18: Diperiksa Oleh ; | L18: Disusun Oleh ; | AS18: Satui, 30 September 2025
N19: Diketahui Oleh ; | X19: Disetujui Oleh ; | AI19: Diperiksa Oleh ; | AS19: Disusun Oleh ;
AS20: Samsir Hadi
I22: Direktur | J22: Pjs. GM Agronomy | L22: Askep Project Re-Planting & Reklamasi | N22: Imam Satoto Yudiono | X22: Hairul Amri | AI22: A r i f
N23: Direktur Utama | X23: Direktur | AI23: Pjs. GM Agronomy | AS23: Askep Project Re-Planting & Reklamasi

Sheet REKAP BIAYA
A2: 45.36 | B2: 45.36
A3: 45.36 | B3: REKAPITULASI RENCANA BIAYA REPLANTING, PERAWATAN TBM 01 TBM 02 TBM 03 BKB INTI TAHUN TANAM 1998 & 1999
B4: TB | J4: TBM 1 | R4: TBM 2 | Z4: TBM 3
B5: No | C5: Pekerjaan | E5: Jumlah Rp | F5: Total Rp | G5: Rp/Ha | H5: Persentase (%) | J5: No | K5: Pekerjaan | M5: Jumlah Rp | N5: Total Rp | O5: Rp/Ha | P5: Persentase (%) | R5: No | S5: Pekerjaan | U5: Jumlah Rp | V5: Total Rp | W5: Rp/Ha | X5: Persentase (%) | Z5: No | AA5: Pekerjaan | AC5: Jumlah Rp | AD5: Total Rp | AE5: Rp/Ha | AF5: Persentase (%)
B6: 1 | C6: Pembukaan Lahan CECT | D6: Identifikasi Blok | E6: ='SI TB LC'!Q7 -> 1690890.6 | F6: =SUM(E6:E11) -> 2.3232915e+09 | G6: =F6/A2 -> 51218948 | H6: =F6/$F$49*100 -> 61.607656 | J6: 1 | K6: Pembuatan Piringan & Titi Pasar Rintis | L6: Pembuatan Piringan | M6: =SUM('S1 TBM 1'!S38:S40) -> 18088740 | N6: =SUM(M6:M7) -> 27359242 | O6: =N6/A3 -> 603157.9 | P6: =N6/N40*100 -> 5.4629797 | R6: 1 | S6: Pemeliharaan Piringan Gawangan Manual & Chemist | T6: Pemeliharaan Piringan Manual | U6: =SUM('S1 TBM 2'!Q59:Q61) -> 19258405 | V6: =SUM(U6:U9) -> 1.0294864e+08 | W6: =V6/$A$3 -> 2269590.8 | X6: =V6/V39*100 -> 17.443799 | Z6: 1 | AA6: Pembuatan TPH, Pemeliharaan Piringan Gawangan Manual & Chemist | AB6: Pembuatan TPH | AC6: =SUM('S1 TBM 3'!Q44:Q46) -> 1105150.9 | AD6: =SUM(AC6:AC11) -> 1.5077158e+08 | AE6: =AD6/$A$3 -> 3323888.4 | AF6: =AD6/AD41*100 -> 17.750384
D7: Reklamasi | E7: =SUM('SI TB LC'!Q22) -> 2.265419e+09 | L7: Pembuatan Titi Pasar Rintis | M7: =SUM('S1 TBM 1'!S48:S50) -> 9270502.6 | T7: Pemeliharaan Piringan /Pasar Rintis(Chemist) | U7: =SUM('S1 TBM 2'!Q71:Q82) -> 27873463 | AB7: Pemeliharaan Piringan Manual | AC7: =SUM('S1 TBM 3'!Q60:Q62) -> 20509002
D8: Tumbang Chipping | E8: =SUM('SI TB LC'!Q27:Q32) -> 0 | J8: 2 | K8: Pemeliharaan Piringan Gawangan Manual & Chemist | L8: Pemeliharaan Piringan Manual | M8: =SUM('S1 TBM 1'!S61:S63) -> 18084081 | N8: =SUM(M8:M11) -> 68028918 | O8: =N8/A3 -> 1499755.7 | P8: =N8/N40*100 -> 13.583732 | T8: Pemeliharaan Gawangan Manual | U8: =SUM('S1 TBM 2'!Q106:Q108) -> 30829753 | AB8: Pemeliharaan Piringan /Pasar Rintis(Chemist) | AC8: =SUM('S1 TBM 3'!Q73:Q84) -> 29532889
D9: Parit CECT | E9: =SUM('SI TB LC'!Q33:Q35) -> 0 | L9: Pemeliharaan Piringan /Pasar Rintis(Chemist) | M9: =SUM('S1 TBM 1'!S73:S83) -> 6970393.7 | T9: Pemeliharaan Gawangan Chemist | U9: =SUM('S1 TBM 2'!Q113:Q124) -> 24987016 | AB9: Pemeliharaan Pasar Rintis Manual | AC9: =SUM('S1 TBM 3'!Q67:Q69) -> 40981776
D10: Tutup Lubang CECT | E10: =SUM('SI TB LC'!Q36:Q38) -> 0 | L10: Pemeliharaan Gawangan Manual | M10: =SUM('S1 TBM 1'!S107:S109) -> 36153253 | R10: 2 | S10: Pemberantasan Lalang | T10: Spot Lalang | U10: =SUM('S1 TBM 2'!Q150:Q159) -> 6057801 | V10: =SUM(U10:U12) -> 21573096 | W10: =V10/$A$3 -> 475597.36 | X10: =V10/V39*100 -> 3.6553836 | AB10: Pemeliharaan Gawangan Manual | AC10: =SUM('S1 TBM 3'!Q108:Q110) -> 32831525
D11: Lubang Tanam Mekanis Auger | E11: =SUM('SI TB LC'!Q40:Q43) -> 56181558 | L11: Pemeliharaan Gawangan Chemist | M11: =SUM('S1 TBM 1'!S114:S125) -> 6821190.7 | T11: Wipping | U11: =SUM('S1 TBM 2'!Q160:Q168) -> 11356766 | AB11: Pemeliharaan Gawangan Chemist | AC11: =SUM('S1 TBM 3'!Q115:Q126) -> 25811237
B12: 2 | C12: Pembukaan Lahan Serak | D12: Identifikasi Blok | E12: 0 | F12: =SUM(E12:E16) -> 0 | G12: =F12/B2 -> 0 | H12: =F12/F49*100 -> 0 | J12: 3 | K12: Pemberantasan Lalang | L12: Spot Lalang | M12: =SUM('S1 TBM 1'!S151:S160) -> 5705960.9 | N12: =SUM(M12:M14) -> 21209889 | O12: =N12/A3 -> 467590.15 | P12: =N12/N40*100 -> 4.2351025 | T12: Transport Air | U12: =SUM('S1 TBM 2'!Q171) -> 4158529.7 | Z12: 2 | AA12: Pemberantasan Lalang | AB12: Wipping | AC12: =SUM('S1 TBM 3'!Q162:Q170) -> 12066338 | AD12: =SUM(AC12:AC13) -> 16432794 | AE12: =AD12/$A$3 -> 362275.01 | AF12: =AD12/AD41*100 -> 1.9346379
D13: Pengolahan Tanah (Ripping) | E13: 0 | L13: Wipping | M13: =SUM('S1 TBM 1'!S161:S170) -> 11543424 | R13: 3 | S13: Pemeliharaan Pokok | T13: Kastrasi | U13: =SUM('S1 TBM 2'!Q179:Q183) -> 46250140 | V13: =SUM(U13:U15) -> 64597752 | W13: =V13/$A$3 -> 1424112.7 | X13: =V13/V39*100 -> 10.945558 | AB13: Transport Air | AC13: =SUM('S1 TBM 3'!Q173) -> 4366456.1
D14: Tumbang Chipping | E14: 0 | L14: Transport Air | M14: =SUM('S1 TBM 1'!S173) -> 3960504.4 | T14: Penyisipan | U14: =SUM('S1 TBM 2'!Q186:Q189) -> 10644442 | Z14: 3 | AA14: Pemeliharaan Pokok | AB14: Sanitasi | AC14: =SUM('S1 TBM 3'!Q177:Q180) -> 16368312 | AD14: =SUM(AC14:AC17) -> 32780557 | AE14: =AD14/$A$3 -> 722675.42 | AF14: =AD14/AD41*100 -> 3.859265
D15: Tutup Lubang | E15: 0 | J15: 4 | K15: Pemeliharaan Pokok | L15: Penyisipan | M15: =SUM('S1 TBM 1'!S187:S190) -> 15146350 | N15: =SUM(M15:M17) -> 31142588 | O15: =N15/A3 -> 686564.98 | P15: =N15/N40*100 -> 6.2184224 | T15: Survey dan Sensus | U15: =SUM('S1 TBM 2'!Q194:Q195) -> 7703170.1 | AB15: Kastrasi | AC15: =SUM('S1 TBM 3'!Q182:Q186) -> 8208845.5
D16: Lubang Tanam Mekanis Auger | E16: 0 | L16: Konsolidasi | M16: =SUM('S1 TBM 1'!S192:S193) -> 13084704 | R16: 4 | S16: Pemeliharaan Prasarana | T16: Jalan Utama / Jalan Akses | U16: =SUM('S1 TBM 2'!Q200:Q205) -> 0 | V16: =SUM(U16:U24) -> 0 | W16: =V16/$A$3 -> 0 | X16: =V16/V39*100 -> 0 | AB16: Penyisipan | AC16: =SUM('S1 TBM 3'!Q189:Q192) -> 0
B17: 3 | C17: Penyemprotan Lalang Gulma & Pasar Rintis | D17: Penyemprotan Pasar Rintis | E17: =SUM('SI TB LC'!Q57:Q67) -> 0 | F17: =SUM(E17) -> 0 | G17: =F17/A3 -> 0 | H17: =F17/F49*100 -> 0 | L17: Survey dan Sensus | M17: =SUM('S1 TBM 1'!S195:S196) -> 2911533.3 | T17: Jalan Produksi | U17: =SUM('S1 TBM 2'!Q206:Q211) -> 0 | AB17: Survey dan Sensus | AC17: =SUM('S1 TBM 3'!Q197:Q198) -> 8203399.6
D18: Pemberantasan Lalang | E18: =SUM('SI TB LC'!Q44:Q56) -> 16479790 | F18: =SUM(E18) -> 16479790 | G18: =F18/A3 -> 363311.06 | H18: =F18/F49*100 -> 0.43700122 | J18: 5 | K18: Pemeliharaan Prasarana | L18: Jalan Utama / Jalan Akses | M18: =SUM('S1 TBM 1'!S201:S206) -> 0 | N18: =SUM(M18:M26) -> 0 | O18: =N18/A3 -> 0 | P18: =N18/N40*100 -> 0 | T18: Jalan Koleksi | U18: =SUM('S1 TBM 2'!Q212:Q217) -> 0 | Z18: 4 | AA18: Pemeliharaan Prasarana | AB18: Jalan Utama / Jalan Akses | AC18: =SUM('S1 TBM 3'!Q203:Q208) -> 0 | AD18: =SUM(AC18:AC26) -> 0 | AE18: =AD18/$A$3 -> 0 | AF18: =AD18/AD41*100 -> 0
B19: 4 | C19: Pembuatan Sarana & Prasarana | D19: Pembuatan Parit Tersier (1x1) | E19: =SUM('SI TB LC'!Q123:Q124) -> 24309486 | F19: =SUM(E19:E24) -> 1.6514983e+08 | G19: =E19/A2 -> 535923.42 | H19: =F19/F49*100 -> 4.3793445 | L19: Jalan Produksi | M19: =SUM('S1 TBM 1'!S207:S212) -> 0 | T19: Jalan Pringgan / Ring | U19: =SUM('S1 TBM 2'!Q218:Q223) -> 0 | AB19: Jalan Produksi | AC19: =SUM('S1 TBM 3'!Q209:Q214) -> 0
D20: Cuci Parit Alam (1x1) Parit Alam | E20: =SUM('SI TB LC'!Q131:Q132) -> 18306669 | G20: =E20/A3 -> 403586.17 | L20: Jalan Koleksi | M20: =SUM('S1 TBM 1'!S213:S218) -> 0 | T20: Jalan Liung | U20: =SUM('S1 TBM 2'!Q224:Q228) -> 0 | AB20: Jalan Koleksi | AC20: =SUM('S1 TBM 3'!Q215:Q220) -> 0
D21: Pembuatan Jembatan | E21: =SUM('SI TB LC'!Q105:Q107) -> 60119641 | G21: =E21/46.36 -> 1296799.9 | L21: Jalan Pringgan / Ring | M21: =SUM('S1 TBM 1'!S219:S224) -> 0 | T21: Jembatan Permanen | U21: =SUM('S1 TBM 2'!Q238:Q249) -> 0 | AB21: Jalan Pringgan / Ring | AC21: =SUM('S1 TBM 3'!Q221:Q226) -> 0
D22: Pembuatan Kontur Teras | E22: 0 | G22: =E22/11.1 -> 0 | L22: Jalan Liung | M22: =SUM('S1 TBM 1'!S225:S229) -> 0 | T22: Gorong-gorong 40 cm | U22: =SUM('S1 TBM 2'!Q253:Q255) -> 0 | AB22: Jalan Liung | AC22: =SUM('S1 TBM 3'!Q227:Q231) -> 0
D23: Pengawetan Tanah | E23: =SUM('SI TB LC'!Q139:Q147) -> 62414032 | G23: =E23/45.36 -> 1375970.7 | L23: Jembatan Permanen | M23: =SUM('S1 TBM 1'!S238:S250) -> 0 | T23: Gorong-gorong 60 CM | U23: =SUM('S1 TBM 2'!Q256:Q258) -> 0 | AB23: Jembatan Permanen | AC23: =SUM('S1 TBM 3'!Q234:Q246) -> 0
D24: Pembuatan Pasar Pikul Mekanis | E24: 0 | G24: =E24/51.1 -> 0 | L24: Gorong-gorong 40 cm | M24: =SUM('S1 TBM 1'!S254:S256) -> 0 | T24: Gorong-gorong 80 CM | U24: =SUM('S1 TBM 2'!Q259:Q261) -> 0 | AB24: Gorong-gorong 40 cm | AC24: =SUM('S1 TBM 3'!Q250:Q252) -> 0
B25: 5 | C25: Tanam Kacangan | D25: Penanaman Kacangan | E25: =SUM('SI TB LC'!Q168:Q179) -> 1.4041943e+08 | F25: =SUM(E25:E32) -> 3.6103791e+08 | G25: =F25/A3 -> 7959389.6 | H25: =F25/F49*100 -> 9.5737878 | L25: Gorong-gorong 60 CM | M25: =SUM('S1 TBM 1'!S257:S259) -> 0 | R25: 6 | S25: Pengawetan Tanah | T25: Tapak Kuda | U25: =SUM('S1 TBM 2'!Q286) -> 0 | V25: =SUM(U25:U26) -> 0 | W25: =V25/$A$3 -> 0 | X25: =V25/V39*100 -> 0 | AB25: Gorong-gorong 60 CM | AC25: =SUM('S1 TBM 3'!Q253:Q255) -> 0
D26: Pembuatan Bedengan | E26: =SUM('SI TB LC'!Q180:Q181) -> 5690815.2 | L26: Gorong-gorong 80 CM | M26: =SUM('S1 TBM 1'!S260:S262) -> 0 | T26: Tapak Timbun | U26: =SUM('S1 TBM 2'!Q288) -> 0 | AB26: Gorong-gorong 80 CM | AC26: =SUM('S1 TBM 3'!Q256:Q258) -> 0
D27: Perakitan Instalasi Air | E27: =SUM('SI TB LC'!Q192:Q193) -> 5794921.9 | J27: 6 | K27: Pengawetan Tanah | L27: Tapak Kuda | M27: =SUM('S1 TBM 1'!S287:S288) -> 16327240 | N27: =SUM(M27:M28) -> 32654480 | O27: =N27/A3 -> 719895.93 | P27: =N27/N40*100 -> 6.5203107 | R27: 7 | S27: Pengendalian Hama dan Penyakit | T27: Hama Tikus | U27: =SUM('S1 TBM 2'!Q296:Q297) -> 12463471 | V27: =SUM(U27:U29) -> 63169073 | W27: =V27/$A$3 -> 1392616.3 | X27: =V27/V39*100 -> 10.70348 | Z27: 6 | AA27: Pengawetan Tanah | AB27: Tapak Kuda | AC27: =SUM('S1 TBM 3'!Q283) -> 0 | AD27: =SUM(AC27:AC28) -> 0 | AE27: =AD27/$A$3 -> 0 | AF27: =AD27/AD41*100 -> 0
D28: Pemeliharaan Weeding Atas | E28: =SUM('SI TB LC'!Q182) -> 2029068.7 | L28: Tapak Timbun | M28: =SUM('S1 TBM 1'!S289:S290) -> 16327240 | T28: Hama Ulat Api | U28: =SUM('S1 TBM 2'!Q301:Q310) -> 580447.16 | AB28: Tapak Timbun | AC28: =SUM('S1 TBM 3'!Q285) -> 0
D29: PHPT Insek | E29: =SUM('SI TB LC'!Q183:Q186) -> 2167731.3 | J29: 7 | K29: Pengendalian Hama dan Penyakit | L29: Hama Tikus | M29: =SUM('S1 TBM 1'!S297:S298) -> 11715618 | N29: =SUM(M29:M31) -> 37230636 | O29: =N29/A3 -> 820781.21 | P29: =N29/N40*100 -> 7.4340585 | T29: Hama (Oryctes) | U29: =SUM('S1 TBM 2'!Q314:Q327) -> 50125155 | Z29: 7 | AA29: Pengendalian Hama dan Penyakit | AB29: Hama Tikus | AC29: =SUM('S1 TBM 3'!Q293:Q295) -> 13259251 | AD29: =SUM(AC29:AC31) -> 1.4274174e+08 | AE29: =AD29/$A$3 -> 3146863.8 | AF29: =AD29/AD41*100 -> 16.805029
D30: PHPT Fungi | E30: =SUM('SI TB LC'!Q187:Q189) -> 0 | L30: Hama Ulat Api | M30: =SUM('S1 TBM 1'!S303:S311) -> 546469.48 | R30: 8 | S30: Pemupukkan Kelapa Sawit | T30: Pemupukkan Hayati | U30: =SUM('S1 TBM 2'!Q340:Q348) -> 0 | V30: =SUM(U30:U36) -> 3.1309794e+08 | W30: =V30/$A$3 -> 6902511.9 | X30: =V30/V39*100 -> 53.051869 | AB30: Hama Ulat Api | AC30: =SUM('S1 TBM 3'!Q299:Q307) -> 616556.23
D31: Penyiraman Bibit | E31: =SUM('SI TB LC'!Q191) -> 2029068.7 | L31: Hama (Oryctes) | M31: =SUM('S1 TBM 1'!S316:S327) -> 24968548 | T31: Pemupukkan NPK 12-12-17-2+0,65B | U31: =SUM('S1 TBM 2'!Q360:Q368) -> 1.9735655e+08 | AB31: Hama (Oryctes) | AC31: =SUM('S1 TBM 3'!Q312:Q326) -> 1.2886593e+08
D32: Pemeliharaan Kacangan | E32: =SUM('SI TB LC'!Q194) -> 2.0290687e+08 | J32: 8 | K32: Pemupukkan Kelapa Sawit | L32: Pemupukkan NPK 12-12-17-2+0,65B | M32: =SUM('S1 TBM 1'!S341:S349) -> 1.4780624e+08 | N32: =SUM(M32:M37) -> 2.5988824e+08 | O32: =N32/A3 -> 5729458.5 | P32: =N32/N40*100 -> 51.893403 | T32: Pemupukkan Dolomite | U32: =SUM('S1 TBM 2'!Q350:Q358) -> 23105570 | Z32: 8 | AA32: Pemupukkan Kelapa Sawit | AB32: Pemupukkan Hayati | AC32: =SUM('S1 TBM 3'!Q339:Q347) -> 0 | AD32: =SUM(AC32:AC38) -> 4.80301e+08 | AE32: =AD32/$A$3 -> 10588646 | AF32: =AD32/AD41*100 -> 56.545983
B33: 6 | C33: Pemupukkan Kacangan | D33: Pemupukkan NPK Granule & RP | E33: =SUM('SI TB LC'!Q219:Q228) -> 34542666 | F33: =SUM(E33:E33) -> 34542666 | G33: =F33/A3 -> 761522.61 | H33: =F33/F49*100 -> 0.91598179 | L33: Pemupukkan Dolomite | M33: =SUM('S1 TBM 1'!S351:S359) -> 24617237 | T33: Pemupukkan Borate | U33: =SUM('S1 TBM 2'!Q370:Q378) -> 7088488.2 | AB33: Pemupukkan NPK 12-12-17-2+0,65B | AC33: =SUM('S1 TBM 3'!Q359:Q367) -> 2.4321751e+08
B34: 7 | C34: Angkutan Pupuk | D34: Angkutan Pupuk Intern | E34: =SUM('SI TB LC'!Q233:Q235) -> 422659.92 | F34: =SUM(E34:E35) -> 1540306.4 | G34: =F34/A3 -> 33957.372 | H34: =F34/F49*100 -> 0.040844925 | L34: Pemupukkan Borate | M34: =SUM('S1 TBM 1'!S361:S369) -> 4493887 | T34: Janjang Kosong & Abu Boiler | U34: =SUM('S1 TBM 2'!Q381:Q385) -> 80649103 | AB34: Pemupukkan Dolomite | AC34: =SUM('S1 TBM 3'!Q349:Q357) -> 30535773
D35: Angkutan Pupuk Ekstern | E35: =SUM('SI TB LC'!Q236:Q237) -> 1117646.4 | L35: Janjang Kosong & Abu Boiler | M35: =SUM('S1 TBM 1'!S371:S380) -> 79704830 | T35: Pengangkutan Pupuk Intern | U35: =SUM('S1 TBM 2'!Q397:Q399) -> 3634398.3 | AB35: Pemupukkan Borate | AC35: =SUM('S1 TBM 3'!Q369:Q377) -> 7339625.1
B36: 8 | C36: Tanam Pokok Sawit | D36: Memancang | E36: =SUM('SI TB LC'!Q241:Q242) -> 20938428 | F36: =SUM(E36:E39) -> 7.2468925e+08 | G36: =F36/A3 -> 15976394 | H36: =F36/F49*100 -> 19.216877 | L36: Pengangkutan Pupuk Intern | M36: =SUM('S1 TBM 1'!S387:S389) -> 2407372.4 | T36: Pengangkutan Pupuk Ekstern | U36: =SUM('S1 TBM 2'!Q400) -> 1263824.1 | AB36: Janjang Kosong & Abu Boiler | AC36: =SUM('S1 TBM 3'!Q379:Q383) -> 1.9216075e+08
D37: Pupuk Lubang Tanam | E37: =SUM('SI TB LC'!Q245:Q253) -> 42936611 | L37: Pengangkutan Pupuk Ekstern | M37: =SUM('S1 TBM 1'!S390) -> 858670.45 | R37: 9 | S37: Pengawasan dan Administrasi | T37: Pengawasan | U37: =SUM('S1 TBM 2'!Q418:Q421) -> 19175717 | V37: =SUM(U37:U38) -> 24786747 | W37: =V37/$A$3 -> 546445.04 | X37: =V37/V39*100 -> 4.1999103 | AB37: Pengangkutan Pupuk Intern | AC37: =SUM('S1 TBM 3'!Q395:Q397) -> 5263293.3
D38: ='SI TB LC'!D243 -> Pengawetan Tanah Tanah Titik Tanam | E38: =SUM('SI TB LC'!Q243:Q244) -> 2.8111533e+08 | J38: 9 | K38: Pengawasan dan Administrasi | L38: Pengawasan | M38: =SUM('S1 TBM 1'!S408:S410) -> 18015620 | N38: =SUM(M38:M39) -> 23297717 | O38: =N38/A3 -> 513618.11 | P38: =N38/N40*100 -> 4.6519913 | T38: Administrasi | U38: =SUM('S1 TBM 2'!Q422:Q423) -> 5611030.5 | AB38: Pengangkutan Pupuk Ekstern | AC38: =SUM('S1 TBM 3'!Q398) -> 1784048.6
D39: Penanaman Kelapa Sawit | E39: =SUM('SI TB LC'!Q254:Q258) -> 3.7969888e+08 | L39: Administrasi | M39: =SUM('S1 TBM 1'!S412:S413) -> 5282096.9 | R39: Total | V39: =SUM(V5:V38) -> 5.9017324e+08 | Z39: 9 | AA39: Pengawasan dan Administrasi | AB39: Pengawasan | AC39: =SUM('S1 TBM 3'!Q416:Q419) -> 20410673 | AD39: =SUM(AC39:AC40) -> 26371297 | AE39: =AD39/$A$3 -> 581377.81 | AF39: =AD39/AD41*100 -> 3.1047009
B40: 9 | C40: Pemupukkan Kelapa Sawit | D40: Pemupukkan Urea | E40: =SUM('SI TB LC'!$Q$285:$Q$293) -> 7430391 | F40: =SUM(E40:E41) -> 17093168 | G40: =F40/A3 -> 376833.52 | H40: =F40/F49*100 -> 0.45326644 | J40: Total | N40: =SUM(N5:N39) -> 5.0081171e+08 | R40: Rp/HA | V40: =V39/$A$3 -> 13010874 | AB40: Administrasi | AC40: =SUM('S1 TBM 3'!Q420:Q422) -> 5960624.6
D41: Aplikasi Abu Boiler | E41: =SUM('SI TB LC'!Q319:Q323) -> 9662777.5 | J41: Rp/HA | N41: =N40/A3 -> 11040823 | Z41: Total | AD41: =SUM(AD5:AD40) -> 8.4939897e+08
...

Sheet SI TB LC
D1: Luas: | E1: 45.36
B2: Pekerjaan | F2: Material | H2: Rotasi APD | J2: TB/LC | P2: 2026 | R2: 2026 | T2: 2027 | V2: Rata-rata | X2: Keterangan | Y2: BIAYA/HA | Z2: Biaya/pkk | AA2: Rp/Ha | AB2: Persentase (%)
F3: Jenis | G3: Sat | J3: Sat | K3: Vol | M3: Norma | N3: Rotasi | O3: Jumlah Unit | P3: Rp Sat | Q3: Jumlah RP | R3: Rp Sat | S3: Jumlah RP | T3: Rp Sat | U3: Jumlah RP | V3: Rp Sat | W3: Jumlah RP
K4: % | L4: Luas/Mtr/Pkk/Unit
B5: PEMBUKAAN LAHAN
C6: IMAS,TUMBANG, PERUN
D7: Identifikasi Blok | F7: Upah PHL | G7: HK | J7: Ha | K7: 1 | L7: 45.36 | M7: 0.25 | N7: 1 | O7: =K7*L7*M7*N7 -> 11.34 | P7: 149108.52 | Q7: =P7*$O7 -> 1690890.6 | R7: 149108.52 | S7: =R7*$O7 -> 1690890.6 | T7: 158800.57 | U7: =T7*$O7 -> 1800798.5 | V7: =W7/O7 -> 152339.2 | W7: =AVERAGEIF($P$3:$U$3,W$3,$P7:$U7) -> 1727526.6 | AA7: =Q7/$E$1 -> 37277.13
F8: Cat | G8: Kg | N8: 1
F9: Kuas | G9: Buah | N9: 1
F10: Kompas | G10: Buah | M10: 0.0007 | N10: 1
F11: GPS | G11: Buah | M11: 0.0013 | N11: 1
D12: Imas | E12: Hutan Primer | F12: Upah PHL | G12: HK | M12: 10 | N12: 1 | X12: Vol sesuai kondisi
E13: Hutan Sekunder | F13: Upah PHL | G13: HK | M13: 10 | N13: 1 | P13: 140008
E14: Semak Belukar | F14: Upah PHL | G14: HK
D15: Tumbang | E15: Hutan Primer | F15: Upah PHL | G15: HK | M15: 20 | N15: 1 | X15: Vol sesuai kondisi
E16: Hutan Sekunder | F16: Upah PHL | G16: HK | M16: 12 | N16: 1
D17: Cincang | E17: Hutan Primer | F17: Upah PHL | G17: HK
E18: Hutan Sekunder | F18: Upah PHL | G18: HK
D19: Perun Mekanis | E19: Hutan Primer | F19: Buldozer 1 | G19: HM | M19: 6 | N19: 1 | X19: Vol sesuai kondisi
E20: Hutan Sekunder | F20: Buldozer 1 | G20: HM | K20: 100 | M20: 5 | N20: 1 | O20: =K20*L20*M20*N20 -> 0 | P20: 993170.33 | Q20: =P20*$O20 -> 0
E21: Semak Belukar | F21: Buldozer 1 | G21: HM | M21: 4 | N21: 1
E22: Reklamasi | F22: Buldozer 1 | G22: HM | K22: 1 | L22: 45.36 | M22: 47.5 | N22: 1 | O22: =K22*L22*M22*N22 -> 2154.6 | P22: 1051433.7 | Q22: =O22*P22 -> 2.265419e+09 | AA22: =Q22/$E$1 -> 49943100
D23: Pengolahan Tanah (Ripping) | F23: Buldozer 1 | G23: HM | J23: HM/Ha | K23: 0 | L23: 140.98 | M23: 2.5 | N23: 1 | O23: =K23*L23*M23*N23 -> 0 | P23: 993170.33 | Q23: =P23*$O23 -> 0 | R23: 1051433.7 | S23: =R23*$O23 -> 0 | T23: 1113470.8 | U23: =T23*$O23 -> 0 | V23: =W23/O23 -> #DIV/0! | W23: =AVERAGEIF($P$3:$U$3,W$3,$P23:$U23) -> 0 | X23: 3 HM/HA Penggemburan Tanah dan Pemutusan Akar, total rupiah sudah termasuk harga sewa alat dan BBM | Y23: =Q23/L23 -> 0 | AA23: =(Q23+Q24+Q25)/35.245 -> 0 | AD23: =92518125/35.245 -> 2625000
F24: Upah PHL | G24: HK | J24: Ha | K24: 1 | L24: =O23/10 -> 0 | M24: =3*2 -> 6 | N24: 1 | O24: =K24*L24*M24*N24 -> 0 | P24: 140008 | Q24: =P24*$O24 -> 0 | X24: Waker Alat
F25: Angkutan Material | G25: RIT | K25: 1 | L25: =(O23*25)/400 -> 0 | M25: 2 | N25: 1 | O25: =K25*L25*M25*N25 -> 0 | P25: 198400 | Q25: =P25*$O25 -> 0 | X25: Angkut BBM
D26: Tumbang Chipping
E27: Pancang Chiping | F27: Upah PHL | G27: HK | J27: Ha | K27: 1 | L27: 0 | M27: 1 | N27: 1 | O27: =K27*L27*M27*N27 -> 0 | P27: 140008 | Q27: =P27*$O27 -> 0 | R27: 149108.52 | S27: =R27*$O27 -> 0 | T27: 158800.57 | U27: =T27*$O27 -> 0 | V27: =W27/O27 -> #DIV/0! | W27: =AVERAGEIF($P$3:$U$3,W$3,$P27:$U27) -> 0 | X27: Pemancangan Titik Rumpuk Hasil Chippingan
E28: Tumbang Chiping | F28: Excavator 1 | G28: HM | J28: HM/Ha | K28: 1 | L28: 0 | M28: 10.8 | N28: 1 | O28: =K28*L28*M28*N28 -> 0 | P28: 681487.18 | Q28: =P28*$O28 -> 0 | R28: 720338.07 | S28: =R28*$O28 -> 0 | T28: 761671.7 | U28: =T28*$O28 -> 0 | V28: =W28/O28 -> #DIV/0! | W28: =AVERAGEIF($P$3:$U$3,W$3,$P28:$U28) -> 0 | X28: 12 Pokok/HM, Total rupiah sudah termasuk harga sewa alat dan BBM | Y28: =Q28/192.08 -> 0 | Z28: =Y28/122 -> 0 | AD28: =AA28/136 -> 0
F29: Upah PHL | G29: HK | J29: Ha | K29: 1 | L29: =O28/10 -> 0 | M29: =3*4 -> 12 | N29: 1 | O29: =K29*L29*M29*N29 -> 0 | P29: 140008 | Q29: =P29*$O29 -> 0 | X29: Waker Alat 4 Orang, 2 Alat
F30: Angkutan Material | G30: RIT | K30: 1 | L30: =(O28*18)/400 -> 0 | M30: 2 | N30: 1 | O30: =K30*L30*M30*N30 -> 0 | P30: 198400 | Q30: =P30*$O30 -> 0 | X30: Angkut Solar
E31: Aplikasi Metharizium | F31: Upah PHL | G31: HK | J31: Ha | K31: 0 | L31: 140.98 | M31: 0.5 | N31: 1 | O31: =K31*L31*M31*N31 -> 0 | P31: 140008 | Q31: =P31*$O31 -> 0
F32: Metharizium | G32: Kg | J32: Kg | K32: 0 | L32: 140.98 | M32: 24 | N32: 1 | O32: =K32*L32*M32*N32 -> 0 | P32: 67000 | Q32: =P32*$O32 -> 0 | R32: 70350 | S32: =R32*$O32 -> 0 | T32: 73867.5 | U32: =T32*$O32 -> 0 | V32: =W32/O32 -> #DIV/0! | W32: =AVERAGEIF($P$3:$U$3,W$3,$P32:$U32) -> 0
D33: Parit CECT | F33: Excavator 1 | G33: HM | J33: HM/Ha | K33: 1 | L33: 0 | M33: 8.5 | N33: 1 | O33: =K33*L33*M33*N33 -> 0 | P33: 681487.18 | Q33: =P33*$O33 -> 0 | X33: Total rupiah sudah termasuk harga sewa alat, dan BBM | AE33: =AB33/600 -> 0
F34: Upah PHL | G34: HK | J34: Ha | K34: 1 | L34: =O33/10 -> 0 | M34: =3*2 -> 6 | N34: 1 | O34: =K34*L34*M34*N34 -> 0 | P34: 140008 | Q34: =P34*$O34 -> 0 | X34: Waker Alat
F35: Angkutan Material | G35: RIT | J35: RIT | K35: 1 | L35: =(O33*18)/400 -> 0 | M35: 2 | N35: 1 | O35: =K35*L35*M35*N35 -> 0 | P35: 198400 | Q35: =P35*$O35 -> 0 | X35: Angkut Solar
D36: Tutup Lubang CECT dan Perataan Tanah | F36: Excavator 1 | G36: HM | J36: HM/Ha | K36: 1 | L36: 0 | M36: =600/60 -> 10 | N36: 1 | O36: =K36*L36*M36*N36 -> 0 | P36: 681487.18 | Q36: =P36*$O36 -> 0 | R36: 720338.07 | S36: =R36*$O36 -> 0 | T36: 761671.7 | U36: =T36*$O36 -> 0 | V36: =W36/O36 -> #DIV/0! | W36: =AVERAGEIF($P$3:$U$3,W$3,$P36:$U36) -> 0 | X36: Total rupiah sudah termasuk harga sewa alat, dan BBM | AE36: =AA36/600 -> 0
F37: Upah PHL | G37: HK | J37: Ha | K37: 1 | L37: =O36/10 -> 0 | M37: =3*2 -> 6 | N37: 1 | O37: =K37*L37*M37*N37 -> 0 | P37: 140008 | Q37: =P37*$O37 -> 0 | X37: Waker Alat 2 Orang
F38: Angkutan Material | G38: RIT | J38: RIT | K38: 1 | L38: =(O36*18)/400 -> 0 | M38: 2 | N38: 1 | O38: =K38*L38*M38*N38 -> 0 | P38: 198400 | Q38: =P38*$O38 -> 0 | X38: Angkut Solar
D39: Lubang Tanam Mekanis/Auger
E40: Pancang Kepala | F40: Upah PHL | G40: HK | K40: 1 | L40: 45.36 | M40: 0.25 | N40: 1 | O40: =K40*L40*M40*N40 -> 11.34 | P40: 149108.52 | Q40: =P40*$O40 -> 1690890.6 | R40: 149108.52 | S40: =R40*$O40 -> 1690890.6 | T40: 158800.57 | U40: =T40*$O40 -> 1800798.5 | V40: =W40/O40 -> 152339.2 | W40: =AVERAGEIF($P$3:$U$3,W$3,$P40:$U40) -> 1727526.6 | X40: Pancang Kepala 1 HK = 4 HA | Y40: =Q40/L40 -> 37277.13 | AA40: =Q40/$E$1 -> 37277.13
...

Sheet S1 TBM 1
C1: Luas: | D1: 45.36
B2: Pekerjaan | F2: Material | H2: Rotasi APD | J2: TBM 1 | P2: 2025 | R2: 2027 | T2: 2027 | V2: Rata-rata | Y2: Rp/Ha | Z2: Persentase (%)
F3: Jenis | G3: Sat | J3: Sat | K3: Vol | M3: Norma | N3: Rotasi | O3: Jumlah Unit | P3: Rp Sat | Q3: Jumlah RP | R3: Rp Sat | S3: Jumlah RP | T3: Rp Sat | U3: Jumlah RP | V3: Rp Sat | W3: Jumlah RP | X3: Keterangan
K4: % | L4: Luas/Mtr/Pkk/Unit
B5: TANAM KACANGAN
C6: Tanam Kacangan | F6: Upah PHL | G6: HK | M6: 6.5 | N6: 1
F7: PJ | G7: Kg | M7: 3 | N7: 1
F8: CM | G8: Kg | M8: 6 | N8: 1
F9: MB (Mocuna Bracteata) | G9: Kg | M9: 0.25 | N9: 1
F10: Rizhobium | G10: Kg | M10: 0.01 | N10: 1
F11: Rock Phosphate | G11: Kg | M11: 2 | N11: 1
F12: Sepatu Boots | G12: Buah | H12: 1 | I12: X | M12: =((M$6*N$6)/240*($H12/N12)) -> 0.027083333 | N12: 1
C13: Pemeliharaan Kacangan | F13: Upah PHL | G13: HK | M13: 4 | N13: 3
C14: Bongkar Tumbuhan Pengganggu | F14: Upah PHL | G14: HK | M14: 2 | N14: 1
F15: Glyphosate | G15: Liter | M15: 1.2 | N15: 1
F16: Metil Metsulfuron | G16: Kg | M16: =48/1000 -> 0.048 | N16: 1
F17: Perekat | G17: Liter | M17: 0.288 | N17: 1
F18: Sprayer | G18: Buah | M18: 0.007 | N18: 1
F19: Premi Extra Fooding | G19: HK | M19: 2 | N19: 1
F20: Celemek | G20: Buah | H20: 4 | I20: X | M20: =((M$14*N$14)/240*($H20/N20)) -> 0.033333333 | N20: 1
F21: Masker Chemical | G21: Buah | H21: 12 | I21: X | M21: =((M$14*N$14)/240*($H21/N21)) -> 0.1 | N21: 1
F22: Kaca mata | G22: Buah | H22: 1 | I22: X | M22: =((M$14*N$14)/240*($H22/N22)) -> 0.0083333333 | N22: 1
F23: Sarung Tangan Karet | G23: Buah | H23: 2 | I23: X | M23: =((M$14*N$14)/240*($H23/N23)) -> 0.016666667 | N23: 1
F24: Sepatu Boots | G24: Buah | H24: 1 | I24: X | M24: =((M$14*N$14)/240*($H24/N24)) -> 0.0083333333 | N24: 1
C25: Pemberantasan Lalang | F25: Upah PHL | G25: HK | M25: 1 | N25: 1
F26: Glyphosate | G26: Liter | M26: 1.08 | N26: 1
F27: Perekat | G27: Liter | M27: 0.18 | N27: 1
F28: Sprayer | G28: Buah | M28: 0.004 | N28: 1
F29: Premi Extra Fooding | G29: HK | M29: 1 | N29: 1
F30: Celemek | G30: Buah | H30: 4 | I30: X | M30: =((M$25*N$25)/240*($H30/N30)) -> 0.016666667 | N30: 1
F31: Masker | G31: Buah | H31: 12 | I31: X | M31: =((M$25*N$25)/240*($H31/N31)) -> 0.05 | N31: 1
F32: Kaca mata | G32: Buah | H32: 1 | I32: X | M32: =((M$25*N$25)/240*($H32/N32)) -> 0.0041666667 | N32: 1
F33: Sarung Tangan Karet | G33: Buah | H33: 2 | I33: X | M33: =((M$25*N$25)/240*($H33/N33)) -> 0.0083333333 | N33: 1
F34: Sepatu Boots | G34: Buah | H34: 1 | I34: X | M34: =((M$25*N$25)/240*($H34/N34)) -> 0.0041666667 | N34: 1
B35: SUB TOTAL TANAMAN KACANGAN | S35: =SUM(S6:S34) -> 0
B36: TANAMAN BELUM MENGHASILKAN
B37: PEMBUATAN PIRINGAN, PASAR RINTIS, TPH DAN TITI PASAR RINTIS
C38: Pembuatan Piringan | F38: Upah PHL | G38: HK | J38: Ha | K38: 1 | L38: 45.36 | M38: 2.5 | N38: 1 | O38: =K38*L38*M38*N38 -> 113.4 | P38: 140008 | Q38: =P38*$O38 -> 15876907 | R38: 158800.57 | S38: =R38*$O38 -> 18007985 | T38: 163305.33 | U38: =$O38*T38 -> 18518825 | V38: =W38/O38 -> 154037.97 | W38: =AVERAGEIF($P$3:$U$3,W$3,$P38:$U38) -> 17467906 | Y38: =S38/$D$1 -> 397001.43
F39: Cangkul | G39: Buah | K39: 1 | L39: 45.36 | M39: 0.01 | N39: 1 | O39: =K39*L39*M39*N39 -> 0.4536 | R39: 83568.122 | S39: =R39*$O39 -> 37906.5 | Y39: =S39/$D$1 -> 835.68122
F40: Sepatu Boots | G40: Buah | K40: 1 | L40: 45.36 | M40: 0.01 | N40: 1 | O40: =K40*L40*M40*N40 -> 0.4536 | R40: 94462.2 | S40: =R40*$O40 -> 42848.054 | Y40: =S40/$D$1 -> 944.622
...

Sheet S1 TBM 2
C1: Luas: | D1: 45.36
B2: Pekerjaan | F2: Material | H2: Rotasi APD | J2: TBM 2 | P2: 2028 | R2: 2028 | T2: 2029 | V2: Rata-rata | Y2: Rp/Ha | Z2: Persentase (%)
F3: Jenis | G3: Sat | J3: Sat | K3: Vol | M3: Norma | N3: Rotasi | O3: Jumlah Unit | P3: Rp Sat | Q3: Jumlah RP | R3: Rp Sat | S3: Jumlah RP | T3: Rp Sat | U3: Jumlah RP | V3: Rp Sat | W3: Jumlah RP | X3: Keterangan
K4: % | L4: Luas/Mtr/Pkk/Unit
B5: TANAM KACANGAN
C6: Tanam Kacangan | F6: Upah PHL | G6: HK
F7: PJ | G7: Kg
F8: CM | G8: Kg
F9: MB (Mocuna Bracteata) | G9: Kg
F10: Rizhobium | G10: Kg
F11: Rock Phosphate | G11: Kg
F12: Sepatu Boots | G12: Buah | H12: 1 | I12: X
C13: Pemeliharaan Kacangan | F13: Upah PHL | G13: HK
C14: Bongkar Tumbuhan Pengganggu | F14: Upah PHL | G14: HK
F15: Glyphosate | G15: Liter
F16: Metil Metsulfuron | G16: Kg
F17: Perekat | G17: Liter
F18: Sprayer | G18: Buah
F19: Premi Extra Fooding | G19: HK
F20: Celemek | G20: Buah | H20: 4 | I20: X
F21: Masker Chemical | G21: Buah | H21: 12 | I21: X
F22: Kaca mata | G22: Buah | H22: 1 | I22: X
F23: Sarung Tangan Karet | G23: Buah | H23: 2 | I23: X
F24: Sepatu Boots | G24: Buah | H24: 1 | I24: X
C25: Pemberantasan Lalang | F25: Upah PHL | G25: HK
F26: Glyphosate | G26: Liter
F27: Perekat | G27: Liter
F28: Sprayer | G28: Buah
F29: Premi Extra Fooding | G29: HK
F30: Celemek | G30: Buah | H30: 4 | I30: X
F31: Masker | G31: Buah | H31: 12 | I31: X
F32: Kaca mata | G32: Buah | H32: 1 | I32: X
F33: Sarung Tangan Karet | G33: Buah | H33: 2 | I33: X
F34: Sepatu Boots | G34: Buah | H34: 1 | I34: X
B35: SUB TOTAL TANAMAN KACANGAN | Q35: =SUM(Q6:Q34) -> 0 | S35: =SUM(S6:S34) -> 0
B36: TANAMAN BELUM MENGHASILKAN
B37: PEMBUATAN PIRINGAN, PASAR RINTIS, TPH DAN TITI PASAR RINTIS
C38: Pembuatan Piringan | F38: Upah PHL | G38: HK | O38: =K38*L38*M38*N38 -> 0 | P38: 151208.64 | Q38: =P38*$O38 -> 0 | R38: 163305.33 | S38: =R38*$O38 -> 0 | T38: 179635.86 | U38: =$O38*T38 -> 0 | V38: =W38/O38 -> #DIV/0! | W38: =AVERAGEIF($P$3:$U$3,W$3,$P38:$U38) -> 0
F39: Cangkul | G39: Buah
F40: Sepatu Boots | G40: Buah
...

Sheet S1 TBM 3
C1: Luas: | D1: 45.36
B2: Pekerjaan | F2: Material | H2: Rotasi APD | J2: TBM 3 | P2: 2029 | R2: 2029 | T2: 2029 | V2: Rata-rata | Y2: Rp/Ha | Z2: Persentase (%)
F3: Jenis | G3: Sat | J3: Sat | K3: Vol | M3: Norma | N3: Rotasi | O3: Jumlah Unit | P3: Rp Sat | Q3: Jumlah RP | R3: Rp Sat | S3: Jumlah RP | T3: Rp Sat | U3: Jumlah RP | V3: Rp Sat | W3: Jumlah RP | X3: Keterangan
K4: % | L4: Luas/Mtr/Pkk/Unit
B5: TANAM KACANGAN
C6: Tanam Kacangan | F6: Upah PHL | G6: HK
F7: PJ | G7: Kg
F8: CM | G8: Kg
F9: MB (Mocuna Bracteata) | G9: Kg
F10: Rizhobium | G10: Kg
F11: Rock Phosphate | G11: Kg
F12: Sepatu Boots | G12: Buah | H12: 1 | I12: X
C13: Pemeliharaan Kacangan | F13: Upah PHL | G13: HK
C14: Bongkar Tumbuhan Pengganggu | F14: Upah PHL | G14: HK
F15: Glyphosate | G15: Liter
F16: Metil Metsulfuron | G16: Kg
F17: Perekat | G17: Liter
F18: Sprayer | G18: Buah
F19: Premi Extra Fooding | G19: HK
F20: Celemek | G20: Buah | H20: 4 | I20: X
F21: Masker Chemical | G21: Buah | H21: 12 | I21: X
F22: Kaca mata | G22: Buah | H22: 1 | I22: X
F23: Sarung Tangan Karet | G23: Buah | H23: 2 | I23: X
F24: Sepatu Boots | G24: Buah | H24: 1 | I24: X
C25: Pemberantasan Lalang | F25: Upah PHL | G25: HK
F26: Glyphosate | G26: Liter
F27: Perekat | G27: Liter
F28: Sprayer | G28: Buah
F29: Premi Extra Fooding | G29: HK
F30: Celemek | G30: Buah | H30: 4 | I30: X
F31: Masker | G31: Buah | H31: 12 | I31: X
F32: Kaca mata | G32: Buah | H32: 1 | I32: X
F33: Sarung Tangan Karet | G33: Buah | H33: 2 | I33: X
F34: Sepatu Boots | G34: Buah | H34: 1 | I34: X
B35: SUB TOTAL TANAM KACANGAN | Q35: =SUM(Q6:Q34) -> 0 | S35: =SUM(S24:S34) -> 0
B36: TANAMAN BELUM MENGHASILKAN
B37: PEMBUATAN PIRINGAN, PASAR RINTIS, TPH DAN TITI PASAR RINTIS
C38: Pembuatan Piringan | F38: Upah PHL | G38: HK | O38: =K38*L38*M38*N38 -> 0 | P38: 169122.61 | Q38: =P38*$O38 -> 0 | R38: 179635.86 | S38: =R38*$O38 -> 0 | T38: 197599.45 | U38: =$O38*T38 -> 0 | V38: =W38/O38 -> #DIV/0! | W38: =AVERAGEIF($P$3:$U$3,W$3,$P38:$U38) -> 0
F39: Cangkul | G39: Buah
F40: Sepatu Boots | G40: Buah
...
